Workbook
Name MN_DBT: SoLieu!$B$6
Name MN_LTK: SoLieu!$B$7
Name MN_LKT: SoLieu!$B$8
Name Z_day: SoLieu!$B$9
Name g_: SoLieu!$B$10
Name a_1: SoLieu!$B$14
Name a_2: SoLieu!$B$15
Name a_3: SoLieu!$B$16
Name t_gio: SoLieu!$B$20
Name k_fl: SoLieu!$B$21
Name D_1: SoLieu!$B$22
Name D_2: SoLieu!$B$23
Name m_TL: SoLieu!$B$24
Name Delta_n: SoLieu!$B$25
Name PT_mai: SoLieu!$B$26
Name Z_dinh_HT: SoLieu!$B$30
Name Z_tuong: SoLieu!$B$31
Name Z_dinh_SC: SoLieu!$B$32
Name dZ_LKT: SoLieu!$B$33
Name dZ_tuong: SoLieu!$B$34
Name Gio_ma: SoLieu!$B$38:$B$45
Name Gio_az: SoLieu!$C$38:$C$45
Name Gio_V4: SoLieu!$D$38:$D$45
Name Gio_V50: SoLieu!$E$38:$E$45
Name KL_V: SoLieu!$B$50:$H$50
Name KL_k: SoLieu!$B$51:$H$51
Name KA_goc: SoLieu!$B$54:$H$54
Name KA_k: SoLieu!$B$55:$H$55
Name KR_x: SoLieu!$B$58:$G$58
Name KR_kr: SoLieu!$B$59:$G$59
Name KP_x: SoLieu!$B$62:$G$62
Name KP_kp: SoLieu!$B$63:$G$63
Name KSP_V: SoLieu!$B$66:$D$66
Name KSP_k: SoLieu!$B$67:$D$67
Name K1_x: SoLieu!$B$70:$G$70
Name K1_k: SoLieu!$B$71:$G$71
Name K1_lg: SoLieu!$B$72:$G$72
Name KRUN_x: SoLieu!$B$75:$H$75
Name KRUN_k: SoLieu!$B$76:$H$76
Name Z_yc: KetQua!$B$9

Sheet HuongDan
B1: XÁC ĐỊNH CAO TRÌNH ĐỈNH ĐẬP HỒ CÀ GIÂY – TCVN 8216:2018 VÀ TCVN 8421:2010
B2: Mọi ô kết quả là công thức. Sửa mực nước, gió, đà gió, cao trình công trình ở sheet SoLieu (ô nền vàng chữ xanh).
B3: 1. Ba trường hợp (TCVN 8216:2018)
B4: Z₁ = MNDBT + Δh + hsl + a Z₂ = MNLTK + Δh′ + h′sl + a′ Z₃ = MNLKT + a″
B5: • Gió tính sóng (Bảng 4, công trình cấp II): ở MNDBT – vận tốc gió lớn nhất tần suất P = 4%; ở MNLTK – vận tốc gió bình quân lớn nhất P = 50%; ở MNLKT không xét sóng do gió. Độ vượt cao an toàn (Bảng 3, cấp II): a = 0,7 m; a′ = 0,5 m; a″ = 0,2 m. Cao trình đỉnh đập yêu cầu Zđ = max(Z₁; Z₂; Z₃).
B6: • Điều 10.1.5 – đập có tường chắn sóng thẳng đứng liên kết với bộ phận chống thấm: độ vượt cao tính đến đỉnh tường (đỉnh tường ≥ Zđ); đỉnh đập không kể tường ≥ MNLKT + 0,3 m; tường cao hơn đỉnh đập không quá 1,2 m.
B7: 2. Độ dềnh do gió và sóng leo (TCVN 8421:2010)
B8: Δh = kw·V²·D/(g·H)·cos α , kw = 3·10⁻⁷·(1 + 0,3·V)
B9: gh̄/V² = 0,16·[1 − (1 + 0,006·√(gD/V²))⁻²] ; gτ̄/V = 19,1·(gh̄/V²)^0,625 ; λ̄ = gτ̄²/(2π)
B10: hsl1% = kr·kp·ksp·krun·kα·h1% ; h1% = K1%·h̄
B11: • V = Vw = kfl·kl·Vl – vận tốc gió tính toán ở độ cao 10 m trên mặt nước (Phụ lục A, A.3.3): Vl – gió trạm Phan Thiết (Bảng 1.4 thuyết minh), kl – Bảng A3 (địa hình dạng A, vùng ven biển trống trải), kfl = 1 (thiên an toàn).
B12: • Sóng nước sâu (H > 0,5λ̄): gh̄/V² và gτ̄/V theo đường bao trên của đồ thị (Hình 1) – tính theo công thức xấp xỉ, với điều kiện đà gió (gD/V²) và điều kiện thời gian gió thổi t = 6 giờ (gt/V), lấy giá trị nhỏ hơn.
... B19: • KetQua: Z₁, Z₂, Z₃ theo hướng gió, Zđ = max, đánh giá đỉnh đập hiện trạng và sau sửa chữa theo điều 10.1.5; bảng in theo mẫu Bảng 2.4 (gió Bắc).

Sheet SoLieu
A1: SỐ LIỆU ĐẦU VÀO – CAO TRÌNH ĐỈNH ĐẬP
A2: Ô nền vàng chữ xanh: được sửa. Chữ đen: công thức.
A4: A. MỰC NƯỚC HỒ
A5: Thông số | B5: Giá trị | C5: Đơn vị | D5: Ghi chú, nguồn
A6: Mực nước dâng bình thường MNDBT | B6: 74.7 | C6: m
A7: Mực nước lũ thiết kế MNLTK (P = 1%) | B7: 77.43 | C7: m | D7: Điều tiết lũ QTVH 72 giờ, vận hành bình thường (DieuTietLu_Potapov – KetQua)
A8: Mực nước lũ kiểm tra MNLKT (P = 0,2%) | B8: 78.39 | C8: m | D8: Như trên
A9: Cao trình đáy hồ trước đập | B9: 59 | C9: m | D9: Tính chiều sâu nước H = Z − Z đáy (H = 15,70 m ở MNDBT)
A10: Gia tốc trọng trường g | B10: 9.81 | C10: m/s²
A12: B. ĐỘ VƯỢT CAO AN TOÀN – TCVN 8216:2018 Bảng 3, đập cấp II
A13: Thông số | B13: Giá trị | C13: Đơn vị | D13: Ghi chú, nguồn
A14: a – trường hợp MNDBT | B14: 0.7 | C14: m
A15: a′ – trường hợp MNLTK | B15: 0.5 | C15: m
A16: a″ – trường hợp MNLKT | B16: 0.2 | C16: m
A18: C. GIÓ, SÓNG VÀ MÁI ĐẬP
A19: Thông số | B19: Giá trị | C19: Đơn vị | D19: Ghi chú, nguồn
A20: Thời gian gió thổi t | B20: 6 | C20: giờ | D20: Điều kiện thời gian khi tính sóng
A21: Hệ số quy đổi số liệu phong tiêu kfl | B21: 1 | D21: TCVN 8421:2010 A.3.3 – lấy bằng 1 (thiên an toàn)
A22: Đà gió D khi hồ ở MNDBT | B22: 2970 | C22: m | D22: Như Bảng 2.4 (bản trước); dùng cho mọi hướng – thiên an toàn
A23: Đà gió D khi hồ ở MNLTK | B23: 3025 | C23: m | D23: Như trên (ứng với MNLTK +77,43 của hồ sơ BCNCKT)
A24: Hệ số mái thượng lưu m | B24: 3 | D24: Bảng ksp dưới đây dùng hàng m = 3 ÷ 5
A25: Độ nhám lớp gia cố mái Δ | B25: 0.02 | C25: m | D25: Mái gia cố đá xây
A26: Phương vị pháp tuyến mái thượng lưu | B26: 6.2 | C26: ° | D26: Tuyến đập N96,2°E, lòng hồ phía Bắc
A28: D. CAO TRÌNH CÔNG TRÌNH (đánh giá theo TCVN 8216:2018 điều 10.1.5)
A29: Thông số | B29: Giá trị | C29: Đơn vị | D29: Ghi chú, nguồn
A30: Đỉnh đập hiện trạng (hồ sơ thiết kế) | B30: 78.5 | C30: m | D30: Khảo sát đo +78,32 ÷ +78,44 – chỉ để đối chiếu
A31: Đỉnh tường chắn sóng | B31: 79.4 | C31: m | D31: Tường chắn sóng thẳng đứng phía thượng lưu – giữ nguyên
A32: Đỉnh đập sau sửa chữa | B32: 78.85 | C32: m | D32: Phương án chọn của đồ án
A33: Đỉnh đập không kể tường cao hơn MNLKT tối thiểu | B33: 0.3 | C33: m | D33: Điều 10.1.5
A34: Tường cao hơn đỉnh đập tối đa | B34: 1.2 | C34: m | D34: Điều 10.1.5
A36: E. VẬN TỐC GIÓ LỚN NHẤT THEO HƯỚNG – TRẠM PHAN THIẾT (Bảng 1.4 thuyết minh), m/s | H36: Tần suất gió theo TCVN 8216:2018 Bảng 4 (cấp II): MNDBT – P = 4%; MNLTK – P = 50% (gió bình quân lớn nhất); MNLKT – không xét sóng.
A37: Hướng gió | B37: Mã | C37: Phương vị (°) | D37: V P = 4% | E37: V P = 50% | F37: Góc tới α (°) | G37: Thổi vào mái TL (α ≤ 60°)?
A38: Bắc | B38: N | C38: 0 | D38: 13.8 | E38: 7.6 | F38: =ABS(MOD(C38-PT_mai+180,360)-180) | G38: =IF(F38<=60,"Có – tính","Không")
A39: Đông Bắc | B39: NE | C39: 45 | D39: 18.6 | E39: 11.9 | F39: =ABS(MOD(C39-PT_mai+180,360)-180) | G39: =IF(F39<=60,"Có – tính","Không")
A40: Đông | B40: E | C40: 90 | D40: 20.9 | E40: 15.2 | F40: =ABS(MOD(C40-PT_mai+180,360)-180) | G40: =IF(F40<=60,"Có – tính","Không")
A41: Đông Nam | B41: SE | C41: 135 | D41: 15.8 | E41: 11.4 | F41: =ABS(MOD(C41-PT_mai+180,360)-180) | G41: =IF(F41<=60,"Có – tính","Không")
A42: Nam | B42: S | C42: 180 | D42: 15.6 | E42: 11 | F42: =ABS(MOD(C42-PT_mai+180,360)-180) | G42: =IF(F42<=60,"Có – tính","Không")
A43: Tây Nam | B43: SW | C43: 225 | D43: 18.9 | E43: 13 | F43: =ABS(MOD(C43-PT_mai+180,360)-180) | G43: =IF(F43<=60,"Có – tính","Không")
A44: Tây | B44: W | C44: 270 | D44: 20.3 | E44: 14.5 | F44: =ABS(MOD(C44-PT_mai+180,360)-180) | G44: =IF(F44<=60,"Có – tính","Không")
A45: Tây Bắc | B45: NW | C45: 315 | D45: 15.6 | E45: 8.9 | F45: =ABS(MOD(C45-PT_mai+180,360)-180) | G45: =IF(F45<=60,"Có – tính","Không")
...

Sheet TinhSong
A1: TÍNH SÓNG DO GIÓ VÀ CAO TRÌNH ĐỈNH YÊU CẦU Z₁, Z₂ – TỪNG BƯỚC (TCVN 8421:2010)
A2: Các cột cùng công thức; muốn tính hướng khác: sửa mã hướng (dòng 4) theo cột “Mã” ở SoLieu mục E.
A3: Đại lượng | B3: Đơn vị | C3: Bắc – MNDBT | D3: Bắc – MNLTK | E3: Đông Bắc – MNDBT | F3: Đông Bắc – MNLTK | G3: Tây Bắc – MNDBT | H3: Tây Bắc – MNLTK | I3: Công thức, nguồn
A4: Mã hướng gió | C4: N | D4: N | E4: NE | F4: NE | G4: NW | H4: NW
A5: Trường hợp (Z1 – MNDBT, gió P = 4%; Z2 – MNLTK, gió P = 50%) | C5: Z1 | D5: Z2 | E5: Z1 | F5: Z2 | G5: Z1 | H5: Z2
A6: Mực nước tính toán Z | B6: m | C6: =IF(C5="Z1",MN_DBT,MN_LTK) | D6: =IF(D5="Z1",MN_DBT,MN_LTK) | E6: =IF(E5="Z1",MN_DBT,MN_LTK) | F6: =IF(F5="Z1",MN_DBT,MN_LTK) | G6: =IF(G5="Z1",MN_DBT,MN_LTK) | H6: =IF(H5="Z1",MN_DBT,MN_LTK) | I6: SoLieu mục A
A7: Chiều sâu nước trước đập H | B7: m | C7: =C6-Z_day | D7: =D6-Z_day | E7: =E6-Z_day | F7: =F6-Z_day | G7: =G6-Z_day | H7: =H6-Z_day | I7: H = Z − Z đáy
A8: Vận tốc gió trạm Vl | B8: m/s | C8: =IF(C5="Z1",INDEX(Gio_V4,MATCH(C4,Gio_ma,0)),INDEX(Gio_V50,MATCH(C4,Gio_ma,0))) | D8: =IF(D5="Z1",INDEX(Gio_V4,MATCH(D4,Gio_ma,0)),INDEX(Gio_V50,MATCH(D4,Gio_ma,0))) | E8: =IF(E5="Z1",INDEX(Gio_V4,MATCH(E4,Gio_ma,0)),INDEX(Gio_V50,MATCH(E4,Gio_ma,0))) | F8: =IF(F5="Z1",INDEX(Gio_V4,MATCH(F4,Gio_ma,0)),INDEX(Gio_V50,MATCH(F4,Gio_ma,0))) | G8: =IF(G5="Z1",INDEX(Gio_V4,MATCH(G4,Gio_ma,0)),INDEX(Gio_V50,MATCH(G4,Gio_ma,0))) | H8: =IF(H5="Z1",INDEX(Gio_V4,MATCH(H4,Gio_ma,0)),INDEX(Gio_V50,MATCH(H4,Gio_ma,0))) | I8: Gió P = 4% (Z1), P = 50% (Z2) – SoLieu mục E
A9: Hệ số quy đổi kl | C9: =IF(C8<=INDEX(KL_V,1),INDEX(KL_k,1),IF(C8>=INDEX(KL_V,COUNT(KL_V)),INDEX(KL_k,COUNT(KL_V)),INDEX(KL_k,MATCH(C8,KL_V,1))+(C8-INDEX(KL_V,MATCH(C8,KL_V,1)))*(INDEX(KL_k,MATCH(C8,KL_V,1)+1)-INDEX(KL_k,MATCH(C8,KL_V,1)))/(INDEX(KL_V,MATCH(C8,KL_V,1)+1)-INDEX(KL_V,MATCH(C8,KL_V,1))))) | D9: =IF(D8<=INDEX(KL_V,1),INDEX(KL_k,1),IF(D8>=INDEX(KL_V,COUNT(KL_V)),INDEX(KL_k,COUNT(KL_V)),INDEX(KL_k,MATCH(D8,KL_V,1))+(D8-INDEX(KL_V,MATCH(D8,KL_V,1)))*(INDEX(KL_k,MATCH(D8,KL_V,1)+1)-INDEX(KL_k,MATCH(D8,KL_V,1)))/(INDEX(KL_V,MATCH(D8,KL_V,1)+1)-INDEX(KL_V,MATCH(D8,KL_V,1))))) | E9: =IF(E8<=INDEX(KL_V,1),INDEX(KL_k,1),IF(E8>=INDEX(KL_V,COUNT(KL_V)),INDEX(KL_k,COUNT(KL_V)),INDEX(KL_k,MATCH(E8,KL_V,1))+(E8-INDEX(KL_V,MATCH(E8,KL_V,1)))*(INDEX(KL_k,MATCH(E8,KL_V,1)+1)-INDEX(KL_k,MATCH(E8,KL_V,1)))/(INDEX(KL_V,MATCH(E8,KL_V,1)+1)-INDEX(KL_V,MATCH(E8,KL_V,1))))) | F9: =IF(F8<=INDEX(KL_V,1),INDEX(KL_k,1),IF(F8>=INDEX(KL_V,COUNT(KL_V)),INDEX(KL_k,COUNT(KL_V)),INDEX(KL_k,MATCH(F8,KL_V,1))+(F8-INDEX(KL_V,MATCH(F8,KL_V,1)))*(INDEX(KL_k,MATCH(F8,KL_V,1)+1)-INDEX(KL_k,MATCH(F8,KL_V,1)))/(INDEX(KL_V,MATCH(F8,KL_V,1)+1)-INDEX(KL_V,MATCH(F8,KL_V,1))))) | G9: =IF(G8<=INDEX(KL_V,1),INDEX(KL_k,1),IF(G8>=INDEX(KL_V,COUNT(KL_V)),INDEX(KL_k,COUNT(KL_V)),INDEX(KL_k,MATCH(G8,KL_V,1))+(G8-INDEX(KL_V,MATCH(G8,KL_V,1)))*(INDEX(KL_k,MATCH(G8,KL_V,1)+1)-INDEX(KL_k,MATCH(G8,KL_V,1)))/(INDEX(KL_V,MATCH(G8,KL_V,1)+1)-INDEX(KL_V,MATCH(G8,KL_V,1))))) | H9: =IF(H8<=INDEX(KL_V,1),INDEX(KL_k,1),IF(H8>=INDEX(KL_V,COUNT(KL_V)),INDEX(KL_k,COUNT(KL_V)),INDEX(KL_k,MATCH(H8,KL_V,1))+(H8-INDEX(KL_V,MATCH(H8,KL_V,1)))*(INDEX(KL_k,MATCH(H8,KL_V,1)+1)-INDEX(KL_k,MATCH(H8,KL_V,1)))/(INDEX(KL_V,MATCH(H8,KL_V,1)+1)-INDEX(KL_V,MATCH(H8,KL_V,1))))) | I9: Bảng A3, địa hình dạng A
A10: Vận tốc gió tính toán V = Vw | B10: m/s | C10: =k_fl*C9*C8 | D10: =k_fl*D9*D8 | E10: =k_fl*E9*E8 | F10: =k_fl*F9*F8 | G10: =k_fl*G9*G8 | H10: =k_fl*H9*H8 | I10: Vw = kfl·kl·Vl (A.3.3)
A11: Góc tới α giữa hướng gió và pháp tuyến mái | B11: ° | C11: =ABS(MOD(INDEX(Gio_az,MATCH(C4,Gio_ma,0))-PT_mai+180,360)-180) | D11: =ABS(MOD(INDEX(Gio_az,MATCH(D4,Gio_ma,0))-PT_mai+180,360)-180) | E11: =ABS(MOD(INDEX(Gio_az,MATCH(E4,Gio_ma,0))-PT_mai+180,360)-180) | F11: =ABS(MOD(INDEX(Gio_az,MATCH(F4,Gio_ma,0))-PT_mai+180,360)-180) | G11: =ABS(MOD(INDEX(Gio_az,MATCH(G4,Gio_ma,0))-PT_mai+180,360)-180) | H11: =ABS(MOD(INDEX(Gio_az,MATCH(H4,Gio_ma,0))-PT_mai+180,360)-180)
A12: Đà gió D | B12: m | C12: =IF(C5="Z1",D_1,D_2) | D12: =IF(D5="Z1",D_1,D_2) | E12: =IF(E5="Z1",D_1,D_2) | F12: =IF(F5="Z1",D_1,D_2) | G12: =IF(G5="Z1",D_1,D_2) | H12: =IF(H5="Z1",D_1,D_2) | I12: SoLieu mục C
A13: gD/V² | C13: =g_*C12/C10^2 | D13: =g_*D12/D10^2 | E13: =g_*E12/E10^2 | F13: =g_*F12/F10^2 | G13: =g_*G12/G10^2 | H13: =g_*H12/H10^2
A14: gt/V (t = 6 giờ) | C14: =g_*t_gio*3600/C10 | D14: =g_*t_gio*3600/D10 | E14: =g_*t_gio*3600/E10 | F14: =g_*t_gio*3600/F10 | G14: =g_*t_gio*3600/G10 | H14: =g_*t_gio*3600/H10
A15: gh̄/V² theo điều kiện đà gió | C15: =0.16*(1-(1+0.006*SQRT(C13))^-2) | D15: =0.16*(1-(1+0.006*SQRT(D13))^-2) | E15: =0.16*(1-(1+0.006*SQRT(E13))^-2) | F15: =0.16*(1-(1+0.006*SQRT(F13))^-2) | G15: =0.16*(1-(1+0.006*SQRT(G13))^-2) | H15: =0.16*(1-(1+0.006*SQRT(H13))^-2) | I15: 0,16·[1 − (1 + 0,006·√(gD/V²))⁻²]
A16: gh̄/V² theo điều kiện thời gian gió thổi | C16: =0.16*(1-(1+0.006*SQRT((C14/4.03)^1.6))^-2) | D16: =0.16*(1-(1+0.006*SQRT((D14/4.03)^1.6))^-2) | E16: =0.16*(1-(1+0.006*SQRT((E14/4.03)^1.6))^-2) | F16: =0.16*(1-(1+0.006*SQRT((F14/4.03)^1.6))^-2) | G16: =0.16*(1-(1+0.006*SQRT((G14/4.03)^1.6))^-2) | H16: =0.16*(1-(1+0.006*SQRT((H14/4.03)^1.6))^-2) | I16: Như trên với đà gió tương đương gD/V² = (gt/V / 4,03)^1,6
A17: gh̄/V² chọn (giá trị nhỏ hơn) | C17: =MIN(C15,C16) | D17: =MIN(D15,D16) | E17: =MIN(E15,E16) | F17: =MIN(F15,F16) | G17: =MIN(G15,G16) | H17: =MIN(H15,H16)
A18: Chiều cao sóng trung bình h̄ | B18: m | C18: =C17*C10^2/g_ | D18: =D17*D10^2/g_ | E18: =E17*E10^2/g_ | F18: =F17*F10^2/g_ | G18: =G17*G10^2/g_ | H18: =H17*H10^2/g_ | I18: h̄ = (gh̄/V²)·V²/g
A19: Chu kỳ sóng trung bình τ̄ | B19: s | C19: =19.1*C17^0.625*C10/g_ | D19: =19.1*D17^0.625*D10/g_ | E19: =19.1*E17^0.625*E10/g_ | F19: =19.1*F17^0.625*F10/g_ | G19: =19.1*G17^0.625*G10/g_ | H19: =19.1*H17^0.625*H10/g_ | I19: gτ̄/V = 19,1·(gh̄/V²)^0,625
A20: Bước sóng trung bình λ̄ | B20: m | C20: =g_*C19^2/(2*PI()) | D20: =g_*D19^2/(2*PI()) | E20: =g_*E19^2/(2*PI()) | F20: =g_*F19^2/(2*PI()) | G20: =g_*G19^2/(2*PI()) | H20: =g_*H19^2/(2*PI()) | I20: λ̄ = g·τ̄²/(2π)
A21: Kiểm tra sóng nước sâu H > 0,5λ̄ | C21: =IF(C7>0.5*C20,"Đúng","Sai – xem lại") | D21: =IF(D7>0.5*D20,"Đúng","Sai – xem lại") | E21: =IF(E7>0.5*E20,"Đúng","Sai – xem lại") | F21: =IF(F7>0.5*F20,"Đúng","Sai – xem lại") | G21: =IF(G7>0.5*G20,"Đúng","Sai – xem lại") | H21: =IF(H7>0.5*H20,"Đúng","Sai – xem lại")
A22: Hệ số K1% | C22: =IF(LOG10(C13)<=INDEX(K1_lg,1),INDEX(K1_k,1),IF(LOG10(C13)>=INDEX(K1_lg,COUNT(K1_lg)),INDEX(K1_k,COUNT(K1_lg)),INDEX(K1_k,MATCH(LOG10(C13),K1_lg,1))+(LOG10(C13)-INDEX(K1_lg,MATCH(LOG10(C13),K1_lg,1)))*(INDEX(K1_k,MATCH(LOG10(C13),K1_lg,1)+1)-INDEX(K1_k,MATCH(LOG10(C13),K1_lg,1)))/(INDEX(K1_lg,MATCH(LOG10(C13),K1_lg,1)+1)-INDEX(K1_lg,MATCH(LOG10(C13),K1_lg,1))))) | D22: =IF(LOG10(D13)<=INDEX(K1_lg,1),INDEX(K1_k,1),IF(LOG10(D13)>=INDEX(K1_lg,COUNT(K1_lg)),INDEX(K1_k,COUNT(K1_lg)),INDEX(K1_k,MATCH(LOG10(D13),K1_lg,1))+(LOG10(D13)-INDEX(K1_lg,MATCH(LOG10(D13),K1_lg,1)))*(INDEX(K1_k,MATCH(LOG10(D13),K1_lg,1)+1)-INDEX(K1_k,MATCH(LOG10(D13),K1_lg,1)))/(INDEX(K1_lg,MATCH(LOG10(D13),K1_lg,1)+1)-INDEX(K1_lg,MATCH(LOG10(D13),K1_lg,1))))) | E22: =IF(LOG10(E13)<=INDEX(K1_lg,1),INDEX(K1_k,1),IF(LOG10(E13)>=INDEX(K1_lg,COUNT(K1_lg)),INDEX(K1_k,COUNT(K1_lg)),INDEX(K1_k,MATCH(LOG10(E13),K1_lg,1))+(LOG10(E13)-INDEX(K1_lg,MATCH(LOG10(E13),K1_lg,1)))*(INDEX(K1_k,MATCH(LOG10(E13),K1_lg,1)+1)-INDEX(K1_k,MATCH(LOG10(E13),K1_lg,1)))/(INDEX(K1_lg,MATCH(LOG10(E13),K1_lg,1)+1)-INDEX(K1_lg,MATCH(LOG10(E13),K1_lg,1))))) | F22: =IF(LOG10(F13)<=INDEX(K1_lg,1),INDEX(K1_k,1),IF(LOG10(F13)>=INDEX(K1_lg,COUNT(K1_lg)),INDEX(K1_k,COUNT(K1_lg)),INDEX(K1_k,MATCH(LOG10(F13),K1_lg,1))+(LOG10(F13)-INDEX(K1_lg,MATCH(LOG10(F13),K1_lg,1)))*(INDEX(K1_k,MATCH(LOG10(F13),K1_lg,1)+1)-INDEX(K1_k,MATCH(LOG10(F13),K1_lg,1)))/(INDEX(K1_lg,MATCH(LOG10(F13),K1_lg,1)+1)-INDEX(K1_lg,MATCH(LOG10(F13),K1_lg,1))))) | G22: =IF(LOG10(G13)<=INDEX(K1_lg,1),INDEX(K1_k,1),IF(LOG10(G13)>=INDEX(K1_lg,COUNT(K1_lg)),INDEX(K1_k,COUNT(K1_lg)),INDEX(K1_k,MATCH(LOG10(G13),K1_lg,1))+(LOG10(G13)-INDEX(K1_lg,MATCH(LOG10(G13),K1_lg,1)))*(INDEX(K1_k,MATCH(LOG10(G13),K1_lg,1)+1)-INDEX(K1_k,MATCH(LOG10(G13),K1_lg,1)))/(INDEX(K1_lg,MATCH(LOG10(G13),K1_lg,1)+1)-INDEX(K1_lg,MATCH(LOG10(G13),K1_lg,1))))) | H22: =IF(LOG10(H13)<=INDEX(K1_lg,1),INDEX(K1_k,1),IF(LOG10(H13)>=INDEX(K1_lg,COUNT(K1_lg)),INDEX(K1_k,COUNT(K1_lg)),INDEX(K1_k,MATCH(LOG10(H13),K1_lg,1))+(LOG10(H13)-INDEX(K1_lg,MATCH(LOG10(H13),K1_lg,1)))*(INDEX(K1_k,MATCH(LOG10(H13),K1_lg,1)+1)-INDEX(K1_k,MATCH(LOG10(H13),K1_lg,1)))/(INDEX(K1_lg,MATCH(LOG10(H13),K1_lg,1)+1)-INDEX(K1_lg,MATCH(LOG10(H13),K1_lg,1))))) | I22: Hình 2, theo gD/V²
A23: Chiều cao sóng h1% = K1%·h̄ | B23: m | C23: =C22*C18 | D23: =D22*D18 | E23: =E22*E18 | F23: =F22*F18 | G23: =G22*G18 | H23: =H22*H18
A24: Độ nhám tương đối Δ/h1% | C24: =Delta_n/C23 | D24: =Delta_n/D23 | E24: =Delta_n/E23 | F24: =Delta_n/F23 | G24: =Delta_n/G23 | H24: =Delta_n/H23 | I24: Δ = 0,02 m
A25: Hệ số nhám kr | C25: =IF(C24<=INDEX(KR_x,1),INDEX(KR_kr,1),IF(C24>=INDEX(KR_x,COUNT(KR_x)),INDEX(KR_kr,COUNT(KR_x)),INDEX(KR_kr,MATCH(C24,KR_x,1))+(C24-INDEX(KR_x,MATCH(C24,KR_x,1)))*(INDEX(KR_kr,MATCH(C24,KR_x,1)+1)-INDEX(KR_kr,MATCH(C24,KR_x,1)))/(INDEX(KR_x,MATCH(C24,KR_x,1)+1)-INDEX(KR_x,MATCH(C24,KR_x,1))))) | D25: =IF(D24<=INDEX(KR_x,1),INDEX(KR_kr,1),IF(D24>=INDEX(KR_x,COUNT(KR_x)),INDEX(KR_kr,COUNT(KR_x)),INDEX(KR_kr,MATCH(D24,KR_x,1))+(D24-INDEX(KR_x,MATCH(D24,KR_x,1)))*(INDEX(KR_kr,MATCH(D24,KR_x,1)+1)-INDEX(KR_kr,MATCH(D24,KR_x,1)))/(INDEX(KR_x,MATCH(D24,KR_x,1)+1)-INDEX(KR_x,MATCH(D24,KR_x,1))))) | E25: =IF(E24<=INDEX(KR_x,1),INDEX(KR_kr,1),IF(E24>=INDEX(KR_x,COUNT(KR_x)),INDEX(KR_kr,COUNT(KR_x)),INDEX(KR_kr,MATCH(E24,KR_x,1))+(E24-INDEX(KR_x,MATCH(E24,KR_x,1)))*(INDEX(KR_kr,MATCH(E24,KR_x,1)+1)-INDEX(KR_kr,MATCH(E24,KR_x,1)))/(INDEX(KR_x,MATCH(E24,KR_x,1)+1)-INDEX(KR_x,MATCH(E24,KR_x,1))))) | F25: =IF(F24<=INDEX(KR_x,1),INDEX(KR_kr,1),IF(F24>=INDEX(KR_x,COUNT(KR_x)),INDEX(KR_kr,COUNT(KR_x)),INDEX(KR_kr,MATCH(F24,KR_x,1))+(F24-INDEX(KR_x,MATCH(F24,KR_x,1)))*(INDEX(KR_kr,MATCH(F24,KR_x,1)+1)-INDEX(KR_kr,MATCH(F24,KR_x,1)))/(INDEX(KR_x,MATCH(F24,KR_x,1)+1)-INDEX(KR_x,MATCH(F24,KR_x,1))))) | G25: =IF(G24<=INDEX(KR_x,1),INDEX(KR_kr,1),IF(G24>=INDEX(KR_x,COUNT(KR_x)),INDEX(KR_kr,COUNT(KR_x)),INDEX(KR_kr,MATCH(G24,KR_x,1))+(G24-INDEX(KR_x,MATCH(G24,KR_x,1)))*(INDEX(KR_kr,MATCH(G24,KR_x,1)+1)-INDEX(KR_kr,MATCH(G24,KR_x,1)))/(INDEX(KR_x,MATCH(G24,KR_x,1)+1)-INDEX(KR_x,MATCH(G24,KR_x,1))))) | H25: =IF(H24<=INDEX(KR_x,1),INDEX(KR_kr,1),IF(H24>=INDEX(KR_x,COUNT(KR_x)),INDEX(KR_kr,COUNT(KR_x)),INDEX(KR_kr,MATCH(H24,KR_x,1))+(H24-INDEX(KR_x,MATCH(H24,KR_x,1)))*(INDEX(KR_kr,MATCH(H24,KR_x,1)+1)-INDEX(KR_kr,MATCH(H24,KR_x,1)))/(INDEX(KR_x,MATCH(H24,KR_x,1)+1)-INDEX(KR_x,MATCH(H24,KR_x,1))))) | I25: Bảng hệ số nhám, thấm
A26: Hệ số thấm kp | C26: =IF(C24<=INDEX(KP_x,1),INDEX(KP_kp,1),IF(C24>=INDEX(KP_x,COUNT(KP_x)),INDEX(KP_kp,COUNT(KP_x)),INDEX(KP_kp,MATCH(C24,KP_x,1))+(C24-INDEX(KP_x,MATCH(C24,KP_x,1)))*(INDEX(KP_kp,MATCH(C24,KP_x,1)+1)-INDEX(KP_kp,MATCH(C24,KP_x,1)))/(INDEX(KP_x,MATCH(C24,KP_x,1)+1)-INDEX(KP_x,MATCH(C24,KP_x,1))))) | D26: =IF(D24<=INDEX(KP_x,1),INDEX(KP_kp,1),IF(D24>=INDEX(KP_x,COUNT(KP_x)),INDEX(KP_kp,COUNT(KP_x)),INDEX(KP_kp,MATCH(D24,KP_x,1))+(D24-INDEX(KP_x,MATCH(D24,KP_x,1)))*(INDEX(KP_kp,MATCH(D24,KP_x,1)+1)-INDEX(KP_kp,MATCH(D24,KP_x,1)))/(INDEX(KP_x,MATCH(D24,KP_x,1)+1)-INDEX(KP_x,MATCH(D24,KP_x,1))))) | E26: =IF(E24<=INDEX(KP_x,1),INDEX(KP_kp,1),IF(E24>=INDEX(KP_x,COUNT(KP_x)),INDEX(KP_kp,COUNT(KP_x)),INDEX(KP_kp,MATCH(E24,KP_x,1))+(E24-INDEX(KP_x,MATCH(E24,KP_x,1)))*(INDEX(KP_kp,MATCH(E24,KP_x,1)+1)-INDEX(KP_kp,MATCH(E24,KP_x,1)))/(INDEX(KP_x,MATCH(E24,KP_x,1)+1)-INDEX(KP_x,MATCH(E24,KP_x,1))))) | F26: =IF(F24<=INDEX(KP_x,1),INDEX(KP_kp,1),IF(F24>=INDEX(KP_x,COUNT(KP_x)),INDEX(KP_kp,COUNT(KP_x)),INDEX(KP_kp,MATCH(F24,KP_x,1))+(F24-INDEX(KP_x,MATCH(F24,KP_x,1)))*(INDEX(KP_kp,MATCH(F24,KP_x,1)+1)-INDEX(KP_kp,MATCH(F24,KP_x,1)))/(INDEX(KP_x,MATCH(F24,KP_x,1)+1)-INDEX(KP_x,MATCH(F24,KP_x,1))))) | G26: =IF(G24<=INDEX(KP_x,1),INDEX(KP_kp,1),IF(G24>=INDEX(KP_x,COUNT(KP_x)),INDEX(KP_kp,COUNT(KP_x)),INDEX(KP_kp,MATCH(G24,KP_x,1))+(G24-INDEX(KP_x,MATCH(G24,KP_x,1)))*(INDEX(KP_kp,MATCH(G24,KP_x,1)+1)-INDEX(KP_kp,MATCH(G24,KP_x,1)))/(INDEX(KP_x,MATCH(G24,KP_x,1)+1)-INDEX(KP_x,MATCH(G24,KP_x,1))))) | H26: =IF(H24<=INDEX(KP_x,1),INDEX(KP_kp,1),IF(H24>=INDEX(KP_x,COUNT(KP_x)),INDEX(KP_kp,COUNT(KP_x)),INDEX(KP_kp,MATCH(H24,KP_x,1))+(H24-INDEX(KP_x,MATCH(H24,KP_x,1)))*(INDEX(KP_kp,MATCH(H24,KP_x,1)+1)-INDEX(KP_kp,MATCH(H24,KP_x,1)))/(INDEX(KP_x,MATCH(H24,KP_x,1)+1)-INDEX(KP_x,MATCH(H24,KP_x,1))))) | I26: Như trên
A27: Hệ số ksp | C27: =IF(C10<=INDEX(KSP_V,1),INDEX(KSP_k,1),IF(C10>=INDEX(KSP_V,COUNT(KSP_V)),INDEX(KSP_k,COUNT(KSP_V)),INDEX(KSP_k,MATCH(C10,KSP_V,1))+(C10-INDEX(KSP_V,MATCH(C10,KSP_V,1)))*(INDEX(KSP_k,MATCH(C10,KSP_V,1)+1)-INDEX(KSP_k,MATCH(C10,KSP_V,1)))/(INDEX(KSP_V,MATCH(C10,KSP_V,1)+1)-INDEX(KSP_V,MATCH(C10,KSP_V,1))))) | D27: =IF(D10<=INDEX(KSP_V,1),INDEX(KSP_k,1),IF(D10>=INDEX(KSP_V,COUNT(KSP_V)),INDEX(KSP_k,COUNT(KSP_V)),INDEX(KSP_k,MATCH(D10,KSP_V,1))+(D10-INDEX(KSP_V,MATCH(D10,KSP_V,1)))*(INDEX(KSP_k,MATCH(D10,KSP_V,1)+1)-INDEX(KSP_k,MATCH(D10,KSP_V,1)))/(INDEX(KSP_V,MATCH(D10,KSP_V,1)+1)-INDEX(KSP_V,MATCH(D10,KSP_V,1))))) | E27: =IF(E10<=INDEX(KSP_V,1),INDEX(KSP_k,1),IF(E10>=INDEX(KSP_V,COUNT(KSP_V)),INDEX(KSP_k,COUNT(KSP_V)),INDEX(KSP_k,MATCH(E10,KSP_V,1))+(E10-INDEX(KSP_V,MATCH(E10,KSP_V,1)))*(INDEX(KSP_k,MATCH(E10,KSP_V,1)+1)-INDEX(KSP_k,MATCH(E10,KSP_V,1)))/(INDEX(KSP_V,MATCH(E10,KSP_V,1)+1)-INDEX(KSP_V,MATCH(E10,KSP_V,1))))) | F27: =IF(F10<=INDEX(KSP_V,1),INDEX(KSP_k,1),IF(F10>=INDEX(KSP_V,COUNT(KSP_V)),INDEX(KSP_k,COUNT(KSP_V)),INDEX(KSP_k,MATCH(F10,KSP_V,1))+(F10-INDEX(KSP_V,MATCH(F10,KSP_V,1)))*(INDEX(KSP_k,MATCH(F10,KSP_V,1)+1)-INDEX(KSP_k,MATCH(F10,KSP_V,1)))/(INDEX(KSP_V,MATCH(F10,KSP_V,1)+1)-INDEX(KSP_V,MATCH(F10,KSP_V,1))))) | G27: =IF(G10<=INDEX(KSP_V,1),INDEX(KSP_k,1),IF(G10>=INDEX(KSP_V,COUNT(KSP_V)),INDEX(KSP_k,COUNT(KSP_V)),INDEX(KSP_k,MATCH(G10,KSP_V,1))+(G10-INDEX(KSP_V,MATCH(G10,KSP_V,1)))*(INDEX(KSP_k,MATCH(G10,KSP_V,1)+1)-INDEX(KSP_k,MATCH(G10,KSP_V,1)))/(INDEX(KSP_V,MATCH(G10,KSP_V,1)+1)-INDEX(KSP_V,MATCH(G10,KSP_V,1))))) | H27: =IF(H10<=INDEX(KSP_V,1),INDEX(KSP_k,1),IF(H10>=INDEX(KSP_V,COUNT(KSP_V)),INDEX(KSP_k,COUNT(KSP_V)),INDEX(KSP_k,MATCH(H10,KSP_V,1))+(H10-INDEX(KSP_V,MATCH(H10,KSP_V,1)))*(INDEX(KSP_k,MATCH(H10,KSP_V,1)+1)-INDEX(KSP_k,MATCH(H10,KSP_V,1)))/(INDEX(KSP_V,MATCH(H10,KSP_V,1)+1)-INDEX(KSP_V,MATCH(H10,KSP_V,1))))) | I27: Bảng ksp, mái m = 3 ÷ 5
A28: Độ thoải sóng λ̄/h1% | C28: =C20/C23 | D28: =D20/D23 | E28: =E20/E23 | F28: =F20/F23 | G28: =G20/G23 | H28: =H20/H23
A29: Hệ số krun | C29: =IF(C28<=INDEX(KRUN_x,1),INDEX(KRUN_k,1),IF(C28>=INDEX(KRUN_x,COUNT(KRUN_x)),INDEX(KRUN_k,COUNT(KRUN_x)),INDEX(KRUN_k,MATCH(C28,KRUN_x,1))+(C28-INDEX(KRUN_x,MATCH(C28,KRUN_x,1)))*(INDEX(KRUN_k,MATCH(C28,KRUN_x,1)+1)-INDEX(KRUN_k,MATCH(C28,KRUN_x,1)))/(INDEX(KRUN_x,MATCH(C28,KRUN_x,1)+1)-INDEX(KRUN_x,MATCH(C28,KRUN_x,1))))) | D29: =IF(D28<=INDEX(KRUN_x,1),INDEX(KRUN_k,1),IF(D28>=INDEX(KRUN_x,COUNT(KRUN_x)),INDEX(KRUN_k,COUNT(KRUN_x)),INDEX(KRUN_k,MATCH(D28,KRUN_x,1))+(D28-INDEX(KRUN_x,MATCH(D28,KRUN_x,1)))*(INDEX(KRUN_k,MATCH(D28,KRUN_x,1)+1)-INDEX(KRUN_k,MATCH(D28,KRUN_x,1)))/(INDEX(KRUN_x,MATCH(D28,KRUN_x,1)+1)-INDEX(KRUN_x,MATCH(D28,KRUN_x,1))))) | E29: =IF(E28<=INDEX(KRUN_x,1),INDEX(KRUN_k,1),IF(E28>=INDEX(KRUN_x,COUNT(KRUN_x)),INDEX(KRUN_k,COUNT(KRUN_x)),INDEX(KRUN_k,MATCH(E28,KRUN_x,1))+(E28-INDEX(KRUN_x,MATCH(E28,KRUN_x,1)))*(INDEX(KRUN_k,MATCH(E28,KRUN_x,1)+1)-INDEX(KRUN_k,MATCH(E28,KRUN_x,1)))/(INDEX(KRUN_x,MATCH(E28,KRUN_x,1)+1)-INDEX(KRUN_x,MATCH(E28,KRUN_x,1))))) | F29: =IF(F28<=INDEX(KRUN_x,1),INDEX(KRUN_k,1),IF(F28>=INDEX(KRUN_x,COUNT(KRUN_x)),INDEX(KRUN_k,COUNT(KRUN_x)),INDEX(KRUN_k,MATCH(F28,KRUN_x,1))+(F28-INDEX(KRUN_x,MATCH(F28,KRUN_x,1)))*(INDEX(KRUN_k,MATCH(F28,KRUN_x,1)+1)-INDEX(KRUN_k,MATCH(F28,KRUN_x,1)))/(INDEX(KRUN_x,MATCH(F28,KRUN_x,1)+1)-INDEX(KRUN_x,MATCH(F28,KRUN_x,1))))) | G29: =IF(G28<=INDEX(KRUN_x,1),INDEX(KRUN_k,1),IF(G28>=INDEX(KRUN_x,COUNT(KRUN_x)),INDEX(KRUN_k,COUNT(KRUN_x)),INDEX(KRUN_k,MATCH(G28,KRUN_x,1))+(G28-INDEX(KRUN_x,MATCH(G28,KRUN_x,1)))*(INDEX(KRUN_k,MATCH(G28,KRUN_x,1)+1)-INDEX(KRUN_k,MATCH(G28,KRUN_x,1)))/(INDEX(KRUN_x,MATCH(G28,KRUN_x,1)+1)-INDEX(KRUN_x,MATCH(G28,KRUN_x,1))))) | H29: =IF(H28<=INDEX(KRUN_x,1),INDEX(KRUN_k,1),IF(H28>=INDEX(KRUN_x,COUNT(KRUN_x)),INDEX(KRUN_k,COUNT(KRUN_x)),INDEX(KRUN_k,MATCH(H28,KRUN_x,1))+(H28-INDEX(KRUN_x,MATCH(H28,KRUN_x,1)))*(INDEX(KRUN_k,MATCH(H28,KRUN_x,1)+1)-INDEX(KRUN_k,MATCH(H28,KRUN_x,1)))/(INDEX(KRUN_x,MATCH(H28,KRUN_x,1)+1)-INDEX(KRUN_x,MATCH(H28,KRUN_x,1))))) | I29: Hình 10, mái m = 3
A30: Hệ số kα | C30: =IF(C11<=INDEX(KA_goc,1),INDEX(KA_k,1),IF(C11>=INDEX(KA_goc,COUNT(KA_goc)),INDEX(KA_k,COUNT(KA_goc)),INDEX(KA_k,MATCH(C11,KA_goc,1))+(C11-INDEX(KA_goc,MATCH(C11,KA_goc,1)))*(INDEX(KA_k,MATCH(C11,KA_goc,1)+1)-INDEX(KA_k,MATCH(C11,KA_goc,1)))/(INDEX(KA_goc,MATCH(C11,KA_goc,1)+1)-INDEX(KA_goc,MATCH(C11,KA_goc,1))))) | D30: =IF(D11<=INDEX(KA_goc,1),INDEX(KA_k,1),IF(D11>=INDEX(KA_goc,COUNT(KA_goc)),INDEX(KA_k,COUNT(KA_goc)),INDEX(KA_k,MATCH(D11,KA_goc,1))+(D11-INDEX(KA_goc,MATCH(D11,KA_goc,1)))*(INDEX(KA_k,MATCH(D11,KA_goc,1)+1)-INDEX(KA_k,MATCH(D11,KA_goc,1)))/(INDEX(KA_goc,MATCH(D11,KA_goc,1)+1)-INDEX(KA_goc,MATCH(D11,KA_goc,1))))) | E30: =IF(E11<=INDEX(KA_goc,1),INDEX(KA_k,1),IF(E11>=INDEX(KA_goc,COUNT(KA_goc)),INDEX(KA_k,COUNT(KA_goc)),INDEX(KA_k,MATCH(E11,KA_goc,1))+(E11-INDEX(KA_goc,MATCH(E11,KA_goc,1)))*(INDEX(KA_k,MATCH(E11,KA_goc,1)+1)-INDEX(KA_k,MATCH(E11,KA_goc,1)))/(INDEX(KA_goc,MATCH(E11,KA_goc,1)+1)-INDEX(KA_goc,MATCH(E11,KA_goc,1))))) | F30: =IF(F11<=INDEX(KA_goc,1),INDEX(KA_k,1),IF(F11>=INDEX(KA_goc,COUNT(KA_goc)),INDEX(KA_k,COUNT(KA_goc)),INDEX(KA_k,MATCH(F11,KA_goc,1))+(F11-INDEX(KA_goc,MATCH(F11,KA_goc,1)))*(INDEX(KA_k,MATCH(F11,KA_goc,1)+1)-INDEX(KA_k,MATCH(F11,KA_goc,1)))/(INDEX(KA_goc,MATCH(F11,KA_goc,1)+1)-INDEX(KA_goc,MATCH(F11,KA_goc,1))))) | G30: =IF(G11<=INDEX(KA_goc,1),INDEX(KA_k,1),IF(G11>=INDEX(KA_goc,COUNT(KA_goc)),INDEX(KA_k,COUNT(KA_goc)),INDEX(KA_k,MATCH(G11,KA_goc,1))+(G11-INDEX(KA_goc,MATCH(G11,KA_goc,1)))*(INDEX(KA_k,MATCH(G11,KA_goc,1)+1)-INDEX(KA_k,MATCH(G11,KA_goc,1)))/(INDEX(KA_goc,MATCH(G11,KA_goc,1)+1)-INDEX(KA_goc,MATCH(G11,KA_goc,1))))) | H30: =IF(H11<=INDEX(KA_goc,1),INDEX(KA_k,1),IF(H11>=INDEX(KA_goc,COUNT(KA_goc)),INDEX(KA_k,COUNT(KA_goc)),INDEX(KA_k,MATCH(H11,KA_goc,1))+(H11-INDEX(KA_goc,MATCH(H11,KA_goc,1)))*(INDEX(KA_k,MATCH(H11,KA_goc,1)+1)-INDEX(KA_k,MATCH(H11,KA_goc,1)))/(INDEX(KA_goc,MATCH(H11,KA_goc,1)+1)-INDEX(KA_goc,MATCH(H11,KA_goc,1))))) | I30: Bảng 9, theo α
A31: Chiều cao sóng leo hsl1% | B31: m | C31: =C25*C26*C27*C29*C30*C23 | D31: =D25*D26*D27*D29*D30*D23 | E31: =E25*E26*E27*E29*E30*E23 | F31: =F25*F26*F27*F29*F30*F23 | G31: =G25*G26*G27*G29*G30*G23 | H31: =H25*H26*H27*H29*H30*H23 | I31: hsl1% = kr·kp·ksp·krun·kα·h1%
A32: Hệ số kw | C32: =3E-7*(1+0.3*C10) | D32: =3E-7*(1+0.3*D10) | E32: =3E-7*(1+0.3*E10) | F32: =3E-7*(1+0.3*F10) | G32: =3E-7*(1+0.3*G10) | H32: =3E-7*(1+0.3*H10) | I32: kw = 3·10⁻⁷·(1 + 0,3·Vw)
A33: Độ dềnh do gió Δh | B33: m | C33: =C32*C10^2*C12/(g_*C7)*COS(RADIANS(C11)) | D33: =D32*D10^2*D12/(g_*D7)*COS(RADIANS(D11)) | E33: =E32*E10^2*E12/(g_*E7)*COS(RADIANS(E11)) | F33: =F32*F10^2*F12/(g_*F7)*COS(RADIANS(F11)) | G33: =G32*G10^2*G12/(g_*G7)*COS(RADIANS(G11)) | H33: =H32*H10^2*H12/(g_*H7)*COS(RADIANS(H11)) | I33: Δh = kw·V²·D/(g·H)·cos α
A34: Độ vượt cao an toàn | B34: m | C34: =IF(C5="Z1",a_1,a_2) | D34: =IF(D5="Z1",a_1,a_2) | E34: =IF(E5="Z1",a_1,a_2) | F34: =IF(F5="Z1",a_1,a_2) | G34: =IF(G5="Z1",a_1,a_2) | H34: =IF(H5="Z1",a_1,a_2) | I34: a (Z1), a′ (Z2) – Bảng 3
A35: Cao trình đỉnh đập yêu cầu Z₁ hoặc Z₂ | B35: m | C35: =C6+C33+C31+C34 | D35: =D6+D33+D31+D34 | E35: =E6+E33+E31+E34 | F35: =F6+F33+F31+F34 | G35: =G6+G33+G31+G34 | H35: =H6+H33+H31+H34 | I35: Z = Z + Δh + hsl + a

Sheet KetQua
A1: KẾT QUẢ: CAO TRÌNH ĐỈNH ĐẬP YÊU CẦU VÀ ĐÁNH GIÁ (TCVN 8216:2018)
A2: ="MNDBT +"&TEXT(MN_DBT,"0.00")&"; MNLTK +"&TEXT(MN_LTK,"0.00")&"; MNLKT +"&TEXT(MN_LKT,"0.00")&" m"
A4: 1. Cao trình đỉnh yêu cầu theo hướng gió (m)
A5: Hướng gió | B5: Góc tới α (°) | C5: kα | D5: Vw P = 4% (m/s) | E5: Vw P = 50% (m/s) | F5: hsl ở MNDBT (m) | G5: hsl′ ở MNLTK (m) | H5: Z₁ | I5: Z₂ | J5: Z₃ | K5: Zđ = max
A6: Bắc | B6: =TinhSong!C11 | C6: =TinhSong!C30 | D6: =TinhSong!C10 | E6: =TinhSong!D10 | F6: =TinhSong!C31 | G6: =TinhSong!D31 | H6: =TinhSong!C35 | I6: =TinhSong!D35 | J6: =MN_LKT+a_3 | K6: =MAX(H6:J6)
A7: Đông Bắc | B7: =TinhSong!E11 | C7: =TinhSong!E30 | D7: =TinhSong!E10 | E7: =TinhSong!F10 | F7: =TinhSong!E31 | G7: =TinhSong!F31 | H7: =TinhSong!E35 | I7: =TinhSong!F35 | J7: =MN_LKT+a_3 | K7: =MAX(H7:J7)
A8: Tây Bắc | B8: =TinhSong!G11 | C8: =TinhSong!G30 | D8: =TinhSong!G10 | E8: =TinhSong!H10 | F8: =TinhSong!G31 | G8: =TinhSong!H31 | H8: =TinhSong!G35 | I8: =TinhSong!H35 | J8: =MN_LKT+a_3 | K8: =MAX(H8:J8)
A9: Cao trình đỉnh yêu cầu lớn nhất Zđ (m) | B9: =MAX(K6:K8) | C9: =INDEX(A6:A8,MATCH(B9,K6:K8,0))&" – "&IF(INDEX(I6:I8,MATCH(B9,K6:K8,0))=B9,"Z₂ (MNLTK)",IF(INDEX(H6:H8,MATCH(B9,K6:K8,0))=B9,"Z₁ (MNDBT)","Z₃ (MNLKT)"))
A10: Các hướng Đông, Tây (góc tới 84 ÷ 96°) và các hướng Nam (thổi từ hạ lưu) không gây sóng leo lên mái thượng lưu.
A12: 2. Đánh giá theo TCVN 8216:2018 điều 10.1.5 (đập có tường chắn sóng)
A13: Điều kiện | B13: Yêu cầu (m) | C13: Hiện trạng (m) | D13: Chênh (m) | E13: Đánh giá | F13: Sau sửa chữa (m) | G13: Chênh (m) | H13: Đánh giá
A14: Đỉnh tường chắn sóng ≥ Zđ = max(Z₁; Z₂; Z₃) | B14: =Z_yc | C14: =Z_tuong | D14: =C14-B14 | E14: =IF(D14>=-0.0001,"Đạt","Không đạt") | F14: =Z_tuong | G14: =F14-B14 | H14: =IF(G14>=-0.0001,"Đạt","Không đạt")
A15: Đỉnh đập không kể tường ≥ MNLKT + 0,3 m | B15: =MN_LKT+dZ_LKT | C15: =Z_dinh_HT | D15: =C15-B15 | E15: =IF(D15>=-0.0001,"Đạt","Không đạt") | F15: =Z_dinh_SC | G15: =F15-B15 | H15: =IF(G15>=-0.0001,"Đạt","Không đạt")
A16: Tường cao hơn đỉnh đập ≤ 1,2 m | B16: =dZ_tuong | C16: =Z_tuong-Z_dinh_HT | D16: =B16-C16 | E16: =IF(D16>=-0.0001,"Đạt","Không đạt") | F16: =Z_tuong-Z_dinh_SC | G16: =B16-F16 | H16: =IF(G16>=-0.0001,"Đạt","Không đạt")
A18: Chênh = giá trị thực − yêu cầu (dòng 1, 2) hoặc yêu cầu − giá trị thực (dòng 3); dương là đạt.
A19: ="Nếu không có tường chắn sóng, đỉnh đập phải ≥ Zđ = +"&TEXT(Z_yc,"0.00")&" m: hiện trạng "&TEXT(Z_dinh_HT-Z_yc,"+0.00;-0.00")&" m, sau sửa chữa "&TEXT(Z_dinh_SC-Z_yc,"+0.00;-0.00")&" m → tường chắn sóng phải được giữ lại."
A21: 3. Bảng in theo mẫu Bảng 2.4 – gió hướng Bắc (chép vào thuyết minh)
A22: Đại lượng | B22: Z₁: MNDBT | D22: Z₂: MNLTK | F22: Z₃: MNLKT
A23: Mực nước tính toán (m) | B23: =TinhSong!C6 | D23: =TinhSong!D6 | F23: =MN_LKT
A24: Vận tốc gió Vl (m/s) | B24: =TinhSong!C8 | D24: =TinhSong!D8 | F24: –
A25: Vận tốc gió tính toán Vw (m/s) | B25: =TinhSong!C10 | D25: =TinhSong!D10 | F25: –
A26: Đà gió D (m) | B26: =TinhSong!C12 | D26: =TinhSong!D12 | F26: –
A27: Chiều sâu nước trước đập H (m) | B27: =TinhSong!C7 | D27: =TinhSong!D7 | F27: –
A28: gD/Vw² | B28: =TinhSong!C13 | D28: =TinhSong!D13 | F28: –
A29: Chiều cao sóng trung bình h̄ (m) | B29: =TinhSong!C18 | D29: =TinhSong!D18 | F29: –
A30: Chu kỳ τ̄ (s) | B30: =TinhSong!C19 | D30: =TinhSong!D19 | F30: –
A31: Bước sóng λ̄ (m) | B31: =TinhSong!C20 | D31: =TinhSong!D20 | F31: –
A32: K1% | B32: =TinhSong!C22 | D32: =TinhSong!D22 | F32: –
A33: h1% (m) | B33: =TinhSong!C23 | D33: =TinhSong!D23 | F33: –
A34: kr | B34: =TinhSong!C25 | D34: =TinhSong!D25 | F34: –
A35: kp | B35: =TinhSong!C26 | D35: =TinhSong!D26 | F35: –
A36: ksp | B36: =TinhSong!C27 | D36: =TinhSong!D27 | F36: –
A37: krun | B37: =TinhSong!C29 | D37: =TinhSong!D29 | F37: –
A38: kα | B38: =TinhSong!C30 | D38: =TinhSong!D30 | F38: –
A39: Sóng leo hsl1% (m) | B39: =TinhSong!C31 | D39: =TinhSong!D31 | F39: –
A40: Độ dềnh Δh (m) | B40: =TinhSong!C33 | D40: =TinhSong!D33 | F40: –
A41: Độ vượt cao an toàn (m) | B41: =TinhSong!C34 | D41: =TinhSong!D34 | F41: =a_3
A42: Cao trình đỉnh yêu cầu (m) | B42: =TinhSong!C35 | D42: =TinhSong!D35 | F42: =MN_LKT+a_3
