Workbook

Sheet HuongDan
B1: ĐIỀU TIẾT LŨ HỒ CÀ GIÂY VỚI HAI TRÀN CÓ NGƯỠNG KHÁC NHAU – PHƯƠNG PHÁP PÔ-TA-PỐP
B2: Mọi ô kết quả là công thức. Đổi thông số tràn, mực nước trước lũ ở sheet SoLieu; đổi tần suất, trường hợp ở ô vàng đầu mỗi sheet điều tiết.
B3: 1. Cộng dồn hay tính song song?
B4: • Hai tràn cùng lấy nước từ MỘT hồ nên ở mỗi thời điểm chỉ có MỘT mực nước Z. Tràn nào có ngưỡng thấp hơn Z thì tràn đó xả: tràn sự cố (ngưỡng +71,00 m) xả khi Z > +71,00; tràn chính (ngưỡng +74,70 m) xả khi Z > +74,70.
B5: • Lưu lượng xả của hồ là TỔNG hai tràn tại CÙNG mực nước: q(Z) = q tràn chính(Z) + q tràn sự cố(Z). Vậy “cộng” là đúng ở bước lập quan hệ q ~ Z (sheet QuanHe, cột q hai tràn), sau đó điều tiết MỘT lần với q tổng – đó chính là tính song song (hai tràn cùng làm việc).
B6: • KHÔNG được điều tiết riêng từng tràn rồi cộng kết quả: mỗi lần tính riêng đã cho TOÀN BỘ trận lũ đi qua một tràn, nên mực nước cao hơn thực tế; cộng hai lưu lượng xả của hai lần tính riêng thì tính trùng lượng nước lũ.
B7: • Kết quả “tính độc lập” trong bảng của bạn chỉ có ý nghĩa là trường hợp MỘT tràn không làm việc: “chỉ tràn chính” chính là trường hợp cửa van tràn sự cố bị kẹt (P = 1%: +78,20 m ở file này, bạn tính +78,28 m); “chỉ tràn sự cố” là trường hợp cả 9 cửa tràn chính không mở – không phải trường hợp thiết kế.
B8: 2. Giả thiết tính toán
B9: • Khi lũ về, mực nước hồ ở MNDBT = +74,70 m (ô SoLieu!B5). Tràn chính 9 khoang × 2,4 m, cửa van mở hết, chảy tự do.
B10: • Tràn sự cố có cửa van phẳng: giả thiết cửa van MỞ HOÀN TOÀN suốt trận lũ (kéo lên khỏi mặt nước) nên tràn làm việc như đập tràn chảy tự do, tính bằng cùng công thức với tràn chính.
B11: • Trường hợp kẹt van: cửa tràn sự cố đóng, chỉ tràn chính xả (chọn “Kẹt van” ở ô F3 của sheet điều tiết).
B12: • Bỏ qua lưu tốc tới gần (H₀ ≈ H), chảy không ngập (σn = 1). Dung tích theo bình đồ 2022 (thuyết minh mục 1.2.3).
... B32: • Nền vàng chữ xanh: ô được sửa. Chữ xanh: số liệu gốc hồ sơ. Chữ đen: công thức. Nền đỏ nhạt: dòng có mực nước lớn nhất.

Sheet SoLieu
A1: SỐ LIỆU ĐẦU VÀO – ĐIỀU TIẾT LŨ HAI TRÀN
A2: Ô nền vàng chữ xanh: được sửa. Chữ xanh: số liệu gốc hồ sơ. Chữ đen: công thức.
A4: A. THÔNG SỐ CHUNG
A5: Thông số | B5: Giá trị | C5: Đơn vị | D5: Ghi chú, nguồn
A6: Mực nước hồ khi lũ đến (MNDBT) | B6: 74.7 | C6: m | D6: Giả thiết bất lợi: lũ đến khi hồ đầy ở MNDBT
A7: Bước thời gian Δt | B7: 1 | C7: giờ | D7: Bằng bước của đường quá trình lũ (cố định 1 giờ)
A8: Δt tính bằng giây | B8: =dt_h*3600 -> 3600 | C8: s
A9: Gia tốc trọng trường g | B9: 9.81 | C9: m/s²
A11: B. TRÀN CHÍNH (9 khoang có cửa van, mở hết – chảy tự do)
A12: Thông số | B12: Giá trị | C12: Đơn vị | D12: Ghi chú, nguồn
A13: Cao trình ngưỡng | B13: 74.7 | C13: m | D13: QTVH 2026; thuyết minh mục 1.6.2
A14: Số khoang n | B14: 9 | C14: khoang | D14: Đơn vị quản lý chia 9 khoang × 2,4 m (QTVH mục 6)
A15: Bề rộng một khoang b | B15: 2.4 | C15: m | D15: Σb = 21,6 m
A16: Hệ số lưu lượng m | B16: 0.45 | D16: Đồ án lấy 0,45 (thuyết minh 2.3.2); BCNCKT 0,467; QTVH 0,40
A17: Hệ số hình dạng mố bên ξmb | B17: 0.7 | D17: Mố bên lượn tròn
A18: Hệ số hình dạng mố trụ ξmt | B18: 0.45 | D18: Mố trụ đầu tròn
A19: Hệ số chảy ngập σn | B19: 1 | D19: Chảy không ngập
A21: C. TRÀN SỰ CỐ (cửa van phẳng – giả thiết mở hoàn toàn)
A22: Thông số | B22: Giá trị | C22: Đơn vị | D22: Ghi chú, nguồn
A23: Cao trình ngưỡng | B23: 71 | C23: m | D23: KTTV Bảng 1-2
A24: Số khoang n | B24: 1 | C24: khoang
A25: Bề rộng khoang b | B25: 5 | C25: m | D25: KTTV Bảng 1-2
A26: Hệ số lưu lượng m | B26: 0.45 | D26: Như chương trình của đồ án
A27: Hệ số hình dạng mố bên ξmb | B27: 0.7
A28: Hệ số hình dạng mố trụ ξmt | B28: 0.45 | D28: Không dùng khi n = 1
A29: Hệ số chảy ngập σn | B29: 1 | D29: Chảy không ngập
A31: D. ĐƯỜNG QUÁ TRÌNH LŨ ĐẾN (m³/s) – BCNCKT 2022, mô hình Gurdich 36 giờ (KTTV Bảng 4-5)
A32: Tần suất P (%) → | B32: 1 | C32: 0.2
A33: t (giờ) | B33: P = 1% | C33: P = 0,2%
A34: 0 | B34: 2 | C34: 4 | D34: Giờ 0 lấy bằng giờ 1 (như chương trình của đồ án); sau giờ 36 lưu lượng đến = 0.
A35: 1 | B35: 2 | C35: 4 | E35: P = 1% | F35: P = 0,2%
A36: 2 | B36: 50 | C36: 84 | D36: Tổng lượng lũ tính từ bảng (10⁶ m³): | E36: =SUMPRODUCT((B34:B69+B35:B70)/2)*dt_s/1000000+B70/2*dt_s/1000000 -> 36.2736 | F36: =SUMPRODUCT((C34:C69+C35:C70)/2)*dt_s/1000000+C70/2*dt_s/1000000 -> 47.6964
A37: 3 | B37: 207 | C37: 324 | D37: Tổng lượng lũ ghi trong KTTV Bảng 4-4 (10⁶ m³): | E37: 32.43 | F37: 41.95
A38: 4 | B38: 437 | C38: 652 | D38: Thuyết minh mục 1.4.3: dùng trực tiếp tung độ đường quá trình (tổng lượng 36,27 / 47,69), không dùng tổng lượng ghi – thiên an toàn.
A39: 5 | B39: 657 | C39: 950
A40: 6 | B40: 816 | C40: 1150
A41: 7 | B41: 898 | C41: 1239
A42: 8 | B42: 914 | C42: 1236
A43: 9 | B43: 879 | C43: 1168
A44: 10 | B44: 812 | C44: 1062
...

Sheet QuanHe
A1: BẢNG QUAN HỆ Z ~ V ~ q ~ f (bước 0,1 m) – dùng để tra trong các sheet điều tiết
A2: f = V·10⁶/Δt + q/2 (m³/s). Cột q hai tràn = q tràn chính + q tràn sự cố tại CÙNG mực nước Z.
A4: Z (m) | B4: F (km²) | C4: V (10⁶ m³) | D4: H tràn chính (m) | E4: ε tràn chính | F4: q tràn chính (m³/s) | G4: H tràn sự cố (m) | H4: ε tràn sự cố | I4: q tràn sự cố (m³/s) | J4: q hai tràn (m³/s) | K4: q kẹt van (m³/s) | L4: f hai tràn (m³/s) | M4: f kẹt van (m³/s)
A5: 71 | B5: =INDEX(Bang_F,MATCH(A5,Bang_Z,1))+(A5-INDEX(Bang_Z,MATCH(A5,Bang_Z,1)))*(INDEX(Bang_F,MATCH(A5,Bang_Z,1)+1)-INDEX(Bang_F,MATCH(A5,Bang_Z,1))) -> 3.95 | C5: =INDEX(Bang_W,MATCH(A5,Bang_Z,1))+(A5-INDEX(Bang_Z,MATCH(A5,Bang_Z,1)))*(INDEX(Bang_F,MATCH(A5,Bang_Z,1))+B5)/2 -> 17.565 | D5: =MAX(A5-TC_Z,0) -> 0 | E5: =1-0.2*(TC_xmb+(TC_n-1)*TC_xmt)*D5/(TC_n*TC_b) -> 1 | F5: =TC_s*E5*TC_m*TC_n*TC_b*SQRT(2*g_)*D5^1.5 -> 0 | G5: =MAX(A5-SC_Z,0) -> 0 | H5: =1-0.2*(SC_xmb+(SC_n-1)*SC_xmt)*G5/(SC_n*SC_b) -> 1 | I5: =SC_s*H5*SC_m*SC_n*SC_b*SQRT(2*g_)*G5^1.5 -> 0 | J5: =F5+I5 -> 0 | K5: =F5 -> 0 | L5: =C5*1000000/dt_s+J5/2 -> 4879.1667 | M5: =C5*1000000/dt_s+K5/2 -> 4879.1667
A6: =ROUND(A5+0.1,2) -> 71.1 | B6: =INDEX(Bang_F,MATCH(A6,Bang_Z,1))+(A6-INDEX(Bang_Z,MATCH(A6,Bang_Z,1)))*(INDEX(Bang_F,MATCH(A6,Bang_Z,1)+1)-INDEX(Bang_F,MATCH(A6,Bang_Z,1))) -> 4.01 | C6: =INDEX(Bang_W,MATCH(A6,Bang_Z,1))+(A6-INDEX(Bang_Z,MATCH(A6,Bang_Z,1)))*(INDEX(Bang_F,MATCH(A6,Bang_Z,1))+B6)/2 -> 17.963 | D6: =MAX(A6-TC_Z,0) -> 0 | E6: =1-0.2*(TC_xmb+(TC_n-1)*TC_xmt)*D6/(TC_n*TC_b) -> 1 | F6: =TC_s*E6*TC_m*TC_n*TC_b*SQRT(2*g_)*D6^1.5 -> 0 | G6: =MAX(A6-SC_Z,0) -> 0.1 | H6: =1-0.2*(SC_xmb+(SC_n-1)*SC_xmt)*G6/(SC_n*SC_b) -> 0.9972 | I6: =SC_s*H6*SC_m*SC_n*SC_b*SQRT(2*g_)*G6^1.5 -> 0.31427822 | J6: =F6+I6 -> 0.31427822 | K6: =F6 -> 0 | L6: =C6*1000000/dt_s+J6/2 -> 4989.8794 | M6: =C6*1000000/dt_s+K6/2 -> 4989.7222
A7: =ROUND(A6+0.1,2) -> 71.2 | B7: =INDEX(Bang_F,MATCH(A7,Bang_Z,1))+(A7-INDEX(Bang_Z,MATCH(A7,Bang_Z,1)))*(INDEX(Bang_F,MATCH(A7,Bang_Z,1)+1)-INDEX(Bang_F,MATCH(A7,Bang_Z,1))) -> 4.07 | C7: =INDEX(Bang_W,MATCH(A7,Bang_Z,1))+(A7-INDEX(Bang_Z,MATCH(A7,Bang_Z,1)))*(INDEX(Bang_F,MATCH(A7,Bang_Z,1))+B7)/2 -> 18.367 | D7: =MAX(A7-TC_Z,0) -> 0 | E7: =1-0.2*(TC_xmb+(TC_n-1)*TC_xmt)*D7/(TC_n*TC_b) -> 1 | F7: =TC_s*E7*TC_m*TC_n*TC_b*SQRT(2*g_)*D7^1.5 -> 0 | G7: =MAX(A7-SC_Z,0) -> 0.2 | H7: =1-0.2*(SC_xmb+(SC_n-1)*SC_xmt)*G7/(SC_n*SC_b) -> 0.9944 | I7: =SC_s*H7*SC_m*SC_n*SC_b*SQRT(2*g_)*G7^1.5 -> 0.88641711 | J7: =F7+I7 -> 0.88641711 | K7: =F7 -> 0 | L7: =C7*1000000/dt_s+J7/2 -> 5102.3877 | M7: =C7*1000000/dt_s+K7/2 -> 5101.9444
A8: =ROUND(A7+0.1,2) -> 71.3 | B8: =INDEX(Bang_F,MATCH(A8,Bang_Z,1))+(A8-INDEX(Bang_Z,MATCH(A8,Bang_Z,1)))*(INDEX(Bang_F,MATCH(A8,Bang_Z,1)+1)-INDEX(Bang_F,MATCH(A8,Bang_Z,1))) -> 4.13 | C8: =INDEX(Bang_W,MATCH(A8,Bang_Z,1))+(A8-INDEX(Bang_Z,MATCH(A8,Bang_Z,1)))*(INDEX(Bang_F,MATCH(A8,Bang_Z,1))+B8)/2 -> 18.777 | D8: =MAX(A8-TC_Z,0) -> 0 | E8: =1-0.2*(TC_xmb+(TC_n-1)*TC_xmt)*D8/(TC_n*TC_b) -> 1 | F8: =TC_s*E8*TC_m*TC_n*TC_b*SQRT(2*g_)*D8^1.5 -> 0 | G8: =MAX(A8-SC_Z,0) -> 0.3 | H8: =1-0.2*(SC_xmb+(SC_n-1)*SC_xmt)*G8/(SC_n*SC_b) -> 0.9916 | I8: =SC_s*H8*SC_m*SC_n*SC_b*SQRT(2*g_)*G8^1.5 -> 1.6238669 | J8: =F8+I8 -> 1.6238669 | K8: =F8 -> 0 | L8: =C8*1000000/dt_s+J8/2 -> 5216.6453 | M8: =C8*1000000/dt_s+K8/2 -> 5215.8333
A9: =ROUND(A8+0.1,2) -> 71.4 | B9: =INDEX(Bang_F,MATCH(A9,Bang_Z,1))+(A9-INDEX(Bang_Z,MATCH(A9,Bang_Z,1)))*(INDEX(Bang_F,MATCH(A9,Bang_Z,1)+1)-INDEX(Bang_F,MATCH(A9,Bang_Z,1))) -> 4.19 | C9: =INDEX(Bang_W,MATCH(A9,Bang_Z,1))+(A9-INDEX(Bang_Z,MATCH(A9,Bang_Z,1)))*(INDEX(Bang_F,MATCH(A9,Bang_Z,1))+B9)/2 -> 19.193 | D9: =MAX(A9-TC_Z,0) -> 0 | E9: =1-0.2*(TC_xmb+(TC_n-1)*TC_xmt)*D9/(TC_n*TC_b) -> 1 | F9: =TC_s*E9*TC_m*TC_n*TC_b*SQRT(2*g_)*D9^1.5 -> 0 | G9: =MAX(A9-SC_Z,0) -> 0.4 | H9: =1-0.2*(SC_xmb+(SC_n-1)*SC_xmt)*G9/(SC_n*SC_b) -> 0.9888 | I9: =SC_s*H9*SC_m*SC_n*SC_b*SQRT(2*g_)*G9^1.5 -> 2.493047 | J9: =F9+I9 -> 2.493047 | K9: =F9 -> 0 | L9: =C9*1000000/dt_s+J9/2 -> 5332.6354 | M9: =C9*1000000/dt_s+K9/2 -> 5331.3889
A10: =ROUND(A9+0.1,2) -> 71.5 | B10: =INDEX(Bang_F,MATCH(A10,Bang_Z,1))+(A10-INDEX(Bang_Z,MATCH(A10,Bang_Z,1)))*(INDEX(Bang_F,MATCH(A10,Bang_Z,1)+1)-INDEX(Bang_F,MATCH(A10,Bang_Z,1))) -> 4.25 | C10: =INDEX(Bang_W,MATCH(A10,Bang_Z,1))+(A10-INDEX(Bang_Z,MATCH(A10,Bang_Z,1)))*(INDEX(Bang_F,MATCH(A10,Bang_Z,1))+B10)/2 -> 19.615 | D10: =MAX(A10-TC_Z,0) -> 0 | E10: =1-0.2*(TC_xmb+(TC_n-1)*TC_xmt)*D10/(TC_n*TC_b) -> 1 | F10: =TC_s*E10*TC_m*TC_n*TC_b*SQRT(2*g_)*D10^1.5 -> 0 | G10: =MAX(A10-SC_Z,0) -> 0.5 | H10: =1-0.2*(SC_xmb+(SC_n-1)*SC_xmt)*G10/(SC_n*SC_b) -> 0.986 | I10: =SC_s*H10*SC_m*SC_n*SC_b*SQRT(2*g_)*G10^1.5 -> 3.474273 | J10: =F10+I10 -> 3.474273 | K10: =F10 -> 0 | L10: =C10*1000000/dt_s+J10/2 -> 5450.3482 | M10: =C10*1000000/dt_s+K10/2 -> 5448.6111
A11: =ROUND(A10+0.1,2) -> 71.6 | B11: =INDEX(Bang_F,MATCH(A11,Bang_Z,1))+(A11-INDEX(Bang_Z,MATCH(A11,Bang_Z,1)))*(INDEX(Bang_F,MATCH(A11,Bang_Z,1)+1)-INDEX(Bang_F,MATCH(A11,Bang_Z,1))) -> 4.31 | C11: =INDEX(Bang_W,MATCH(A11,Bang_Z,1))+(A11-INDEX(Bang_Z,MATCH(A11,Bang_Z,1)))*(INDEX(Bang_F,MATCH(A11,Bang_Z,1))+B11)/2 -> 20.043 | D11: =MAX(A11-TC_Z,0) -> 0 | E11: =1-0.2*(TC_xmb+(TC_n-1)*TC_xmt)*D11/(TC_n*TC_b) -> 1 | F11: =TC_s*E11*TC_m*TC_n*TC_b*SQRT(2*g_)*D11^1.5 -> 0 | G11: =MAX(A11-SC_Z,0) -> 0.6 | H11: =1-0.2*(SC_xmb+(SC_n-1)*SC_xmt)*G11/(SC_n*SC_b) -> 0.9832 | I11: =SC_s*H11*SC_m*SC_n*SC_b*SQRT(2*g_)*G11^1.5 -> 4.5540811 | J11: =F11+I11 -> 4.5540811 | K11: =F11 -> 0 | L11: =C11*1000000/dt_s+J11/2 -> 5569.777 | M11: =C11*1000000/dt_s+K11/2 -> 5567.5
A12: =ROUND(A11+0.1,2) -> 71.7 | B12: =INDEX(Bang_F,MATCH(A12,Bang_Z,1))+(A12-INDEX(Bang_Z,MATCH(A12,Bang_Z,1)))*(INDEX(Bang_F,MATCH(A12,Bang_Z,1)+1)-INDEX(Bang_F,MATCH(A12,Bang_Z,1))) -> 4.37 | C12: =INDEX(Bang_W,MATCH(A12,Bang_Z,1))+(A12-INDEX(Bang_Z,MATCH(A12,Bang_Z,1)))*(INDEX(Bang_F,MATCH(A12,Bang_Z,1))+B12)/2 -> 20.477 | D12: =MAX(A12-TC_Z,0) -> 0 | E12: =1-0.2*(TC_xmb+(TC_n-1)*TC_xmt)*D12/(TC_n*TC_b) -> 1 | F12: =TC_s*E12*TC_m*TC_n*TC_b*SQRT(2*g_)*D12^1.5 -> 0 | G12: =MAX(A12-SC_Z,0) -> 0.7 | H12: =1-0.2*(SC_xmb+(SC_n-1)*SC_xmt)*G12/(SC_n*SC_b) -> 0.9804 | I12: =SC_s*H12*SC_m*SC_n*SC_b*SQRT(2*g_)*G12^1.5 -> 5.7224549 | J12: =F12+I12 -> 5.7224549 | K12: =F12 -> 0 | L12: =C12*1000000/dt_s+J12/2 -> 5690.9168 | M12: =C12*1000000/dt_s+K12/2 -> 5688.0556
A13: =ROUND(A12+0.1,2) -> 71.8 | B13: =INDEX(Bang_F,MATCH(A13,Bang_Z,1))+(A13-INDEX(Bang_Z,MATCH(A13,Bang_Z,1)))*(INDEX(Bang_F,MATCH(A13,Bang_Z,1)+1)-INDEX(Bang_F,MATCH(A13,Bang_Z,1))) -> 4.43 | C13: =INDEX(Bang_W,MATCH(A13,Bang_Z,1))+(A13-INDEX(Bang_Z,MATCH(A13,Bang_Z,1)))*(INDEX(Bang_F,MATCH(A13,Bang_Z,1))+B13)/2 -> 20.917 | D13: =MAX(A13-TC_Z,0) -> 0 | E13: =1-0.2*(TC_xmb+(TC_n-1)*TC_xmt)*D13/(TC_n*TC_b) -> 1 | F13: =TC_s*E13*TC_m*TC_n*TC_b*SQRT(2*g_)*D13^1.5 -> 0 | G13: =MAX(A13-SC_Z,0) -> 0.8 | H13: =1-0.2*(SC_xmb+(SC_n-1)*SC_xmt)*G13/(SC_n*SC_b) -> 0.9776 | I13: =SC_s*H13*SC_m*SC_n*SC_b*SQRT(2*g_)*G13^1.5 -> 6.9715315 | J13: =F13+I13 -> 6.9715315 | K13: =F13 -> 0 | L13: =C13*1000000/dt_s+J13/2 -> 5813.7635 | M13: =C13*1000000/dt_s+K13/2 -> 5810.2778
A14: =ROUND(A13+0.1,2) -> 71.9 | B14: =INDEX(Bang_F,MATCH(A14,Bang_Z,1))+(A14-INDEX(Bang_Z,MATCH(A14,Bang_Z,1)))*(INDEX(Bang_F,MATCH(A14,Bang_Z,1)+1)-INDEX(Bang_F,MATCH(A14,Bang_Z,1))) -> 4.49 | C14: =INDEX(Bang_W,MATCH(A14,Bang_Z,1))+(A14-INDEX(Bang_Z,MATCH(A14,Bang_Z,1)))*(INDEX(Bang_F,MATCH(A14,Bang_Z,1))+B14)/2 -> 21.363 | D14: =MAX(A14-TC_Z,0) -> 0 | E14: =1-0.2*(TC_xmb+(TC_n-1)*TC_xmt)*D14/(TC_n*TC_b) -> 1 | F14: =TC_s*E14*TC_m*TC_n*TC_b*SQRT(2*g_)*D14^1.5 -> 0 | G14: =MAX(A14-SC_Z,0) -> 0.9 | H14: =1-0.2*(SC_xmb+(SC_n-1)*SC_xmt)*G14/(SC_n*SC_b) -> 0.9748 | I14: =SC_s*H14*SC_m*SC_n*SC_b*SQRT(2*g_)*G14^1.5 -> 8.2949029 | J14: =F14+I14 -> 8.2949029 | K14: =F14 -> 0 | L14: =C14*1000000/dt_s+J14/2 -> 5938.3141 | M14: =C14*1000000/dt_s+K14/2 -> 5934.1667
A15: =ROUND(A14+0.1,2) -> 72 | B15: =INDEX(Bang_F,MATCH(A15,Bang_Z,1))+(A15-INDEX(Bang_Z,MATCH(A15,Bang_Z,1)))*(INDEX(Bang_F,MATCH(A15,Bang_Z,1)+1)-INDEX(Bang_F,MATCH(A15,Bang_Z,1))) -> 4.55 | C15: =INDEX(Bang_W,MATCH(A15,Bang_Z,1))+(A15-INDEX(Bang_Z,MATCH(A15,Bang_Z,1)))*(INDEX(Bang_F,MATCH(A15,Bang_Z,1))+B15)/2 -> 21.815 | D15: =MAX(A15-TC_Z,0) -> 0 | E15: =1-0.2*(TC_xmb+(TC_n-1)*TC_xmt)*D15/(TC_n*TC_b) -> 1 | F15: =TC_s*E15*TC_m*TC_n*TC_b*SQRT(2*g_)*D15^1.5 -> 0 | G15: =MAX(A15-SC_Z,0) -> 1 | H15: =1-0.2*(SC_xmb+(SC_n-1)*SC_xmt)*G15/(SC_n*SC_b) -> 0.972 | I15: =SC_s*H15*SC_m*SC_n*SC_b*SQRT(2*g_)*G15^1.5 -> 9.6872004 | J15: =F15+I15 -> 9.6872004 | K15: =F15 -> 0 | L15: =C15*1000000/dt_s+J15/2 -> 6064.5658 | M15: =C15*1000000/dt_s+K15/2 -> 6059.7222
A16: =ROUND(A15+0.1,2) -> 72.1 | B16: =INDEX(Bang_F,MATCH(A16,Bang_Z,1))+(A16-INDEX(Bang_Z,MATCH(A16,Bang_Z,1)))*(INDEX(Bang_F,MATCH(A16,Bang_Z,1)+1)-INDEX(Bang_F,MATCH(A16,Bang_Z,1))) -> 4.615 | C16: =INDEX(Bang_W,MATCH(A16,Bang_Z,1))+(A16-INDEX(Bang_Z,MATCH(A16,Bang_Z,1)))*(INDEX(Bang_F,MATCH(A16,Bang_Z,1))+B16)/2 -> 22.27325 | D16: =MAX(A16-TC_Z,0) -> 0 | E16: =1-0.2*(TC_xmb+(TC_n-1)*TC_xmt)*D16/(TC_n*TC_b) -> 1 | F16: =TC_s*E16*TC_m*TC_n*TC_b*SQRT(2*g_)*D16^1.5 -> 0 | G16: =MAX(A16-SC_Z,0) -> 1.1 | H16: =1-0.2*(SC_xmb+(SC_n-1)*SC_xmt)*G16/(SC_n*SC_b) -> 0.9692 | I16: =SC_s*H16*SC_m*SC_n*SC_b*SQRT(2*g_)*G16^1.5 -> 11.143829 | J16: =F16+I16 -> 11.143829 | K16: =F16 -> 0 | L16: =C16*1000000/dt_s+J16/2 -> 6192.5858 | M16: =C16*1000000/dt_s+K16/2 -> 6187.0139
A17: =ROUND(A16+0.1,2) -> 72.2 | B17: =INDEX(Bang_F,MATCH(A17,Bang_Z,1))+(A17-INDEX(Bang_Z,MATCH(A17,Bang_Z,1)))*(INDEX(Bang_F,MATCH(A17,Bang_Z,1)+1)-INDEX(Bang_F,MATCH(A17,Bang_Z,1))) -> 4.68 | C17: =INDEX(Bang_W,MATCH(A17,Bang_Z,1))+(A17-INDEX(Bang_Z,MATCH(A17,Bang_Z,1)))*(INDEX(Bang_F,MATCH(A17,Bang_Z,1))+B17)/2 -> 22.738 | D17: =MAX(A17-TC_Z,0) -> 0 | E17: =1-0.2*(TC_xmb+(TC_n-1)*TC_xmt)*D17/(TC_n*TC_b) -> 1 | F17: =TC_s*E17*TC_m*TC_n*TC_b*SQRT(2*g_)*D17^1.5 -> 0 | G17: =MAX(A17-SC_Z,0) -> 1.2 | H17: =1-0.2*(SC_xmb+(SC_n-1)*SC_xmt)*G17/(SC_n*SC_b) -> 0.9664 | I17: =SC_s*H17*SC_m*SC_n*SC_b*SQRT(2*g_)*G17^1.5 -> 12.66079 | J17: =F17+I17 -> 12.66079 | K17: =F17 -> 0 | L17: =C17*1000000/dt_s+J17/2 -> 6322.4415 | M17: =C17*1000000/dt_s+K17/2 -> 6316.1111
... A105: =ROUND(A104+0.1,2) -> 81 | B105: =INDEX(Bang_F,MATCH(A105,Bang_Z,1))+(A105-INDEX(Bang_Z,MATCH(A105,Bang_Z,1)))*(INDEX(Bang_F,MATCH(A105,Bang_Z,1)+1)-INDEX(Bang_F,MATCH(A105,Bang_Z,1))) -> 9.99 | C105: =INDEX(Bang_W,MATCH(A105,Bang_Z,1))+(A105-INDEX(Bang_Z,MATCH(A105,Bang_Z,1)))*(INDEX(Bang_F,MATCH(A105,Bang_Z,1))+B105)/2 -> 86.315 | D105: =MAX(A105-TC_Z,0) -> 6.3 | E105: =1-0.2*(TC_xmb+(TC_n-1)*TC_xmt)*D105/(TC_n*TC_b) -> 0.74916667 | F105: =TC_s*E105*TC_m*TC_n*TC_b*SQRT(2*g_)*D105^1.5 -> 510.04094 | G105: =MAX(A105-SC_Z,0) -> 10 | H105: =1-0.2*(SC_xmb+(SC_n-1)*SC_xmt)*G105/(SC_n*SC_b) -> 0.72 | I105: =SC_s*H105*SC_m*SC_n*SC_b*SQRT(2*g_)*G105^1.5 -> 226.91568 | J105: =F105+I105 -> 736.95662 | K105: =F105 -> 510.04094 | L105: =C105*1000000/dt_s+J105/2 -> 24344.867 | M105: =C105*1000000/dt_s+K105/2 -> 24231.409

Sheet P1_HaiTran
A1: ĐIỀU TIẾT LŨ – PHƯƠNG PHÁP PÔ-TA-PỐP (Δt = 1 giờ)
A3: Tần suất P (%) | C3: 1 | D3: Trường hợp | F3: Hai tràn | H3: ← sửa ô vàng: P = 1 hoặc 0,2; trường hợp “Hai tràn” hoặc “Kẹt van”
A4: Cột lũ | C4: =MATCH(C3,Lu_P,0) -> 1 | D4: Cột f | F4: =IF(F3="Kẹt van",2,1) -> 1
H5: Giờ 0: Z = MNDBT, q = q(MNDBT) theo trường hợp chọn. Từ giờ 1: f₂ = f₁ + Qtb − q₁ → tìm dòng k, tỷ lệ w
A6: Mực nước lớn nhất Zmax (m) | F6: =MAX(G16:G64) -> 77.607926 | H6: trong bảng QuanHe (cột M, N) → Z₂, q₂, V₂ nội suy với cùng k, w (cột L kiểm tra bằng f₂).
A7: Thời điểm xuất hiện (giờ) | F7: =INDEX(A16:A64,MATCH(MAX(G16:G64),G16:G64,0)) -> 16
A8: Lưu lượng xả lớn nhất qmax (m³/s) | F8: =MAX(J16:J64) -> 326.74824
A9: Lúc Zmax: q tràn chính / q tràn sự cố (m³/s) | F9: =INDEX(H16:H64,MATCH(MAX(G16:G64),G16:G64,0)) -> 188.78102 | G9: =INDEX(I16:I64,MATCH(MAX(G16:G64),G16:G64,0)) -> 137.96722
A10: Cột nước trên ngưỡng lúc Zmax: tràn chính / tràn sự cố (m) | F10: =F6-TC_Z -> 2.9079256 | G10: =F6-SC_Z -> 6.6079256
A11: Dung tích phòng lũ V(Zmax) − V(MNDBT) (10⁶ m³) | F11: =INDEX(K16:K64,MATCH(MAX(G16:G64),G16:G64,0))-K16 -> 20.331377
A12: Cân bằng nước: W đến − W xả − ΔV (10⁶ m³, phải ≈ 0) | F12: =SUMPRODUCT((B16:B63+B17:B64)/2)*dt_s/1000000-SUMPRODUCT((J16:J63+J17:J64)/2)*dt_s/1000000-(K64-K16) -> 1.4210855e-14
A15: t (giờ) | B15: Q đến (m³/s) | C15: Qtb = (Q₁+Q₂)/2 | D15: f₁ (giờ trước) | E15: q₁ (giờ trước) | F15: f₂ = f₁ + Qtb − q₁ | G15: Z₂ (m) | H15: q tràn chính (m³/s) | I15: q tràn sự cố (m³/s) | J15: q xả = tổng (m³/s) | K15: V₂ (10⁶ m³) | L15: Kiểm tra V₂/Δt + q₂/2 (= f₂) | M15: k – dòng tra bảng QuanHe | N15: w – tỷ lệ nội suy
A16: 0 | B16: =IFERROR(INDEX(Lu_Q,MATCH(A16,Lu_t,0),$C$4),0) -> 2 | G16: =Z0 -> 74.7 | H16: =INDEX(QH_qtc,M16)+N16*(INDEX(QH_qtc,M16+1)-INDEX(QH_qtc,M16)) -> 0 | I16: =IF($F$4=2,0,INDEX(QH_qsc,M16)+N16*(INDEX(QH_qsc,M16+1)-INDEX(QH_qsc,M16))) -> 63.582332 | J16: =H16+I16 -> 63.582332 | K16: =INDEX(QH_V,M16)+N16*(INDEX(QH_V,M16+1)-INDEX(QH_V,M16)) -> 36.4117 | L16: =K16*1000000/dt_s+J16/2 -> 10146.152 | M16: =MATCH(G16,QH_Z,1) -> 38 | N16: =(G16-INDEX(QH_Z,M16))/(INDEX(QH_Z,M16+1)-INDEX(QH_Z,M16)) -> 0
A17: 1 | B17: =IFERROR(INDEX(Lu_Q,MATCH(A17,Lu_t,0),$C$4),0) -> 2 | C17: =(B16+B17)/2 -> 2 | D17: =L16 -> 10146.152 | E17: =J16 -> 63.582332 | F17: =D17+C17-E17 -> 10084.57 | G17: =INDEX(QH_Z,M17)+N17*(INDEX(QH_Z,M17+1)-INDEX(QH_Z,M17)) -> 74.664651 | H17: =INDEX(QH_qtc,M17)+N17*(INDEX(QH_qtc,M17+1)-INDEX(QH_qtc,M17)) -> 0 | I17: =IF($F$4=2,0,INDEX(QH_qsc,M17)+N17*(INDEX(QH_qsc,M17+1)-INDEX(QH_qsc,M17))) -> 62.744718 | J17: =H17+I17 -> 62.744718 | K17: =INDEX(QH_V,M17)+N17*(INDEX(QH_V,M17+1)-INDEX(QH_V,M17)) -> 36.191511 | L17: =K17*1000000/dt_s+J17/2 -> 10084.57 | M17: =MATCH(F17,INDEX(QH_f,0,$F$4),1) -> 37 | N17: =(F17-INDEX(QH_f,M17,$F$4))/(INDEX(QH_f,M17+1,$F$4)-INDEX(QH_f,M17,$F$4)) -> 0.64651037
A18: 2 | B18: =IFERROR(INDEX(Lu_Q,MATCH(A18,Lu_t,0),$C$4),0) -> 50 | C18: =(B17+B18)/2 -> 26 | D18: =L17 -> 10084.57 | E18: =J17 -> 62.744718 | F18: =D18+C18-E18 -> 10047.825 | G18: =INDEX(QH_Z,M18)+N18*(INDEX(QH_Z,M18+1)-INDEX(QH_Z,M18)) -> 74.643559 | H18: =INDEX(QH_qtc,M18)+N18*(INDEX(QH_qtc,M18+1)-INDEX(QH_qtc,M18)) -> 0 | I18: =IF($F$4=2,0,INDEX(QH_qsc,M18)+N18*(INDEX(QH_qsc,M18+1)-INDEX(QH_qsc,M18))) -> 62.244934 | J18: =H18+I18 -> 62.244934 | K18: =INDEX(QH_V,M18)+N18*(INDEX(QH_V,M18+1)-INDEX(QH_V,M18)) -> 36.06013 | L18: =K18*1000000/dt_s+J18/2 -> 10047.825 | M18: =MATCH(F18,INDEX(QH_f,0,$F$4),1) -> 37 | N18: =(F18-INDEX(QH_f,M18,$F$4))/(INDEX(QH_f,M18+1,$F$4)-INDEX(QH_f,M18,$F$4)) -> 0.43559148
A19: 3 | B19: =IFERROR(INDEX(Lu_Q,MATCH(A19,Lu_t,0),$C$4),0) -> 207 | C19: =(B18+B19)/2 -> 128.5 | D19: =L18 -> 10047.825 | E19: =J18 -> 62.244934 | F19: =D19+C19-E19 -> 10114.08 | G19: =INDEX(QH_Z,M19)+N19*(INDEX(QH_Z,M19+1)-INDEX(QH_Z,M19)) -> 74.68159 | H19: =INDEX(QH_qtc,M19)+N19*(INDEX(QH_qtc,M19+1)-INDEX(QH_qtc,M19)) -> 0 | I19: =IF($F$4=2,0,INDEX(QH_qsc,M19)+N19*(INDEX(QH_qsc,M19+1)-INDEX(QH_qsc,M19))) -> 63.146104 | J19: =H19+I19 -> 63.146104 | K19: =INDEX(QH_V,M19)+N19*(INDEX(QH_V,M19+1)-INDEX(QH_V,M19)) -> 36.297026 | L19: =K19*1000000/dt_s+J19/2 -> 10114.08 | M19: =MATCH(F19,INDEX(QH_f,0,$F$4),1) -> 37 | N19: =(F19-INDEX(QH_f,M19,$F$4))/(INDEX(QH_f,M19+1,$F$4)-INDEX(QH_f,M19,$F$4)) -> 0.81590314
A20: 4 | B20: =IFERROR(INDEX(Lu_Q,MATCH(A20,Lu_t,0),$C$4),0) -> 437 | C20: =(B19+B20)/2 -> 322 | D20: =L19 -> 10114.08 | E20: =J19 -> 63.146104 | F20: =D20+C20-E20 -> 10372.934 | G20: =INDEX(QH_Z,M20)+N20*(INDEX(QH_Z,M20+1)-INDEX(QH_Z,M20)) -> 74.82794 | H20: =INDEX(QH_qtc,M20)+N20*(INDEX(QH_qtc,M20+1)-INDEX(QH_qtc,M20)) -> 2.0445538 | I20: =IF($F$4=2,0,INDEX(QH_qsc,M20)+N20*(INDEX(QH_qsc,M20+1)-INDEX(QH_qsc,M20))) -> 66.642921 | J20: =H20+I20 -> 68.687475 | K20: =INDEX(QH_V,M20)+N20*(INDEX(QH_V,M20+1)-INDEX(QH_V,M20)) -> 37.218926 | L20: =K20*1000000/dt_s+J20/2 -> 10372.934 | M20: =MATCH(F20,INDEX(QH_f,0,$F$4),1) -> 39 | N20: =(F20-INDEX(QH_f,M20,$F$4))/(INDEX(QH_f,M20+1,$F$4)-INDEX(QH_f,M20,$F$4)) -> 0.27939887
A21: 5 | B21: =IFERROR(INDEX(Lu_Q,MATCH(A21,Lu_t,0),$C$4),0) -> 657 | C21: =(B20+B21)/2 -> 547 | D21: =L20 -> 10372.934 | E21: =J20 -> 68.687475 | F21: =D21+C21-E21 -> 10851.247 | G21: =INDEX(QH_Z,M21)+N21*(INDEX(QH_Z,M21+1)-INDEX(QH_Z,M21)) -> 75.091683 | H21: =INDEX(QH_qtc,M21)+N21*(INDEX(QH_qtc,M21+1)-INDEX(QH_qtc,M21)) -> 10.408375 | I21: =IF($F$4=2,0,INDEX(QH_qsc,M21)+N21*(INDEX(QH_qsc,M21+1)-INDEX(QH_qsc,M21))) -> 73.037212 | J21: =H21+I21 -> 83.445587 | K21: =INDEX(QH_V,M21)+N21*(INDEX(QH_V,M21+1)-INDEX(QH_V,M21)) -> 38.914286 | L21: =K21*1000000/dt_s+J21/2 -> 10851.247 | M21: =MATCH(F21,INDEX(QH_f,0,$F$4),1) -> 41 | N21: =(F21-INDEX(QH_f,M21,$F$4))/(INDEX(QH_f,M21+1,$F$4)-INDEX(QH_f,M21,$F$4)) -> 0.91682523
A22: 6 | B22: =IFERROR(INDEX(Lu_Q,MATCH(A22,Lu_t,0),$C$4),0) -> 816 | C22: =(B21+B22)/2 -> 736.5 | D22: =L21 -> 10851.247 | E22: =J21 -> 83.445587 | F22: =D22+C22-E22 -> 11504.301 | G22: =INDEX(QH_Z,M22)+N22*(INDEX(QH_Z,M22+1)-INDEX(QH_Z,M22)) -> 75.442213 | H22: =INDEX(QH_qtc,M22)+N22*(INDEX(QH_qtc,M22+1)-INDEX(QH_qtc,M22)) -> 26.755391 | I22: =IF($F$4=2,0,INDEX(QH_qsc,M22)+N22*(INDEX(QH_qsc,M22+1)-INDEX(QH_qsc,M22))) -> 81.706093 | J22: =H22+I22 -> 108.46148 | K22: =INDEX(QH_V,M22)+N22*(INDEX(QH_V,M22+1)-INDEX(QH_V,M22)) -> 41.220253 | L22: =K22*1000000/dt_s+J22/2 -> 11504.301 | M22: =MATCH(F22,INDEX(QH_f,0,$F$4),1) -> 45 | N22: =(F22-INDEX(QH_f,M22,$F$4))/(INDEX(QH_f,M22+1,$F$4)-INDEX(QH_f,M22,$F$4)) -> 0.42212885
A23: 7 | B23: =IFERROR(INDEX(Lu_Q,MATCH(A23,Lu_t,0),$C$4),0) -> 898 | C23: =(B22+B23)/2 -> 857 | D23: =L22 -> 11504.301 | E23: =J22 -> 108.46148 | F23: =D23+C23-E23 -> 12252.84 | G23: =INDEX(QH_Z,M23)+N23*(INDEX(QH_Z,M23+1)-INDEX(QH_Z,M23)) -> 75.833257 | H23: =INDEX(QH_qtc,M23)+N23*(INDEX(QH_qtc,M23+1)-INDEX(QH_qtc,M23)) -> 49.623045 | I23: =IF($F$4=2,0,INDEX(QH_qsc,M23)+N23*(INDEX(QH_qsc,M23+1)-INDEX(QH_qsc,M23))) -> 91.56877 | J23: =H23+I23 -> 141.19181 | K23: =INDEX(QH_V,M23)+N23*(INDEX(QH_V,M23+1)-INDEX(QH_V,M23)) -> 43.856077 | L23: =K23*1000000/dt_s+J23/2 -> 12252.84 | M23: =MATCH(F23,INDEX(QH_f,0,$F$4),1) -> 49 | N23: =(F23-INDEX(QH_f,M23,$F$4))/(INDEX(QH_f,M23+1,$F$4)-INDEX(QH_f,M23,$F$4)) -> 0.3325687
A24: 8 | B24: =IFERROR(INDEX(Lu_Q,MATCH(A24,Lu_t,0),$C$4),0) -> 914 | C24: =(B23+B24)/2 -> 906 | D24: =L23 -> 12252.84 | E24: =J23 -> 141.19181 | F24: =D24+C24-E24 -> 13017.648 | G24: =INDEX(QH_Z,M24)+N24*(INDEX(QH_Z,M24+1)-INDEX(QH_Z,M24)) -> 76.221928 | H24: =INDEX(QH_qtc,M24)+N24*(INDEX(QH_qtc,M24+1)-INDEX(QH_qtc,M24)) -> 75.953554 | I24: =IF($F$4=2,0,INDEX(QH_qsc,M24)+N24*(INDEX(QH_qsc,M24+1)-INDEX(QH_qsc,M24))) -> 101.53847 | J24: =H24+I24 -> 177.49202 | K24: =INDEX(QH_V,M24)+N24*(INDEX(QH_V,M24+1)-INDEX(QH_V,M24)) -> 46.544047 | L24: =K24*1000000/dt_s+J24/2 -> 13017.648 | M24: =MATCH(F24,INDEX(QH_f,0,$F$4),1) -> 53 | N24: =(F24-INDEX(QH_f,M24,$F$4))/(INDEX(QH_f,M24+1,$F$4)-INDEX(QH_f,M24,$F$4)) -> 0.21928334
A25: 9 | B25: =IFERROR(INDEX(Lu_Q,MATCH(A25,Lu_t,0),$C$4),0) -> 879 | C25: =(B24+B25)/2 -> 896.5 | D25: =L24 -> 13017.648 | E25: =J24 -> 177.49202 | F25: =D25+C25-E25 -> 13736.656 | G25: =INDEX(QH_Z,M25)+N25*(INDEX(QH_Z,M25+1)-INDEX(QH_Z,M25)) -> 76.577434 | H25: =INDEX(QH_qtc,M25)+N25*(INDEX(QH_qtc,M25+1)-INDEX(QH_qtc,M25)) -> 102.48897 | I25: =IF($F$4=2,0,INDEX(QH_qsc,M25)+N25*(INDEX(QH_qsc,M25+1)-INDEX(QH_qsc,M25))) -> 110.77505 | J25: =H25+I25 -> 213.26402 | K25: =INDEX(QH_V,M25)+N25*(INDEX(QH_V,M25+1)-INDEX(QH_V,M25)) -> 49.068086 | L25: =K25*1000000/dt_s+J25/2 -> 13736.656 | M25: =MATCH(F25,INDEX(QH_f,0,$F$4),1) -> 56 | N25: =(F25-INDEX(QH_f,M25,$F$4))/(INDEX(QH_f,M25+1,$F$4)-INDEX(QH_f,M25,$F$4)) -> 0.77433545
A26: 10 | B26: =IFERROR(INDEX(Lu_Q,MATCH(A26,Lu_t,0),$C$4),0) -> 812 | C26: =(B25+B26)/2 -> 845.5 | D26: =L25 -> 13736.656 | E26: =J25 -> 213.26402 | F26: =D26+C26-E26 -> 14368.892 | G26: =INDEX(QH_Z,M26)+N26*(INDEX(QH_Z,M26+1)-INDEX(QH_Z,M26)) -> 76.88273 | H26: =INDEX(QH_qtc,M26)+N26*(INDEX(QH_qtc,M26+1)-INDEX(QH_qtc,M26)) -> 126.78343 | I26: =IF($F$4=2,0,INDEX(QH_qsc,M26)+N26*(INDEX(QH_qsc,M26+1)-INDEX(QH_qsc,M26))) -> 118.77795 | J26: =H26+I26 -> 245.56138 | K26: =INDEX(QH_V,M26)+N26*(INDEX(QH_V,M26+1)-INDEX(QH_V,M26)) -> 51.286 | L26: =K26*1000000/dt_s+J26/2 -> 14368.892 | M26: =MATCH(F26,INDEX(QH_f,0,$F$4),1) -> 59 | N26: =(F26-INDEX(QH_f,M26,$F$4))/(INDEX(QH_f,M26+1,$F$4)-INDEX(QH_f,M26,$F$4)) -> 0.82730373
A27: 11 | B27: =IFERROR(INDEX(Lu_Q,MATCH(A27,Lu_t,0),$C$4),0) -> 727 | C27: =(B26+B27)/2 -> 769.5 | D27: =L26 -> 14368.892 | E27: =J26 -> 245.56138 | F27: =D27+C27-E27 -> 14892.83 | G27: =INDEX(QH_Z,M27)+N27*(INDEX(QH_Z,M27+1)-INDEX(QH_Z,M27)) -> 77.130864 | H27: =INDEX(QH_qtc,M27)+N27*(INDEX(QH_qtc,M27+1)-INDEX(QH_qtc,M27)) -> 147.39456 | I27: =IF($F$4=2,0,INDEX(QH_qsc,M27)+N27*(INDEX(QH_qsc,M27+1)-INDEX(QH_qsc,M27))) -> 125.32061 | J27: =H27+I27 -> 272.71517 | K27: =INDEX(QH_V,M27)+N27*(INDEX(QH_V,M27+1)-INDEX(QH_V,M27)) -> 53.123302 | L27: =K27*1000000/dt_s+J27/2 -> 14892.83 | M27: =MATCH(F27,INDEX(QH_f,0,$F$4),1) -> 62 | N27: =(F27-INDEX(QH_f,M27,$F$4))/(INDEX(QH_f,M27+1,$F$4)-INDEX(QH_f,M27,$F$4)) -> 0.30863665
A28: 12 | B28: =IFERROR(INDEX(Lu_Q,MATCH(A28,Lu_t,0),$C$4),0) -> 636 | C28: =(B27+B28)/2 -> 681.5 | D28: =L27 -> 14892.83 | E28: =J27 -> 272.71517 | F28: =D28+C28-E28 -> 15301.615 | G28: =INDEX(QH_Z,M28)+N28*(INDEX(QH_Z,M28+1)-INDEX(QH_Z,M28)) -> 77.321584 | H28: =INDEX(QH_qtc,M28)+N28*(INDEX(QH_qtc,M28+1)-INDEX(QH_qtc,M28)) -> 163.68441 | I28: =IF($F$4=2,0,INDEX(QH_qsc,M28)+N28*(INDEX(QH_qsc,M28+1)-INDEX(QH_qsc,M28))) -> 130.3675 | J28: =H28+I28 -> 294.05191 | K28: =INDEX(QH_V,M28)+N28*(INDEX(QH_V,M28+1)-INDEX(QH_V,M28)) -> 54.556521 | L28: =K28*1000000/dt_s+J28/2 -> 15301.615 | M28: =MATCH(F28,INDEX(QH_f,0,$F$4),1) -> 64 | N28: =(F28-INDEX(QH_f,M28,$F$4))/(INDEX(QH_f,M28+1,$F$4)-INDEX(QH_f,M28,$F$4)) -> 0.21583617
... A64: 48 | B64: =IFERROR(INDEX(Lu_Q,MATCH(A64,Lu_t,0),$C$4),0) -> 0 | C64: =(B63+B64)/2 -> 0 | D64: =L63 -> 11127.603 | E64: =J63 -> 93.528061 | F64: =D64+C64-E64 -> 11034.075 | G64: =INDEX(QH_Z,M64)+N64*(INDEX(QH_Z,M64+1)-INDEX(QH_Z,M64)) -> 75.190786 | H64: =INDEX(QH_qtc,M64)+N64*(INDEX(QH_qtc,M64+1)-INDEX(QH_qtc,M64)) -> 14.531889 | I64: =IF($F$4=2,0,INDEX(QH_qsc,M64)+N64*(INDEX(QH_qsc,M64+1)-INDEX(QH_qsc,M64))) -> 75.469473 | J64: =H64+I64 -> 90.001362 | K64: =INDEX(QH_V,M64)+N64*(INDEX(QH_V,M64+1)-INDEX(QH_V,M64)) -> 39.560667 | L64: =K64*1000000/dt_s+J64/2 -> 11034.075 | M64: =MATCH(F64,INDEX(QH_f,0,$F$4),1) -> 42 | N64: =(F64-INDEX(QH_f,M64,$F$4))/(INDEX(QH_f,M64+1,$F$4)-INDEX(QH_f,M64,$F$4)) -> 0.90785556

Sheet P1_KetVan
A1: ĐIỀU TIẾT LŨ – PHƯƠNG PHÁP PÔ-TA-PỐP (Δt = 1 giờ)
A3: Tần suất P (%) | C3: 1 | D3: Trường hợp | F3: Kẹt van | H3: ← sửa ô vàng: P = 1 hoặc 0,2; trường hợp “Hai tràn” hoặc “Kẹt van”
A4: Cột lũ | C4: =MATCH(C3,Lu_P,0) -> 1 | D4: Cột f | F4: =IF(F3="Kẹt van",2,1) -> 2
H5: Giờ 0: Z = MNDBT, q = q(MNDBT) theo trường hợp chọn. Từ giờ 1: f₂ = f₁ + Qtb − q₁ → tìm dòng k, tỷ lệ w
A6: Mực nước lớn nhất Zmax (m) | F6: =MAX(G16:G64) -> 78.204802 | H6: trong bảng QuanHe (cột M, N) → Z₂, q₂, V₂ nội suy với cùng k, w (cột L kiểm tra bằng f₂).
A7: Thời điểm xuất hiện (giờ) | F7: =INDEX(A16:A64,MATCH(MAX(G16:G64),G16:G64,0)) -> 17
A8: Lưu lượng xả lớn nhất qmax (m³/s) | F8: =MAX(J16:J64) -> 243.07612
A9: Lúc Zmax: q tràn chính / q tràn sự cố (m³/s) | F9: =INDEX(H16:H64,MATCH(MAX(G16:G64),G16:G64,0)) -> 243.07612 | G9: =INDEX(I16:I64,MATCH(MAX(G16:G64),G16:G64,0)) -> 0
A10: Cột nước trên ngưỡng lúc Zmax: tràn chính / tràn sự cố (m) | F10: =F6-TC_Z -> 3.5048024 | G10: =F6-SC_Z -> 7.2048024
A11: Dung tích phòng lũ V(Zmax) − V(MNDBT) (10⁶ m³) | F11: =INDEX(K16:K64,MATCH(MAX(G16:G64),G16:G64,0))-K16 -> 25.024311
A12: Cân bằng nước: W đến − W xả − ΔV (10⁶ m³, phải ≈ 0) | F12: =SUMPRODUCT((B16:B63+B17:B64)/2)*dt_s/1000000-SUMPRODUCT((J16:J63+J17:J64)/2)*dt_s/1000000-(K64-K16) -> 6.0396133e-14
A15: t (giờ) | B15: Q đến (m³/s) | C15: Qtb = (Q₁+Q₂)/2 | D15: f₁ (giờ trước) | E15: q₁ (giờ trước) | F15: f₂ = f₁ + Qtb − q₁ | G15: Z₂ (m) | H15: q tràn chính (m³/s) | I15: q tràn sự cố (m³/s) | J15: q xả = tổng (m³/s) | K15: V₂ (10⁶ m³) | L15: Kiểm tra V₂/Δt + q₂/2 (= f₂) | M15: k – dòng tra bảng QuanHe | N15: w – tỷ lệ nội suy
A16: 0 | B16: =IFERROR(INDEX(Lu_Q,MATCH(A16,Lu_t,0),$C$4),0) -> 2 | G16: =Z0 -> 74.7 | H16: =INDEX(QH_qtc,M16)+N16*(INDEX(QH_qtc,M16+1)-INDEX(QH_qtc,M16)) -> 0 | I16: =IF($F$4=2,0,INDEX(QH_qsc,M16)+N16*(INDEX(QH_qsc,M16+1)-INDEX(QH_qsc,M16))) -> 0 | J16: =H16+I16 -> 0 | K16: =INDEX(QH_V,M16)+N16*(INDEX(QH_V,M16+1)-INDEX(QH_V,M16)) -> 36.4117 | L16: =K16*1000000/dt_s+J16/2 -> 10114.361 | M16: =MATCH(G16,QH_Z,1) -> 38 | N16: =(G16-INDEX(QH_Z,M16))/(INDEX(QH_Z,M16+1)-INDEX(QH_Z,M16)) -> 0
A17: 1 | B17: =IFERROR(INDEX(Lu_Q,MATCH(A17,Lu_t,0),$C$4),0) -> 2 | C17: =(B16+B17)/2 -> 2 | D17: =L16 -> 10114.361 | E17: =J16 -> 0 | F17: =D17+C17-E17 -> 10116.361 | G17: =INDEX(QH_Z,M17)+N17*(INDEX(QH_Z,M17+1)-INDEX(QH_Z,M17)) -> 74.701139 | H17: =INDEX(QH_qtc,M17)+N17*(INDEX(QH_qtc,M17+1)-INDEX(QH_qtc,M17)) -> 0.015450381 | I17: =IF($F$4=2,0,INDEX(QH_qsc,M17)+N17*(INDEX(QH_qsc,M17+1)-INDEX(QH_qsc,M17))) -> 0 | J17: =H17+I17 -> 0.015450381 | K17: =INDEX(QH_V,M17)+N17*(INDEX(QH_V,M17+1)-INDEX(QH_V,M17)) -> 36.418872 | L17: =K17*1000000/dt_s+J17/2 -> 10116.361 | M17: =MATCH(F17,INDEX(QH_f,0,$F$4),1) -> 38 | N17: =(F17-INDEX(QH_f,M17,$F$4))/(INDEX(QH_f,M17+1,$F$4)-INDEX(QH_f,M17,$F$4)) -> 0.01139347
A18: 2 | B18: =IFERROR(INDEX(Lu_Q,MATCH(A18,Lu_t,0),$C$4),0) -> 50 | C18: =(B17+B18)/2 -> 26 | D18: =L17 -> 10116.361 | E18: =J17 -> 0.015450381 | F18: =D18+C18-E18 -> 10142.346 | G18: =INDEX(QH_Z,M18)+N18*(INDEX(QH_Z,M18+1)-INDEX(QH_Z,M18)) -> 74.715942 | H18: =INDEX(QH_qtc,M18)+N18*(INDEX(QH_qtc,M18+1)-INDEX(QH_qtc,M18)) -> 0.21618597 | I18: =IF($F$4=2,0,INDEX(QH_qsc,M18)+N18*(INDEX(QH_qsc,M18+1)-INDEX(QH_qsc,M18))) -> 0 | J18: =H18+I18 -> 0.21618597 | K18: =INDEX(QH_V,M18)+N18*(INDEX(QH_V,M18+1)-INDEX(QH_V,M18)) -> 36.512055 | L18: =K18*1000000/dt_s+J18/2 -> 10142.346 | M18: =MATCH(F18,INDEX(QH_f,0,$F$4),1) -> 38 | N18: =(F18-INDEX(QH_f,M18,$F$4))/(INDEX(QH_f,M18+1,$F$4)-INDEX(QH_f,M18,$F$4)) -> 0.15942056
A19: 3 | B19: =IFERROR(INDEX(Lu_Q,MATCH(A19,Lu_t,0),$C$4),0) -> 207 | C19: =(B18+B19)/2 -> 128.5 | D19: =L18 -> 10142.346 | E19: =J18 -> 0.21618597 | F19: =D19+C19-E19 -> 10270.629 | G19: =INDEX(QH_Z,M19)+N19*(INDEX(QH_Z,M19+1)-INDEX(QH_Z,M19)) -> 74.789022 | H19: =INDEX(QH_qtc,M19)+N19*(INDEX(QH_qtc,M19+1)-INDEX(QH_qtc,M19)) -> 1.2072029 | I19: =IF($F$4=2,0,INDEX(QH_qsc,M19)+N19*(INDEX(QH_qsc,M19+1)-INDEX(QH_qsc,M19))) -> 0 | J19: =H19+I19 -> 1.2072029 | K19: =INDEX(QH_V,M19)+N19*(INDEX(QH_V,M19+1)-INDEX(QH_V,M19)) -> 36.972093 | L19: =K19*1000000/dt_s+J19/2 -> 10270.629 | M19: =MATCH(F19,INDEX(QH_f,0,$F$4),1) -> 38 | N19: =(F19-INDEX(QH_f,M19,$F$4))/(INDEX(QH_f,M19+1,$F$4)-INDEX(QH_f,M19,$F$4)) -> 0.89021945
A20: 4 | B20: =IFERROR(INDEX(Lu_Q,MATCH(A20,Lu_t,0),$C$4),0) -> 437 | C20: =(B19+B20)/2 -> 322 | D20: =L19 -> 10270.629 | E20: =J19 -> 1.2072029 | F20: =D20+C20-E20 -> 10591.422 | G20: =INDEX(QH_Z,M20)+N20*(INDEX(QH_Z,M20+1)-INDEX(QH_Z,M20)) -> 74.968621 | H20: =INDEX(QH_qtc,M20)+N20*(INDEX(QH_qtc,M20+1)-INDEX(QH_qtc,M20)) -> 5.9953823 | I20: =IF($F$4=2,0,INDEX(QH_qsc,M20)+N20*(INDEX(QH_qsc,M20+1)-INDEX(QH_qsc,M20))) -> 0 | J20: =H20+I20 -> 5.9953823 | K20: =INDEX(QH_V,M20)+N20*(INDEX(QH_V,M20+1)-INDEX(QH_V,M20)) -> 38.118328 | L20: =K20*1000000/dt_s+J20/2 -> 10591.422 | M20: =MATCH(F20,INDEX(QH_f,0,$F$4),1) -> 40 | N20: =(F20-INDEX(QH_f,M20,$F$4))/(INDEX(QH_f,M20+1,$F$4)-INDEX(QH_f,M20,$F$4)) -> 0.68621206
A21: 5 | B21: =IFERROR(INDEX(Lu_Q,MATCH(A21,Lu_t,0),$C$4),0) -> 657 | C21: =(B20+B21)/2 -> 547 | D21: =L20 -> 10591.422 | E21: =J20 -> 5.9953823 | F21: =D21+C21-E21 -> 11132.427 | G21: =INDEX(QH_Z,M21)+N21*(INDEX(QH_Z,M21+1)-INDEX(QH_Z,M21)) -> 75.264494 | H21: =INDEX(QH_qtc,M21)+N21*(INDEX(QH_qtc,M21+1)-INDEX(QH_qtc,M21)) -> 17.893961 | I21: =IF($F$4=2,0,INDEX(QH_qsc,M21)+N21*(INDEX(QH_qsc,M21+1)-INDEX(QH_qsc,M21))) -> 0 | J21: =H21+I21 -> 17.893961 | K21: =INDEX(QH_V,M21)+N21*(INDEX(QH_V,M21+1)-INDEX(QH_V,M21)) -> 40.044528 | L21: =K21*1000000/dt_s+J21/2 -> 11132.427 | M21: =MATCH(F21,INDEX(QH_f,0,$F$4),1) -> 43 | N21: =(F21-INDEX(QH_f,M21,$F$4))/(INDEX(QH_f,M21+1,$F$4)-INDEX(QH_f,M21,$F$4)) -> 0.64494319
A22: 6 | B22: =IFERROR(INDEX(Lu_Q,MATCH(A22,Lu_t,0),$C$4),0) -> 816 | C22: =(B21+B22)/2 -> 736.5 | D22: =L21 -> 11132.427 | E22: =J21 -> 17.893961 | F22: =D22+C22-E22 -> 11851.033 | G22: =INDEX(QH_Z,M22)+N22*(INDEX(QH_Z,M22+1)-INDEX(QH_Z,M22)) -> 75.64739 | H22: =INDEX(QH_qtc,M22)+N22*(INDEX(QH_qtc,M22+1)-INDEX(QH_qtc,M22)) -> 38.237633 | I22: =IF($F$4=2,0,INDEX(QH_qsc,M22)+N22*(INDEX(QH_qsc,M22+1)-INDEX(QH_qsc,M22))) -> 0 | J22: =H22+I22 -> 38.237633 | K22: =INDEX(QH_V,M22)+N22*(INDEX(QH_V,M22+1)-INDEX(QH_V,M22)) -> 42.594891 | L22: =K22*1000000/dt_s+J22/2 -> 11851.033 | M22: =MATCH(F22,INDEX(QH_f,0,$F$4),1) -> 47 | N22: =(F22-INDEX(QH_f,M22,$F$4))/(INDEX(QH_f,M22+1,$F$4)-INDEX(QH_f,M22,$F$4)) -> 0.47389683
A23: 7 | B23: =IFERROR(INDEX(Lu_Q,MATCH(A23,Lu_t,0),$C$4),0) -> 898 | C23: =(B22+B23)/2 -> 857 | D23: =L22 -> 11851.033 | E23: =J22 -> 38.237633 | F23: =D23+C23-E23 -> 12669.795 | G23: =INDEX(QH_Z,M23)+N23*(INDEX(QH_Z,M23+1)-INDEX(QH_Z,M23)) -> 76.071274 | H23: =INDEX(QH_qtc,M23)+N23*(INDEX(QH_qtc,M23+1)-INDEX(QH_qtc,M23)) -> 65.381807 | I23: =IF($F$4=2,0,INDEX(QH_qsc,M23)+N23*(INDEX(QH_qsc,M23+1)-INDEX(QH_qsc,M23))) -> 0 | J23: =H23+I23 -> 65.381807 | K23: =INDEX(QH_V,M23)+N23*(INDEX(QH_V,M23+1)-INDEX(QH_V,M23)) -> 45.493576 | L23: =K23*1000000/dt_s+J23/2 -> 12669.795 | M23: =MATCH(F23,INDEX(QH_f,0,$F$4),1) -> 51 | N23: =(F23-INDEX(QH_f,M23,$F$4))/(INDEX(QH_f,M23+1,$F$4)-INDEX(QH_f,M23,$F$4)) -> 0.71274485
A24: 8 | B24: =IFERROR(INDEX(Lu_Q,MATCH(A24,Lu_t,0),$C$4),0) -> 914 | C24: =(B23+B24)/2 -> 906 | D24: =L23 -> 12669.795 | E24: =J23 -> 65.381807 | F24: =D24+C24-E24 -> 13510.413 | G24: =INDEX(QH_Z,M24)+N24*(INDEX(QH_Z,M24+1)-INDEX(QH_Z,M24)) -> 76.493286 | H24: =INDEX(QH_qtc,M24)+N24*(INDEX(QH_qtc,M24+1)-INDEX(QH_qtc,M24)) -> 96.015496 | I24: =IF($F$4=2,0,INDEX(QH_qsc,M24)+N24*(INDEX(QH_qsc,M24+1)-INDEX(QH_qsc,M24))) -> 0 | J24: =H24+I24 -> 96.015496 | K24: =INDEX(QH_V,M24)+N24*(INDEX(QH_V,M24+1)-INDEX(QH_V,M24)) -> 48.464661 | L24: =K24*1000000/dt_s+J24/2 -> 13510.413 | M24: =MATCH(F24,INDEX(QH_f,0,$F$4),1) -> 55 | N24: =(F24-INDEX(QH_f,M24,$F$4))/(INDEX(QH_f,M24+1,$F$4)-INDEX(QH_f,M24,$F$4)) -> 0.93285708
A25: 9 | B25: =IFERROR(INDEX(Lu_Q,MATCH(A25,Lu_t,0),$C$4),0) -> 879 | C25: =(B24+B25)/2 -> 896.5 | D25: =L24 -> 13510.413 | E25: =J24 -> 96.015496 | F25: =D25+C25-E25 -> 14310.898 | G25: =INDEX(QH_Z,M25)+N25*(INDEX(QH_Z,M25+1)-INDEX(QH_Z,M25)) -> 76.883403 | H25: =INDEX(QH_qtc,M25)+N25*(INDEX(QH_qtc,M25+1)-INDEX(QH_qtc,M25)) -> 126.83801 | I25: =IF($F$4=2,0,INDEX(QH_qsc,M25)+N25*(INDEX(QH_qsc,M25+1)-INDEX(QH_qsc,M25))) -> 0 | J25: =H25+I25 -> 126.83801 | K25: =INDEX(QH_V,M25)+N25*(INDEX(QH_V,M25+1)-INDEX(QH_V,M25)) -> 51.290924 | L25: =K25*1000000/dt_s+J25/2 -> 14310.898 | M25: =MATCH(F25,INDEX(QH_f,0,$F$4),1) -> 59 | N25: =(F25-INDEX(QH_f,M25,$F$4))/(INDEX(QH_f,M25+1,$F$4)-INDEX(QH_f,M25,$F$4)) -> 0.83402643
A26: 10 | B26: =IFERROR(INDEX(Lu_Q,MATCH(A26,Lu_t,0),$C$4),0) -> 812 | C26: =(B25+B26)/2 -> 845.5 | D26: =L25 -> 14310.898 | E26: =J25 -> 126.83801 | F26: =D26+C26-E26 -> 15029.56 | G26: =INDEX(QH_Z,M26)+N26*(INDEX(QH_Z,M26+1)-INDEX(QH_Z,M26)) -> 77.224782 | H26: =INDEX(QH_qtc,M26)+N26*(INDEX(QH_qtc,M26+1)-INDEX(QH_qtc,M26)) -> 155.37011 | I26: =IF($F$4=2,0,INDEX(QH_qsc,M26)+N26*(INDEX(QH_qsc,M26+1)-INDEX(QH_qsc,M26))) -> 0 | J26: =H26+I26 -> 155.37011 | K26: =INDEX(QH_V,M26)+N26*(INDEX(QH_V,M26+1)-INDEX(QH_V,M26)) -> 53.82675 | L26: =K26*1000000/dt_s+J26/2 -> 15029.56 | M26: =MATCH(F26,INDEX(QH_f,0,$F$4),1) -> 63 | N26: =(F26-INDEX(QH_f,M26,$F$4))/(INDEX(QH_f,M26+1,$F$4)-INDEX(QH_f,M26,$F$4)) -> 0.24782431
A27: 11 | B27: =IFERROR(INDEX(Lu_Q,MATCH(A27,Lu_t,0),$C$4),0) -> 727 | C27: =(B26+B27)/2 -> 769.5 | D27: =L26 -> 15029.56 | E27: =J26 -> 155.37011 | F27: =D27+C27-E27 -> 15643.69 | G27: =INDEX(QH_Z,M27)+N27*(INDEX(QH_Z,M27+1)-INDEX(QH_Z,M27)) -> 77.510321 | H27: =INDEX(QH_qtc,M27)+N27*(INDEX(QH_qtc,M27+1)-INDEX(QH_qtc,M27)) -> 180.14597 | I27: =IF($F$4=2,0,INDEX(QH_qsc,M27)+N27*(INDEX(QH_qsc,M27+1)-INDEX(QH_qsc,M27))) -> 0 | J27: =H27+I27 -> 180.14597 | K27: =INDEX(QH_V,M27)+N27*(INDEX(QH_V,M27+1)-INDEX(QH_V,M27)) -> 55.993021 | L27: =K27*1000000/dt_s+J27/2 -> 15643.69 | M27: =MATCH(F27,INDEX(QH_f,0,$F$4),1) -> 66 | N27: =(F27-INDEX(QH_f,M27,$F$4))/(INDEX(QH_f,M27+1,$F$4)-INDEX(QH_f,M27,$F$4)) -> 0.10321046
A28: 12 | B28: =IFERROR(INDEX(Lu_Q,MATCH(A28,Lu_t,0),$C$4),0) -> 636 | C28: =(B27+B28)/2 -> 681.5 | D28: =L27 -> 15643.69 | E28: =J27 -> 180.14597 | F28: =D28+C28-E28 -> 16145.044 | G28: =INDEX(QH_Z,M28)+N28*(INDEX(QH_Z,M28+1)-INDEX(QH_Z,M28)) -> 77.739351 | H28: =INDEX(QH_qtc,M28)+N28*(INDEX(QH_qtc,M28+1)-INDEX(QH_qtc,M28)) -> 200.53451 | I28: =IF($F$4=2,0,INDEX(QH_qsc,M28)+N28*(INDEX(QH_qsc,M28+1)-INDEX(QH_qsc,M28))) -> 0 | J28: =H28+I28 -> 200.53451 | K28: =INDEX(QH_V,M28)+N28*(INDEX(QH_V,M28+1)-INDEX(QH_V,M28)) -> 57.761196 | L28: =K28*1000000/dt_s+J28/2 -> 16145.044 | M28: =MATCH(F28,INDEX(QH_f,0,$F$4),1) -> 68 | N28: =(F28-INDEX(QH_f,M28,$F$4))/(INDEX(QH_f,M28+1,$F$4)-INDEX(QH_f,M28,$F$4)) -> 0.39350583
... A64: 48 | B64: =IFERROR(INDEX(Lu_Q,MATCH(A64,Lu_t,0),$C$4),0) -> 0 | C64: =(B63+B64)/2 -> 0 | D64: =L63 -> 13339.619 | E64: =J63 -> 89.621397 | F64: =D64+C64-E64 -> 13249.997 | G64: =INDEX(QH_Z,M64)+N64*(INDEX(QH_Z,M64+1)-INDEX(QH_Z,M64)) -> 76.363907 | H64: =INDEX(QH_qtc,M64)+N64*(INDEX(QH_qtc,M64+1)-INDEX(QH_qtc,M64)) -> 86.305495 | I64: =IF($F$4=2,0,INDEX(QH_qsc,M64)+N64*(INDEX(QH_qsc,M64+1)-INDEX(QH_qsc,M64))) -> 0 | J64: =H64+I64 -> 86.305495 | K64: =INDEX(QH_V,M64)+N64*(INDEX(QH_V,M64+1)-INDEX(QH_V,M64)) -> 47.54464 | L64: =K64*1000000/dt_s+J64/2 -> 13249.997 | M64: =MATCH(F64,INDEX(QH_f,0,$F$4),1) -> 54 | N64: =(F64-INDEX(QH_f,M64,$F$4))/(INDEX(QH_f,M64+1,$F$4)-INDEX(QH_f,M64,$F$4)) -> 0.63906777

Sheet P02_HaiTran
A1: ĐIỀU TIẾT LŨ – PHƯƠNG PHÁP PÔ-TA-PỐP (Δt = 1 giờ)
A3: Tần suất P (%) | C3: 0.2 | D3: Trường hợp | F3: Hai tràn | H3: ← sửa ô vàng: P = 1 hoặc 0,2; trường hợp “Hai tràn” hoặc “Kẹt van”
A4: Cột lũ | C4: =MATCH(C3,Lu_P,0) -> 2 | D4: Cột f | F4: =IF(F3="Kẹt van",2,1) -> 1
H5: Giờ 0: Z = MNDBT, q = q(MNDBT) theo trường hợp chọn. Từ giờ 1: f₂ = f₁ + Qtb − q₁ → tìm dòng k, tỷ lệ w
A6: Mực nước lớn nhất Zmax (m) | F6: =MAX(G16:G64) -> 78.51436 | H6: trong bảng QuanHe (cột M, N) → Z₂, q₂, V₂ nội suy với cùng k, w (cột L kiểm tra bằng f₂).
A7: Thời điểm xuất hiện (giờ) | F7: =INDEX(A16:A64,MATCH(MAX(G16:G64),G16:G64,0)) -> 15
A8: Lưu lượng xả lớn nhất qmax (m³/s) | F8: =MAX(J16:J64) -> 434.12651
A9: Lúc Zmax: q tràn chính / q tràn sự cố (m³/s) | F9: =INDEX(H16:H64,MATCH(MAX(G16:G64),G16:G64,0)) -> 272.02921 | G9: =INDEX(I16:I64,MATCH(MAX(G16:G64),G16:G64,0)) -> 162.0973
A10: Cột nước trên ngưỡng lúc Zmax: tràn chính / tràn sự cố (m) | F10: =F6-TC_Z -> 3.8143601 | G10: =F6-SC_Z -> 7.5143601
A11: Dung tích phòng lũ V(Zmax) − V(MNDBT) (10⁶ m³) | F11: =INDEX(K16:K64,MATCH(MAX(G16:G64),G16:G64,0))-K16 -> 27.530995
A12: Cân bằng nước: W đến − W xả − ΔV (10⁶ m³, phải ≈ 0) | F12: =SUMPRODUCT((B16:B63+B17:B64)/2)*dt_s/1000000-SUMPRODUCT((J16:J63+J17:J64)/2)*dt_s/1000000-(K64-K16) -> 0
A15: t (giờ) | B15: Q đến (m³/s) | C15: Qtb = (Q₁+Q₂)/2 | D15: f₁ (giờ trước) | E15: q₁ (giờ trước) | F15: f₂ = f₁ + Qtb − q₁ | G15: Z₂ (m) | H15: q tràn chính (m³/s) | I15: q tràn sự cố (m³/s) | J15: q xả = tổng (m³/s) | K15: V₂ (10⁶ m³) | L15: Kiểm tra V₂/Δt + q₂/2 (= f₂) | M15: k – dòng tra bảng QuanHe | N15: w – tỷ lệ nội suy
A16: 0 | B16: =IFERROR(INDEX(Lu_Q,MATCH(A16,Lu_t,0),$C$4),0) -> 4 | G16: =Z0 -> 74.7 | H16: =INDEX(QH_qtc,M16)+N16*(INDEX(QH_qtc,M16+1)-INDEX(QH_qtc,M16)) -> 0 | I16: =IF($F$4=2,0,INDEX(QH_qsc,M16)+N16*(INDEX(QH_qsc,M16+1)-INDEX(QH_qsc,M16))) -> 63.582332 | J16: =H16+I16 -> 63.582332 | K16: =INDEX(QH_V,M16)+N16*(INDEX(QH_V,M16+1)-INDEX(QH_V,M16)) -> 36.4117 | L16: =K16*1000000/dt_s+J16/2 -> 10146.152 | M16: =MATCH(G16,QH_Z,1) -> 38 | N16: =(G16-INDEX(QH_Z,M16))/(INDEX(QH_Z,M16+1)-INDEX(QH_Z,M16)) -> 0
A17: 1 | B17: =IFERROR(INDEX(Lu_Q,MATCH(A17,Lu_t,0),$C$4),0) -> 4 | C17: =(B16+B17)/2 -> 4 | D17: =L16 -> 10146.152 | E17: =J16 -> 63.582332 | F17: =D17+C17-E17 -> 10086.57 | G17: =INDEX(QH_Z,M17)+N17*(INDEX(QH_Z,M17+1)-INDEX(QH_Z,M17)) -> 74.665799 | H17: =INDEX(QH_qtc,M17)+N17*(INDEX(QH_qtc,M17+1)-INDEX(QH_qtc,M17)) -> 0 | I17: =IF($F$4=2,0,INDEX(QH_qsc,M17)+N17*(INDEX(QH_qsc,M17+1)-INDEX(QH_qsc,M17))) -> 62.771921 | J17: =H17+I17 -> 62.771921 | K17: =INDEX(QH_V,M17)+N17*(INDEX(QH_V,M17+1)-INDEX(QH_V,M17)) -> 36.198662 | L17: =K17*1000000/dt_s+J17/2 -> 10086.57 | M17: =MATCH(F17,INDEX(QH_f,0,$F$4),1) -> 37 | N17: =(F17-INDEX(QH_f,M17,$F$4))/(INDEX(QH_f,M17+1,$F$4)-INDEX(QH_f,M17,$F$4)) -> 0.6579906
A18: 2 | B18: =IFERROR(INDEX(Lu_Q,MATCH(A18,Lu_t,0),$C$4),0) -> 84 | C18: =(B17+B18)/2 -> 44 | D18: =L17 -> 10086.57 | E18: =J17 -> 62.771921 | F18: =D18+C18-E18 -> 10067.798 | G18: =INDEX(QH_Z,M18)+N18*(INDEX(QH_Z,M18+1)-INDEX(QH_Z,M18)) -> 74.655024 | H18: =INDEX(QH_qtc,M18)+N18*(INDEX(QH_qtc,M18+1)-INDEX(QH_qtc,M18)) -> 0 | I18: =IF($F$4=2,0,INDEX(QH_qsc,M18)+N18*(INDEX(QH_qsc,M18+1)-INDEX(QH_qsc,M18))) -> 62.516595 | J18: =H18+I18 -> 62.516595 | K18: =INDEX(QH_V,M18)+N18*(INDEX(QH_V,M18+1)-INDEX(QH_V,M18)) -> 36.131543 | L18: =K18*1000000/dt_s+J18/2 -> 10067.798 | M18: =MATCH(F18,INDEX(QH_f,0,$F$4),1) -> 37 | N18: =(F18-INDEX(QH_f,M18,$F$4))/(INDEX(QH_f,M18+1,$F$4)-INDEX(QH_f,M18,$F$4)) -> 0.55023762
A19: 3 | B19: =IFERROR(INDEX(Lu_Q,MATCH(A19,Lu_t,0),$C$4),0) -> 324 | C19: =(B18+B19)/2 -> 204 | D19: =L18 -> 10067.798 | E19: =J18 -> 62.516595 | F19: =D19+C19-E19 -> 10209.281 | G19: =INDEX(QH_Z,M19)+N19*(INDEX(QH_Z,M19+1)-INDEX(QH_Z,M19)) -> 74.73572 | H19: =INDEX(QH_qtc,M19)+N19*(INDEX(QH_qtc,M19+1)-INDEX(QH_qtc,M19)) -> 0.48438955 | I19: =IF($F$4=2,0,INDEX(QH_qsc,M19)+N19*(INDEX(QH_qsc,M19+1)-INDEX(QH_qsc,M19))) -> 64.435429 | J19: =H19+I19 -> 64.919819 | K19: =INDEX(QH_V,M19)+N19*(INDEX(QH_V,M19+1)-INDEX(QH_V,M19)) -> 36.636557 | L19: =K19*1000000/dt_s+J19/2 -> 10209.281 | M19: =MATCH(F19,INDEX(QH_f,0,$F$4),1) -> 38 | N19: =(F19-INDEX(QH_f,M19,$F$4))/(INDEX(QH_f,M19+1,$F$4)-INDEX(QH_f,M19,$F$4)) -> 0.35720011
A20: 4 | B20: =IFERROR(INDEX(Lu_Q,MATCH(A20,Lu_t,0),$C$4),0) -> 652 | C20: =(B19+B20)/2 -> 488 | D20: =L19 -> 10209.281 | E20: =J19 -> 64.919819 | F20: =D20+C20-E20 -> 10632.362 | G20: =INDEX(QH_Z,M20)+N20*(INDEX(QH_Z,M20+1)-INDEX(QH_Z,M20)) -> 74.971886 | H20: =INDEX(QH_qtc,M20)+N20*(INDEX(QH_qtc,M20+1)-INDEX(QH_qtc,M20)) -> 6.0988621 | I20: =IF($F$4=2,0,INDEX(QH_qsc,M20)+N20*(INDEX(QH_qsc,M20+1)-INDEX(QH_qsc,M20))) -> 70.118953 | J20: =H20+I20 -> 76.217815 | K20: =INDEX(QH_V,M20)+N20*(INDEX(QH_V,M20+1)-INDEX(QH_V,M20)) -> 38.13931 | L20: =K20*1000000/dt_s+J20/2 -> 10632.362 | M20: =MATCH(F20,INDEX(QH_f,0,$F$4),1) -> 40 | N20: =(F20-INDEX(QH_f,M20,$F$4))/(INDEX(QH_f,M20+1,$F$4)-INDEX(QH_f,M20,$F$4)) -> 0.71885752
A21: 5 | B21: =IFERROR(INDEX(Lu_Q,MATCH(A21,Lu_t,0),$C$4),0) -> 950 | C21: =(B20+B21)/2 -> 801 | D21: =L20 -> 10632.362 | E21: =J20 -> 76.217815 | F21: =D21+C21-E21 -> 11357.144 | G21: =INDEX(QH_Z,M21)+N21*(INDEX(QH_Z,M21+1)-INDEX(QH_Z,M21)) -> 75.364024 | H21: =INDEX(QH_qtc,M21)+N21*(INDEX(QH_qtc,M21+1)-INDEX(QH_qtc,M21)) -> 22.720635 | I21: =IF($F$4=2,0,INDEX(QH_qsc,M21)+N21*(INDEX(QH_qsc,M21+1)-INDEX(QH_qsc,M21))) -> 79.757354 | J21: =H21+I21 -> 102.47799 | K21: =INDEX(QH_V,M21)+N21*(INDEX(QH_V,M21+1)-INDEX(QH_V,M21)) -> 40.701257 | L21: =K21*1000000/dt_s+J21/2 -> 11357.144 | M21: =MATCH(F21,INDEX(QH_f,0,$F$4),1) -> 44 | N21: =(F21-INDEX(QH_f,M21,$F$4))/(INDEX(QH_f,M21+1,$F$4)-INDEX(QH_f,M21,$F$4)) -> 0.64024385
A22: 6 | B22: =IFERROR(INDEX(Lu_Q,MATCH(A22,Lu_t,0),$C$4),0) -> 1150 | C22: =(B21+B22)/2 -> 1050 | D22: =L21 -> 11357.144 | E22: =J21 -> 102.47799 | F22: =D22+C22-E22 -> 12304.666 | G22: =INDEX(QH_Z,M22)+N22*(INDEX(QH_Z,M22+1)-INDEX(QH_Z,M22)) -> 75.859929 | H22: =INDEX(QH_qtc,M22)+N22*(INDEX(QH_qtc,M22+1)-INDEX(QH_qtc,M22)) -> 51.32913 | I22: =IF($F$4=2,0,INDEX(QH_qsc,M22)+N22*(INDEX(QH_qsc,M22+1)-INDEX(QH_qsc,M22))) -> 92.248144 | J22: =H22+I22 -> 143.57727 | K22: =INDEX(QH_V,M22)+N22*(INDEX(QH_V,M22+1)-INDEX(QH_V,M22)) -> 44.038358 | L22: =K22*1000000/dt_s+J22/2 -> 12304.666 | M22: =MATCH(F22,INDEX(QH_f,0,$F$4),1) -> 49 | N22: =(F22-INDEX(QH_f,M22,$F$4))/(INDEX(QH_f,M22+1,$F$4)-INDEX(QH_f,M22,$F$4)) -> 0.59929443
A23: 7 | B23: =IFERROR(INDEX(Lu_Q,MATCH(A23,Lu_t,0),$C$4),0) -> 1239 | C23: =(B22+B23)/2 -> 1194.5 | D23: =L22 -> 12304.666 | E23: =J22 -> 143.57727 | F23: =D23+C23-E23 -> 13355.589 | G23: =INDEX(QH_Z,M23)+N23*(INDEX(QH_Z,M23+1)-INDEX(QH_Z,M23)) -> 76.390199 | H23: =INDEX(QH_qtc,M23)+N23*(INDEX(QH_qtc,M23+1)-INDEX(QH_qtc,M23)) -> 88.247669 | I23: =IF($F$4=2,0,INDEX(QH_qsc,M23)+N23*(INDEX(QH_qsc,M23+1)-INDEX(QH_qsc,M23))) -> 105.89767 | J23: =H23+I23 -> 194.14534 | K23: =INDEX(QH_V,M23)+N23*(INDEX(QH_V,M23+1)-INDEX(QH_V,M23)) -> 47.730657 | L23: =K23*1000000/dt_s+J23/2 -> 13355.589 | M23: =MATCH(F23,INDEX(QH_f,0,$F$4),1) -> 54 | N23: =(F23-INDEX(QH_f,M23,$F$4))/(INDEX(QH_f,M23+1,$F$4)-INDEX(QH_f,M23,$F$4)) -> 0.90198883
A24: 8 | B24: =IFERROR(INDEX(Lu_Q,MATCH(A24,Lu_t,0),$C$4),0) -> 1236 | C24: =(B23+B24)/2 -> 1237.5 | D24: =L23 -> 13355.589 | E24: =J23 -> 194.14534 | F24: =D24+C24-E24 -> 14398.943 | G24: =INDEX(QH_Z,M24)+N24*(INDEX(QH_Z,M24+1)-INDEX(QH_Z,M24)) -> 76.89712 | H24: =INDEX(QH_qtc,M24)+N24*(INDEX(QH_qtc,M24+1)-INDEX(QH_qtc,M24)) -> 127.95158 | I24: =IF($F$4=2,0,INDEX(QH_qsc,M24)+N24*(INDEX(QH_qsc,M24+1)-INDEX(QH_qsc,M24))) -> 119.15619 | J24: =H24+I24 -> 247.10777 | K24: =INDEX(QH_V,M24)+N24*(INDEX(QH_V,M24+1)-INDEX(QH_V,M24)) -> 51.391402 | L24: =K24*1000000/dt_s+J24/2 -> 14398.943 | M24: =MATCH(F24,INDEX(QH_f,0,$F$4),1) -> 59 | N24: =(F24-INDEX(QH_f,M24,$F$4))/(INDEX(QH_f,M24+1,$F$4)-INDEX(QH_f,M24,$F$4)) -> 0.97119659
A25: 9 | B25: =IFERROR(INDEX(Lu_Q,MATCH(A25,Lu_t,0),$C$4),0) -> 1168 | C25: =(B24+B25)/2 -> 1202 | D25: =L24 -> 14398.943 | E25: =J24 -> 247.10777 | F25: =D25+C25-E25 -> 15353.835 | G25: =INDEX(QH_Z,M25)+N25*(INDEX(QH_Z,M25+1)-INDEX(QH_Z,M25)) -> 77.34574 | H25: =INDEX(QH_qtc,M25)+N25*(INDEX(QH_qtc,M25+1)-INDEX(QH_qtc,M25)) -> 165.77739 | I25: =IF($F$4=2,0,INDEX(QH_qsc,M25)+N25*(INDEX(QH_qsc,M25+1)-INDEX(QH_qsc,M25))) -> 131.00784 | J25: =H25+I25 -> 296.78524 | K25: =INDEX(QH_V,M25)+N25*(INDEX(QH_V,M25+1)-INDEX(QH_V,M25)) -> 54.739594 | L25: =K25*1000000/dt_s+J25/2 -> 15353.835 | M25: =MATCH(F25,INDEX(QH_f,0,$F$4),1) -> 64 | N25: =(F25-INDEX(QH_f,M25,$F$4))/(INDEX(QH_f,M25+1,$F$4)-INDEX(QH_f,M25,$F$4)) -> 0.45740463
A26: 10 | B26: =IFERROR(INDEX(Lu_Q,MATCH(A26,Lu_t,0),$C$4),0) -> 1062 | C26: =(B25+B26)/2 -> 1115 | D26: =L25 -> 15353.835 | E26: =J25 -> 296.78524 | F26: =D26+C26-E26 -> 16172.05 | G26: =INDEX(QH_Z,M26)+N26*(INDEX(QH_Z,M26+1)-INDEX(QH_Z,M26)) -> 77.719656 | H26: =INDEX(QH_qtc,M26)+N26*(INDEX(QH_qtc,M26+1)-INDEX(QH_qtc,M26)) -> 198.7628 | I26: =IF($F$4=2,0,INDEX(QH_qsc,M26)+N26*(INDEX(QH_qsc,M26+1)-INDEX(QH_qsc,M26))) -> 140.93814 | J26: =H26+I26 -> 339.70094 | K26: =INDEX(QH_V,M26)+N26*(INDEX(QH_V,M26+1)-INDEX(QH_V,M26)) -> 57.607919 | L26: =K26*1000000/dt_s+J26/2 -> 16172.05 | M26: =MATCH(F26,INDEX(QH_f,0,$F$4),1) -> 68 | N26: =(F26-INDEX(QH_f,M26,$F$4))/(INDEX(QH_f,M26+1,$F$4)-INDEX(QH_f,M26,$F$4)) -> 0.19655507
A27: 11 | B27: =IFERROR(INDEX(Lu_Q,MATCH(A27,Lu_t,0),$C$4),0) -> 937 | C27: =(B26+B27)/2 -> 999.5 | D27: =L26 -> 16172.05 | E27: =J26 -> 339.70094 | F27: =D27+C27-E27 -> 16831.849 | G27: =INDEX(QH_Z,M27)+N27*(INDEX(QH_Z,M27+1)-INDEX(QH_Z,M27)) -> 78.014602 | H27: =INDEX(QH_qtc,M27)+N27*(INDEX(QH_qtc,M27+1)-INDEX(QH_qtc,M27)) -> 225.53014 | I27: =IF($F$4=2,0,INDEX(QH_qsc,M27)+N27*(INDEX(QH_qsc,M27+1)-INDEX(QH_qsc,M27))) -> 148.78933 | J27: =H27+I27 -> 374.31947 | K27: =INDEX(QH_V,M27)+N27*(INDEX(QH_V,M27+1)-INDEX(QH_V,M27)) -> 59.920882 | L27: =K27*1000000/dt_s+J27/2 -> 16831.849 | M27: =MATCH(F27,INDEX(QH_f,0,$F$4),1) -> 71 | N27: =(F27-INDEX(QH_f,M27,$F$4))/(INDEX(QH_f,M27+1,$F$4)-INDEX(QH_f,M27,$F$4)) -> 0.14602098
A28: 12 | B28: =IFERROR(INDEX(Lu_Q,MATCH(A28,Lu_t,0),$C$4),0) -> 808 | C28: =(B27+B28)/2 -> 872.5 | D28: =L27 -> 16831.849 | E28: =J27 -> 374.31947 | F28: =D28+C28-E28 -> 17330.03 | G28: =INDEX(QH_Z,M28)+N28*(INDEX(QH_Z,M28+1)-INDEX(QH_Z,M28)) -> 78.233586 | H28: =INDEX(QH_qtc,M28)+N28*(INDEX(QH_qtc,M28+1)-INDEX(QH_qtc,M28)) -> 245.75341 | I28: =IF($F$4=2,0,INDEX(QH_qsc,M28)+N28*(INDEX(QH_qsc,M28+1)-INDEX(QH_qsc,M28))) -> 154.62192 | J28: =H28+I28 -> 400.37533 | K28: =INDEX(QH_V,M28)+N28*(INDEX(QH_V,M28+1)-INDEX(QH_V,M28)) -> 61.667432 | L28: =K28*1000000/dt_s+J28/2 -> 17330.03 | M28: =MATCH(F28,INDEX(QH_f,0,$F$4),1) -> 73 | N28: =(F28-INDEX(QH_f,M28,$F$4))/(INDEX(QH_f,M28+1,$F$4)-INDEX(QH_f,M28,$F$4)) -> 0.33586021
... A64: 48 | B64: =IFERROR(INDEX(Lu_Q,MATCH(A64,Lu_t,0),$C$4),0) -> 0 | C64: =(B63+B64)/2 -> 0 | D64: =L63 -> 11614.576 | E64: =J63 -> 113.02469 | F64: =D64+C64-E64 -> 11501.551 | G64: =INDEX(QH_Z,M64)+N64*(INDEX(QH_Z,M64+1)-INDEX(QH_Z,M64)) -> 75.440757 | H64: =INDEX(QH_qtc,M64)+N64*(INDEX(QH_qtc,M64+1)-INDEX(QH_qtc,M64)) -> 26.67802 | I64: =IF($F$4=2,0,INDEX(QH_qsc,M64)+N64*(INDEX(QH_qsc,M64+1)-INDEX(QH_qsc,M64))) -> 81.669708 | J64: =H64+I64 -> 108.34773 | K64: =INDEX(QH_V,M64)+N64*(INDEX(QH_V,M64+1)-INDEX(QH_V,M64)) -> 41.210558 | L64: =K64*1000000/dt_s+J64/2 -> 11501.551 | M64: =MATCH(F64,INDEX(QH_f,0,$F$4),1) -> 45 | N64: =(F64-INDEX(QH_f,M64,$F$4))/(INDEX(QH_f,M64+1,$F$4)-INDEX(QH_f,M64,$F$4)) -> 0.40756718

Sheet P02_KetVan
A1: ĐIỀU TIẾT LŨ – PHƯƠNG PHÁP PÔ-TA-PỐP (Δt = 1 giờ)
A3: Tần suất P (%) | C3: 0.2 | D3: Trường hợp | F3: Kẹt van | H3: ← sửa ô vàng: P = 1 hoặc 0,2; trường hợp “Hai tràn” hoặc “Kẹt van”
A4: Cột lũ | C4: =MATCH(C3,Lu_P,0) -> 2 | D4: Cột f | F4: =IF(F3="Kẹt van",2,1) -> 2
H5: Giờ 0: Z = MNDBT, q = q(MNDBT) theo trường hợp chọn. Từ giờ 1: f₂ = f₁ + Qtb − q₁ → tìm dòng k, tỷ lệ w
A6: Mực nước lớn nhất Zmax (m) | F6: =MAX(G16:G64) -> 79.140251 | H6: trong bảng QuanHe (cột M, N) → Z₂, q₂, V₂ nội suy với cùng k, w (cột L kiểm tra bằng f₂).
A7: Thời điểm xuất hiện (giờ) | F7: =INDEX(A16:A64,MATCH(MAX(G16:G64),G16:G64,0)) -> 17
A8: Lưu lượng xả lớn nhất qmax (m³/s) | F8: =MAX(J16:J64) -> 331.62067
A9: Lúc Zmax: q tràn chính / q tràn sự cố (m³/s) | F9: =INDEX(H16:H64,MATCH(MAX(G16:G64),G16:G64,0)) -> 331.62067 | G9: =INDEX(I16:I64,MATCH(MAX(G16:G64),G16:G64,0)) -> 0
A10: Cột nước trên ngưỡng lúc Zmax: tràn chính / tràn sự cố (m) | F10: =F6-TC_Z -> 4.4402507 | G10: =F6-SC_Z -> 8.1402507
A11: Dung tích phòng lũ V(Zmax) − V(MNDBT) (10⁶ m³) | F11: =INDEX(K16:K64,MATCH(MAX(G16:G64),G16:G64,0))-K16 -> 32.75334
A12: Cân bằng nước: W đến − W xả − ΔV (10⁶ m³, phải ≈ 0) | F12: =SUMPRODUCT((B16:B63+B17:B64)/2)*dt_s/1000000-SUMPRODUCT((J16:J63+J17:J64)/2)*dt_s/1000000-(K64-K16) -> 0
A15: t (giờ) | B15: Q đến (m³/s) | C15: Qtb = (Q₁+Q₂)/2 | D15: f₁ (giờ trước) | E15: q₁ (giờ trước) | F15: f₂ = f₁ + Qtb − q₁ | G15: Z₂ (m) | H15: q tràn chính (m³/s) | I15: q tràn sự cố (m³/s) | J15: q xả = tổng (m³/s) | K15: V₂ (10⁶ m³) | L15: Kiểm tra V₂/Δt + q₂/2 (= f₂) | M15: k – dòng tra bảng QuanHe | N15: w – tỷ lệ nội suy
A16: 0 | B16: =IFERROR(INDEX(Lu_Q,MATCH(A16,Lu_t,0),$C$4),0) -> 4 | G16: =Z0 -> 74.7 | H16: =INDEX(QH_qtc,M16)+N16*(INDEX(QH_qtc,M16+1)-INDEX(QH_qtc,M16)) -> 0 | I16: =IF($F$4=2,0,INDEX(QH_qsc,M16)+N16*(INDEX(QH_qsc,M16+1)-INDEX(QH_qsc,M16))) -> 0 | J16: =H16+I16 -> 0 | K16: =INDEX(QH_V,M16)+N16*(INDEX(QH_V,M16+1)-INDEX(QH_V,M16)) -> 36.4117 | L16: =K16*1000000/dt_s+J16/2 -> 10114.361 | M16: =MATCH(G16,QH_Z,1) -> 38 | N16: =(G16-INDEX(QH_Z,M16))/(INDEX(QH_Z,M16+1)-INDEX(QH_Z,M16)) -> 0
A17: 1 | B17: =IFERROR(INDEX(Lu_Q,MATCH(A17,Lu_t,0),$C$4),0) -> 4 | C17: =(B16+B17)/2 -> 4 | D17: =L16 -> 10114.361 | E17: =J16 -> 0 | F17: =D17+C17-E17 -> 10118.361 | G17: =INDEX(QH_Z,M17)+N17*(INDEX(QH_Z,M17+1)-INDEX(QH_Z,M17)) -> 74.702279 | H17: =INDEX(QH_qtc,M17)+N17*(INDEX(QH_qtc,M17+1)-INDEX(QH_qtc,M17)) -> 0.030900762 | I17: =IF($F$4=2,0,INDEX(QH_qsc,M17)+N17*(INDEX(QH_qsc,M17+1)-INDEX(QH_qsc,M17))) -> 0 | J17: =H17+I17 -> 0.030900762 | K17: =INDEX(QH_V,M17)+N17*(INDEX(QH_V,M17+1)-INDEX(QH_V,M17)) -> 36.426044 | L17: =K17*1000000/dt_s+J17/2 -> 10118.361 | M17: =MATCH(F17,INDEX(QH_f,0,$F$4),1) -> 38 | N17: =(F17-INDEX(QH_f,M17,$F$4))/(INDEX(QH_f,M17+1,$F$4)-INDEX(QH_f,M17,$F$4)) -> 0.02278694
A18: 2 | B18: =IFERROR(INDEX(Lu_Q,MATCH(A18,Lu_t,0),$C$4),0) -> 84 | C18: =(B17+B18)/2 -> 44 | D18: =L17 -> 10118.361 | E18: =J17 -> 0.030900762 | F18: =D18+C18-E18 -> 10162.33 | G18: =INDEX(QH_Z,M18)+N18*(INDEX(QH_Z,M18+1)-INDEX(QH_Z,M18)) -> 74.727327 | H18: =INDEX(QH_qtc,M18)+N18*(INDEX(QH_qtc,M18+1)-INDEX(QH_qtc,M18)) -> 0.37057043 | I18: =IF($F$4=2,0,INDEX(QH_qsc,M18)+N18*(INDEX(QH_qsc,M18+1)-INDEX(QH_qsc,M18))) -> 0 | J18: =H18+I18 -> 0.37057043 | K18: =INDEX(QH_V,M18)+N18*(INDEX(QH_V,M18+1)-INDEX(QH_V,M18)) -> 36.583722 | L18: =K18*1000000/dt_s+J18/2 -> 10162.33 | M18: =MATCH(F18,INDEX(QH_f,0,$F$4),1) -> 38 | N18: =(F18-INDEX(QH_f,M18,$F$4))/(INDEX(QH_f,M18+1,$F$4)-INDEX(QH_f,M18,$F$4)) -> 0.27326724
A19: 3 | B19: =IFERROR(INDEX(Lu_Q,MATCH(A19,Lu_t,0),$C$4),0) -> 324 | C19: =(B18+B19)/2 -> 204 | D19: =L18 -> 10162.33 | E19: =J18 -> 0.37057043 | F19: =D19+C19-E19 -> 10365.96 | G19: =INDEX(QH_Z,M19)+N19*(INDEX(QH_Z,M19+1)-INDEX(QH_Z,M19)) -> 74.842748 | H19: =INDEX(QH_qtc,M19)+N19*(INDEX(QH_qtc,M19+1)-INDEX(QH_qtc,M19)) -> 2.4094388 | I19: =IF($F$4=2,0,INDEX(QH_qsc,M19)+N19*(INDEX(QH_qsc,M19+1)-INDEX(QH_qsc,M19))) -> 0 | J19: =H19+I19 -> 2.4094388 | K19: =INDEX(QH_V,M19)+N19*(INDEX(QH_V,M19+1)-INDEX(QH_V,M19)) -> 37.313118 | L19: =K19*1000000/dt_s+J19/2 -> 10365.96 | M19: =MATCH(F19,INDEX(QH_f,0,$F$4),1) -> 39 | N19: =(F19-INDEX(QH_f,M19,$F$4))/(INDEX(QH_f,M19+1,$F$4)-INDEX(QH_f,M19,$F$4)) -> 0.42747636
A20: 4 | B20: =IFERROR(INDEX(Lu_Q,MATCH(A20,Lu_t,0),$C$4),0) -> 652 | C20: =(B19+B20)/2 -> 488 | D20: =L19 -> 10365.96 | E20: =J19 -> 2.4094388 | F20: =D20+C20-E20 -> 10851.55 | G20: =INDEX(QH_Z,M20)+N20*(INDEX(QH_Z,M20+1)-INDEX(QH_Z,M20)) -> 75.111829 | H20: =INDEX(QH_qtc,M20)+N20*(INDEX(QH_qtc,M20+1)-INDEX(QH_qtc,M20)) -> 11.215341 | I20: =IF($F$4=2,0,INDEX(QH_qsc,M20)+N20*(INDEX(QH_qsc,M20+1)-INDEX(QH_qsc,M20))) -> 0 | J20: =H20+I20 -> 11.215341 | K20: =INDEX(QH_V,M20)+N20*(INDEX(QH_V,M20+1)-INDEX(QH_V,M20)) -> 39.045393 | L20: =K20*1000000/dt_s+J20/2 -> 10851.55 | M20: =MATCH(F20,INDEX(QH_f,0,$F$4),1) -> 42 | N20: =(F20-INDEX(QH_f,M20,$F$4))/(INDEX(QH_f,M20+1,$F$4)-INDEX(QH_f,M20,$F$4)) -> 0.11828549
A21: 5 | B21: =IFERROR(INDEX(Lu_Q,MATCH(A21,Lu_t,0),$C$4),0) -> 950 | C21: =(B20+B21)/2 -> 801 | D21: =L20 -> 10851.55 | E21: =J20 -> 11.215341 | F21: =D21+C21-E21 -> 11641.335 | G21: =INDEX(QH_Z,M21)+N21*(INDEX(QH_Z,M21+1)-INDEX(QH_Z,M21)) -> 75.536765 | H21: =INDEX(QH_qtc,M21)+N21*(INDEX(QH_qtc,M21+1)-INDEX(QH_qtc,M21)) -> 31.891041 | I21: =IF($F$4=2,0,INDEX(QH_qsc,M21)+N21*(INDEX(QH_qsc,M21+1)-INDEX(QH_qsc,M21))) -> 0 | J21: =H21+I21 -> 31.891041 | K21: =INDEX(QH_V,M21)+N21*(INDEX(QH_V,M21+1)-INDEX(QH_V,M21)) -> 41.851402 | L21: =K21*1000000/dt_s+J21/2 -> 11641.335 | M21: =MATCH(F21,INDEX(QH_f,0,$F$4),1) -> 46 | N21: =(F21-INDEX(QH_f,M21,$F$4))/(INDEX(QH_f,M21+1,$F$4)-INDEX(QH_f,M21,$F$4)) -> 0.36765387
A22: 6 | B22: =IFERROR(INDEX(Lu_Q,MATCH(A22,Lu_t,0),$C$4),0) -> 1150 | C22: =(B21+B22)/2 -> 1050 | D22: =L21 -> 11641.335 | E22: =J21 -> 31.891041 | F22: =D22+C22-E22 -> 12659.444 | G22: =INDEX(QH_Z,M22)+N22*(INDEX(QH_Z,M22+1)-INDEX(QH_Z,M22)) -> 76.065987 | H22: =INDEX(QH_qtc,M22)+N22*(INDEX(QH_qtc,M22+1)-INDEX(QH_qtc,M22)) -> 65.020629 | I22: =IF($F$4=2,0,INDEX(QH_qsc,M22)+N22*(INDEX(QH_qsc,M22+1)-INDEX(QH_qsc,M22))) -> 0 | J22: =H22+I22 -> 65.020629 | K22: =INDEX(QH_V,M22)+N22*(INDEX(QH_V,M22+1)-INDEX(QH_V,M22)) -> 45.456961 | L22: =K22*1000000/dt_s+J22/2 -> 12659.444 | M22: =MATCH(F22,INDEX(QH_f,0,$F$4),1) -> 51 | N22: =(F22-INDEX(QH_f,M22,$F$4))/(INDEX(QH_f,M22+1,$F$4)-INDEX(QH_f,M22,$F$4)) -> 0.65987093
A23: 7 | B23: =IFERROR(INDEX(Lu_Q,MATCH(A23,Lu_t,0),$C$4),0) -> 1239 | C23: =(B22+B23)/2 -> 1194.5 | D23: =L22 -> 12659.444 | E23: =J22 -> 65.020629 | F23: =D23+C23-E23 -> 13788.923 | G23: =INDEX(QH_Z,M23)+N23*(INDEX(QH_Z,M23+1)-INDEX(QH_Z,M23)) -> 76.630207 | H23: =INDEX(QH_qtc,M23)+N23*(INDEX(QH_qtc,M23+1)-INDEX(QH_qtc,M23)) -> 106.59932 | I23: =IF($F$4=2,0,INDEX(QH_qsc,M23)+N23*(INDEX(QH_qsc,M23+1)-INDEX(QH_qsc,M23))) -> 0 | J23: =H23+I23 -> 106.59932 | K23: =INDEX(QH_V,M23)+N23*(INDEX(QH_V,M23+1)-INDEX(QH_V,M23)) -> 49.448245 | L23: =K23*1000000/dt_s+J23/2 -> 13788.923 | M23: =MATCH(F23,INDEX(QH_f,0,$F$4),1) -> 57 | N23: =(F23-INDEX(QH_f,M23,$F$4))/(INDEX(QH_f,M23+1,$F$4)-INDEX(QH_f,M23,$F$4)) -> 0.3020688
A24: 8 | B24: =IFERROR(INDEX(Lu_Q,MATCH(A24,Lu_t,0),$C$4),0) -> 1236 | C24: =(B23+B24)/2 -> 1237.5 | D24: =L23 -> 13788.923 | E24: =J23 -> 106.59932 | F24: =D24+C24-E24 -> 14919.824 | G24: =INDEX(QH_Z,M24)+N24*(INDEX(QH_Z,M24+1)-INDEX(QH_Z,M24)) -> 77.173171 | H24: =INDEX(QH_qtc,M24)+N24*(INDEX(QH_qtc,M24+1)-INDEX(QH_qtc,M24)) -> 150.97579 | I24: =IF($F$4=2,0,INDEX(QH_qsc,M24)+N24*(INDEX(QH_qsc,M24+1)-INDEX(QH_qsc,M24))) -> 0 | J24: =H24+I24 -> 150.97579 | K24: =INDEX(QH_V,M24)+N24*(INDEX(QH_V,M24+1)-INDEX(QH_V,M24)) -> 53.43961 | L24: =K24*1000000/dt_s+J24/2 -> 14919.824 | M24: =MATCH(F24,INDEX(QH_f,0,$F$4),1) -> 62 | N24: =(F24-INDEX(QH_f,M24,$F$4))/(INDEX(QH_f,M24+1,$F$4)-INDEX(QH_f,M24,$F$4)) -> 0.73170535
A25: 9 | B25: =IFERROR(INDEX(Lu_Q,MATCH(A25,Lu_t,0),$C$4),0) -> 1168 | C25: =(B24+B25)/2 -> 1202 | D25: =L24 -> 14919.824 | E25: =J24 -> 150.97579 | F25: =D25+C25-E25 -> 15970.848 | G25: =INDEX(QH_Z,M25)+N25*(INDEX(QH_Z,M25+1)-INDEX(QH_Z,M25)) -> 77.660151 | H25: =INDEX(QH_qtc,M25)+N25*(INDEX(QH_qtc,M25+1)-INDEX(QH_qtc,M25)) -> 193.4399 | I25: =IF($F$4=2,0,INDEX(QH_qsc,M25)+N25*(INDEX(QH_qsc,M25+1)-INDEX(QH_qsc,M25))) -> 0 | J25: =H25+I25 -> 193.4399 | K25: =INDEX(QH_V,M25)+N25*(INDEX(QH_V,M25+1)-INDEX(QH_V,M25)) -> 57.146861 | L25: =K25*1000000/dt_s+J25/2 -> 15970.848 | M25: =MATCH(F25,INDEX(QH_f,0,$F$4),1) -> 67 | N25: =(F25-INDEX(QH_f,M25,$F$4))/(INDEX(QH_f,M25+1,$F$4)-INDEX(QH_f,M25,$F$4)) -> 0.60151491
A26: 10 | B26: =IFERROR(INDEX(Lu_Q,MATCH(A26,Lu_t,0),$C$4),0) -> 1062 | C26: =(B25+B26)/2 -> 1115 | D26: =L25 -> 15970.848 | E26: =J25 -> 193.4399 | F26: =D26+C26-E26 -> 16892.408 | G26: =INDEX(QH_Z,M26)+N26*(INDEX(QH_Z,M26+1)-INDEX(QH_Z,M26)) -> 78.074571 | H26: =INDEX(QH_qtc,M26)+N26*(INDEX(QH_qtc,M26+1)-INDEX(QH_qtc,M26)) -> 231.04274 | I26: =IF($F$4=2,0,INDEX(QH_qsc,M26)+N26*(INDEX(QH_qsc,M26+1)-INDEX(QH_qsc,M26))) -> 0 | J26: =H26+I26 -> 231.04274 | K26: =INDEX(QH_V,M26)+N26*(INDEX(QH_V,M26+1)-INDEX(QH_V,M26)) -> 60.396792 | L26: =K26*1000000/dt_s+J26/2 -> 16892.408 | M26: =MATCH(F26,INDEX(QH_f,0,$F$4),1) -> 71 | N26: =(F26-INDEX(QH_f,M26,$F$4))/(INDEX(QH_f,M26+1,$F$4)-INDEX(QH_f,M26,$F$4)) -> 0.74570627
