Workbook
Name Z0: SoLieu!$B$6
Name dt_h: SoLieu!$B$7
Name dt_s: SoLieu!$B$8
Name g_: SoLieu!$B$9
Name TC_Z: SoLieu!$B$13
Name TC_n: SoLieu!$B$14
Name TC_b: SoLieu!$B$15
Name TC_d: SoLieu!$B$16
Name TC_B: SoLieu!$B$17
Name TC_m: SoLieu!$B$18
Name TC_xmb: SoLieu!$B$19
Name TC_xmt: SoLieu!$B$20
Name TC_s: SoLieu!$B$21
Name TC_hong: SoLieu!$B$22
Name TC_n_sc: SoLieu!$B$23
Name SC_Z: SoLieu!$B$27
Name SC_n: SoLieu!$B$28
Name SC_b: SoLieu!$B$29
Name SC_m: SoLieu!$B$30
Name SC_xmb: SoLieu!$B$31
Name SC_xmt: SoLieu!$B$32
Name SC_s: SoLieu!$B$33
Name Lu_t: SoLieu!$A$38:$A$74
Name Lu_Q: SoLieu!$B$38:$C$74
Name Lu_P: SoLieu!$B$36:$C$36
Name Bang_Z: SoLieu!$A$79:$A$105
Name Bang_F: SoLieu!$B$79:$B$105
Name Bang_W: SoLieu!$C$79:$C$105
Name QH_Z: QuanHe!$A$5:$A$105
Name QH_V: QuanHe!$C$5:$C$105
Name QH_qtc: QuanHe!$H$5:$I$105
Name QH_qsc: QuanHe!$L$5:$L$105
Name QH_q: QuanHe!$M$5:$N$105
Name QH_f1: QuanHe!$O$5:$P$105
Name QH_f2: QuanHe!$Q$5:$R$105
Name Z_dau_in: BangIn!$C$4
Name Z_cuoi_in: BangIn!$F$4
Name Buoc_in: BangIn!$I$4
Name Z_dinh_SC: KetQua!$B$9

Sheet HuongDan
B1: ĐIỀU TIẾT LŨ HỒ CÀ GIÂY – PHƯƠNG PHÁP PÔ-TA-PỐP VỚI HAI ĐƯỜNG PHỤ TRỢ q ~ f₁, q ~ f₂
B2: Mọi ô kết quả là công thức. Sửa thông số tràn, mực nước trước lũ ở sheet SoLieu; đổi tần suất, trường hợp ở ô vàng đầu mỗi sheet điều tiết.
B3: 1. Công trình tháo lũ và các trường hợp tính
B4: • Tràn chính: 9 khoang có cửa van, mỗi khoang b = 2,4 m (Σb = 21,6 m), ngưỡng +74,70 m; 8 trụ pin dày 0,6 m đầu lượn tròn → tổng bề rộng tràn 26,4 m. Tràn sự cố: 1 khoang có cửa van, b = 5 m, ngưỡng +71,00 m.
B5: • Vận hành bình thường: khi đón lũ, tất cả cửa van (9 cửa tràn chính và cửa tràn sự cố) kéo lên hoàn toàn – hai tràn chảy tự do. Sự cố: 1 cửa tràn chính không mở được – tràn chính còn 8 khoang làm việc (Σb = 19,2 m), tràn sự cố mở hoàn toàn. Mỗi trường hợp tính cho lũ thiết kế P = 1% (MNLTK) và lũ kiểm tra P = 0,2% (MNLKT).
B6: • Hồ ở MNDBT +74,70 m khi lũ đến (ô SoLieu!B5). Vì ngưỡng tràn sự cố thấp hơn MNDBT 3,7 m, cửa mở hết từ đầu nên những giờ đầu xả khoảng 64 m³/s trong khi lũ đến mới 2 ÷ 50 m³/s – mực nước giảm nhẹ (≈ +74,64 m) rồi mới dâng.
B7: 2. Lưu lượng qua tràn (TCVN 9147:2012 – công thức đập tràn chảy tự do)
B8: q = σn·ε·m·n·b·√(2g)·H^1,5 ε = 1 − 0,2·[ξmb + (n − 1)·ξmt]·H / (n·b)
B9: • H = Z − Z ngưỡng; n – số khoang làm việc; b – bề rộng một khoang; m = 0,45; ξmb = 0,70 (mố bên lượn tròn); ξmt = 0,45 (trụ pin đầu lượn tròn). Bề dày trụ 0,6 m không có trong công thức – chỉ hình dạng đầu trụ ảnh hưởng tới co hẹp ε. Sự cố: n = 8 (coi cửa hỏng ở khoang biên; nếu cửa hỏng ở giữa – hai nhóm 4 khoang – Zmax chỉ cao thêm 0,3 ÷ 0,7 cm). Hai tràn cùng một mực nước: q(Z) = q tràn chính(Z) + q tràn sự cố(Z).
B10: 3. Phương pháp Pô-ta-pốp với hai đường phụ trợ
B11: (Q₁ + Q₂)/2·Δt − (q₁ + q₂)/2·Δt = V₂ − V₁ ⇒ V₂/Δt + q₂/2 = (V₁/Δt − q₁/2) + Qtb ⇒ f₂ = f₁ + Qtb
B12: • f₁ = V/Δt − q/2 và f₂ = V/Δt + q/2 (m³/s) chỉ phụ thuộc mực nước Z → lập sẵn bảng Z ~ V ~ q ~ f₁ ~ f₂ (sheet QuanHe, bước 0,1 m) và vẽ hai đường q ~ f₁, q ~ f₂ (sheet BieuDoPhuTro) cho từng trường hợp.
... B23: • Nền vàng chữ xanh: ô được sửa. Chữ đen: công thức. Nền xanh lá: f₁, f₂. Nền đỏ nhạt: dòng có mực nước lớn nhất.

Sheet SoLieu
A1: SỐ LIỆU ĐẦU VÀO – ĐIỀU TIẾT LŨ (PÔ-TA-PỐP, HAI ĐƯỜNG f₁, f₂)
A2: Ô nền vàng chữ xanh: được sửa. Chữ đen: công thức.
A4: A. THÔNG SỐ CHUNG
A5: Thông số | B5: Giá trị | C5: Đơn vị | D5: Ghi chú, nguồn
A6: Mực nước hồ khi lũ đến (MNDBT) | B6: 74.7 | C6: m | D6: Giả thiết bất lợi: lũ đến khi hồ đầy ở MNDBT
A7: Bước thời gian Δt | B7: 1 | C7: giờ | D7: Bằng bước của đường quá trình lũ (cố định 1 giờ)
A8: Δt tính bằng giây | B8: =dt_h*3600 | C8: s
A9: Gia tốc trọng trường g | B9: 9.81 | C9: m/s²
A11: B. TRÀN CHÍNH (9 khoang có cửa van – mở hoàn toàn khi đón lũ)
A12: Thông số | B12: Giá trị | C12: Đơn vị | D12: Ghi chú, nguồn
A13: Cao trình ngưỡng | B13: 74.7 | C13: m | D13: Không thay đổi
A14: Số khoang n | B14: 9 | C14: khoang
A15: Bề rộng một khoang b | B15: 2.4 | C15: m | D15: Σb = 9 × 2,4 = 21,6 m
A16: Bề dày trụ pin d | B16: 0.6 | C16: m | D16: Đầu trụ lượn tròn
A17: Tổng bề rộng tràn kể trụ pin | B17: =TC_n*TC_b+(TC_n-1)*TC_d | C17: m | D17: n·b + (n − 1)·d = 21,6 + 8 × 0,6
A18: Hệ số lưu lượng m | B18: 0.45 | D18: Như thuyết minh (mục 2.3.2)
A19: Hệ số hình dạng mố bên ξmb | B19: 0.7 | D19: Mố bên lượn tròn
A20: Hệ số hình dạng trụ pin ξmt | B20: 0.45 | D20: Trụ pin đầu lượn tròn
A21: Hệ số chảy ngập σn | B21: 1 | D21: Chảy không ngập
A22: Số cửa không mở được khi sự cố | B22: 1 | C22: cửa | D22: Trường hợp sự cố
A23: Số khoang làm việc khi sự cố | B23: =TC_n-TC_hong | C23: khoang
A25: C. TRÀN SỰ CỐ (1 khoang có cửa van – mở hoàn toàn khi đón lũ)
A26: Thông số | B26: Giá trị | C26: Đơn vị | D26: Ghi chú, nguồn
A27: Cao trình ngưỡng | B27: 71 | C27: m | D27: KTTV Bảng 1-2
A28: Số khoang n | B28: 1 | C28: khoang
A29: Bề rộng khoang b | B29: 5 | C29: m
A30: Hệ số lưu lượng m | B30: 0.45 | D30: Như tràn chính
A31: Hệ số hình dạng mố bên ξmb | B31: 0.7
A32: Hệ số hình dạng trụ pin ξmt | B32: 0.45 | D32: Không dùng khi n = 1
A33: Hệ số chảy ngập σn | B33: 1 | D33: Chảy không ngập
A35: D. ĐƯỜNG QUÁ TRÌNH LŨ ĐẾN (m³/s) – BCNCKT 2022, mô hình Gurdich 36 giờ (KTTV Bảng 4-5)
A36: Tần suất P (%) → | B36: 1 | C36: 0.2
A37: t (giờ) | B37: P = 1% | C37: P = 0,2%
A38: 0 | B38: 2 | C38: 4 | D38: Giờ 0 lấy bằng giờ 1 (như thuyết minh); sau giờ 36 lưu lượng đến = 0.
A39: 1 | B39: 2 | C39: 4
A40: 2 | B40: 50 | C40: 84
A41: 3 | B41: 207 | C41: 324
A42: 4 | B42: 437 | C42: 652
A43: 5 | B43: 657 | C43: 950
A44: 6 | B44: 816 | C44: 1150
...

Sheet QuanHe
A1: BẢNG QUAN HỆ PHỤ TRỢ Z ~ V ~ q ~ f₁ ~ f₂ (bước 0,1 m) – dùng để tra trong các sheet điều tiết
A2: f₁ = V/Δt − q/2; f₂ = V/Δt + q/2 (m³/s). BT – vận hành bình thường (tràn chính 9 khoang); SC – sự cố (tràn chính 8 khoang). q của hồ = q tràn chính + q tràn sự cố tại CÙNG mực nước Z.
A4: Z (m) | B4: F (km²) | C4: V (10⁶ m³) | D4: V/Δt (m³/s) | E4: H tràn chính (m) | F4: ε tràn chính 9 khoang | G4: ε tràn chính 8 khoang | H4: q tràn chính 9 khoang (m³/s) | I4: q tràn chính 8 khoang (m³/s) | J4: H tràn sự cố (m) | K4: ε tràn sự cố | L4: q tràn sự cố (m³/s) | M4: q BT (m³/s) | N4: q SC (m³/s) | O4: f₁ BT (m³/s) | P4: f₁ SC (m³/s) | Q4: f₂ BT (m³/s) | R4: f₂ SC (m³/s)
A5: 71 | B5: =INDEX(Bang_F,MATCH(A5,Bang_Z,1))+(A5-INDEX(Bang_Z,MATCH(A5,Bang_Z,1)))*(INDEX(Bang_F,MATCH(A5,Bang_Z,1)+1)-INDEX(Bang_F,MATCH(A5,Bang_Z,1))) | C5: =INDEX(Bang_W,MATCH(A5,Bang_Z,1))+(A5-INDEX(Bang_Z,MATCH(A5,Bang_Z,1)))*(INDEX(Bang_F,MATCH(A5,Bang_Z,1))+B5)/2 | D5: =C5*1000000/dt_s | E5: =MAX(A5-TC_Z,0) | F5: =1-0.2*(TC_xmb+(TC_n-1)*TC_xmt)*E5/(TC_n*TC_b) | G5: =1-0.2*(TC_xmb+(TC_n_sc-1)*TC_xmt)*E5/(TC_n_sc*TC_b) | H5: =TC_s*F5*TC_m*TC_n*TC_b*SQRT(2*g_)*E5^1.5 | I5: =TC_s*G5*TC_m*TC_n_sc*TC_b*SQRT(2*g_)*E5^1.5 | J5: =MAX(A5-SC_Z,0) | K5: =1-0.2*(SC_xmb+(SC_n-1)*SC_xmt)*J5/(SC_n*SC_b) | L5: =SC_s*K5*SC_m*SC_n*SC_b*SQRT(2*g_)*J5^1.5 | M5: =H5+L5 | N5: =I5+L5 | O5: =D5-M5/2 | P5: =D5-N5/2 | Q5: =D5+M5/2 | R5: =D5+N5/2
A6: =ROUND(A5+0.1,2) | B6: =INDEX(Bang_F,MATCH(A6,Bang_Z,1))+(A6-INDEX(Bang_Z,MATCH(A6,Bang_Z,1)))*(INDEX(Bang_F,MATCH(A6,Bang_Z,1)+1)-INDEX(Bang_F,MATCH(A6,Bang_Z,1))) | C6: =INDEX(Bang_W,MATCH(A6,Bang_Z,1))+(A6-INDEX(Bang_Z,MATCH(A6,Bang_Z,1)))*(INDEX(Bang_F,MATCH(A6,Bang_Z,1))+B6)/2 | D6: =C6*1000000/dt_s | E6: =MAX(A6-TC_Z,0) | F6: =1-0.2*(TC_xmb+(TC_n-1)*TC_xmt)*E6/(TC_n*TC_b) | G6: =1-0.2*(TC_xmb+(TC_n_sc-1)*TC_xmt)*E6/(TC_n_sc*TC_b) | H6: =TC_s*F6*TC_m*TC_n*TC_b*SQRT(2*g_)*E6^1.5 | I6: =TC_s*G6*TC_m*TC_n_sc*TC_b*SQRT(2*g_)*E6^1.5 | J6: =MAX(A6-SC_Z,0) | K6: =1-0.2*(SC_xmb+(SC_n-1)*SC_xmt)*J6/(SC_n*SC_b) | L6: =SC_s*K6*SC_m*SC_n*SC_b*SQRT(2*g_)*J6^1.5 | M6: =H6+L6 | N6: =I6+L6 | O6: =D6-M6/2 | P6: =D6-N6/2 | Q6: =D6+M6/2 | R6: =D6+N6/2
A7: =ROUND(A6+0.1,2) | B7: =INDEX(Bang_F,MATCH(A7,Bang_Z,1))+(A7-INDEX(Bang_Z,MATCH(A7,Bang_Z,1)))*(INDEX(Bang_F,MATCH(A7,Bang_Z,1)+1)-INDEX(Bang_F,MATCH(A7,Bang_Z,1))) | C7: =INDEX(Bang_W,MATCH(A7,Bang_Z,1))+(A7-INDEX(Bang_Z,MATCH(A7,Bang_Z,1)))*(INDEX(Bang_F,MATCH(A7,Bang_Z,1))+B7)/2 | D7: =C7*1000000/dt_s | E7: =MAX(A7-TC_Z,0) | F7: =1-0.2*(TC_xmb+(TC_n-1)*TC_xmt)*E7/(TC_n*TC_b) | G7: =1-0.2*(TC_xmb+(TC_n_sc-1)*TC_xmt)*E7/(TC_n_sc*TC_b) | H7: =TC_s*F7*TC_m*TC_n*TC_b*SQRT(2*g_)*E7^1.5 | I7: =TC_s*G7*TC_m*TC_n_sc*TC_b*SQRT(2*g_)*E7^1.5 | J7: =MAX(A7-SC_Z,0) | K7: =1-0.2*(SC_xmb+(SC_n-1)*SC_xmt)*J7/(SC_n*SC_b) | L7: =SC_s*K7*SC_m*SC_n*SC_b*SQRT(2*g_)*J7^1.5 | M7: =H7+L7 | N7: =I7+L7 | O7: =D7-M7/2 | P7: =D7-N7/2 | Q7: =D7+M7/2 | R7: =D7+N7/2
A8: =ROUND(A7+0.1,2) | B8: =INDEX(Bang_F,MATCH(A8,Bang_Z,1))+(A8-INDEX(Bang_Z,MATCH(A8,Bang_Z,1)))*(INDEX(Bang_F,MATCH(A8,Bang_Z,1)+1)-INDEX(Bang_F,MATCH(A8,Bang_Z,1))) | C8: =INDEX(Bang_W,MATCH(A8,Bang_Z,1))+(A8-INDEX(Bang_Z,MATCH(A8,Bang_Z,1)))*(INDEX(Bang_F,MATCH(A8,Bang_Z,1))+B8)/2 | D8: =C8*1000000/dt_s | E8: =MAX(A8-TC_Z,0) | F8: =1-0.2*(TC_xmb+(TC_n-1)*TC_xmt)*E8/(TC_n*TC_b) | G8: =1-0.2*(TC_xmb+(TC_n_sc-1)*TC_xmt)*E8/(TC_n_sc*TC_b) | H8: =TC_s*F8*TC_m*TC_n*TC_b*SQRT(2*g_)*E8^1.5 | I8: =TC_s*G8*TC_m*TC_n_sc*TC_b*SQRT(2*g_)*E8^1.5 | J8: =MAX(A8-SC_Z,0) | K8: =1-0.2*(SC_xmb+(SC_n-1)*SC_xmt)*J8/(SC_n*SC_b) | L8: =SC_s*K8*SC_m*SC_n*SC_b*SQRT(2*g_)*J8^1.5 | M8: =H8+L8 | N8: =I8+L8 | O8: =D8-M8/2 | P8: =D8-N8/2 | Q8: =D8+M8/2 | R8: =D8+N8/2
A9: =ROUND(A8+0.1,2) | B9: =INDEX(Bang_F,MATCH(A9,Bang_Z,1))+(A9-INDEX(Bang_Z,MATCH(A9,Bang_Z,1)))*(INDEX(Bang_F,MATCH(A9,Bang_Z,1)+1)-INDEX(Bang_F,MATCH(A9,Bang_Z,1))) | C9: =INDEX(Bang_W,MATCH(A9,Bang_Z,1))+(A9-INDEX(Bang_Z,MATCH(A9,Bang_Z,1)))*(INDEX(Bang_F,MATCH(A9,Bang_Z,1))+B9)/2 | D9: =C9*1000000/dt_s | E9: =MAX(A9-TC_Z,0) | F9: =1-0.2*(TC_xmb+(TC_n-1)*TC_xmt)*E9/(TC_n*TC_b) | G9: =1-0.2*(TC_xmb+(TC_n_sc-1)*TC_xmt)*E9/(TC_n_sc*TC_b) | H9: =TC_s*F9*TC_m*TC_n*TC_b*SQRT(2*g_)*E9^1.5 | I9: =TC_s*G9*TC_m*TC_n_sc*TC_b*SQRT(2*g_)*E9^1.5 | J9: =MAX(A9-SC_Z,0) | K9: =1-0.2*(SC_xmb+(SC_n-1)*SC_xmt)*J9/(SC_n*SC_b) | L9: =SC_s*K9*SC_m*SC_n*SC_b*SQRT(2*g_)*J9^1.5 | M9: =H9+L9 | N9: =I9+L9 | O9: =D9-M9/2 | P9: =D9-N9/2 | Q9: =D9+M9/2 | R9: =D9+N9/2
A10: =ROUND(A9+0.1,2) | B10: =INDEX(Bang_F,MATCH(A10,Bang_Z,1))+(A10-INDEX(Bang_Z,MATCH(A10,Bang_Z,1)))*(INDEX(Bang_F,MATCH(A10,Bang_Z,1)+1)-INDEX(Bang_F,MATCH(A10,Bang_Z,1))) | C10: =INDEX(Bang_W,MATCH(A10,Bang_Z,1))+(A10-INDEX(Bang_Z,MATCH(A10,Bang_Z,1)))*(INDEX(Bang_F,MATCH(A10,Bang_Z,1))+B10)/2 | D10: =C10*1000000/dt_s | E10: =MAX(A10-TC_Z,0) | F10: =1-0.2*(TC_xmb+(TC_n-1)*TC_xmt)*E10/(TC_n*TC_b) | G10: =1-0.2*(TC_xmb+(TC_n_sc-1)*TC_xmt)*E10/(TC_n_sc*TC_b) | H10: =TC_s*F10*TC_m*TC_n*TC_b*SQRT(2*g_)*E10^1.5 | I10: =TC_s*G10*TC_m*TC_n_sc*TC_b*SQRT(2*g_)*E10^1.5 | J10: =MAX(A10-SC_Z,0) | K10: =1-0.2*(SC_xmb+(SC_n-1)*SC_xmt)*J10/(SC_n*SC_b) | L10: =SC_s*K10*SC_m*SC_n*SC_b*SQRT(2*g_)*J10^1.5 | M10: =H10+L10 | N10: =I10+L10 | O10: =D10-M10/2 | P10: =D10-N10/2 | Q10: =D10+M10/2 | R10: =D10+N10/2
A11: =ROUND(A10+0.1,2) | B11: =INDEX(Bang_F,MATCH(A11,Bang_Z,1))+(A11-INDEX(Bang_Z,MATCH(A11,Bang_Z,1)))*(INDEX(Bang_F,MATCH(A11,Bang_Z,1)+1)-INDEX(Bang_F,MATCH(A11,Bang_Z,1))) | C11: =INDEX(Bang_W,MATCH(A11,Bang_Z,1))+(A11-INDEX(Bang_Z,MATCH(A11,Bang_Z,1)))*(INDEX(Bang_F,MATCH(A11,Bang_Z,1))+B11)/2 | D11: =C11*1000000/dt_s | E11: =MAX(A11-TC_Z,0) | F11: =1-0.2*(TC_xmb+(TC_n-1)*TC_xmt)*E11/(TC_n*TC_b) | G11: =1-0.2*(TC_xmb+(TC_n_sc-1)*TC_xmt)*E11/(TC_n_sc*TC_b) | H11: =TC_s*F11*TC_m*TC_n*TC_b*SQRT(2*g_)*E11^1.5 | I11: =TC_s*G11*TC_m*TC_n_sc*TC_b*SQRT(2*g_)*E11^1.5 | J11: =MAX(A11-SC_Z,0) | K11: =1-0.2*(SC_xmb+(SC_n-1)*SC_xmt)*J11/(SC_n*SC_b) | L11: =SC_s*K11*SC_m*SC_n*SC_b*SQRT(2*g_)*J11^1.5 | M11: =H11+L11 | N11: =I11+L11 | O11: =D11-M11/2 | P11: =D11-N11/2 | Q11: =D11+M11/2 | R11: =D11+N11/2
A12: =ROUND(A11+0.1,2) | B12: =INDEX(Bang_F,MATCH(A12,Bang_Z,1))+(A12-INDEX(Bang_Z,MATCH(A12,Bang_Z,1)))*(INDEX(Bang_F,MATCH(A12,Bang_Z,1)+1)-INDEX(Bang_F,MATCH(A12,Bang_Z,1))) | C12: =INDEX(Bang_W,MATCH(A12,Bang_Z,1))+(A12-INDEX(Bang_Z,MATCH(A12,Bang_Z,1)))*(INDEX(Bang_F,MATCH(A12,Bang_Z,1))+B12)/2 | D12: =C12*1000000/dt_s | E12: =MAX(A12-TC_Z,0) | F12: =1-0.2*(TC_xmb+(TC_n-1)*TC_xmt)*E12/(TC_n*TC_b) | G12: =1-0.2*(TC_xmb+(TC_n_sc-1)*TC_xmt)*E12/(TC_n_sc*TC_b) | H12: =TC_s*F12*TC_m*TC_n*TC_b*SQRT(2*g_)*E12^1.5 | I12: =TC_s*G12*TC_m*TC_n_sc*TC_b*SQRT(2*g_)*E12^1.5 | J12: =MAX(A12-SC_Z,0) | K12: =1-0.2*(SC_xmb+(SC_n-1)*SC_xmt)*J12/(SC_n*SC_b) | L12: =SC_s*K12*SC_m*SC_n*SC_b*SQRT(2*g_)*J12^1.5 | M12: =H12+L12 | N12: =I12+L12 | O12: =D12-M12/2 | P12: =D12-N12/2 | Q12: =D12+M12/2 | R12: =D12+N12/2
A13: =ROUND(A12+0.1,2) | B13: =INDEX(Bang_F,MATCH(A13,Bang_Z,1))+(A13-INDEX(Bang_Z,MATCH(A13,Bang_Z,1)))*(INDEX(Bang_F,MATCH(A13,Bang_Z,1)+1)-INDEX(Bang_F,MATCH(A13,Bang_Z,1))) | C13: =INDEX(Bang_W,MATCH(A13,Bang_Z,1))+(A13-INDEX(Bang_Z,MATCH(A13,Bang_Z,1)))*(INDEX(Bang_F,MATCH(A13,Bang_Z,1))+B13)/2 | D13: =C13*1000000/dt_s | E13: =MAX(A13-TC_Z,0) | F13: =1-0.2*(TC_xmb+(TC_n-1)*TC_xmt)*E13/(TC_n*TC_b) | G13: =1-0.2*(TC_xmb+(TC_n_sc-1)*TC_xmt)*E13/(TC_n_sc*TC_b) | H13: =TC_s*F13*TC_m*TC_n*TC_b*SQRT(2*g_)*E13^1.5 | I13: =TC_s*G13*TC_m*TC_n_sc*TC_b*SQRT(2*g_)*E13^1.5 | J13: =MAX(A13-SC_Z,0) | K13: =1-0.2*(SC_xmb+(SC_n-1)*SC_xmt)*J13/(SC_n*SC_b) | L13: =SC_s*K13*SC_m*SC_n*SC_b*SQRT(2*g_)*J13^1.5 | M13: =H13+L13 | N13: =I13+L13 | O13: =D13-M13/2 | P13: =D13-N13/2 | Q13: =D13+M13/2 | R13: =D13+N13/2
A14: =ROUND(A13+0.1,2) | B14: =INDEX(Bang_F,MATCH(A14,Bang_Z,1))+(A14-INDEX(Bang_Z,MATCH(A14,Bang_Z,1)))*(INDEX(Bang_F,MATCH(A14,Bang_Z,1)+1)-INDEX(Bang_F,MATCH(A14,Bang_Z,1))) | C14: =INDEX(Bang_W,MATCH(A14,Bang_Z,1))+(A14-INDEX(Bang_Z,MATCH(A14,Bang_Z,1)))*(INDEX(Bang_F,MATCH(A14,Bang_Z,1))+B14)/2 | D14: =C14*1000000/dt_s | E14: =MAX(A14-TC_Z,0) | F14: =1-0.2*(TC_xmb+(TC_n-1)*TC_xmt)*E14/(TC_n*TC_b) | G14: =1-0.2*(TC_xmb+(TC_n_sc-1)*TC_xmt)*E14/(TC_n_sc*TC_b) | H14: =TC_s*F14*TC_m*TC_n*TC_b*SQRT(2*g_)*E14^1.5 | I14: =TC_s*G14*TC_m*TC_n_sc*TC_b*SQRT(2*g_)*E14^1.5 | J14: =MAX(A14-SC_Z,0) | K14: =1-0.2*(SC_xmb+(SC_n-1)*SC_xmt)*J14/(SC_n*SC_b) | L14: =SC_s*K14*SC_m*SC_n*SC_b*SQRT(2*g_)*J14^1.5 | M14: =H14+L14 | N14: =I14+L14 | O14: =D14-M14/2 | P14: =D14-N14/2 | Q14: =D14+M14/2 | R14: =D14+N14/2
A15: =ROUND(A14+0.1,2) | B15: =INDEX(Bang_F,MATCH(A15,Bang_Z,1))+(A15-INDEX(Bang_Z,MATCH(A15,Bang_Z,1)))*(INDEX(Bang_F,MATCH(A15,Bang_Z,1)+1)-INDEX(Bang_F,MATCH(A15,Bang_Z,1))) | C15: =INDEX(Bang_W,MATCH(A15,Bang_Z,1))+(A15-INDEX(Bang_Z,MATCH(A15,Bang_Z,1)))*(INDEX(Bang_F,MATCH(A15,Bang_Z,1))+B15)/2 | D15: =C15*1000000/dt_s | E15: =MAX(A15-TC_Z,0) | F15: =1-0.2*(TC_xmb+(TC_n-1)*TC_xmt)*E15/(TC_n*TC_b) | G15: =1-0.2*(TC_xmb+(TC_n_sc-1)*TC_xmt)*E15/(TC_n_sc*TC_b) | H15: =TC_s*F15*TC_m*TC_n*TC_b*SQRT(2*g_)*E15^1.5 | I15: =TC_s*G15*TC_m*TC_n_sc*TC_b*SQRT(2*g_)*E15^1.5 | J15: =MAX(A15-SC_Z,0) | K15: =1-0.2*(SC_xmb+(SC_n-1)*SC_xmt)*J15/(SC_n*SC_b) | L15: =SC_s*K15*SC_m*SC_n*SC_b*SQRT(2*g_)*J15^1.5 | M15: =H15+L15 | N15: =I15+L15 | O15: =D15-M15/2 | P15: =D15-N15/2 | Q15: =D15+M15/2 | R15: =D15+N15/2
A16: =ROUND(A15+0.1,2) | B16: =INDEX(Bang_F,MATCH(A16,Bang_Z,1))+(A16-INDEX(Bang_Z,MATCH(A16,Bang_Z,1)))*(INDEX(Bang_F,MATCH(A16,Bang_Z,1)+1)-INDEX(Bang_F,MATCH(A16,Bang_Z,1))) | C16: =INDEX(Bang_W,MATCH(A16,Bang_Z,1))+(A16-INDEX(Bang_Z,MATCH(A16,Bang_Z,1)))*(INDEX(Bang_F,MATCH(A16,Bang_Z,1))+B16)/2 | D16: =C16*1000000/dt_s | E16: =MAX(A16-TC_Z,0) | F16: =1-0.2*(TC_xmb+(TC_n-1)*TC_xmt)*E16/(TC_n*TC_b) | G16: =1-0.2*(TC_xmb+(TC_n_sc-1)*TC_xmt)*E16/(TC_n_sc*TC_b) | H16: =TC_s*F16*TC_m*TC_n*TC_b*SQRT(2*g_)*E16^1.5 | I16: =TC_s*G16*TC_m*TC_n_sc*TC_b*SQRT(2*g_)*E16^1.5 | J16: =MAX(A16-SC_Z,0) | K16: =1-0.2*(SC_xmb+(SC_n-1)*SC_xmt)*J16/(SC_n*SC_b) | L16: =SC_s*K16*SC_m*SC_n*SC_b*SQRT(2*g_)*J16^1.5 | M16: =H16+L16 | N16: =I16+L16 | O16: =D16-M16/2 | P16: =D16-N16/2 | Q16: =D16+M16/2 | R16: =D16+N16/2
A17: =ROUND(A16+0.1,2) | B17: =INDEX(Bang_F,MATCH(A17,Bang_Z,1))+(A17-INDEX(Bang_Z,MATCH(A17,Bang_Z,1)))*(INDEX(Bang_F,MATCH(A17,Bang_Z,1)+1)-INDEX(Bang_F,MATCH(A17,Bang_Z,1))) | C17: =INDEX(Bang_W,MATCH(A17,Bang_Z,1))+(A17-INDEX(Bang_Z,MATCH(A17,Bang_Z,1)))*(INDEX(Bang_F,MATCH(A17,Bang_Z,1))+B17)/2 | D17: =C17*1000000/dt_s | E17: =MAX(A17-TC_Z,0) | F17: =1-0.2*(TC_xmb+(TC_n-1)*TC_xmt)*E17/(TC_n*TC_b) | G17: =1-0.2*(TC_xmb+(TC_n_sc-1)*TC_xmt)*E17/(TC_n_sc*TC_b) | H17: =TC_s*F17*TC_m*TC_n*TC_b*SQRT(2*g_)*E17^1.5 | I17: =TC_s*G17*TC_m*TC_n_sc*TC_b*SQRT(2*g_)*E17^1.5 | J17: =MAX(A17-SC_Z,0) | K17: =1-0.2*(SC_xmb+(SC_n-1)*SC_xmt)*J17/(SC_n*SC_b) | L17: =SC_s*K17*SC_m*SC_n*SC_b*SQRT(2*g_)*J17^1.5 | M17: =H17+L17 | N17: =I17+L17 | O17: =D17-M17/2 | P17: =D17-N17/2 | Q17: =D17+M17/2 | R17: =D17+N17/2
... A105: =ROUND(A104+0.1,2) | B105: =INDEX(Bang_F,MATCH(A105,Bang_Z,1))+(A105-INDEX(Bang_Z,MATCH(A105,Bang_Z,1)))*(INDEX(Bang_F,MATCH(A105,Bang_Z,1)+1)-INDEX(Bang_F,MATCH(A105,Bang_Z,1))) | C105: =INDEX(Bang_W,MATCH(A105,Bang_Z,1))+(A105-INDEX(Bang_Z,MATCH(A105,Bang_Z,1)))*(INDEX(Bang_F,MATCH(A105,Bang_Z,1))+B105)/2 | D105: =C105*1000000/dt_s | E105: =MAX(A105-TC_Z,0) | F105: =1-0.2*(TC_xmb+(TC_n-1)*TC_xmt)*E105/(TC_n*TC_b) | G105: =1-0.2*(TC_xmb+(TC_n_sc-1)*TC_xmt)*E105/(TC_n_sc*TC_b) | H105: =TC_s*F105*TC_m*TC_n*TC_b*SQRT(2*g_)*E105^1.5 | I105: =TC_s*G105*TC_m*TC_n_sc*TC_b*SQRT(2*g_)*E105^1.5 | J105: =MAX(A105-SC_Z,0) | K105: =1-0.2*(SC_xmb+(SC_n-1)*SC_xmt)*J105/(SC_n*SC_b) | L105: =SC_s*K105*SC_m*SC_n*SC_b*SQRT(2*g_)*J105^1.5 | M105: =H105+L105 | N105: =I105+L105 | O105: =D105-M105/2 | P105: =D105-N105/2 | Q105: =D105+M105/2 | R105: =D105+N105/2

Sheet BieuDoPhuTro
A1: BIỂU ĐỒ PHỤ TRỢ PÔ-TA-PỐP: HAI ĐƯỜNG q ~ f₁ VÀ q ~ f₂
A2: Cách dùng mỗi giờ: (1) từ q₁ trên trục đứng gióng ngang sang đường q ~ f₁, đọc f₁ trên trục ngang; (2) f₂ = f₁ + Qtb;
A3: (3) từ f₂ trên trục ngang gióng thẳng lên đường q ~ f₂, đọc q₂ trên trục đứng. Hai đường cách nhau đúng bằng q theo phương ngang (f₂ − f₁ = q).
A4: Số liệu vẽ lấy từ sheet QuanHe, mực nước +74,00 ÷ +80,00 m; muốn đổi khoảng vẽ: bấm chuột phải vào biểu đồ → Select Data.
A49: Ví dụ tra giờ thứ 10 – sheet P1_BinhThuong (số liệu tự cập nhật)
A50: Bước tra | B50: Giá trị | D50: Điểm gióng | E50: f (m³/s) | F50: q (m³/s)
A51: Qtb = (Q₁ + Q₂)/2 (m³/s) | B51: =P1_BinhThuong!C26 | D51: q₁ trên trục q | E51: 8500 | F51: =B52
A52: q₁ – cuối giờ trước (m³/s) | B52: =P1_BinhThuong!D26 | D52: gặp đường f₁ | E52: =B53 | F52: =B52
A53: f₁ – tra đường q ~ f₁ với q₁ (m³/s) | B53: =P1_BinhThuong!E26 | D53: + Qtb → f₂ | E53: =B54 | F53: =B52
A54: f₂ = f₁ + Qtb (m³/s) | B54: =P1_BinhThuong!F26 | D54: gặp đường f₂ | E54: =B54 | F54: =B55
A55: q₂ – tra đường q ~ f₂ với f₂ (m³/s) | B55: =P1_BinhThuong!G26 | D55: q₂ trên trục q | E55: 8500 | F55: =B55
A56: Z₂ (m) | B56: =P1_BinhThuong!H26 | D56: Đường nét đứt trên biểu đồ vận hành bình thường.

Sheet P1_BinhThuong
A1: ĐIỀU TIẾT LŨ – PHƯƠNG PHÁP PÔ-TA-PỐP, HAI ĐƯỜNG q ~ f₁, q ~ f₂ (Δt = 1 giờ)
A3: Tần suất P (%) | C3: 1 | D3: Trường hợp | F3: Bình thường | H3: ← sửa ô vàng: P = 1 hoặc 0,2; trường hợp “Bình thường” hoặc “Sự cố” (1 cửa tràn chính không mở)
A4: Cột lũ | C4: =MATCH(C3,Lu_P,0) | D4: Cột bảng tra | F4: =IF(F3="Sự cố",2,1)
H5: Giờ 0: Z = MNDBT, q = q(MNDBT). Từ giờ 1: q₁ → tra đường q ~ f₁ được f₁ → f₂ = f₁ + Qtb → tra đường q ~ f₂ được q₂, Z₂, V₂.
A6: Mực nước lớn nhất Zmax (m) | F6: =MAX(H16:H64) | H6: Cột M, N: vị trí tra q₁; cột O, P: vị trí tra f₂ trong bảng QuanHe. Cột L kiểm tra V₂/Δt + q₂/2 = f₂.
A7: Thời điểm xuất hiện (giờ) | F7: =INDEX(A16:A64,MATCH(MAX(H16:H64),H16:H64,0))
A8: Lưu lượng xả lớn nhất qmax (m³/s) | F8: =MAX(G16:G64)
A9: Lúc Zmax: q tràn chính / q tràn sự cố (m³/s) | F9: =INDEX(I16:I64,MATCH(MAX(H16:H64),H16:H64,0)) | G9: =INDEX(J16:J64,MATCH(MAX(H16:H64),H16:H64,0))
A10: Cột nước trên ngưỡng lúc Zmax: tràn chính / tràn sự cố (m) | F10: =F6-TC_Z | G10: =F6-SC_Z
A11: Dung tích phòng lũ V(Zmax) − V(MNDBT) (10⁶ m³) | F11: =INDEX(K16:K64,MATCH(MAX(H16:H64),H16:H64,0))-K16
A12: Cân bằng nước: W đến − W xả − ΔV (10⁶ m³, phải ≈ 0) | F12: =SUMPRODUCT((B16:B63+B17:B64)/2)*dt_s/1000000-SUMPRODUCT((G16:G63+G17:G64)/2)*dt_s/1000000-(K64-K16)
A15: t (giờ) | B15: Q đến (m³/s) | C15: Qtb = (Q₁+Q₂)/2 | D15: q₁ (cuối giờ trước) | E15: f₁ – tra đường q ~ f₁ với q₁ | F15: f₂ = f₁ + Qtb | G15: q₂ – tra đường q ~ f₂ với f₂ | H15: Z₂ (m) | I15: q tràn chính (m³/s) | J15: q tràn sự cố (m³/s) | K15: V₂ (10⁶ m³) | L15: Kiểm tra V₂/Δt + q₂/2 (= f₂) | M15: k₁ – dòng tra q₁ | N15: w₁ | O15: k – dòng tra f₂ | P15: w
A16: 0 | B16: =IFERROR(INDEX(Lu_Q,MATCH(A16,Lu_t,0),$C$4),0) | G16: =INDEX(QH_q,O16,$F$4)+P16*(INDEX(QH_q,O16+1,$F$4)-INDEX(QH_q,O16,$F$4)) | H16: =INDEX(QH_Z,O16)+P16*(INDEX(QH_Z,O16+1)-INDEX(QH_Z,O16)) | I16: =INDEX(QH_qtc,O16,$F$4)+P16*(INDEX(QH_qtc,O16+1,$F$4)-INDEX(QH_qtc,O16,$F$4)) | J16: =INDEX(QH_qsc,O16)+P16*(INDEX(QH_qsc,O16+1)-INDEX(QH_qsc,O16)) | K16: =INDEX(QH_V,O16)+P16*(INDEX(QH_V,O16+1)-INDEX(QH_V,O16)) | L16: =K16*1000000/dt_s+G16/2 | O16: =MATCH(Z0,QH_Z,1) | P16: =(Z0-INDEX(QH_Z,O16))/(INDEX(QH_Z,O16+1)-INDEX(QH_Z,O16))
A17: 1 | B17: =IFERROR(INDEX(Lu_Q,MATCH(A17,Lu_t,0),$C$4),0) | C17: =(B16+B17)/2 | D17: =G16 | E17: =INDEX(QH_f1,M17,$F$4)+N17*(INDEX(QH_f1,M17+1,$F$4)-INDEX(QH_f1,M17,$F$4)) | F17: =E17+C17 | G17: =INDEX(QH_q,O17,$F$4)+P17*(INDEX(QH_q,O17+1,$F$4)-INDEX(QH_q,O17,$F$4)) | H17: =INDEX(QH_Z,O17)+P17*(INDEX(QH_Z,O17+1)-INDEX(QH_Z,O17)) | I17: =INDEX(QH_qtc,O17,$F$4)+P17*(INDEX(QH_qtc,O17+1,$F$4)-INDEX(QH_qtc,O17,$F$4)) | J17: =INDEX(QH_qsc,O17)+P17*(INDEX(QH_qsc,O17+1)-INDEX(QH_qsc,O17)) | K17: =INDEX(QH_V,O17)+P17*(INDEX(QH_V,O17+1)-INDEX(QH_V,O17)) | L17: =K17*1000000/dt_s+G17/2 | M17: =MATCH(D17,INDEX(QH_q,0,$F$4),1) | N17: =(D17-INDEX(QH_q,M17,$F$4))/(INDEX(QH_q,M17+1,$F$4)-INDEX(QH_q,M17,$F$4)) | O17: =MATCH(F17,INDEX(QH_f2,0,$F$4),1) | P17: =(F17-INDEX(QH_f2,O17,$F$4))/(INDEX(QH_f2,O17+1,$F$4)-INDEX(QH_f2,O17,$F$4))
A18: 2 | B18: =IFERROR(INDEX(Lu_Q,MATCH(A18,Lu_t,0),$C$4),0) | C18: =(B17+B18)/2 | D18: =G17 | E18: =INDEX(QH_f1,M18,$F$4)+N18*(INDEX(QH_f1,M18+1,$F$4)-INDEX(QH_f1,M18,$F$4)) | F18: =E18+C18 | G18: =INDEX(QH_q,O18,$F$4)+P18*(INDEX(QH_q,O18+1,$F$4)-INDEX(QH_q,O18,$F$4)) | H18: =INDEX(QH_Z,O18)+P18*(INDEX(QH_Z,O18+1)-INDEX(QH_Z,O18)) | I18: =INDEX(QH_qtc,O18,$F$4)+P18*(INDEX(QH_qtc,O18+1,$F$4)-INDEX(QH_qtc,O18,$F$4)) | J18: =INDEX(QH_qsc,O18)+P18*(INDEX(QH_qsc,O18+1)-INDEX(QH_qsc,O18)) | K18: =INDEX(QH_V,O18)+P18*(INDEX(QH_V,O18+1)-INDEX(QH_V,O18)) | L18: =K18*1000000/dt_s+G18/2 | M18: =MATCH(D18,INDEX(QH_q,0,$F$4),1) | N18: =(D18-INDEX(QH_q,M18,$F$4))/(INDEX(QH_q,M18+1,$F$4)-INDEX(QH_q,M18,$F$4)) | O18: =MATCH(F18,INDEX(QH_f2,0,$F$4),1) | P18: =(F18-INDEX(QH_f2,O18,$F$4))/(INDEX(QH_f2,O18+1,$F$4)-INDEX(QH_f2,O18,$F$4))
A19: 3 | B19: =IFERROR(INDEX(Lu_Q,MATCH(A19,Lu_t,0),$C$4),0) | C19: =(B18+B19)/2 | D19: =G18 | E19: =INDEX(QH_f1,M19,$F$4)+N19*(INDEX(QH_f1,M19+1,$F$4)-INDEX(QH_f1,M19,$F$4)) | F19: =E19+C19 | G19: =INDEX(QH_q,O19,$F$4)+P19*(INDEX(QH_q,O19+1,$F$4)-INDEX(QH_q,O19,$F$4)) | H19: =INDEX(QH_Z,O19)+P19*(INDEX(QH_Z,O19+1)-INDEX(QH_Z,O19)) | I19: =INDEX(QH_qtc,O19,$F$4)+P19*(INDEX(QH_qtc,O19+1,$F$4)-INDEX(QH_qtc,O19,$F$4)) | J19: =INDEX(QH_qsc,O19)+P19*(INDEX(QH_qsc,O19+1)-INDEX(QH_qsc,O19)) | K19: =INDEX(QH_V,O19)+P19*(INDEX(QH_V,O19+1)-INDEX(QH_V,O19)) | L19: =K19*1000000/dt_s+G19/2 | M19: =MATCH(D19,INDEX(QH_q,0,$F$4),1) | N19: =(D19-INDEX(QH_q,M19,$F$4))/(INDEX(QH_q,M19+1,$F$4)-INDEX(QH_q,M19,$F$4)) | O19: =MATCH(F19,INDEX(QH_f2,0,$F$4),1) | P19: =(F19-INDEX(QH_f2,O19,$F$4))/(INDEX(QH_f2,O19+1,$F$4)-INDEX(QH_f2,O19,$F$4))
A20: 4 | B20: =IFERROR(INDEX(Lu_Q,MATCH(A20,Lu_t,0),$C$4),0) | C20: =(B19+B20)/2 | D20: =G19 | E20: =INDEX(QH_f1,M20,$F$4)+N20*(INDEX(QH_f1,M20+1,$F$4)-INDEX(QH_f1,M20,$F$4)) | F20: =E20+C20 | G20: =INDEX(QH_q,O20,$F$4)+P20*(INDEX(QH_q,O20+1,$F$4)-INDEX(QH_q,O20,$F$4)) | H20: =INDEX(QH_Z,O20)+P20*(INDEX(QH_Z,O20+1)-INDEX(QH_Z,O20)) | I20: =INDEX(QH_qtc,O20,$F$4)+P20*(INDEX(QH_qtc,O20+1,$F$4)-INDEX(QH_qtc,O20,$F$4)) | J20: =INDEX(QH_qsc,O20)+P20*(INDEX(QH_qsc,O20+1)-INDEX(QH_qsc,O20)) | K20: =INDEX(QH_V,O20)+P20*(INDEX(QH_V,O20+1)-INDEX(QH_V,O20)) | L20: =K20*1000000/dt_s+G20/2 | M20: =MATCH(D20,INDEX(QH_q,0,$F$4),1) | N20: =(D20-INDEX(QH_q,M20,$F$4))/(INDEX(QH_q,M20+1,$F$4)-INDEX(QH_q,M20,$F$4)) | O20: =MATCH(F20,INDEX(QH_f2,0,$F$4),1) | P20: =(F20-INDEX(QH_f2,O20,$F$4))/(INDEX(QH_f2,O20+1,$F$4)-INDEX(QH_f2,O20,$F$4))
A21: 5 | B21: =IFERROR(INDEX(Lu_Q,MATCH(A21,Lu_t,0),$C$4),0) | C21: =(B20+B21)/2 | D21: =G20 | E21: =INDEX(QH_f1,M21,$F$4)+N21*(INDEX(QH_f1,M21+1,$F$4)-INDEX(QH_f1,M21,$F$4)) | F21: =E21+C21 | G21: =INDEX(QH_q,O21,$F$4)+P21*(INDEX(QH_q,O21+1,$F$4)-INDEX(QH_q,O21,$F$4)) | H21: =INDEX(QH_Z,O21)+P21*(INDEX(QH_Z,O21+1)-INDEX(QH_Z,O21)) | I21: =INDEX(QH_qtc,O21,$F$4)+P21*(INDEX(QH_qtc,O21+1,$F$4)-INDEX(QH_qtc,O21,$F$4)) | J21: =INDEX(QH_qsc,O21)+P21*(INDEX(QH_qsc,O21+1)-INDEX(QH_qsc,O21)) | K21: =INDEX(QH_V,O21)+P21*(INDEX(QH_V,O21+1)-INDEX(QH_V,O21)) | L21: =K21*1000000/dt_s+G21/2 | M21: =MATCH(D21,INDEX(QH_q,0,$F$4),1) | N21: =(D21-INDEX(QH_q,M21,$F$4))/(INDEX(QH_q,M21+1,$F$4)-INDEX(QH_q,M21,$F$4)) | O21: =MATCH(F21,INDEX(QH_f2,0,$F$4),1) | P21: =(F21-INDEX(QH_f2,O21,$F$4))/(INDEX(QH_f2,O21+1,$F$4)-INDEX(QH_f2,O21,$F$4))
A22: 6 | B22: =IFERROR(INDEX(Lu_Q,MATCH(A22,Lu_t,0),$C$4),0) | C22: =(B21+B22)/2 | D22: =G21 | E22: =INDEX(QH_f1,M22,$F$4)+N22*(INDEX(QH_f1,M22+1,$F$4)-INDEX(QH_f1,M22,$F$4)) | F22: =E22+C22 | G22: =INDEX(QH_q,O22,$F$4)+P22*(INDEX(QH_q,O22+1,$F$4)-INDEX(QH_q,O22,$F$4)) | H22: =INDEX(QH_Z,O22)+P22*(INDEX(QH_Z,O22+1)-INDEX(QH_Z,O22)) | I22: =INDEX(QH_qtc,O22,$F$4)+P22*(INDEX(QH_qtc,O22+1,$F$4)-INDEX(QH_qtc,O22,$F$4)) | J22: =INDEX(QH_qsc,O22)+P22*(INDEX(QH_qsc,O22+1)-INDEX(QH_qsc,O22)) | K22: =INDEX(QH_V,O22)+P22*(INDEX(QH_V,O22+1)-INDEX(QH_V,O22)) | L22: =K22*1000000/dt_s+G22/2 | M22: =MATCH(D22,INDEX(QH_q,0,$F$4),1) | N22: =(D22-INDEX(QH_q,M22,$F$4))/(INDEX(QH_q,M22+1,$F$4)-INDEX(QH_q,M22,$F$4)) | O22: =MATCH(F22,INDEX(QH_f2,0,$F$4),1) | P22: =(F22-INDEX(QH_f2,O22,$F$4))/(INDEX(QH_f2,O22+1,$F$4)-INDEX(QH_f2,O22,$F$4))
A23: 7 | B23: =IFERROR(INDEX(Lu_Q,MATCH(A23,Lu_t,0),$C$4),0) | C23: =(B22+B23)/2 | D23: =G22 | E23: =INDEX(QH_f1,M23,$F$4)+N23*(INDEX(QH_f1,M23+1,$F$4)-INDEX(QH_f1,M23,$F$4)) | F23: =E23+C23 | G23: =INDEX(QH_q,O23,$F$4)+P23*(INDEX(QH_q,O23+1,$F$4)-INDEX(QH_q,O23,$F$4)) | H23: =INDEX(QH_Z,O23)+P23*(INDEX(QH_Z,O23+1)-INDEX(QH_Z,O23)) | I23: =INDEX(QH_qtc,O23,$F$4)+P23*(INDEX(QH_qtc,O23+1,$F$4)-INDEX(QH_qtc,O23,$F$4)) | J23: =INDEX(QH_qsc,O23)+P23*(INDEX(QH_qsc,O23+1)-INDEX(QH_qsc,O23)) | K23: =INDEX(QH_V,O23)+P23*(INDEX(QH_V,O23+1)-INDEX(QH_V,O23)) | L23: =K23*1000000/dt_s+G23/2 | M23: =MATCH(D23,INDEX(QH_q,0,$F$4),1) | N23: =(D23-INDEX(QH_q,M23,$F$4))/(INDEX(QH_q,M23+1,$F$4)-INDEX(QH_q,M23,$F$4)) | O23: =MATCH(F23,INDEX(QH_f2,0,$F$4),1) | P23: =(F23-INDEX(QH_f2,O23,$F$4))/(INDEX(QH_f2,O23+1,$F$4)-INDEX(QH_f2,O23,$F$4))
A24: 8 | B24: =IFERROR(INDEX(Lu_Q,MATCH(A24,Lu_t,0),$C$4),0) | C24: =(B23+B24)/2 | D24: =G23 | E24: =INDEX(QH_f1,M24,$F$4)+N24*(INDEX(QH_f1,M24+1,$F$4)-INDEX(QH_f1,M24,$F$4)) | F24: =E24+C24 | G24: =INDEX(QH_q,O24,$F$4)+P24*(INDEX(QH_q,O24+1,$F$4)-INDEX(QH_q,O24,$F$4)) | H24: =INDEX(QH_Z,O24)+P24*(INDEX(QH_Z,O24+1)-INDEX(QH_Z,O24)) | I24: =INDEX(QH_qtc,O24,$F$4)+P24*(INDEX(QH_qtc,O24+1,$F$4)-INDEX(QH_qtc,O24,$F$4)) | J24: =INDEX(QH_qsc,O24)+P24*(INDEX(QH_qsc,O24+1)-INDEX(QH_qsc,O24)) | K24: =INDEX(QH_V,O24)+P24*(INDEX(QH_V,O24+1)-INDEX(QH_V,O24)) | L24: =K24*1000000/dt_s+G24/2 | M24: =MATCH(D24,INDEX(QH_q,0,$F$4),1) | N24: =(D24-INDEX(QH_q,M24,$F$4))/(INDEX(QH_q,M24+1,$F$4)-INDEX(QH_q,M24,$F$4)) | O24: =MATCH(F24,INDEX(QH_f2,0,$F$4),1) | P24: =(F24-INDEX(QH_f2,O24,$F$4))/(INDEX(QH_f2,O24+1,$F$4)-INDEX(QH_f2,O24,$F$4))
A25: 9 | B25: =IFERROR(INDEX(Lu_Q,MATCH(A25,Lu_t,0),$C$4),0) | C25: =(B24+B25)/2 | D25: =G24 | E25: =INDEX(QH_f1,M25,$F$4)+N25*(INDEX(QH_f1,M25+1,$F$4)-INDEX(QH_f1,M25,$F$4)) | F25: =E25+C25 | G25: =INDEX(QH_q,O25,$F$4)+P25*(INDEX(QH_q,O25+1,$F$4)-INDEX(QH_q,O25,$F$4)) | H25: =INDEX(QH_Z,O25)+P25*(INDEX(QH_Z,O25+1)-INDEX(QH_Z,O25)) | I25: =INDEX(QH_qtc,O25,$F$4)+P25*(INDEX(QH_qtc,O25+1,$F$4)-INDEX(QH_qtc,O25,$F$4)) | J25: =INDEX(QH_qsc,O25)+P25*(INDEX(QH_qsc,O25+1)-INDEX(QH_qsc,O25)) | K25: =INDEX(QH_V,O25)+P25*(INDEX(QH_V,O25+1)-INDEX(QH_V,O25)) | L25: =K25*1000000/dt_s+G25/2 | M25: =MATCH(D25,INDEX(QH_q,0,$F$4),1) | N25: =(D25-INDEX(QH_q,M25,$F$4))/(INDEX(QH_q,M25+1,$F$4)-INDEX(QH_q,M25,$F$4)) | O25: =MATCH(F25,INDEX(QH_f2,0,$F$4),1) | P25: =(F25-INDEX(QH_f2,O25,$F$4))/(INDEX(QH_f2,O25+1,$F$4)-INDEX(QH_f2,O25,$F$4))
A26: 10 | B26: =IFERROR(INDEX(Lu_Q,MATCH(A26,Lu_t,0),$C$4),0) | C26: =(B25+B26)/2 | D26: =G25 | E26: =INDEX(QH_f1,M26,$F$4)+N26*(INDEX(QH_f1,M26+1,$F$4)-INDEX(QH_f1,M26,$F$4)) | F26: =E26+C26 | G26: =INDEX(QH_q,O26,$F$4)+P26*(INDEX(QH_q,O26+1,$F$4)-INDEX(QH_q,O26,$F$4)) | H26: =INDEX(QH_Z,O26)+P26*(INDEX(QH_Z,O26+1)-INDEX(QH_Z,O26)) | I26: =INDEX(QH_qtc,O26,$F$4)+P26*(INDEX(QH_qtc,O26+1,$F$4)-INDEX(QH_qtc,O26,$F$4)) | J26: =INDEX(QH_qsc,O26)+P26*(INDEX(QH_qsc,O26+1)-INDEX(QH_qsc,O26)) | K26: =INDEX(QH_V,O26)+P26*(INDEX(QH_V,O26+1)-INDEX(QH_V,O26)) | L26: =K26*1000000/dt_s+G26/2 | M26: =MATCH(D26,INDEX(QH_q,0,$F$4),1) | N26: =(D26-INDEX(QH_q,M26,$F$4))/(INDEX(QH_q,M26+1,$F$4)-INDEX(QH_q,M26,$F$4)) | O26: =MATCH(F26,INDEX(QH_f2,0,$F$4),1) | P26: =(F26-INDEX(QH_f2,O26,$F$4))/(INDEX(QH_f2,O26+1,$F$4)-INDEX(QH_f2,O26,$F$4))
A27: 11 | B27: =IFERROR(INDEX(Lu_Q,MATCH(A27,Lu_t,0),$C$4),0) | C27: =(B26+B27)/2 | D27: =G26 | E27: =INDEX(QH_f1,M27,$F$4)+N27*(INDEX(QH_f1,M27+1,$F$4)-INDEX(QH_f1,M27,$F$4)) | F27: =E27+C27 | G27: =INDEX(QH_q,O27,$F$4)+P27*(INDEX(QH_q,O27+1,$F$4)-INDEX(QH_q,O27,$F$4)) | H27: =INDEX(QH_Z,O27)+P27*(INDEX(QH_Z,O27+1)-INDEX(QH_Z,O27)) | I27: =INDEX(QH_qtc,O27,$F$4)+P27*(INDEX(QH_qtc,O27+1,$F$4)-INDEX(QH_qtc,O27,$F$4)) | J27: =INDEX(QH_qsc,O27)+P27*(INDEX(QH_qsc,O27+1)-INDEX(QH_qsc,O27)) | K27: =INDEX(QH_V,O27)+P27*(INDEX(QH_V,O27+1)-INDEX(QH_V,O27)) | L27: =K27*1000000/dt_s+G27/2 | M27: =MATCH(D27,INDEX(QH_q,0,$F$4),1) | N27: =(D27-INDEX(QH_q,M27,$F$4))/(INDEX(QH_q,M27+1,$F$4)-INDEX(QH_q,M27,$F$4)) | O27: =MATCH(F27,INDEX(QH_f2,0,$F$4),1) | P27: =(F27-INDEX(QH_f2,O27,$F$4))/(INDEX(QH_f2,O27+1,$F$4)-INDEX(QH_f2,O27,$F$4))
A28: 12 | B28: =IFERROR(INDEX(Lu_Q,MATCH(A28,Lu_t,0),$C$4),0) | C28: =(B27+B28)/2 | D28: =G27 | E28: =INDEX(QH_f1,M28,$F$4)+N28*(INDEX(QH_f1,M28+1,$F$4)-INDEX(QH_f1,M28,$F$4)) | F28: =E28+C28 | G28: =INDEX(QH_q,O28,$F$4)+P28*(INDEX(QH_q,O28+1,$F$4)-INDEX(QH_q,O28,$F$4)) | H28: =INDEX(QH_Z,O28)+P28*(INDEX(QH_Z,O28+1)-INDEX(QH_Z,O28)) | I28: =INDEX(QH_qtc,O28,$F$4)+P28*(INDEX(QH_qtc,O28+1,$F$4)-INDEX(QH_qtc,O28,$F$4)) | J28: =INDEX(QH_qsc,O28)+P28*(INDEX(QH_qsc,O28+1)-INDEX(QH_qsc,O28)) | K28: =INDEX(QH_V,O28)+P28*(INDEX(QH_V,O28+1)-INDEX(QH_V,O28)) | L28: =K28*1000000/dt_s+G28/2 | M28: =MATCH(D28,INDEX(QH_q,0,$F$4),1) | N28: =(D28-INDEX(QH_q,M28,$F$4))/(INDEX(QH_q,M28+1,$F$4)-INDEX(QH_q,M28,$F$4)) | O28: =MATCH(F28,INDEX(QH_f2,0,$F$4),1) | P28: =(F28-INDEX(QH_f2,O28,$F$4))/(INDEX(QH_f2,O28+1,$F$4)-INDEX(QH_f2,O28,$F$4))
... A64: 48 | B64: =IFERROR(INDEX(Lu_Q,MATCH(A64,Lu_t,0),$C$4),0) | C64: =(B63+B64)/2 | D64: =G63 | E64: =INDEX(QH_f1,M64,$F$4)+N64*(INDEX(QH_f1,M64+1,$F$4)-INDEX(QH_f1,M64,$F$4)) | F64: =E64+C64 | G64: =INDEX(QH_q,O64,$F$4)+P64*(INDEX(QH_q,O64+1,$F$4)-INDEX(QH_q,O64,$F$4)) | H64: =INDEX(QH_Z,O64)+P64*(INDEX(QH_Z,O64+1)-INDEX(QH_Z,O64)) | I64: =INDEX(QH_qtc,O64,$F$4)+P64*(INDEX(QH_qtc,O64+1,$F$4)-INDEX(QH_qtc,O64,$F$4)) | J64: =INDEX(QH_qsc,O64)+P64*(INDEX(QH_qsc,O64+1)-INDEX(QH_qsc,O64)) | K64: =INDEX(QH_V,O64)+P64*(INDEX(QH_V,O64+1)-INDEX(QH_V,O64)) | L64: =K64*1000000/dt_s+G64/2 | M64: =MATCH(D64,INDEX(QH_q,0,$F$4),1) | N64: =(D64-INDEX(QH_q,M64,$F$4))/(INDEX(QH_q,M64+1,$F$4)-INDEX(QH_q,M64,$F$4)) | O64: =MATCH(F64,INDEX(QH_f2,0,$F$4),1) | P64: =(F64-INDEX(QH_f2,O64,$F$4))/(INDEX(QH_f2,O64+1,$F$4)-INDEX(QH_f2,O64,$F$4))

Sheet P1_SuCo
A1: ĐIỀU TIẾT LŨ – PHƯƠNG PHÁP PÔ-TA-PỐP, HAI ĐƯỜNG q ~ f₁, q ~ f₂ (Δt = 1 giờ)
A3: Tần suất P (%) | C3: 1 | D3: Trường hợp | F3: Sự cố | H3: ← sửa ô vàng: P = 1 hoặc 0,2; trường hợp “Bình thường” hoặc “Sự cố” (1 cửa tràn chính không mở)
A4: Cột lũ | C4: =MATCH(C3,Lu_P,0) | D4: Cột bảng tra | F4: =IF(F3="Sự cố",2,1)
H5: Giờ 0: Z = MNDBT, q = q(MNDBT). Từ giờ 1: q₁ → tra đường q ~ f₁ được f₁ → f₂ = f₁ + Qtb → tra đường q ~ f₂ được q₂, Z₂, V₂.
A6: Mực nước lớn nhất Zmax (m) | F6: =MAX(H16:H64) | H6: Cột M, N: vị trí tra q₁; cột O, P: vị trí tra f₂ trong bảng QuanHe. Cột L kiểm tra V₂/Δt + q₂/2 = f₂.
A7: Thời điểm xuất hiện (giờ) | F7: =INDEX(A16:A64,MATCH(MAX(H16:H64),H16:H64,0))
A8: Lưu lượng xả lớn nhất qmax (m³/s) | F8: =MAX(G16:G64)
A9: Lúc Zmax: q tràn chính / q tràn sự cố (m³/s) | F9: =INDEX(I16:I64,MATCH(MAX(H16:H64),H16:H64,0)) | G9: =INDEX(J16:J64,MATCH(MAX(H16:H64),H16:H64,0))
A10: Cột nước trên ngưỡng lúc Zmax: tràn chính / tràn sự cố (m) | F10: =F6-TC_Z | G10: =F6-SC_Z
A11: Dung tích phòng lũ V(Zmax) − V(MNDBT) (10⁶ m³) | F11: =INDEX(K16:K64,MATCH(MAX(H16:H64),H16:H64,0))-K16
A12: Cân bằng nước: W đến − W xả − ΔV (10⁶ m³, phải ≈ 0) | F12: =SUMPRODUCT((B16:B63+B17:B64)/2)*dt_s/1000000-SUMPRODUCT((G16:G63+G17:G64)/2)*dt_s/1000000-(K64-K16)
A15: t (giờ) | B15: Q đến (m³/s) | C15: Qtb = (Q₁+Q₂)/2 | D15: q₁ (cuối giờ trước) | E15: f₁ – tra đường q ~ f₁ với q₁ | F15: f₂ = f₁ + Qtb | G15: q₂ – tra đường q ~ f₂ với f₂ | H15: Z₂ (m) | I15: q tràn chính (m³/s) | J15: q tràn sự cố (m³/s) | K15: V₂ (10⁶ m³) | L15: Kiểm tra V₂/Δt + q₂/2 (= f₂) | M15: k₁ – dòng tra q₁ | N15: w₁ | O15: k – dòng tra f₂ | P15: w
A16: 0 | B16: =IFERROR(INDEX(Lu_Q,MATCH(A16,Lu_t,0),$C$4),0) | G16: =INDEX(QH_q,O16,$F$4)+P16*(INDEX(QH_q,O16+1,$F$4)-INDEX(QH_q,O16,$F$4)) | H16: =INDEX(QH_Z,O16)+P16*(INDEX(QH_Z,O16+1)-INDEX(QH_Z,O16)) | I16: =INDEX(QH_qtc,O16,$F$4)+P16*(INDEX(QH_qtc,O16+1,$F$4)-INDEX(QH_qtc,O16,$F$4)) | J16: =INDEX(QH_qsc,O16)+P16*(INDEX(QH_qsc,O16+1)-INDEX(QH_qsc,O16)) | K16: =INDEX(QH_V,O16)+P16*(INDEX(QH_V,O16+1)-INDEX(QH_V,O16)) | L16: =K16*1000000/dt_s+G16/2 | O16: =MATCH(Z0,QH_Z,1) | P16: =(Z0-INDEX(QH_Z,O16))/(INDEX(QH_Z,O16+1)-INDEX(QH_Z,O16))
A17: 1 | B17: =IFERROR(INDEX(Lu_Q,MATCH(A17,Lu_t,0),$C$4),0) | C17: =(B16+B17)/2 | D17: =G16 | E17: =INDEX(QH_f1,M17,$F$4)+N17*(INDEX(QH_f1,M17+1,$F$4)-INDEX(QH_f1,M17,$F$4)) | F17: =E17+C17 | G17: =INDEX(QH_q,O17,$F$4)+P17*(INDEX(QH_q,O17+1,$F$4)-INDEX(QH_q,O17,$F$4)) | H17: =INDEX(QH_Z,O17)+P17*(INDEX(QH_Z,O17+1)-INDEX(QH_Z,O17)) | I17: =INDEX(QH_qtc,O17,$F$4)+P17*(INDEX(QH_qtc,O17+1,$F$4)-INDEX(QH_qtc,O17,$F$4)) | J17: =INDEX(QH_qsc,O17)+P17*(INDEX(QH_qsc,O17+1)-INDEX(QH_qsc,O17)) | K17: =INDEX(QH_V,O17)+P17*(INDEX(QH_V,O17+1)-INDEX(QH_V,O17)) | L17: =K17*1000000/dt_s+G17/2 | M17: =MATCH(D17,INDEX(QH_q,0,$F$4),1) | N17: =(D17-INDEX(QH_q,M17,$F$4))/(INDEX(QH_q,M17+1,$F$4)-INDEX(QH_q,M17,$F$4)) | O17: =MATCH(F17,INDEX(QH_f2,0,$F$4),1) | P17: =(F17-INDEX(QH_f2,O17,$F$4))/(INDEX(QH_f2,O17+1,$F$4)-INDEX(QH_f2,O17,$F$4))
A18: 2 | B18: =IFERROR(INDEX(Lu_Q,MATCH(A18,Lu_t,0),$C$4),0) | C18: =(B17+B18)/2 | D18: =G17 | E18: =INDEX(QH_f1,M18,$F$4)+N18*(INDEX(QH_f1,M18+1,$F$4)-INDEX(QH_f1,M18,$F$4)) | F18: =E18+C18 | G18: =INDEX(QH_q,O18,$F$4)+P18*(INDEX(QH_q,O18+1,$F$4)-INDEX(QH_q,O18,$F$4)) | H18: =INDEX(QH_Z,O18)+P18*(INDEX(QH_Z,O18+1)-INDEX(QH_Z,O18)) | I18: =INDEX(QH_qtc,O18,$F$4)+P18*(INDEX(QH_qtc,O18+1,$F$4)-INDEX(QH_qtc,O18,$F$4)) | J18: =INDEX(QH_qsc,O18)+P18*(INDEX(QH_qsc,O18+1)-INDEX(QH_qsc,O18)) | K18: =INDEX(QH_V,O18)+P18*(INDEX(QH_V,O18+1)-INDEX(QH_V,O18)) | L18: =K18*1000000/dt_s+G18/2 | M18: =MATCH(D18,INDEX(QH_q,0,$F$4),1) | N18: =(D18-INDEX(QH_q,M18,$F$4))/(INDEX(QH_q,M18+1,$F$4)-INDEX(QH_q,M18,$F$4)) | O18: =MATCH(F18,INDEX(QH_f2,0,$F$4),1) | P18: =(F18-INDEX(QH_f2,O18,$F$4))/(INDEX(QH_f2,O18+1,$F$4)-INDEX(QH_f2,O18,$F$4))
A19: 3 | B19: =IFERROR(INDEX(Lu_Q,MATCH(A19,Lu_t,0),$C$4),0) | C19: =(B18+B19)/2 | D19: =G18 | E19: =INDEX(QH_f1,M19,$F$4)+N19*(INDEX(QH_f1,M19+1,$F$4)-INDEX(QH_f1,M19,$F$4)) | F19: =E19+C19 | G19: =INDEX(QH_q,O19,$F$4)+P19*(INDEX(QH_q,O19+1,$F$4)-INDEX(QH_q,O19,$F$4)) | H19: =INDEX(QH_Z,O19)+P19*(INDEX(QH_Z,O19+1)-INDEX(QH_Z,O19)) | I19: =INDEX(QH_qtc,O19,$F$4)+P19*(INDEX(QH_qtc,O19+1,$F$4)-INDEX(QH_qtc,O19,$F$4)) | J19: =INDEX(QH_qsc,O19)+P19*(INDEX(QH_qsc,O19+1)-INDEX(QH_qsc,O19)) | K19: =INDEX(QH_V,O19)+P19*(INDEX(QH_V,O19+1)-INDEX(QH_V,O19)) | L19: =K19*1000000/dt_s+G19/2 | M19: =MATCH(D19,INDEX(QH_q,0,$F$4),1) | N19: =(D19-INDEX(QH_q,M19,$F$4))/(INDEX(QH_q,M19+1,$F$4)-INDEX(QH_q,M19,$F$4)) | O19: =MATCH(F19,INDEX(QH_f2,0,$F$4),1) | P19: =(F19-INDEX(QH_f2,O19,$F$4))/(INDEX(QH_f2,O19+1,$F$4)-INDEX(QH_f2,O19,$F$4))
A20: 4 | B20: =IFERROR(INDEX(Lu_Q,MATCH(A20,Lu_t,0),$C$4),0) | C20: =(B19+B20)/2 | D20: =G19 | E20: =INDEX(QH_f1,M20,$F$4)+N20*(INDEX(QH_f1,M20+1,$F$4)-INDEX(QH_f1,M20,$F$4)) | F20: =E20+C20 | G20: =INDEX(QH_q,O20,$F$4)+P20*(INDEX(QH_q,O20+1,$F$4)-INDEX(QH_q,O20,$F$4)) | H20: =INDEX(QH_Z,O20)+P20*(INDEX(QH_Z,O20+1)-INDEX(QH_Z,O20)) | I20: =INDEX(QH_qtc,O20,$F$4)+P20*(INDEX(QH_qtc,O20+1,$F$4)-INDEX(QH_qtc,O20,$F$4)) | J20: =INDEX(QH_qsc,O20)+P20*(INDEX(QH_qsc,O20+1)-INDEX(QH_qsc,O20)) | K20: =INDEX(QH_V,O20)+P20*(INDEX(QH_V,O20+1)-INDEX(QH_V,O20)) | L20: =K20*1000000/dt_s+G20/2 | M20: =MATCH(D20,INDEX(QH_q,0,$F$4),1) | N20: =(D20-INDEX(QH_q,M20,$F$4))/(INDEX(QH_q,M20+1,$F$4)-INDEX(QH_q,M20,$F$4)) | O20: =MATCH(F20,INDEX(QH_f2,0,$F$4),1) | P20: =(F20-INDEX(QH_f2,O20,$F$4))/(INDEX(QH_f2,O20+1,$F$4)-INDEX(QH_f2,O20,$F$4))
A21: 5 | B21: =IFERROR(INDEX(Lu_Q,MATCH(A21,Lu_t,0),$C$4),0) | C21: =(B20+B21)/2 | D21: =G20 | E21: =INDEX(QH_f1,M21,$F$4)+N21*(INDEX(QH_f1,M21+1,$F$4)-INDEX(QH_f1,M21,$F$4)) | F21: =E21+C21 | G21: =INDEX(QH_q,O21,$F$4)+P21*(INDEX(QH_q,O21+1,$F$4)-INDEX(QH_q,O21,$F$4)) | H21: =INDEX(QH_Z,O21)+P21*(INDEX(QH_Z,O21+1)-INDEX(QH_Z,O21)) | I21: =INDEX(QH_qtc,O21,$F$4)+P21*(INDEX(QH_qtc,O21+1,$F$4)-INDEX(QH_qtc,O21,$F$4)) | J21: =INDEX(QH_qsc,O21)+P21*(INDEX(QH_qsc,O21+1)-INDEX(QH_qsc,O21)) | K21: =INDEX(QH_V,O21)+P21*(INDEX(QH_V,O21+1)-INDEX(QH_V,O21)) | L21: =K21*1000000/dt_s+G21/2 | M21: =MATCH(D21,INDEX(QH_q,0,$F$4),1) | N21: =(D21-INDEX(QH_q,M21,$F$4))/(INDEX(QH_q,M21+1,$F$4)-INDEX(QH_q,M21,$F$4)) | O21: =MATCH(F21,INDEX(QH_f2,0,$F$4),1) | P21: =(F21-INDEX(QH_f2,O21,$F$4))/(INDEX(QH_f2,O21+1,$F$4)-INDEX(QH_f2,O21,$F$4))
A22: 6 | B22: =IFERROR(INDEX(Lu_Q,MATCH(A22,Lu_t,0),$C$4),0) | C22: =(B21+B22)/2 | D22: =G21 | E22: =INDEX(QH_f1,M22,$F$4)+N22*(INDEX(QH_f1,M22+1,$F$4)-INDEX(QH_f1,M22,$F$4)) | F22: =E22+C22 | G22: =INDEX(QH_q,O22,$F$4)+P22*(INDEX(QH_q,O22+1,$F$4)-INDEX(QH_q,O22,$F$4)) | H22: =INDEX(QH_Z,O22)+P22*(INDEX(QH_Z,O22+1)-INDEX(QH_Z,O22)) | I22: =INDEX(QH_qtc,O22,$F$4)+P22*(INDEX(QH_qtc,O22+1,$F$4)-INDEX(QH_qtc,O22,$F$4)) | J22: =INDEX(QH_qsc,O22)+P22*(INDEX(QH_qsc,O22+1)-INDEX(QH_qsc,O22)) | K22: =INDEX(QH_V,O22)+P22*(INDEX(QH_V,O22+1)-INDEX(QH_V,O22)) | L22: =K22*1000000/dt_s+G22/2 | M22: =MATCH(D22,INDEX(QH_q,0,$F$4),1) | N22: =(D22-INDEX(QH_q,M22,$F$4))/(INDEX(QH_q,M22+1,$F$4)-INDEX(QH_q,M22,$F$4)) | O22: =MATCH(F22,INDEX(QH_f2,0,$F$4),1) | P22: =(F22-INDEX(QH_f2,O22,$F$4))/(INDEX(QH_f2,O22+1,$F$4)-INDEX(QH_f2,O22,$F$4))
A23: 7 | B23: =IFERROR(INDEX(Lu_Q,MATCH(A23,Lu_t,0),$C$4),0) | C23: =(B22+B23)/2 | D23: =G22 | E23: =INDEX(QH_f1,M23,$F$4)+N23*(INDEX(QH_f1,M23+1,$F$4)-INDEX(QH_f1,M23,$F$4)) | F23: =E23+C23 | G23: =INDEX(QH_q,O23,$F$4)+P23*(INDEX(QH_q,O23+1,$F$4)-INDEX(QH_q,O23,$F$4)) | H23: =INDEX(QH_Z,O23)+P23*(INDEX(QH_Z,O23+1)-INDEX(QH_Z,O23)) | I23: =INDEX(QH_qtc,O23,$F$4)+P23*(INDEX(QH_qtc,O23+1,$F$4)-INDEX(QH_qtc,O23,$F$4)) | J23: =INDEX(QH_qsc,O23)+P23*(INDEX(QH_qsc,O23+1)-INDEX(QH_qsc,O23)) | K23: =INDEX(QH_V,O23)+P23*(INDEX(QH_V,O23+1)-INDEX(QH_V,O23)) | L23: =K23*1000000/dt_s+G23/2 | M23: =MATCH(D23,INDEX(QH_q,0,$F$4),1) | N23: =(D23-INDEX(QH_q,M23,$F$4))/(INDEX(QH_q,M23+1,$F$4)-INDEX(QH_q,M23,$F$4)) | O23: =MATCH(F23,INDEX(QH_f2,0,$F$4),1) | P23: =(F23-INDEX(QH_f2,O23,$F$4))/(INDEX(QH_f2,O23+1,$F$4)-INDEX(QH_f2,O23,$F$4))
A24: 8 | B24: =IFERROR(INDEX(Lu_Q,MATCH(A24,Lu_t,0),$C$4),0) | C24: =(B23+B24)/2 | D24: =G23 | E24: =INDEX(QH_f1,M24,$F$4)+N24*(INDEX(QH_f1,M24+1,$F$4)-INDEX(QH_f1,M24,$F$4)) | F24: =E24+C24 | G24: =INDEX(QH_q,O24,$F$4)+P24*(INDEX(QH_q,O24+1,$F$4)-INDEX(QH_q,O24,$F$4)) | H24: =INDEX(QH_Z,O24)+P24*(INDEX(QH_Z,O24+1)-INDEX(QH_Z,O24)) | I24: =INDEX(QH_qtc,O24,$F$4)+P24*(INDEX(QH_qtc,O24+1,$F$4)-INDEX(QH_qtc,O24,$F$4)) | J24: =INDEX(QH_qsc,O24)+P24*(INDEX(QH_qsc,O24+1)-INDEX(QH_qsc,O24)) | K24: =INDEX(QH_V,O24)+P24*(INDEX(QH_V,O24+1)-INDEX(QH_V,O24)) | L24: =K24*1000000/dt_s+G24/2 | M24: =MATCH(D24,INDEX(QH_q,0,$F$4),1) | N24: =(D24-INDEX(QH_q,M24,$F$4))/(INDEX(QH_q,M24+1,$F$4)-INDEX(QH_q,M24,$F$4)) | O24: =MATCH(F24,INDEX(QH_f2,0,$F$4),1) | P24: =(F24-INDEX(QH_f2,O24,$F$4))/(INDEX(QH_f2,O24+1,$F$4)-INDEX(QH_f2,O24,$F$4))
A25: 9 | B25: =IFERROR(INDEX(Lu_Q,MATCH(A25,Lu_t,0),$C$4),0) | C25: =(B24+B25)/2 | D25: =G24 | E25: =INDEX(QH_f1,M25,$F$4)+N25*(INDEX(QH_f1,M25+1,$F$4)-INDEX(QH_f1,M25,$F$4)) | F25: =E25+C25 | G25: =INDEX(QH_q,O25,$F$4)+P25*(INDEX(QH_q,O25+1,$F$4)-INDEX(QH_q,O25,$F$4)) | H25: =INDEX(QH_Z,O25)+P25*(INDEX(QH_Z,O25+1)-INDEX(QH_Z,O25)) | I25: =INDEX(QH_qtc,O25,$F$4)+P25*(INDEX(QH_qtc,O25+1,$F$4)-INDEX(QH_qtc,O25,$F$4)) | J25: =INDEX(QH_qsc,O25)+P25*(INDEX(QH_qsc,O25+1)-INDEX(QH_qsc,O25)) | K25: =INDEX(QH_V,O25)+P25*(INDEX(QH_V,O25+1)-INDEX(QH_V,O25)) | L25: =K25*1000000/dt_s+G25/2 | M25: =MATCH(D25,INDEX(QH_q,0,$F$4),1) | N25: =(D25-INDEX(QH_q,M25,$F$4))/(INDEX(QH_q,M25+1,$F$4)-INDEX(QH_q,M25,$F$4)) | O25: =MATCH(F25,INDEX(QH_f2,0,$F$4),1) | P25: =(F25-INDEX(QH_f2,O25,$F$4))/(INDEX(QH_f2,O25+1,$F$4)-INDEX(QH_f2,O25,$F$4))
A26: 10 | B26: =IFERROR(INDEX(Lu_Q,MATCH(A26,Lu_t,0),$C$4),0) | C26: =(B25+B26)/2 | D26: =G25 | E26: =INDEX(QH_f1,M26,$F$4)+N26*(INDEX(QH_f1,M26+1,$F$4)-INDEX(QH_f1,M26,$F$4)) | F26: =E26+C26 | G26: =INDEX(QH_q,O26,$F$4)+P26*(INDEX(QH_q,O26+1,$F$4)-INDEX(QH_q,O26,$F$4)) | H26: =INDEX(QH_Z,O26)+P26*(INDEX(QH_Z,O26+1)-INDEX(QH_Z,O26)) | I26: =INDEX(QH_qtc,O26,$F$4)+P26*(INDEX(QH_qtc,O26+1,$F$4)-INDEX(QH_qtc,O26,$F$4)) | J26: =INDEX(QH_qsc,O26)+P26*(INDEX(QH_qsc,O26+1)-INDEX(QH_qsc,O26)) | K26: =INDEX(QH_V,O26)+P26*(INDEX(QH_V,O26+1)-INDEX(QH_V,O26)) | L26: =K26*1000000/dt_s+G26/2 | M26: =MATCH(D26,INDEX(QH_q,0,$F$4),1) | N26: =(D26-INDEX(QH_q,M26,$F$4))/(INDEX(QH_q,M26+1,$F$4)-INDEX(QH_q,M26,$F$4)) | O26: =MATCH(F26,INDEX(QH_f2,0,$F$4),1) | P26: =(F26-INDEX(QH_f2,O26,$F$4))/(INDEX(QH_f2,O26+1,$F$4)-INDEX(QH_f2,O26,$F$4))
A27: 11 | B27: =IFERROR(INDEX(Lu_Q,MATCH(A27,Lu_t,0),$C$4),0) | C27: =(B26+B27)/2 | D27: =G26 | E27: =INDEX(QH_f1,M27,$F$4)+N27*(INDEX(QH_f1,M27+1,$F$4)-INDEX(QH_f1,M27,$F$4)) | F27: =E27+C27 | G27: =INDEX(QH_q,O27,$F$4)+P27*(INDEX(QH_q,O27+1,$F$4)-INDEX(QH_q,O27,$F$4)) | H27: =INDEX(QH_Z,O27)+P27*(INDEX(QH_Z,O27+1)-INDEX(QH_Z,O27)) | I27: =INDEX(QH_qtc,O27,$F$4)+P27*(INDEX(QH_qtc,O27+1,$F$4)-INDEX(QH_qtc,O27,$F$4)) | J27: =INDEX(QH_qsc,O27)+P27*(INDEX(QH_qsc,O27+1)-INDEX(QH_qsc,O27)) | K27: =INDEX(QH_V,O27)+P27*(INDEX(QH_V,O27+1)-INDEX(QH_V,O27)) | L27: =K27*1000000/dt_s+G27/2 | M27: =MATCH(D27,INDEX(QH_q,0,$F$4),1) | N27: =(D27-INDEX(QH_q,M27,$F$4))/(INDEX(QH_q,M27+1,$F$4)-INDEX(QH_q,M27,$F$4)) | O27: =MATCH(F27,INDEX(QH_f2,0,$F$4),1) | P27: =(F27-INDEX(QH_f2,O27,$F$4))/(INDEX(QH_f2,O27+1,$F$4)-INDEX(QH_f2,O27,$F$4))
A28: 12 | B28: =IFERROR(INDEX(Lu_Q,MATCH(A28,Lu_t,0),$C$4),0) | C28: =(B27+B28)/2 | D28: =G27 | E28: =INDEX(QH_f1,M28,$F$4)+N28*(INDEX(QH_f1,M28+1,$F$4)-INDEX(QH_f1,M28,$F$4)) | F28: =E28+C28 | G28: =INDEX(QH_q,O28,$F$4)+P28*(INDEX(QH_q,O28+1,$F$4)-INDEX(QH_q,O28,$F$4)) | H28: =INDEX(QH_Z,O28)+P28*(INDEX(QH_Z,O28+1)-INDEX(QH_Z,O28)) | I28: =INDEX(QH_qtc,O28,$F$4)+P28*(INDEX(QH_qtc,O28+1,$F$4)-INDEX(QH_qtc,O28,$F$4)) | J28: =INDEX(QH_qsc,O28)+P28*(INDEX(QH_qsc,O28+1)-INDEX(QH_qsc,O28)) | K28: =INDEX(QH_V,O28)+P28*(INDEX(QH_V,O28+1)-INDEX(QH_V,O28)) | L28: =K28*1000000/dt_s+G28/2 | M28: =MATCH(D28,INDEX(QH_q,0,$F$4),1) | N28: =(D28-INDEX(QH_q,M28,$F$4))/(INDEX(QH_q,M28+1,$F$4)-INDEX(QH_q,M28,$F$4)) | O28: =MATCH(F28,INDEX(QH_f2,0,$F$4),1) | P28: =(F28-INDEX(QH_f2,O28,$F$4))/(INDEX(QH_f2,O28+1,$F$4)-INDEX(QH_f2,O28,$F$4))
... A64: 48 | B64: =IFERROR(INDEX(Lu_Q,MATCH(A64,Lu_t,0),$C$4),0) | C64: =(B63+B64)/2 | D64: =G63 | E64: =INDEX(QH_f1,M64,$F$4)+N64*(INDEX(QH_f1,M64+1,$F$4)-INDEX(QH_f1,M64,$F$4)) | F64: =E64+C64 | G64: =INDEX(QH_q,O64,$F$4)+P64*(INDEX(QH_q,O64+1,$F$4)-INDEX(QH_q,O64,$F$4)) | H64: =INDEX(QH_Z,O64)+P64*(INDEX(QH_Z,O64+1)-INDEX(QH_Z,O64)) | I64: =INDEX(QH_qtc,O64,$F$4)+P64*(INDEX(QH_qtc,O64+1,$F$4)-INDEX(QH_qtc,O64,$F$4)) | J64: =INDEX(QH_qsc,O64)+P64*(INDEX(QH_qsc,O64+1)-INDEX(QH_qsc,O64)) | K64: =INDEX(QH_V,O64)+P64*(INDEX(QH_V,O64+1)-INDEX(QH_V,O64)) | L64: =K64*1000000/dt_s+G64/2 | M64: =MATCH(D64,INDEX(QH_q,0,$F$4),1) | N64: =(D64-INDEX(QH_q,M64,$F$4))/(INDEX(QH_q,M64+1,$F$4)-INDEX(QH_q,M64,$F$4)) | O64: =MATCH(F64,INDEX(QH_f2,0,$F$4),1) | P64: =(F64-INDEX(QH_f2,O64,$F$4))/(INDEX(QH_f2,O64+1,$F$4)-INDEX(QH_f2,O64,$F$4))

Sheet P02_BinhThuong
A1: ĐIỀU TIẾT LŨ – PHƯƠNG PHÁP PÔ-TA-PỐP, HAI ĐƯỜNG q ~ f₁, q ~ f₂ (Δt = 1 giờ)
A3: Tần suất P (%) | C3: 0.2 | D3: Trường hợp | F3: Bình thường | H3: ← sửa ô vàng: P = 1 hoặc 0,2; trường hợp “Bình thường” hoặc “Sự cố” (1 cửa tràn chính không mở)
A4: Cột lũ | C4: =MATCH(C3,Lu_P,0) | D4: Cột bảng tra | F4: =IF(F3="Sự cố",2,1)
H5: Giờ 0: Z = MNDBT, q = q(MNDBT). Từ giờ 1: q₁ → tra đường q ~ f₁ được f₁ → f₂ = f₁ + Qtb → tra đường q ~ f₂ được q₂, Z₂, V₂.
A6: Mực nước lớn nhất Zmax (m) | F6: =MAX(H16:H64) | H6: Cột M, N: vị trí tra q₁; cột O, P: vị trí tra f₂ trong bảng QuanHe. Cột L kiểm tra V₂/Δt + q₂/2 = f₂.
A7: Thời điểm xuất hiện (giờ) | F7: =INDEX(A16:A64,MATCH(MAX(H16:H64),H16:H64,0))
A8: Lưu lượng xả lớn nhất qmax (m³/s) | F8: =MAX(G16:G64)
A9: Lúc Zmax: q tràn chính / q tràn sự cố (m³/s) | F9: =INDEX(I16:I64,MATCH(MAX(H16:H64),H16:H64,0)) | G9: =INDEX(J16:J64,MATCH(MAX(H16:H64),H16:H64,0))
A10: Cột nước trên ngưỡng lúc Zmax: tràn chính / tràn sự cố (m) | F10: =F6-TC_Z | G10: =F6-SC_Z
A11: Dung tích phòng lũ V(Zmax) − V(MNDBT) (10⁶ m³) | F11: =INDEX(K16:K64,MATCH(MAX(H16:H64),H16:H64,0))-K16
A12: Cân bằng nước: W đến − W xả − ΔV (10⁶ m³, phải ≈ 0) | F12: =SUMPRODUCT((B16:B63+B17:B64)/2)*dt_s/1000000-SUMPRODUCT((G16:G63+G17:G64)/2)*dt_s/1000000-(K64-K16)
A15: t (giờ) | B15: Q đến (m³/s) | C15: Qtb = (Q₁+Q₂)/2 | D15: q₁ (cuối giờ trước) | E15: f₁ – tra đường q ~ f₁ với q₁ | F15: f₂ = f₁ + Qtb | G15: q₂ – tra đường q ~ f₂ với f₂ | H15: Z₂ (m) | I15: q tràn chính (m³/s) | J15: q tràn sự cố (m³/s) | K15: V₂ (10⁶ m³) | L15: Kiểm tra V₂/Δt + q₂/2 (= f₂) | M15: k₁ – dòng tra q₁ | N15: w₁ | O15: k – dòng tra f₂ | P15: w
A16: 0 | B16: =IFERROR(INDEX(Lu_Q,MATCH(A16,Lu_t,0),$C$4),0) | G16: =INDEX(QH_q,O16,$F$4)+P16*(INDEX(QH_q,O16+1,$F$4)-INDEX(QH_q,O16,$F$4)) | H16: =INDEX(QH_Z,O16)+P16*(INDEX(QH_Z,O16+1)-INDEX(QH_Z,O16)) | I16: =INDEX(QH_qtc,O16,$F$4)+P16*(INDEX(QH_qtc,O16+1,$F$4)-INDEX(QH_qtc,O16,$F$4)) | J16: =INDEX(QH_qsc,O16)+P16*(INDEX(QH_qsc,O16+1)-INDEX(QH_qsc,O16)) | K16: =INDEX(QH_V,O16)+P16*(INDEX(QH_V,O16+1)-INDEX(QH_V,O16)) | L16: =K16*1000000/dt_s+G16/2 | O16: =MATCH(Z0,QH_Z,1) | P16: =(Z0-INDEX(QH_Z,O16))/(INDEX(QH_Z,O16+1)-INDEX(QH_Z,O16))
A17: 1 | B17: =IFERROR(INDEX(Lu_Q,MATCH(A17,Lu_t,0),$C$4),0) | C17: =(B16+B17)/2 | D17: =G16 | E17: =INDEX(QH_f1,M17,$F$4)+N17*(INDEX(QH_f1,M17+1,$F$4)-INDEX(QH_f1,M17,$F$4)) | F17: =E17+C17 | G17: =INDEX(QH_q,O17,$F$4)+P17*(INDEX(QH_q,O17+1,$F$4)-INDEX(QH_q,O17,$F$4)) | H17: =INDEX(QH_Z,O17)+P17*(INDEX(QH_Z,O17+1)-INDEX(QH_Z,O17)) | I17: =INDEX(QH_qtc,O17,$F$4)+P17*(INDEX(QH_qtc,O17+1,$F$4)-INDEX(QH_qtc,O17,$F$4)) | J17: =INDEX(QH_qsc,O17)+P17*(INDEX(QH_qsc,O17+1)-INDEX(QH_qsc,O17)) | K17: =INDEX(QH_V,O17)+P17*(INDEX(QH_V,O17+1)-INDEX(QH_V,O17)) | L17: =K17*1000000/dt_s+G17/2 | M17: =MATCH(D17,INDEX(QH_q,0,$F$4),1) | N17: =(D17-INDEX(QH_q,M17,$F$4))/(INDEX(QH_q,M17+1,$F$4)-INDEX(QH_q,M17,$F$4)) | O17: =MATCH(F17,INDEX(QH_f2,0,$F$4),1) | P17: =(F17-INDEX(QH_f2,O17,$F$4))/(INDEX(QH_f2,O17+1,$F$4)-INDEX(QH_f2,O17,$F$4))
A18: 2 | B18: =IFERROR(INDEX(Lu_Q,MATCH(A18,Lu_t,0),$C$4),0) | C18: =(B17+B18)/2 | D18: =G17 | E18: =INDEX(QH_f1,M18,$F$4)+N18*(INDEX(QH_f1,M18+1,$F$4)-INDEX(QH_f1,M18,$F$4)) | F18: =E18+C18 | G18: =INDEX(QH_q,O18,$F$4)+P18*(INDEX(QH_q,O18+1,$F$4)-INDEX(QH_q,O18,$F$4)) | H18: =INDEX(QH_Z,O18)+P18*(INDEX(QH_Z,O18+1)-INDEX(QH_Z,O18)) | I18: =INDEX(QH_qtc,O18,$F$4)+P18*(INDEX(QH_qtc,O18+1,$F$4)-INDEX(QH_qtc,O18,$F$4)) | J18: =INDEX(QH_qsc,O18)+P18*(INDEX(QH_qsc,O18+1)-INDEX(QH_qsc,O18)) | K18: =INDEX(QH_V,O18)+P18*(INDEX(QH_V,O18+1)-INDEX(QH_V,O18)) | L18: =K18*1000000/dt_s+G18/2 | M18: =MATCH(D18,INDEX(QH_q,0,$F$4),1) | N18: =(D18-INDEX(QH_q,M18,$F$4))/(INDEX(QH_q,M18+1,$F$4)-INDEX(QH_q,M18,$F$4)) | O18: =MATCH(F18,INDEX(QH_f2,0,$F$4),1) | P18: =(F18-INDEX(QH_f2,O18,$F$4))/(INDEX(QH_f2,O18+1,$F$4)-INDEX(QH_f2,O18,$F$4))
A19: 3 | B19: =IFERROR(INDEX(Lu_Q,MATCH(A19,Lu_t,0),$C$4),0) | C19: =(B18+B19)/2 | D19: =G18 | E19: =INDEX(QH_f1,M19,$F$4)+N19*(INDEX(QH_f1,M19+1,$F$4)-INDEX(QH_f1,M19,$F$4)) | F19: =E19+C19 | G19: =INDEX(QH_q,O19,$F$4)+P19*(INDEX(QH_q,O19+1,$F$4)-INDEX(QH_q,O19,$F$4)) | H19: =INDEX(QH_Z,O19)+P19*(INDEX(QH_Z,O19+1)-INDEX(QH_Z,O19)) | I19: =INDEX(QH_qtc,O19,$F$4)+P19*(INDEX(QH_qtc,O19+1,$F$4)-INDEX(QH_qtc,O19,$F$4)) | J19: =INDEX(QH_qsc,O19)+P19*(INDEX(QH_qsc,O19+1)-INDEX(QH_qsc,O19)) | K19: =INDEX(QH_V,O19)+P19*(INDEX(QH_V,O19+1)-INDEX(QH_V,O19)) | L19: =K19*1000000/dt_s+G19/2 | M19: =MATCH(D19,INDEX(QH_q,0,$F$4),1) | N19: =(D19-INDEX(QH_q,M19,$F$4))/(INDEX(QH_q,M19+1,$F$4)-INDEX(QH_q,M19,$F$4)) | O19: =MATCH(F19,INDEX(QH_f2,0,$F$4),1) | P19: =(F19-INDEX(QH_f2,O19,$F$4))/(INDEX(QH_f2,O19+1,$F$4)-INDEX(QH_f2,O19,$F$4))
A20: 4 | B20: =IFERROR(INDEX(Lu_Q,MATCH(A20,Lu_t,0),$C$4),0) | C20: =(B19+B20)/2 | D20: =G19 | E20: =INDEX(QH_f1,M20,$F$4)+N20*(INDEX(QH_f1,M20+1,$F$4)-INDEX(QH_f1,M20,$F$4)) | F20: =E20+C20 | G20: =INDEX(QH_q,O20,$F$4)+P20*(INDEX(QH_q,O20+1,$F$4)-INDEX(QH_q,O20,$F$4)) | H20: =INDEX(QH_Z,O20)+P20*(INDEX(QH_Z,O20+1)-INDEX(QH_Z,O20)) | I20: =INDEX(QH_qtc,O20,$F$4)+P20*(INDEX(QH_qtc,O20+1,$F$4)-INDEX(QH_qtc,O20,$F$4)) | J20: =INDEX(QH_qsc,O20)+P20*(INDEX(QH_qsc,O20+1)-INDEX(QH_qsc,O20)) | K20: =INDEX(QH_V,O20)+P20*(INDEX(QH_V,O20+1)-INDEX(QH_V,O20)) | L20: =K20*1000000/dt_s+G20/2 | M20: =MATCH(D20,INDEX(QH_q,0,$F$4),1) | N20: =(D20-INDEX(QH_q,M20,$F$4))/(INDEX(QH_q,M20+1,$F$4)-INDEX(QH_q,M20,$F$4)) | O20: =MATCH(F20,INDEX(QH_f2,0,$F$4),1) | P20: =(F20-INDEX(QH_f2,O20,$F$4))/(INDEX(QH_f2,O20+1,$F$4)-INDEX(QH_f2,O20,$F$4))
A21: 5 | B21: =IFERROR(INDEX(Lu_Q,MATCH(A21,Lu_t,0),$C$4),0) | C21: =(B20+B21)/2 | D21: =G20 | E21: =INDEX(QH_f1,M21,$F$4)+N21*(INDEX(QH_f1,M21+1,$F$4)-INDEX(QH_f1,M21,$F$4)) | F21: =E21+C21 | G21: =INDEX(QH_q,O21,$F$4)+P21*(INDEX(QH_q,O21+1,$F$4)-INDEX(QH_q,O21,$F$4)) | H21: =INDEX(QH_Z,O21)+P21*(INDEX(QH_Z,O21+1)-INDEX(QH_Z,O21)) | I21: =INDEX(QH_qtc,O21,$F$4)+P21*(INDEX(QH_qtc,O21+1,$F$4)-INDEX(QH_qtc,O21,$F$4)) | J21: =INDEX(QH_qsc,O21)+P21*(INDEX(QH_qsc,O21+1)-INDEX(QH_qsc,O21)) | K21: =INDEX(QH_V,O21)+P21*(INDEX(QH_V,O21+1)-INDEX(QH_V,O21)) | L21: =K21*1000000/dt_s+G21/2 | M21: =MATCH(D21,INDEX(QH_q,0,$F$4),1) | N21: =(D21-INDEX(QH_q,M21,$F$4))/(INDEX(QH_q,M21+1,$F$4)-INDEX(QH_q,M21,$F$4)) | O21: =MATCH(F21,INDEX(QH_f2,0,$F$4),1) | P21: =(F21-INDEX(QH_f2,O21,$F$4))/(INDEX(QH_f2,O21+1,$F$4)-INDEX(QH_f2,O21,$F$4))
A22: 6 | B22: =IFERROR(INDEX(Lu_Q,MATCH(A22,Lu_t,0),$C$4),0) | C22: =(B21+B22)/2 | D22: =G21 | E22: =INDEX(QH_f1,M22,$F$4)+N22*(INDEX(QH_f1,M22+1,$F$4)-INDEX(QH_f1,M22,$F$4)) | F22: =E22+C22 | G22: =INDEX(QH_q,O22,$F$4)+P22*(INDEX(QH_q,O22+1,$F$4)-INDEX(QH_q,O22,$F$4)) | H22: =INDEX(QH_Z,O22)+P22*(INDEX(QH_Z,O22+1)-INDEX(QH_Z,O22)) | I22: =INDEX(QH_qtc,O22,$F$4)+P22*(INDEX(QH_qtc,O22+1,$F$4)-INDEX(QH_qtc,O22,$F$4)) | J22: =INDEX(QH_qsc,O22)+P22*(INDEX(QH_qsc,O22+1)-INDEX(QH_qsc,O22)) | K22: =INDEX(QH_V,O22)+P22*(INDEX(QH_V,O22+1)-INDEX(QH_V,O22)) | L22: =K22*1000000/dt_s+G22/2 | M22: =MATCH(D22,INDEX(QH_q,0,$F$4),1) | N22: =(D22-INDEX(QH_q,M22,$F$4))/(INDEX(QH_q,M22+1,$F$4)-INDEX(QH_q,M22,$F$4)) | O22: =MATCH(F22,INDEX(QH_f2,0,$F$4),1) | P22: =(F22-INDEX(QH_f2,O22,$F$4))/(INDEX(QH_f2,O22+1,$F$4)-INDEX(QH_f2,O22,$F$4))
A23: 7 | B23: =IFERROR(INDEX(Lu_Q,MATCH(A23,Lu_t,0),$C$4),0) | C23: =(B22+B23)/2 | D23: =G22 | E23: =INDEX(QH_f1,M23,$F$4)+N23*(INDEX(QH_f1,M23+1,$F$4)-INDEX(QH_f1,M23,$F$4)) | F23: =E23+C23 | G23: =INDEX(QH_q,O23,$F$4)+P23*(INDEX(QH_q,O23+1,$F$4)-INDEX(QH_q,O23,$F$4)) | H23: =INDEX(QH_Z,O23)+P23*(INDEX(QH_Z,O23+1)-INDEX(QH_Z,O23)) | I23: =INDEX(QH_qtc,O23,$F$4)+P23*(INDEX(QH_qtc,O23+1,$F$4)-INDEX(QH_qtc,O23,$F$4)) | J23: =INDEX(QH_qsc,O23)+P23*(INDEX(QH_qsc,O23+1)-INDEX(QH_qsc,O23)) | K23: =INDEX(QH_V,O23)+P23*(INDEX(QH_V,O23+1)-INDEX(QH_V,O23)) | L23: =K23*1000000/dt_s+G23/2 | M23: =MATCH(D23,INDEX(QH_q,0,$F$4),1) | N23: =(D23-INDEX(QH_q,M23,$F$4))/(INDEX(QH_q,M23+1,$F$4)-INDEX(QH_q,M23,$F$4)) | O23: =MATCH(F23,INDEX(QH_f2,0,$F$4),1) | P23: =(F23-INDEX(QH_f2,O23,$F$4))/(INDEX(QH_f2,O23+1,$F$4)-INDEX(QH_f2,O23,$F$4))
A24: 8 | B24: =IFERROR(INDEX(Lu_Q,MATCH(A24,Lu_t,0),$C$4),0) | C24: =(B23+B24)/2 | D24: =G23 | E24: =INDEX(QH_f1,M24,$F$4)+N24*(INDEX(QH_f1,M24+1,$F$4)-INDEX(QH_f1,M24,$F$4)) | F24: =E24+C24 | G24: =INDEX(QH_q,O24,$F$4)+P24*(INDEX(QH_q,O24+1,$F$4)-INDEX(QH_q,O24,$F$4)) | H24: =INDEX(QH_Z,O24)+P24*(INDEX(QH_Z,O24+1)-INDEX(QH_Z,O24)) | I24: =INDEX(QH_qtc,O24,$F$4)+P24*(INDEX(QH_qtc,O24+1,$F$4)-INDEX(QH_qtc,O24,$F$4)) | J24: =INDEX(QH_qsc,O24)+P24*(INDEX(QH_qsc,O24+1)-INDEX(QH_qsc,O24)) | K24: =INDEX(QH_V,O24)+P24*(INDEX(QH_V,O24+1)-INDEX(QH_V,O24)) | L24: =K24*1000000/dt_s+G24/2 | M24: =MATCH(D24,INDEX(QH_q,0,$F$4),1) | N24: =(D24-INDEX(QH_q,M24,$F$4))/(INDEX(QH_q,M24+1,$F$4)-INDEX(QH_q,M24,$F$4)) | O24: =MATCH(F24,INDEX(QH_f2,0,$F$4),1) | P24: =(F24-INDEX(QH_f2,O24,$F$4))/(INDEX(QH_f2,O24+1,$F$4)-INDEX(QH_f2,O24,$F$4))
A25: 9 | B25: =IFERROR(INDEX(Lu_Q,MATCH(A25,Lu_t,0),$C$4),0) | C25: =(B24+B25)/2 | D25: =G24 | E25: =INDEX(QH_f1,M25,$F$4)+N25*(INDEX(QH_f1,M25+1,$F$4)-INDEX(QH_f1,M25,$F$4)) | F25: =E25+C25 | G25: =INDEX(QH_q,O25,$F$4)+P25*(INDEX(QH_q,O25+1,$F$4)-INDEX(QH_q,O25,$F$4)) | H25: =INDEX(QH_Z,O25)+P25*(INDEX(QH_Z,O25+1)-INDEX(QH_Z,O25)) | I25: =INDEX(QH_qtc,O25,$F$4)+P25*(INDEX(QH_qtc,O25+1,$F$4)-INDEX(QH_qtc,O25,$F$4)) | J25: =INDEX(QH_qsc,O25)+P25*(INDEX(QH_qsc,O25+1)-INDEX(QH_qsc,O25)) | K25: =INDEX(QH_V,O25)+P25*(INDEX(QH_V,O25+1)-INDEX(QH_V,O25)) | L25: =K25*1000000/dt_s+G25/2 | M25: =MATCH(D25,INDEX(QH_q,0,$F$4),1) | N25: =(D25-INDEX(QH_q,M25,$F$4))/(INDEX(QH_q,M25+1,$F$4)-INDEX(QH_q,M25,$F$4)) | O25: =MATCH(F25,INDEX(QH_f2,0,$F$4),1) | P25: =(F25-INDEX(QH_f2,O25,$F$4))/(INDEX(QH_f2,O25+1,$F$4)-INDEX(QH_f2,O25,$F$4))
A26: 10 | B26: =IFERROR(INDEX(Lu_Q,MATCH(A26,Lu_t,0),$C$4),0) | C26: =(B25+B26)/2 | D26: =G25 | E26: =INDEX(QH_f1,M26,$F$4)+N26*(INDEX(QH_f1,M26+1,$F$4)-INDEX(QH_f1,M26,$F$4)) | F26: =E26+C26 | G26: =INDEX(QH_q,O26,$F$4)+P26*(INDEX(QH_q,O26+1,$F$4)-INDEX(QH_q,O26,$F$4)) | H26: =INDEX(QH_Z,O26)+P26*(INDEX(QH_Z,O26+1)-INDEX(QH_Z,O26)) | I26: =INDEX(QH_qtc,O26,$F$4)+P26*(INDEX(QH_qtc,O26+1,$F$4)-INDEX(QH_qtc,O26,$F$4)) | J26: =INDEX(QH_qsc,O26)+P26*(INDEX(QH_qsc,O26+1)-INDEX(QH_qsc,O26)) | K26: =INDEX(QH_V,O26)+P26*(INDEX(QH_V,O26+1)-INDEX(QH_V,O26)) | L26: =K26*1000000/dt_s+G26/2 | M26: =MATCH(D26,INDEX(QH_q,0,$F$4),1) | N26: =(D26-INDEX(QH_q,M26,$F$4))/(INDEX(QH_q,M26+1,$F$4)-INDEX(QH_q,M26,$F$4)) | O26: =MATCH(F26,INDEX(QH_f2,0,$F$4),1) | P26: =(F26-INDEX(QH_f2,O26,$F$4))/(INDEX(QH_f2,O26+1,$F$4)-INDEX(QH_f2,O26,$F$4))
A27: 11 | B27: =IFERROR(INDEX(Lu_Q,MATCH(A27,Lu_t,0),$C$4),0) | C27: =(B26+B27)/2 | D27: =G26 | E27: =INDEX(QH_f1,M27,$F$4)+N27*(INDEX(QH_f1,M27+1,$F$4)-INDEX(QH_f1,M27,$F$4)) | F27: =E27+C27 | G27: =INDEX(QH_q,O27,$F$4)+P27*(INDEX(QH_q,O27+1,$F$4)-INDEX(QH_q,O27,$F$4)) | H27: =INDEX(QH_Z,O27)+P27*(INDEX(QH_Z,O27+1)-INDEX(QH_Z,O27)) | I27: =INDEX(QH_qtc,O27,$F$4)+P27*(INDEX(QH_qtc,O27+1,$F$4)-INDEX(QH_qtc,O27,$F$4)) | J27: =INDEX(QH_qsc,O27)+P27*(INDEX(QH_qsc,O27+1)-INDEX(QH_qsc,O27)) | K27: =INDEX(QH_V,O27)+P27*(INDEX(QH_V,O27+1)-INDEX(QH_V,O27)) | L27: =K27*1000000/dt_s+G27/2 | M27: =MATCH(D27,INDEX(QH_q,0,$F$4),1) | N27: =(D27-INDEX(QH_q,M27,$F$4))/(INDEX(QH_q,M27+1,$F$4)-INDEX(QH_q,M27,$F$4)) | O27: =MATCH(F27,INDEX(QH_f2,0,$F$4),1) | P27: =(F27-INDEX(QH_f2,O27,$F$4))/(INDEX(QH_f2,O27+1,$F$4)-INDEX(QH_f2,O27,$F$4))
A28: 12 | B28: =IFERROR(INDEX(Lu_Q,MATCH(A28,Lu_t,0),$C$4),0) | C28: =(B27+B28)/2 | D28: =G27 | E28: =INDEX(QH_f1,M28,$F$4)+N28*(INDEX(QH_f1,M28+1,$F$4)-INDEX(QH_f1,M28,$F$4)) | F28: =E28+C28 | G28: =INDEX(QH_q,O28,$F$4)+P28*(INDEX(QH_q,O28+1,$F$4)-INDEX(QH_q,O28,$F$4)) | H28: =INDEX(QH_Z,O28)+P28*(INDEX(QH_Z,O28+1)-INDEX(QH_Z,O28)) | I28: =INDEX(QH_qtc,O28,$F$4)+P28*(INDEX(QH_qtc,O28+1,$F$4)-INDEX(QH_qtc,O28,$F$4)) | J28: =INDEX(QH_qsc,O28)+P28*(INDEX(QH_qsc,O28+1)-INDEX(QH_qsc,O28)) | K28: =INDEX(QH_V,O28)+P28*(INDEX(QH_V,O28+1)-INDEX(QH_V,O28)) | L28: =K28*1000000/dt_s+G28/2 | M28: =MATCH(D28,INDEX(QH_q,0,$F$4),1) | N28: =(D28-INDEX(QH_q,M28,$F$4))/(INDEX(QH_q,M28+1,$F$4)-INDEX(QH_q,M28,$F$4)) | O28: =MATCH(F28,INDEX(QH_f2,0,$F$4),1) | P28: =(F28-INDEX(QH_f2,O28,$F$4))/(INDEX(QH_f2,O28+1,$F$4)-INDEX(QH_f2,O28,$F$4))
... A64: 48 | B64: =IFERROR(INDEX(Lu_Q,MATCH(A64,Lu_t,0),$C$4),0) | C64: =(B63+B64)/2 | D64: =G63 | E64: =INDEX(QH_f1,M64,$F$4)+N64*(INDEX(QH_f1,M64+1,$F$4)-INDEX(QH_f1,M64,$F$4)) | F64: =E64+C64 | G64: =INDEX(QH_q,O64,$F$4)+P64*(INDEX(QH_q,O64+1,$F$4)-INDEX(QH_q,O64,$F$4)) | H64: =INDEX(QH_Z,O64)+P64*(INDEX(QH_Z,O64+1)-INDEX(QH_Z,O64)) | I64: =INDEX(QH_qtc,O64,$F$4)+P64*(INDEX(QH_qtc,O64+1,$F$4)-INDEX(QH_qtc,O64,$F$4)) | J64: =INDEX(QH_qsc,O64)+P64*(INDEX(QH_qsc,O64+1)-INDEX(QH_qsc,O64)) | K64: =INDEX(QH_V,O64)+P64*(INDEX(QH_V,O64+1)-INDEX(QH_V,O64)) | L64: =K64*1000000/dt_s+G64/2 | M64: =MATCH(D64,INDEX(QH_q,0,$F$4),1) | N64: =(D64-INDEX(QH_q,M64,$F$4))/(INDEX(QH_q,M64+1,$F$4)-INDEX(QH_q,M64,$F$4)) | O64: =MATCH(F64,INDEX(QH_f2,0,$F$4),1) | P64: =(F64-INDEX(QH_f2,O64,$F$4))/(INDEX(QH_f2,O64+1,$F$4)-INDEX(QH_f2,O64,$F$4))

Sheet P02_SuCo
A1: ĐIỀU TIẾT LŨ – PHƯƠNG PHÁP PÔ-TA-PỐP, HAI ĐƯỜNG q ~ f₁, q ~ f₂ (Δt = 1 giờ)
A3: Tần suất P (%) | C3: 0.2 | D3: Trường hợp | F3: Sự cố | H3: ← sửa ô vàng: P = 1 hoặc 0,2; trường hợp “Bình thường” hoặc “Sự cố” (1 cửa tràn chính không mở)
A4: Cột lũ | C4: =MATCH(C3,Lu_P,0) | D4: Cột bảng tra | F4: =IF(F3="Sự cố",2,1)
H5: Giờ 0: Z = MNDBT, q = q(MNDBT). Từ giờ 1: q₁ → tra đường q ~ f₁ được f₁ → f₂ = f₁ + Qtb → tra đường q ~ f₂ được q₂, Z₂, V₂.
A6: Mực nước lớn nhất Zmax (m) | F6: =MAX(H16:H64) | H6: Cột M, N: vị trí tra q₁; cột O, P: vị trí tra f₂ trong bảng QuanHe. Cột L kiểm tra V₂/Δt + q₂/2 = f₂.
A7: Thời điểm xuất hiện (giờ) | F7: =INDEX(A16:A64,MATCH(MAX(H16:H64),H16:H64,0))
A8: Lưu lượng xả lớn nhất qmax (m³/s) | F8: =MAX(G16:G64)
A9: Lúc Zmax: q tràn chính / q tràn sự cố (m³/s) | F9: =INDEX(I16:I64,MATCH(MAX(H16:H64),H16:H64,0)) | G9: =INDEX(J16:J64,MATCH(MAX(H16:H64),H16:H64,0))
A10: Cột nước trên ngưỡng lúc Zmax: tràn chính / tràn sự cố (m) | F10: =F6-TC_Z | G10: =F6-SC_Z
A11: Dung tích phòng lũ V(Zmax) − V(MNDBT) (10⁶ m³) | F11: =INDEX(K16:K64,MATCH(MAX(H16:H64),H16:H64,0))-K16
A12: Cân bằng nước: W đến − W xả − ΔV (10⁶ m³, phải ≈ 0) | F12: =SUMPRODUCT((B16:B63+B17:B64)/2)*dt_s/1000000-SUMPRODUCT((G16:G63+G17:G64)/2)*dt_s/1000000-(K64-K16)
A15: t (giờ) | B15: Q đến (m³/s) | C15: Qtb = (Q₁+Q₂)/2 | D15: q₁ (cuối giờ trước) | E15: f₁ – tra đường q ~ f₁ với q₁ | F15: f₂ = f₁ + Qtb | G15: q₂ – tra đường q ~ f₂ với f₂ | H15: Z₂ (m) | I15: q tràn chính (m³/s) | J15: q tràn sự cố (m³/s) | K15: V₂ (10⁶ m³) | L15: Kiểm tra V₂/Δt + q₂/2 (= f₂) | M15: k₁ – dòng tra q₁ | N15: w₁ | O15: k – dòng tra f₂ | P15: w
A16: 0 | B16: =IFERROR(INDEX(Lu_Q,MATCH(A16,Lu_t,0),$C$4),0) | G16: =INDEX(QH_q,O16,$F$4)+P16*(INDEX(QH_q,O16+1,$F$4)-INDEX(QH_q,O16,$F$4)) | H16: =INDEX(QH_Z,O16)+P16*(INDEX(QH_Z,O16+1)-INDEX(QH_Z,O16)) | I16: =INDEX(QH_qtc,O16,$F$4)+P16*(INDEX(QH_qtc,O16+1,$F$4)-INDEX(QH_qtc,O16,$F$4)) | J16: =INDEX(QH_qsc,O16)+P16*(INDEX(QH_qsc,O16+1)-INDEX(QH_qsc,O16)) | K16: =INDEX(QH_V,O16)+P16*(INDEX(QH_V,O16+1)-INDEX(QH_V,O16)) | L16: =K16*1000000/dt_s+G16/2 | O16: =MATCH(Z0,QH_Z,1) | P16: =(Z0-INDEX(QH_Z,O16))/(INDEX(QH_Z,O16+1)-INDEX(QH_Z,O16))
