Workbook

Sheet HuongDan
B1: ĐIỀU TIẾT NĂM – PHƯƠNG PHÁP LẬP BẢNG CÓ KỂ TỔN THẤT (năm thiết kế P = 85%) – HỒ CHỨA NƯỚC CÀ GIÂY
B2: Mọi ô kết quả là công thức: đổi số liệu ở sheet SoLieu (trường hợp dùng nước, MNC, MNDBT, k_t, tháng bắt đầu năm thủy lợi) thì toàn bộ file tự tính lại.
B3: 1. Vì sao chọn phương pháp lập bảng cho đồ án
B4: • Là phương pháp chuẩn của giáo trình Thủy văn công trình, Quy hoạch và thiết kế hệ thống thủy lợi – thầy, cô và hội đồng quen; mỗi con số tính tay được và giải thích được.
B5: • Khối lượng vừa với đồ án: 1 năm thiết kế × 12 tháng, 4 bảng (không kể tổn thất, có kể tổn thất lần 1, 2, 3), in vào thuyết minh 2 ÷ 3 trang. Phương pháp toàn chuỗi cần 44 năm × 12 tháng = 528 bước tính – phải lập trình hoặc bảng tính lớn.
B6: • Đủ trả lời câu hỏi của đồ án sửa chữa: giữ MNC +67,50 m, MNDBT +74,70 m thì dung tích hữu ích hiện có (bình đồ 2022) có đủ cấp nước cho năm thiết kế không, MNDBT cần thiết là bao nhiêu.
B7: • Hạn chế: chỉ xét một năm đại biểu nên không cho mức bảo đảm thực của cả chuỗi; trường hợp sát ngưỡng có thể kết luận khác toàn chuỗi (TH2 ở mục 5). Nếu được hỏi, nêu kết quả kiểm tra toàn chuỗi đã có trong thuyết minh: TH1A 39/44 năm (86,7%), TH2 37/44 năm (82,2%).
B8: 2. Số liệu (sheet SoLieu, có ghi nguồn)
B9: • Dòng chảy năm thiết kế P = 85% đến hồ: QTVH 2026 Bảng 3-19 = nội lưu vực 141 km² (Bảng 3-15, mô hình năm 2023 có phân phối bất lợi) + khu giữa 244 km² đến đập dâng Sông Lũy đã trừ dòng chảy tối thiểu (Bảng 3-17) + nước hồ Sông Lũy cấp qua kênh tiếp nước (Bảng 3-18).
B10: • Nhu cầu dùng nước theo tháng: QTVH Bảng 4-20 (TH1), 4-21 (TH1A), 4-22 (TH2). Tổn thất bốc hơi phụ thêm ΔZ: QTVH Bảng 3-24. Tổn thất thấm k_t = 1%/tháng dung tích bình quân (TCVN 10778:2024 Bảng 1).
B11: • Quan hệ Z ~ F ~ W: bình đồ khảo sát 2022 (QTVH Bảng 1-2), dung tích tính lại từ diện tích; sheet BangTra lập bảng chi tiết 0,1 m để nội suy (Vc = V(+67,50) = 6,82; V(+74,70) = 36,41 triệu m³ – trùng thuyết minh).
B12: 3. Hình thức điều tiết (sheet B1, phần đầu)
... B28: • Bài tập: chọn TH1, TH2 ở ô SoLieu!C5 rồi xem KetLuan; đổi k_t = 0,5% xem Vhi giảm bao nhiêu; tự bấm máy tính tay tháng 12 của bảng B2 rồi so với Excel.

Sheet SoLieu
A1: SỐ LIỆU ĐẦU VÀO – ĐIỀU TIẾT NĂM THIẾT KẾ P = 85%
A2: Ô nền vàng chữ xanh: được sửa. Chữ xanh: số liệu gốc hồ sơ. Chữ đen: công thức. Dung tích: 10⁶ m³.
A4: A. THÔNG SỐ TÍNH TOÁN | C4: Giá trị | D4: Đơn vị | E4: Ghi chú, nguồn
A5: Trường hợp dùng nước (chọn TH1 / TH1A / TH2) | C5: TH1A | E5: Mặc định TH1A – trường hợp thuyết minh kết luận đạt
A6: Mực nước chết MNC | C6: 67.5 | D6: m | E6: Giữ như thiết kế (thuyết minh 2.2.1)
A7: Mực nước dâng bình thường MNDBT hiện có | C7: 74.7 | D7: m | E7: Bằng ngưỡng tràn chính
A8: Hệ số tổn thất thấm k_t | C8: 0.01 | D8: /tháng | E8: TCVN 10778:2024 Bảng 1: 0,5 ÷ 1,0%/tháng (địa chất lòng hồ tốt); đồ án lấy 1%
A9: Sai số cho phép của Vhi giữa hai lần lặp | C9: 0.01 | E9: Dừng lặp khi |Vhi lần k − Vhi lần k−1| / Vhi lần k ≤ giá trị này
A10: Tháng bắt đầu năm thủy lợi | C10: 5 | D10: tháng | E10: Tháng đầu tiên W đến > W dùng sau mùa khô (xem B1)
A11: Dung tích chết Vc = V(MNC) | C11: =INDEX(BT_V,MATCH(Z_MNC,BT_Z,1))+(Z_MNC-INDEX(BT_Z,MATCH(Z_MNC,BT_Z,1)))*(INDEX(BT_V,MATCH(Z_MNC,BT_Z,1)+1)-INDEX(BT_V,MATCH(Z_MNC,BT_Z,1)))/(INDEX(BT_Z,MATCH(Z_MNC,BT_Z,1)+1)-INDEX(BT_Z,MATCH(Z_MNC,BT_Z,1))) -> 6.8157017 | D11: 10⁶ m³ | E11: Tra bảng 0,1 m (sheet BangTra) – bình đồ 2022. Thiết kế ban đầu 8,41 (chỉ so sánh)
A12: Dung tích ứng MNDBT hiện có Vbt = V(MNDBT) | C12: =INDEX(BT_V,MATCH(Z_MNDBT,BT_Z,1))+(Z_MNDBT-INDEX(BT_Z,MATCH(Z_MNDBT,BT_Z,1)))*(INDEX(BT_V,MATCH(Z_MNDBT,BT_Z,1)+1)-INDEX(BT_V,MATCH(Z_MNDBT,BT_Z,1)))/(INDEX(BT_Z,MATCH(Z_MNDBT,BT_Z,1)+1)-INDEX(BT_Z,MATCH(Z_MNDBT,BT_Z,1))) -> 36.410907 | D12: 10⁶ m³ | E12: Thiết kế ban đầu 37,24
A13: Dung tích hữu ích hiện có Vhi = Vbt − Vc | C13: =C12-C11 -> 29.595205 | D13: 10⁶ m³ | E13: Thiết kế ban đầu 28,83
A15: B. DÒNG CHẢY NĂM THIẾT KẾ P = 85% ĐẾN HỒ CÀ GIÂY (10⁶ m³/tháng) – QTVH 2026
A16: Thành phần | C16: Tháng 1 | D16: Tháng 2 | E16: Tháng 3 | F16: Tháng 4 | G16: Tháng 5 | H16: Tháng 6 | I16: Tháng 7 | J16: Tháng 8 | K16: Tháng 9 | L16: Tháng 10 | M16: Tháng 11 | N16: Tháng 12 | O16: Cả năm | P16: Nguồn
A17: Nội lưu vực hồ 141 km² (mô hình năm 2023) | C17: 0.584 | D17: 0.322 | E17: 0.177 | F17: 0.096 | G17: 0.054 | H17: 0.031 | I17: 0.016 | J17: 6.359 | K17: 11.747 | L17: 15.744 | M17: 8.779 | N17: 2.344 | O17: =SUM(C17:N17) -> 46.253 | P17: Bảng 3-15
A18: Khu giữa 244 km² đến đập dâng Sông Lũy (đã trừ dòng chảy tối thiểu) | C18: 1.83 | D18: 0.77 | E18: 0.43 | F18: 1.48 | G18: 12.64 | H18: 20.18 | I18: 11.52 | J18: 11.18 | K18: 8.28 | L18: 16.23 | M18: 1.15 | N18: 0.33 | O18: =SUM(C18:N18) -> 86.02 | P18: Bảng 3-17
A19: Hồ Sông Lũy cấp bổ sung qua kênh tiếp nước | C19: 6.66 | D19: 3.8 | E19: 3.59 | F19: 7.39 | G19: 2.93 | H19: 4.26 | I19: 2.47 | J19: 1.44 | K19: 0 | L19: 0 | M19: 3.03 | N19: 7.13 | O19: =SUM(C19:N19) -> 42.7 | P19: Bảng 3-18
A20: TỔNG LƯỢNG NƯỚC ĐẾN HỒ – dùng tính toán | C20: 9.3 | D20: 4.77 | E20: 4.19 | F20: 9.21 | G20: 15.62 | H20: 24.62 | I20: 14.01 | J20: 19.03 | K20: 20.02 | L20: 31.97 | M20: 12.96 | N20: 10.04 | O20: =SUM(C20:N20) -> 175.74 | P20: Bảng 3-19 (tổng QTVH; cộng 3 dòng trên lệch < 0,5%)
A22: C. NHU CẦU DÙNG NƯỚC TỔNG (tưới + sinh hoạt), 10⁶ m³/tháng – QTVH Bảng 4-20 ÷ 4-22
A23: Trường hợp | C23: Tháng 1 | D23: Tháng 2 | E23: Tháng 3 | F23: Tháng 4 | G23: Tháng 5 | H23: Tháng 6 | I23: Tháng 7 | J23: Tháng 8 | K23: Tháng 9 | L23: Tháng 10 | M23: Tháng 11 | N23: Tháng 12 | O23: Cả năm | P23: Nội dung
A24: TH1 | C24: 9.8 | D24: 11.93 | E24: 11.22 | F24: 17.62 | G24: 7.04 | H24: 10.13 | I24: 5.73 | J24: 9.91 | K24: 3.62 | L24: 3.2 | M24: 11.75 | N24: 20.19 | O24: =SUM(C24:N24) -> 122.14 | P24: Tưới 8.965 ha, 100% cây trồng cạn tưới truyền thống + sinh hoạt (QTVH Bảng 4-20)
A25: TH1A | C25: 13.27 | D25: 10.48 | E25: 9.37 | F25: 14.2 | G25: 5.92 | H25: 8.31 | I25: 5.59 | J25: 8.9 | K25: 2.57 | L25: 2.99 | M25: 9.5 | N25: 15.54 | O25: =SUM(C25:N25) -> 106.64 | P25: Tưới 8.965 ha, 50% cây trồng cạn tưới tiết kiệm + sinh hoạt (QTVH Bảng 4-21)
A26: TH2 | C26: 13.48 | D26: 10.69 | E26: 9.61 | F26: 14.44 | G26: 5.94 | H26: 8.31 | I26: 5.59 | J26: 8.9 | K26: 2.57 | L26: 2.99 | M26: 9.5 | N26: 15.54 | O26: =SUM(C26:N26) -> 107.56 | P26: Tưới tiềm năng 9.540 ha, 50% tưới tiết kiệm + sinh hoạt (QTVH Bảng 4-22)
A27: → Trường hợp đang chọn | B27: =TH_chon -> TH1A | C27: =INDEX(C$24:C$26,MATCH(TH_chon,$A$24:$A$26,0)) -> 13.27 | D27: =INDEX(D$24:D$26,MATCH(TH_chon,$A$24:$A$26,0)) -> 10.48 | E27: =INDEX(E$24:E$26,MATCH(TH_chon,$A$24:$A$26,0)) -> 9.37 | F27: =INDEX(F$24:F$26,MATCH(TH_chon,$A$24:$A$26,0)) -> 14.2 | G27: =INDEX(G$24:G$26,MATCH(TH_chon,$A$24:$A$26,0)) -> 5.92 | H27: =INDEX(H$24:H$26,MATCH(TH_chon,$A$24:$A$26,0)) -> 8.31 | I27: =INDEX(I$24:I$26,MATCH(TH_chon,$A$24:$A$26,0)) -> 5.59 | J27: =INDEX(J$24:J$26,MATCH(TH_chon,$A$24:$A$26,0)) -> 8.9 | ... N27: =INDEX(N$24:N$26,MATCH(TH_chon,$A$24:$A$26,0)) -> 15.54 | O27: =SUM(C27:N27) -> 106.64
A29: D. TỔN THẤT BỐC HƠI PHỤ THÊM ΔZ (mm/tháng) – QTVH Bảng 3-24
A30: Đại lượng | C30: Tháng 1 | D30: Tháng 2 | E30: Tháng 3 | F30: Tháng 4 | G30: Tháng 5 | H30: Tháng 6 | I30: Tháng 7 | J30: Tháng 8 | K30: Tháng 9 | L30: Tháng 10 | M30: Tháng 11 | N30: Tháng 12 | O30: Cả năm
A31: ΔZ (mm) | C31: 68.4 | D31: 64.4 | E31: 76.9 | F31: 66.6 | G31: 62.3 | H31: 55.1 | I31: 49.8 | J31: 51.8 | K31: 43.9 | L31: 40.8 | M31: 52.2 | N31: 66.7 | O31: =SUM(C31:N31) -> 698.9
A33: E. QUAN HỆ Z ~ F ~ W LÒNG HỒ – BÌNH ĐỒ 2022 (QTVH Bảng 1-2)
A34: Z (m) | B34: F (km²) | C34: W hồ sơ | D34: W tính lại
A35: 59 | B35: 0 | C35: 0 | D35: =0 -> 0 | F35: F ghi “ha” trong hồ sơ nhưng đúng là km² (TKCS Hình 1-1).
A36: 60 | B36: 0.09 | C36: 0.03 | D36: =D35+(A36-A35)/3*(B35+B36+SQRT(B35*B36)) -> 0.03 | F36: W tính lại theo chóp cụt ΔW = ΔZ/3·(F₁ + F₂ + √(F₁F₂)); dưới +69 m khớp cột W hồ sơ, từ +70 m cột W hồ sơ không khớp F.
A37: 61 | B37: 0.21 | C37: 0.17 | D37: =D36+(A37-A36)/3*(B36+B37+SQRT(B36*B37)) -> 0.17582576 | F37: Khi tính dùng bảng chi tiết 0,1 m (sheet BangTra) lập từ cột F.
A38: 62 | B38: 0.4 | C38: 0.47 | D38: =D37+(A38-A37)/3*(B37+B38+SQRT(B37*B38)) -> 0.47576827
A39: 63 | B39: 0.62 | C39: 0.98 | D39: =D38+(A39-A38)/3*(B38+B39+SQRT(B38*B39)) -> 0.98176693
A40: 64 | B40: 0.87 | C40: 1.72 | D40: =D39+(A40-A39)/3*(B39+B40+SQRT(B39*B40)) -> 1.7232465
A41: 65 | B41: 1.16 | C41: 2.74 | D41: =D40+(A41-A40)/3*(B40+B41+SQRT(B40*B41)) -> 2.7347763
A42: 66 | B42: 1.48 | C42: 4.06 | D42: =D41+(A42-A41)/3*(B41+B42+SQRT(B41*B42)) -> 4.051532
A43: 67 | B43: 1.92 | C43: 5.75 | D43: =D42+(A43-A42)/3*(B42+B43+SQRT(B42*B43)) -> 5.7467669
A44: 68 | B44: 2.45 | C44: 7.93 | D44: =D43+(A44-A43)/3*(B43+B44+SQRT(B43*B44)) -> 7.9263904
A45: 69 | B45: 2.94 | C45: 10.63 | D45: =D44+(A45-A44)/3*(B44+B45+SQRT(B44*B45)) -> 10.617671
...

Sheet BangTra
A1: BẢNG TRA Z ~ F ~ V CHI TIẾT (bước 0,1 m)
A2: F nội suy tuyến tính từ bảng 1 m (SoLieu mục E); V cộng dồn chóp cụt ΔV = ΔZ/3·(F₁ + F₂ + √(F₁F₂)).
A4: Z (m) | B4: F (km²) | C4: V (10⁶ m³)
A5: 59 | B5: =IF(A5>=MAX(Bang_Z),INDEX(Bang_F,ROWS(Bang_F)),INDEX(Bang_F,MATCH(A5,Bang_Z,1))+(A5-INDEX(Bang_Z,MATCH(A5,Bang_Z,1)))*(INDEX(Bang_F,MATCH(A5,Bang_Z,1)+1)-INDEX(Bang_F,MATCH(A5,Bang_Z,1)))/(INDEX(Bang_Z,MATCH(A5,Bang_Z,1)+1)-INDEX(Bang_Z,MATCH(A5,Bang_Z,1)))) -> 0 | C5: 0 | E5: Biết Z tìm V (hoặc ngược lại): tìm dòng kẹp giá trị cần tra rồi nội suy tuyến tính.
A6: =ROUND(A5+0.1,1) -> 59.1 | B6: =IF(A6>=MAX(Bang_Z),INDEX(Bang_F,ROWS(Bang_F)),INDEX(Bang_F,MATCH(A6,Bang_Z,1))+(A6-INDEX(Bang_Z,MATCH(A6,Bang_Z,1)))*(INDEX(Bang_F,MATCH(A6,Bang_Z,1)+1)-INDEX(Bang_F,MATCH(A6,Bang_Z,1)))/(INDEX(Bang_Z,MATCH(A6,Bang_Z,1)+1)-INDEX(Bang_Z,MATCH(A6,Bang_Z,1)))) -> 0.009 | C6: =C5+(A6-A5)/3*(B5+B6+SQRT(B5*B6)) -> 0.0003 | E6: Ví dụ: V(+67,50) = 6,816; V(+74,70) = 36,412 triệu m³.
A7: =ROUND(A6+0.1,1) -> 59.2 | B7: =IF(A7>=MAX(Bang_Z),INDEX(Bang_F,ROWS(Bang_F)),INDEX(Bang_F,MATCH(A7,Bang_Z,1))+(A7-INDEX(Bang_Z,MATCH(A7,Bang_Z,1)))*(INDEX(Bang_F,MATCH(A7,Bang_Z,1)+1)-INDEX(Bang_F,MATCH(A7,Bang_Z,1)))/(INDEX(Bang_Z,MATCH(A7,Bang_Z,1)+1)-INDEX(Bang_Z,MATCH(A7,Bang_Z,1)))) -> 0.018 | C7: =C6+(A7-A6)/3*(B6+B7+SQRT(B6*B7)) -> 0.0016242641
A8: =ROUND(A7+0.1,1) -> 59.3 | B8: =IF(A8>=MAX(Bang_Z),INDEX(Bang_F,ROWS(Bang_F)),INDEX(Bang_F,MATCH(A8,Bang_Z,1))+(A8-INDEX(Bang_Z,MATCH(A8,Bang_Z,1)))*(INDEX(Bang_F,MATCH(A8,Bang_Z,1)+1)-INDEX(Bang_F,MATCH(A8,Bang_Z,1)))/(INDEX(Bang_Z,MATCH(A8,Bang_Z,1)+1)-INDEX(Bang_Z,MATCH(A8,Bang_Z,1)))) -> 0.027 | C8: =C7+(A8-A7)/3*(B7+B8+SQRT(B7*B8)) -> 0.003859111
A9: =ROUND(A8+0.1,1) -> 59.4 | B9: =IF(A9>=MAX(Bang_Z),INDEX(Bang_F,ROWS(Bang_F)),INDEX(Bang_F,MATCH(A9,Bang_Z,1))+(A9-INDEX(Bang_Z,MATCH(A9,Bang_Z,1)))*(INDEX(Bang_F,MATCH(A9,Bang_Z,1)+1)-INDEX(Bang_F,MATCH(A9,Bang_Z,1)))/(INDEX(Bang_Z,MATCH(A9,Bang_Z,1)+1)-INDEX(Bang_Z,MATCH(A9,Bang_Z,1)))) -> 0.036 | C9: =C8+(A9-A8)/3*(B8+B9+SQRT(B8*B9)) -> 0.0069983415
A10: =ROUND(A9+0.1,1) -> 59.5 | B10: =IF(A10>=MAX(Bang_Z),INDEX(Bang_F,ROWS(Bang_F)),INDEX(Bang_F,MATCH(A10,Bang_Z,1))+(A10-INDEX(Bang_Z,MATCH(A10,Bang_Z,1)))*(INDEX(Bang_F,MATCH(A10,Bang_Z,1)+1)-INDEX(Bang_F,MATCH(A10,Bang_Z,1)))/(INDEX(Bang_Z,MATCH(A10,Bang_Z,1)+1)-INDEX(Bang_Z,MATCH(A10,Bang_Z,1)))) -> 0.045 | C10: =C9+(A10-A9)/3*(B9+B10+SQRT(B9*B10)) -> 0.011039982
A11: =ROUND(A10+0.1,1) -> 59.6 | B11: =IF(A11>=MAX(Bang_Z),INDEX(Bang_F,ROWS(Bang_F)),INDEX(Bang_F,MATCH(A11,Bang_Z,1))+(A11-INDEX(Bang_Z,MATCH(A11,Bang_Z,1)))*(INDEX(Bang_F,MATCH(A11,Bang_Z,1)+1)-INDEX(Bang_F,MATCH(A11,Bang_Z,1)))/(INDEX(Bang_Z,MATCH(A11,Bang_Z,1)+1)-INDEX(Bang_Z,MATCH(A11,Bang_Z,1)))) -> 0.054 | C11: =C10+(A11-A10)/3*(B10+B11+SQRT(B10*B11)) -> 0.01598315
A12: =ROUND(A11+0.1,1) -> 59.7 | B12: =IF(A12>=MAX(Bang_Z),INDEX(Bang_F,ROWS(Bang_F)),INDEX(Bang_F,MATCH(A12,Bang_Z,1))+(A12-INDEX(Bang_Z,MATCH(A12,Bang_Z,1)))*(INDEX(Bang_F,MATCH(A12,Bang_Z,1)+1)-INDEX(Bang_F,MATCH(A12,Bang_Z,1)))/(INDEX(Bang_Z,MATCH(A12,Bang_Z,1)+1)-INDEX(Bang_Z,MATCH(A12,Bang_Z,1)))) -> 0.063 | C12: =C11+(A12-A11)/3*(B11+B12+SQRT(B11*B12)) -> 0.021827372
A13: =ROUND(A12+0.1,1) -> 59.8 | B13: =IF(A13>=MAX(Bang_Z),INDEX(Bang_F,ROWS(Bang_F)),INDEX(Bang_F,MATCH(A13,Bang_Z,1))+(A13-INDEX(Bang_Z,MATCH(A13,Bang_Z,1)))*(INDEX(Bang_F,MATCH(A13,Bang_Z,1)+1)-INDEX(Bang_F,MATCH(A13,Bang_Z,1)))/(INDEX(Bang_Z,MATCH(A13,Bang_Z,1)+1)-INDEX(Bang_Z,MATCH(A13,Bang_Z,1)))) -> 0.072 | C13: =C12+(A13-A12)/3*(B12+B13+SQRT(B12*B13)) -> 0.028572367
A14: =ROUND(A13+0.1,1) -> 59.9 | B14: =IF(A14>=MAX(Bang_Z),INDEX(Bang_F,ROWS(Bang_F)),INDEX(Bang_F,MATCH(A14,Bang_Z,1))+(A14-INDEX(Bang_Z,MATCH(A14,Bang_Z,1)))*(INDEX(Bang_F,MATCH(A14,Bang_Z,1)+1)-INDEX(Bang_F,MATCH(A14,Bang_Z,1)))/(INDEX(Bang_Z,MATCH(A14,Bang_Z,1)+1)-INDEX(Bang_Z,MATCH(A14,Bang_Z,1)))) -> 0.081 | C14: =C13+(A14-A13)/3*(B13+B14+SQRT(B13*B14)) -> 0.036217951
A15: =ROUND(A14+0.1,1) -> 60 | B15: =IF(A15>=MAX(Bang_Z),INDEX(Bang_F,ROWS(Bang_F)),INDEX(Bang_F,MATCH(A15,Bang_Z,1))+(A15-INDEX(Bang_Z,MATCH(A15,Bang_Z,1)))*(INDEX(Bang_F,MATCH(A15,Bang_Z,1)+1)-INDEX(Bang_F,MATCH(A15,Bang_Z,1)))/(INDEX(Bang_Z,MATCH(A15,Bang_Z,1)+1)-INDEX(Bang_Z,MATCH(A15,Bang_Z,1)))) -> 0.09 | C15: =C14+(A15-A14)/3*(B14+B15+SQRT(B14*B15)) -> 0.044764001
A16: =ROUND(A15+0.1,1) -> 60.1 | B16: =IF(A16>=MAX(Bang_Z),INDEX(Bang_F,ROWS(Bang_F)),INDEX(Bang_F,MATCH(A16,Bang_Z,1))+(A16-INDEX(Bang_Z,MATCH(A16,Bang_Z,1)))*(INDEX(Bang_F,MATCH(A16,Bang_Z,1)+1)-INDEX(Bang_F,MATCH(A16,Bang_Z,1)))/(INDEX(Bang_Z,MATCH(A16,Bang_Z,1)+1)-INDEX(Bang_Z,MATCH(A16,Bang_Z,1)))) -> 0.102 | C16: =C15+(A16-A15)/3*(B15+B16+SQRT(B15*B16)) -> 0.054357745
A17: =ROUND(A16+0.1,1) -> 60.2 | B17: =IF(A17>=MAX(Bang_Z),INDEX(Bang_F,ROWS(Bang_F)),INDEX(Bang_F,MATCH(A17,Bang_Z,1))+(A17-INDEX(Bang_Z,MATCH(A17,Bang_Z,1)))*(INDEX(Bang_F,MATCH(A17,Bang_Z,1)+1)-INDEX(Bang_F,MATCH(A17,Bang_Z,1)))/(INDEX(Bang_Z,MATCH(A17,Bang_Z,1)+1)-INDEX(Bang_Z,MATCH(A17,Bang_Z,1)))) -> 0.114 | C17: =C16+(A17-A16)/3*(B16+B17+SQRT(B16*B17)) -> 0.065152185
A18: =ROUND(A17+0.1,1) -> 60.3 | B18: =IF(A18>=MAX(Bang_Z),INDEX(Bang_F,ROWS(Bang_F)),INDEX(Bang_F,MATCH(A18,Bang_Z,1))+(A18-INDEX(Bang_Z,MATCH(A18,Bang_Z,1)))*(INDEX(Bang_F,MATCH(A18,Bang_Z,1)+1)-INDEX(Bang_F,MATCH(A18,Bang_Z,1)))/(INDEX(Bang_Z,MATCH(A18,Bang_Z,1)+1)-INDEX(Bang_Z,MATCH(A18,Bang_Z,1)))) -> 0.126 | C18: =C17+(A18-A17)/3*(B17+B18+SQRT(B17*B18)) -> 0.077147182
... A265: =ROUND(A264+0.1,1) -> 85 | B265: =IF(A265>=MAX(Bang_Z),INDEX(Bang_F,ROWS(Bang_F)),INDEX(Bang_F,MATCH(A265,Bang_Z,1))+(A265-INDEX(Bang_Z,MATCH(A265,Bang_Z,1)))*(INDEX(Bang_F,MATCH(A265,Bang_Z,1)+1)-INDEX(Bang_F,MATCH(A265,Bang_Z,1)))/(INDEX(Bang_Z,MATCH(A265,Bang_Z,1)+1)-INDEX(Bang_Z,MATCH(A265,Bang_Z,1)))) -> 12.95 | C265: =C264+(A265-A264)/3*(B264+B265+SQRT(B264*B265)) -> 131.45401

Sheet B1_KhongTonThat
A1: BƯỚC 1 – XÁC ĐỊNH HÌNH THỨC ĐIỀU TIẾT VÀ ĐIỀU TIẾT NĂM KHÔNG KỂ TỔN THẤT
A2: TH | B2: =TH_chon -> TH1A | D2: Vc = | E2: =V_chet -> 6.8157017 | G2: k_t = | H2: =k_tham -> 0.01
A4: BẢNG ĐIỀU TIẾT NĂM KHÔNG KỂ TỔN THẤT
A5: Tháng | B5: W đến (10⁶ m³) | C5: W dùng (10⁶ m³) | D5: W tổn thất (10⁶ m³) | E5: W dùng + W tổn thất | F5: Thừa ΔV+ = W đến − (W dùng + W tt) | G5: Thiếu ΔV− = (W dùng + W tt) − W đến | H5: V đầu tháng (10⁶ m³) | I5: V cuối tháng (10⁶ m³) | J5: W xả thừa (10⁶ m³) | K5: Z cuối tháng (m)
A6: =Thang_dau -> 5 | B6: =INDEX(DongChay85,1,A6) -> 15.62 | C6: =INDEX(NhuCau_chon,1,A6) -> 5.92 | D6: 0 | E6: =C6+D6 -> 5.92 | F6: =MAX(B6-E6,0) -> 9.7 | G6: =MAX(E6-B6,0) -> 0 | H6: =V_chet -> 6.8157017 | I6: =IF(F6>0,MIN(H6+F6,V_chet+$H$20),H6-G6) -> 16.515702 | J6: =IF(F6>0,MAX(H6+F6-(V_chet+$H$20),0),0) -> 0 | K6: =INDEX(BT_Z,MATCH(I6,BT_V,1))+(I6-INDEX(BT_V,MATCH(I6,BT_V,1)))*(INDEX(BT_Z,MATCH(I6,BT_V,1)+1)-INDEX(BT_Z,MATCH(I6,BT_V,1)))/(INDEX(BT_V,MATCH(I6,BT_V,1)+1)-INDEX(BT_V,MATCH(I6,BT_V,1))) -> 70.729769 | M6: XÁC ĐỊNH HÌNH THỨC ĐIỀU TIẾT
A7: =MOD(A6,12)+1 -> 6 | B7: =INDEX(DongChay85,1,A7) -> 24.62 | C7: =INDEX(NhuCau_chon,1,A7) -> 8.31 | D7: 0 | E7: =C7+D7 -> 8.31 | F7: =MAX(B7-E7,0) -> 16.31 | G7: =MAX(E7-B7,0) -> 0 | H7: =I6 -> 16.515702 | I7: =IF(F7>0,MIN(H7+F7,V_chet+$H$20),H7-G7) -> 32.165702 | J7: =IF(F7>0,MAX(H7+F7-(V_chet+$H$20),0),0) -> 0.66 | K7: =INDEX(BT_Z,MATCH(I7,BT_V,1))+(I7-INDEX(BT_V,MATCH(I7,BT_V,1)))*(INDEX(BT_Z,MATCH(I7,BT_V,1)+1)-INDEX(BT_Z,MATCH(I7,BT_V,1)))/(INDEX(BT_V,MATCH(I7,BT_V,1)+1)-INDEX(BT_V,MATCH(I7,BT_V,1))) -> 73.995923 | M7: Tổng lượng nước đến năm thiết kế P = 85%, W đến (10⁶ m³) | N7: =SUM(DongChay85) -> 175.74
A8: =MOD(A7,12)+1 -> 7 | B8: =INDEX(DongChay85,1,A8) -> 14.01 | C8: =INDEX(NhuCau_chon,1,A8) -> 5.59 | D8: 0 | E8: =C8+D8 -> 5.59 | F8: =MAX(B8-E8,0) -> 8.42 | G8: =MAX(E8-B8,0) -> 0 | H8: =I7 -> 32.165702 | I8: =IF(F8>0,MIN(H8+F8,V_chet+$H$20),H8-G8) -> 32.165702 | J8: =IF(F8>0,MAX(H8+F8-(V_chet+$H$20),0),0) -> 8.42 | K8: =INDEX(BT_Z,MATCH(I8,BT_V,1))+(I8-INDEX(BT_V,MATCH(I8,BT_V,1)))*(INDEX(BT_Z,MATCH(I8,BT_V,1)+1)-INDEX(BT_Z,MATCH(I8,BT_V,1)))/(INDEX(BT_V,MATCH(I8,BT_V,1)+1)-INDEX(BT_V,MATCH(I8,BT_V,1))) -> 73.995923 | M8: Tổng nhu cầu dùng nước trong năm, W dùng (10⁶ m³) | N8: =SUM(NhuCau_chon) -> 106.64
A9: =MOD(A8,12)+1 -> 8 | B9: =INDEX(DongChay85,1,A9) -> 19.03 | C9: =INDEX(NhuCau_chon,1,A9) -> 8.9 | D9: 0 | E9: =C9+D9 -> 8.9 | F9: =MAX(B9-E9,0) -> 10.13 | G9: =MAX(E9-B9,0) -> 0 | H9: =I8 -> 32.165702 | I9: =IF(F9>0,MIN(H9+F9,V_chet+$H$20),H9-G9) -> 32.165702 | J9: =IF(F9>0,MAX(H9+F9-(V_chet+$H$20),0),0) -> 10.13 | K9: =INDEX(BT_Z,MATCH(I9,BT_V,1))+(I9-INDEX(BT_V,MATCH(I9,BT_V,1)))*(INDEX(BT_Z,MATCH(I9,BT_V,1)+1)-INDEX(BT_Z,MATCH(I9,BT_V,1)))/(INDEX(BT_V,MATCH(I9,BT_V,1)+1)-INDEX(BT_V,MATCH(I9,BT_V,1))) -> 73.995923 | M9: So sánh | N9: =IF(N7>N8,"W đến > W dùng → ĐIỀU TIẾT NĂM","W đến ≤ W dùng → cần ĐIỀU TIẾT NHIỀU NĂM") -> W đến > W dùng → ĐIỀU TIẾT NĂM
A10: =MOD(A9,12)+1 -> 9 | B10: =INDEX(DongChay85,1,A10) -> 20.02 | C10: =INDEX(NhuCau_chon,1,A10) -> 2.57 | D10: 0 | E10: =C10+D10 -> 2.57 | F10: =MAX(B10-E10,0) -> 17.45 | G10: =MAX(E10-B10,0) -> 0 | H10: =I9 -> 32.165702 | I10: =IF(F10>0,MIN(H10+F10,V_chet+$H$20),H10-G10) -> 32.165702 | J10: =IF(F10>0,MAX(H10+F10-(V_chet+$H$20),0),0) -> 17.45 | K10: =INDEX(BT_Z,MATCH(I10,BT_V,1))+(I10-INDEX(BT_V,MATCH(I10,BT_V,1)))*(INDEX(BT_Z,MATCH(I10,BT_V,1)+1)-INDEX(BT_Z,MATCH(I10,BT_V,1)))/(INDEX(BT_V,MATCH(I10,BT_V,1)+1)-INDEX(BT_V,MATCH(I10,BT_V,1))) -> 73.995923 | M10: Riêng nội lưu vực 141 km² (10⁶ m³) | N10: =SoLieu!O17 -> 46.253
A11: =MOD(A10,12)+1 -> 10 | B11: =INDEX(DongChay85,1,A11) -> 31.97 | C11: =INDEX(NhuCau_chon,1,A11) -> 2.99 | D11: 0 | E11: =C11+D11 -> 2.99 | F11: =MAX(B11-E11,0) -> 28.98 | G11: =MAX(E11-B11,0) -> 0 | H11: =I10 -> 32.165702 | I11: =IF(F11>0,MIN(H11+F11,V_chet+$H$20),H11-G11) -> 32.165702 | J11: =IF(F11>0,MAX(H11+F11-(V_chet+$H$20),0),0) -> 28.98 | K11: =INDEX(BT_Z,MATCH(I11,BT_V,1))+(I11-INDEX(BT_V,MATCH(I11,BT_V,1)))*(INDEX(BT_Z,MATCH(I11,BT_V,1)+1)-INDEX(BT_Z,MATCH(I11,BT_V,1)))/(INDEX(BT_V,MATCH(I11,BT_V,1)+1)-INDEX(BT_V,MATCH(I11,BT_V,1))) -> 73.995923 | M11: Tổng lượng thừa trong năm Σ ΔV+ (10⁶ m³) | N11: =F18 -> 94.45
A12: =MOD(A11,12)+1 -> 11 | B12: =INDEX(DongChay85,1,A12) -> 12.96 | C12: =INDEX(NhuCau_chon,1,A12) -> 9.5 | D12: 0 | E12: =C12+D12 -> 9.5 | F12: =MAX(B12-E12,0) -> 3.46 | G12: =MAX(E12-B12,0) -> 0 | H12: =I11 -> 32.165702 | I12: =IF(F12>0,MIN(H12+F12,V_chet+$H$20),H12-G12) -> 32.165702 | J12: =IF(F12>0,MAX(H12+F12-(V_chet+$H$20),0),0) -> 3.46 | K12: =INDEX(BT_Z,MATCH(I12,BT_V,1))+(I12-INDEX(BT_V,MATCH(I12,BT_V,1)))*(INDEX(BT_Z,MATCH(I12,BT_V,1)+1)-INDEX(BT_Z,MATCH(I12,BT_V,1)))/(INDEX(BT_V,MATCH(I12,BT_V,1)+1)-INDEX(BT_V,MATCH(I12,BT_V,1))) -> 73.995923 | M12: Tổng lượng thiếu trong năm Σ ΔV− (10⁶ m³) | N12: =G18 -> 25.35
A13: =MOD(A12,12)+1 -> 12 | B13: =INDEX(DongChay85,1,A13) -> 10.04 | C13: =INDEX(NhuCau_chon,1,A13) -> 15.54 | D13: 0 | E13: =C13+D13 -> 15.54 | F13: =MAX(B13-E13,0) -> 0 | G13: =MAX(E13-B13,0) -> 5.5 | H13: =I12 -> 32.165702 | I13: =IF(F13>0,MIN(H13+F13,V_chet+$H$20),H13-G13) -> 26.665702 | J13: =IF(F13>0,MAX(H13+F13-(V_chet+$H$20),0),0) -> 0 | K13: =INDEX(BT_Z,MATCH(I13,BT_V,1))+(I13-INDEX(BT_V,MATCH(I13,BT_V,1)))*(INDEX(BT_Z,MATCH(I13,BT_V,1)+1)-INDEX(BT_Z,MATCH(I13,BT_V,1)))/(INDEX(BT_V,MATCH(I13,BT_V,1)+1)-INDEX(BT_V,MATCH(I13,BT_V,1))) -> 72.995442
A14: =MOD(A13,12)+1 -> 1 | B14: =INDEX(DongChay85,1,A14) -> 9.3 | C14: =INDEX(NhuCau_chon,1,A14) -> 13.27 | D14: 0 | E14: =C14+D14 -> 13.27 | F14: =MAX(B14-E14,0) -> 0 | G14: =MAX(E14-B14,0) -> 3.97 | H14: =I13 -> 26.665702 | I14: =IF(F14>0,MIN(H14+F14,V_chet+$H$20),H14-G14) -> 22.695702 | J14: =IF(F14>0,MAX(H14+F14-(V_chet+$H$20),0),0) -> 0 | K14: =INDEX(BT_Z,MATCH(I14,BT_V,1))+(I14-INDEX(BT_V,MATCH(I14,BT_V,1)))*(INDEX(BT_Z,MATCH(I14,BT_V,1)+1)-INDEX(BT_Z,MATCH(I14,BT_V,1)))/(INDEX(BT_V,MATCH(I14,BT_V,1)+1)-INDEX(BT_V,MATCH(I14,BT_V,1))) -> 72.191053 | M14: W là tổng lượng nước, đơn vị 10⁶ m³ (không phải m³/s).
A15: =MOD(A14,12)+1 -> 2 | B15: =INDEX(DongChay85,1,A15) -> 4.77 | C15: =INDEX(NhuCau_chon,1,A15) -> 10.48 | D15: 0 | E15: =C15+D15 -> 10.48 | F15: =MAX(B15-E15,0) -> 0 | G15: =MAX(E15-B15,0) -> 5.71 | H15: =I14 -> 22.695702 | I15: =IF(F15>0,MIN(H15+F15,V_chet+$H$20),H15-G15) -> 16.985702 | J15: =IF(F15>0,MAX(H15+F15-(V_chet+$H$20),0),0) -> 0 | K15: =INDEX(BT_Z,MATCH(I15,BT_V,1))+(I15-INDEX(BT_V,MATCH(I15,BT_V,1)))*(INDEX(BT_Z,MATCH(I15,BT_V,1)+1)-INDEX(BT_Z,MATCH(I15,BT_V,1)))/(INDEX(BT_V,MATCH(I15,BT_V,1)+1)-INDEX(BT_V,MATCH(I15,BT_V,1))) -> 70.851967 | M15: Năm thủy lợi bắt đầu từ tháng có W đến > W dùng đầu tiên sau mùa khô (tháng 5): đầu tháng 5 hồ ở MNC,
A16: =MOD(A15,12)+1 -> 3 | B16: =INDEX(DongChay85,1,A16) -> 4.19 | C16: =INDEX(NhuCau_chon,1,A16) -> 9.37 | D16: 0 | E16: =C16+D16 -> 9.37 | F16: =MAX(B16-E16,0) -> 0 | G16: =MAX(E16-B16,0) -> 5.18 | H16: =I15 -> 16.985702 | I16: =IF(F16>0,MIN(H16+F16,V_chet+$H$20),H16-G16) -> 11.805702 | J16: =IF(F16>0,MAX(H16+F16-(V_chet+$H$20),0),0) -> 0 | K16: =INDEX(BT_Z,MATCH(I16,BT_V,1))+(I16-INDEX(BT_V,MATCH(I16,BT_V,1)))*(INDEX(BT_Z,MATCH(I16,BT_V,1)+1)-INDEX(BT_Z,MATCH(I16,BT_V,1)))/(INDEX(BT_V,MATCH(I16,BT_V,1)+1)-INDEX(BT_V,MATCH(I16,BT_V,1))) -> 69.374195 | M16: tích nước các tháng thừa, cuối mùa lũ (tháng 11) hồ đầy MNDBT, cấp nước tháng 12 ÷ 4, cuối tháng 4 về MNC.
A17: =MOD(A16,12)+1 -> 4 | B17: =INDEX(DongChay85,1,A17) -> 9.21 | C17: =INDEX(NhuCau_chon,1,A17) -> 14.2 | D17: 0 | E17: =C17+D17 -> 14.2 | F17: =MAX(B17-E17,0) -> 0 | G17: =MAX(E17-B17,0) -> 4.99 | H17: =I16 -> 11.805702 | I17: =IF(F17>0,MIN(H17+F17,V_chet+$H$20),H17-G17) -> 6.8157017 | J17: =IF(F17>0,MAX(H17+F17-(V_chet+$H$20),0),0) -> 0 | K17: =INDEX(BT_Z,MATCH(I17,BT_V,1))+(I17-INDEX(BT_V,MATCH(I17,BT_V,1)))*(INDEX(BT_Z,MATCH(I17,BT_V,1)+1)-INDEX(BT_Z,MATCH(I17,BT_V,1)))/(INDEX(BT_V,MATCH(I17,BT_V,1)+1)-INDEX(BT_V,MATCH(I17,BT_V,1))) -> 67.5 | M17: Kết luận điều tiết năm dựa vào nước bổ sung từ hệ thống Sông Lũy (riêng nội lưu vực nhỏ hơn nhu cầu).
A18: Cộng | B18: =SUM(B6:B17) -> 175.74 | C18: =SUM(C6:C17) -> 106.64 | D18: =SUM(D6:D17) -> 0 | E18: =SUM(E6:E17) -> 106.64 | F18: =SUM(F6:F17) -> 94.45 | G18: =SUM(G6:G17) -> 25.35 | J18: =SUM(J6:J17) -> 69.1
A20: Dung tích hữu ích cần Vhi = Σ ΔV− (tổng lượng thiếu của thời kỳ cấp nước) | H20: =G18 -> 25.35
A21: Dung tích ứng MNDBT cần Vbt = Vc + Vhi | H21: =V_chet+H20 -> 32.165702
A22: MNDBT cần = Z(Vbt cần) (m) | H22: =INDEX(BT_Z,MATCH(H21,BT_V,1))+(H21-INDEX(BT_V,MATCH(H21,BT_V,1)))*(INDEX(BT_Z,MATCH(H21,BT_V,1)+1)-INDEX(BT_Z,MATCH(H21,BT_V,1)))/(INDEX(BT_V,MATCH(H21,BT_V,1)+1)-INDEX(BT_V,MATCH(H21,BT_V,1))) -> 73.995923
A23: Kiểm tra: V cuối năm thủy lợi − Vc (phải = 0) | H23: =I17-V_chet -> 0
A24: Kiểm tra: số đợt thiếu nước trong năm (phải = 1) | H24: =SUMPRODUCT((G7:G17>0)*(G6:G16=0))+IF(G6>0,1,0) -> 1
A29: Cách tích nước: tích sớm – tháng thừa thì tích đến khi đầy (Vc + Vhi), phần thừa còn lại xả qua tràn; tháng thiếu thì hồ cấp nước (dung tích giảm đúng bằng lượng thiếu).

Sheet B2_Lan1
A1: BƯỚC 2 – ĐIỀU TIẾT NĂM CÓ KỂ TỔN THẤT – LẦN 1
A2: TH | B2: =TH_chon -> TH1A | D2: Vc = | E2: =V_chet -> 6.8157017 | G2: k_t = | H2: =k_tham -> 0.01
A4: BẢNG ĐIỀU TIẾT NĂM CÓ KỂ TỔN THẤT | M4: BẢNG TÍNH TỔN THẤT (theo quá trình dung tích của sheet B1_KhongTonThat)
A5: Tháng | B5: W đến (10⁶ m³) | C5: W dùng (10⁶ m³) | D5: W tổn thất (10⁶ m³) | E5: W dùng + W tổn thất | F5: Thừa ΔV+ = W đến − (W dùng + W tt) | G5: Thiếu ΔV− = (W dùng + W tt) − W đến | H5: V đầu tháng (10⁶ m³) | I5: V cuối tháng (10⁶ m³) | J5: W xả thừa (10⁶ m³) | K5: Z cuối tháng (m) | M5: Tháng | N5: V đầu tháng (lần trước) | O5: V cuối tháng (lần trước) | P5: V̄ = (V đầu + V cuối)/2 | Q5: Z̄ (m) tra V ~ Z | R5: F̄ (km²) tra Z ~ F | S5: ΔZ bốc hơi (mm) | T5: W bốc hơi = ΔZ·F̄ | U5: W thấm = k_t·V̄ | V5: W tổn thất
A6: =Thang_dau -> 5 | B6: =INDEX(DongChay85,1,A6) -> 15.62 | C6: =INDEX(NhuCau_chon,1,A6) -> 5.92 | D6: =V6 -> 0.31028189 | E6: =C6+D6 -> 6.2302819 | F6: =MAX(B6-E6,0) -> 9.3897181 | G6: =MAX(E6-B6,0) -> 0 | H6: =V_chet -> 6.8157017 | I6: =IF(F6>0,MIN(H6+F6,V_chet+$H$20),H6-G6) -> 16.20542 | J6: =IF(F6>0,MAX(H6+F6-(V_chet+$H$20),0),0) -> 0 | K6: =INDEX(BT_Z,MATCH(I6,BT_V,1))+(I6-INDEX(BT_V,MATCH(I6,BT_V,1)))*(INDEX(BT_Z,MATCH(I6,BT_V,1)+1)-INDEX(BT_Z,MATCH(I6,BT_V,1)))/(INDEX(BT_V,MATCH(I6,BT_V,1)+1)-INDEX(BT_V,MATCH(I6,BT_V,1))) -> 70.647969 | M6: =A6 -> 5 | N6: =B1_KhongTonThat!H6 -> 6.8157017 | O6: =B1_KhongTonThat!I6 -> 16.515702 | P6: =(N6+O6)/2 -> 11.665702 | Q6: =INDEX(BT_Z,MATCH(P6,BT_V,1))+(P6-INDEX(BT_V,MATCH(P6,BT_V,1)))*(INDEX(BT_Z,MATCH(P6,BT_V,1)+1)-INDEX(BT_Z,MATCH(P6,BT_V,1)))/(INDEX(BT_V,MATCH(P6,BT_V,1)+1)-INDEX(BT_V,MATCH(P6,BT_V,1))) -> 69.329301 | R6: =INDEX(Bang_F,MATCH(Q6,Bang_Z,1))+(Q6-INDEX(Bang_Z,MATCH(Q6,Bang_Z,1)))*(INDEX(Bang_F,MATCH(Q6,Bang_Z,1)+1)-INDEX(Bang_F,MATCH(Q6,Bang_Z,1)))/(INDEX(Bang_Z,MATCH(Q6,Bang_Z,1)+1)-INDEX(Bang_Z,MATCH(Q6,Bang_Z,1))) -> 3.1079434 | S6: =INDEX(BocHoi,1,M6) -> 62.3 | T6: =S6/1000*R6 -> 0.19362487 | U6: =k_tham*P6 -> 0.11665702 | V6: =T6+U6 -> 0.31028189
A7: =MOD(A6,12)+1 -> 6 | B7: =INDEX(DongChay85,1,A7) -> 24.62 | C7: =INDEX(NhuCau_chon,1,A7) -> 8.31 | D7: =V7 -> 0.51326149 | E7: =C7+D7 -> 8.8232615 | F7: =MAX(B7-E7,0) -> 15.796739 | G7: =MAX(E7-B7,0) -> 0 | H7: =I6 -> 16.20542 | I7: =IF(F7>0,MIN(H7+F7,V_chet+$H$20),H7-G7) -> 32.002158 | J7: =IF(F7>0,MAX(H7+F7-(V_chet+$H$20),0),0) -> 0 | K7: =INDEX(BT_Z,MATCH(I7,BT_V,1))+(I7-INDEX(BT_V,MATCH(I7,BT_V,1)))*(INDEX(BT_Z,MATCH(I7,BT_V,1)+1)-INDEX(BT_Z,MATCH(I7,BT_V,1)))/(INDEX(BT_V,MATCH(I7,BT_V,1)+1)-INDEX(BT_V,MATCH(I7,BT_V,1))) -> 73.967579 | M7: =A7 -> 6 | N7: =B1_KhongTonThat!H7 -> 16.515702 | O7: =B1_KhongTonThat!I7 -> 32.165702 | P7: =(N7+O7)/2 -> 24.340702 | Q7: =INDEX(BT_Z,MATCH(P7,BT_V,1))+(P7-INDEX(BT_V,MATCH(P7,BT_V,1)))*(INDEX(BT_Z,MATCH(P7,BT_V,1)+1)-INDEX(BT_Z,MATCH(P7,BT_V,1)))/(INDEX(BT_V,MATCH(P7,BT_V,1)+1)-INDEX(BT_V,MATCH(P7,BT_V,1))) -> 72.534678 | R7: =INDEX(Bang_F,MATCH(Q7,Bang_Z,1))+(Q7-INDEX(Bang_Z,MATCH(Q7,Bang_Z,1)))*(INDEX(Bang_F,MATCH(Q7,Bang_Z,1)+1)-INDEX(Bang_F,MATCH(Q7,Bang_Z,1)))/(INDEX(Bang_Z,MATCH(Q7,Bang_Z,1)+1)-INDEX(Bang_Z,MATCH(Q7,Bang_Z,1))) -> 4.8975404 | S7: =INDEX(BocHoi,1,M7) -> 55.1 | T7: =S7/1000*R7 -> 0.26985448 | U7: =k_tham*P7 -> 0.24340702 | V7: =T7+U7 -> 0.51326149
A8: =MOD(A7,12)+1 -> 7 | B8: =INDEX(DongChay85,1,A8) -> 14.01 | C8: =INDEX(NhuCau_chon,1,A8) -> 5.59 | D8: =V8 -> 0.61037518 | E8: =C8+D8 -> 6.2003752 | F8: =MAX(B8-E8,0) -> 7.8096248 | G8: =MAX(E8-B8,0) -> 0 | H8: =I7 -> 32.002158 | I8: =IF(F8>0,MIN(H8+F8,V_chet+$H$20),H8-G8) -> 34.574416 | J8: =IF(F8>0,MAX(H8+F8-(V_chet+$H$20),0),0) -> 5.2373673 | K8: =INDEX(BT_Z,MATCH(I8,BT_V,1))+(I8-INDEX(BT_V,MATCH(I8,BT_V,1)))*(INDEX(BT_Z,MATCH(I8,BT_V,1)+1)-INDEX(BT_Z,MATCH(I8,BT_V,1)))/(INDEX(BT_V,MATCH(I8,BT_V,1)+1)-INDEX(BT_V,MATCH(I8,BT_V,1))) -> 74.402034 | M8: =A8 -> 7 | N8: =B1_KhongTonThat!H8 -> 32.165702 | O8: =B1_KhongTonThat!I8 -> 32.165702 | P8: =(N8+O8)/2 -> 32.165702 | Q8: =INDEX(BT_Z,MATCH(P8,BT_V,1))+(P8-INDEX(BT_V,MATCH(P8,BT_V,1)))*(INDEX(BT_Z,MATCH(P8,BT_V,1)+1)-INDEX(BT_Z,MATCH(P8,BT_V,1)))/(INDEX(BT_V,MATCH(P8,BT_V,1)+1)-INDEX(BT_V,MATCH(P8,BT_V,1))) -> 73.995923 | R8: =INDEX(Bang_F,MATCH(Q8,Bang_Z,1))+(Q8-INDEX(Bang_Z,MATCH(Q8,Bang_Z,1)))*(INDEX(Bang_F,MATCH(Q8,Bang_Z,1)+1)-INDEX(Bang_F,MATCH(Q8,Bang_Z,1)))/(INDEX(Bang_Z,MATCH(Q8,Bang_Z,1)+1)-INDEX(Bang_Z,MATCH(Q8,Bang_Z,1))) -> 5.7975536 | S8: =INDEX(BocHoi,1,M8) -> 49.8 | T8: =S8/1000*R8 -> 0.28871817 | U8: =k_tham*P8 -> 0.32165702 | V8: =T8+U8 -> 0.61037518
A9: =MOD(A8,12)+1 -> 8 | B9: =INDEX(DongChay85,1,A9) -> 19.03 | C9: =INDEX(NhuCau_chon,1,A9) -> 8.9 | D9: =V9 -> 0.62197029 | E9: =C9+D9 -> 9.5219703 | F9: =MAX(B9-E9,0) -> 9.5080297 | G9: =MAX(E9-B9,0) -> 0 | H9: =I8 -> 34.574416 | I9: =IF(F9>0,MIN(H9+F9,V_chet+$H$20),H9-G9) -> 34.574416 | J9: =IF(F9>0,MAX(H9+F9-(V_chet+$H$20),0),0) -> 9.5080297 | K9: =INDEX(BT_Z,MATCH(I9,BT_V,1))+(I9-INDEX(BT_V,MATCH(I9,BT_V,1)))*(INDEX(BT_Z,MATCH(I9,BT_V,1)+1)-INDEX(BT_Z,MATCH(I9,BT_V,1)))/(INDEX(BT_V,MATCH(I9,BT_V,1)+1)-INDEX(BT_V,MATCH(I9,BT_V,1))) -> 74.402034 | M9: =A9 -> 8 | N9: =B1_KhongTonThat!H9 -> 32.165702 | O9: =B1_KhongTonThat!I9 -> 32.165702 | P9: =(N9+O9)/2 -> 32.165702 | Q9: =INDEX(BT_Z,MATCH(P9,BT_V,1))+(P9-INDEX(BT_V,MATCH(P9,BT_V,1)))*(INDEX(BT_Z,MATCH(P9,BT_V,1)+1)-INDEX(BT_Z,MATCH(P9,BT_V,1)))/(INDEX(BT_V,MATCH(P9,BT_V,1)+1)-INDEX(BT_V,MATCH(P9,BT_V,1))) -> 73.995923 | R9: =INDEX(Bang_F,MATCH(Q9,Bang_Z,1))+(Q9-INDEX(Bang_Z,MATCH(Q9,Bang_Z,1)))*(INDEX(Bang_F,MATCH(Q9,Bang_Z,1)+1)-INDEX(Bang_F,MATCH(Q9,Bang_Z,1)))/(INDEX(Bang_Z,MATCH(Q9,Bang_Z,1)+1)-INDEX(Bang_Z,MATCH(Q9,Bang_Z,1))) -> 5.7975536 | S9: =INDEX(BocHoi,1,M9) -> 51.8 | T9: =S9/1000*R9 -> 0.30031327 | U9: =k_tham*P9 -> 0.32165702 | V9: =T9+U9 -> 0.62197029
A10: =MOD(A9,12)+1 -> 9 | B10: =INDEX(DongChay85,1,A10) -> 20.02 | C10: =INDEX(NhuCau_chon,1,A10) -> 2.57 | D10: =V10 -> 0.57616962 | E10: =C10+D10 -> 3.1461696 | F10: =MAX(B10-E10,0) -> 16.87383 | G10: =MAX(E10-B10,0) -> 0 | H10: =I9 -> 34.574416 | I10: =IF(F10>0,MIN(H10+F10,V_chet+$H$20),H10-G10) -> 34.574416 | J10: =IF(F10>0,MAX(H10+F10-(V_chet+$H$20),0),0) -> 16.87383 | K10: =INDEX(BT_Z,MATCH(I10,BT_V,1))+(I10-INDEX(BT_V,MATCH(I10,BT_V,1)))*(INDEX(BT_Z,MATCH(I10,BT_V,1)+1)-INDEX(BT_Z,MATCH(I10,BT_V,1)))/(INDEX(BT_V,MATCH(I10,BT_V,1)+1)-INDEX(BT_V,MATCH(I10,BT_V,1))) -> 74.402034 | M10: =A10 -> 9 | N10: =B1_KhongTonThat!H10 -> 32.165702 | O10: =B1_KhongTonThat!I10 -> 32.165702 | P10: =(N10+O10)/2 -> 32.165702 | Q10: =INDEX(BT_Z,MATCH(P10,BT_V,1))+(P10-INDEX(BT_V,MATCH(P10,BT_V,1)))*(INDEX(BT_Z,MATCH(P10,BT_V,1)+1)-INDEX(BT_Z,MATCH(P10,BT_V,1)))/(INDEX(BT_V,MATCH(P10,BT_V,1)+1)-INDEX(BT_V,MATCH(P10,BT_V,1))) -> 73.995923 | R10: =INDEX(Bang_F,MATCH(Q10,Bang_Z,1))+(Q10-INDEX(Bang_Z,MATCH(Q10,Bang_Z,1)))*(INDEX(Bang_F,MATCH(Q10,Bang_Z,1)+1)-INDEX(Bang_F,MATCH(Q10,Bang_Z,1)))/(INDEX(Bang_Z,MATCH(Q10,Bang_Z,1)+1)-INDEX(Bang_Z,MATCH(Q10,Bang_Z,1))) -> 5.7975536 | S10: =INDEX(BocHoi,1,M10) -> 43.9 | T10: =S10/1000*R10 -> 0.2545126 | U10: =k_tham*P10 -> 0.32165702 | V10: =T10+U10 -> 0.57616962
A11: =MOD(A10,12)+1 -> 10 | B11: =INDEX(DongChay85,1,A11) -> 31.97 | C11: =INDEX(NhuCau_chon,1,A11) -> 2.99 | D11: =V11 -> 0.5581972 | E11: =C11+D11 -> 3.5481972 | F11: =MAX(B11-E11,0) -> 28.421803 | G11: =MAX(E11-B11,0) -> 0 | H11: =I10 -> 34.574416 | I11: =IF(F11>0,MIN(H11+F11,V_chet+$H$20),H11-G11) -> 34.574416 | J11: =IF(F11>0,MAX(H11+F11-(V_chet+$H$20),0),0) -> 28.421803 | K11: =INDEX(BT_Z,MATCH(I11,BT_V,1))+(I11-INDEX(BT_V,MATCH(I11,BT_V,1)))*(INDEX(BT_Z,MATCH(I11,BT_V,1)+1)-INDEX(BT_Z,MATCH(I11,BT_V,1)))/(INDEX(BT_V,MATCH(I11,BT_V,1)+1)-INDEX(BT_V,MATCH(I11,BT_V,1))) -> 74.402034 | M11: =A11 -> 10 | N11: =B1_KhongTonThat!H11 -> 32.165702 | O11: =B1_KhongTonThat!I11 -> 32.165702 | P11: =(N11+O11)/2 -> 32.165702 | Q11: =INDEX(BT_Z,MATCH(P11,BT_V,1))+(P11-INDEX(BT_V,MATCH(P11,BT_V,1)))*(INDEX(BT_Z,MATCH(P11,BT_V,1)+1)-INDEX(BT_Z,MATCH(P11,BT_V,1)))/(INDEX(BT_V,MATCH(P11,BT_V,1)+1)-INDEX(BT_V,MATCH(P11,BT_V,1))) -> 73.995923 | R11: =INDEX(Bang_F,MATCH(Q11,Bang_Z,1))+(Q11-INDEX(Bang_Z,MATCH(Q11,Bang_Z,1)))*(INDEX(Bang_F,MATCH(Q11,Bang_Z,1)+1)-INDEX(Bang_F,MATCH(Q11,Bang_Z,1)))/(INDEX(Bang_Z,MATCH(Q11,Bang_Z,1)+1)-INDEX(Bang_Z,MATCH(Q11,Bang_Z,1))) -> 5.7975536 | S11: =INDEX(BocHoi,1,M11) -> 40.8 | T11: =S11/1000*R11 -> 0.23654019 | U11: =k_tham*P11 -> 0.32165702 | V11: =T11+U11 -> 0.5581972
A12: =MOD(A11,12)+1 -> 11 | B12: =INDEX(DongChay85,1,A12) -> 12.96 | C12: =INDEX(NhuCau_chon,1,A12) -> 9.5 | D12: =V12 -> 0.62428931 | E12: =C12+D12 -> 10.124289 | F12: =MAX(B12-E12,0) -> 2.8357107 | G12: =MAX(E12-B12,0) -> 0 | H12: =I11 -> 34.574416 | I12: =IF(F12>0,MIN(H12+F12,V_chet+$H$20),H12-G12) -> 34.574416 | J12: =IF(F12>0,MAX(H12+F12-(V_chet+$H$20),0),0) -> 2.8357107 | K12: =INDEX(BT_Z,MATCH(I12,BT_V,1))+(I12-INDEX(BT_V,MATCH(I12,BT_V,1)))*(INDEX(BT_Z,MATCH(I12,BT_V,1)+1)-INDEX(BT_Z,MATCH(I12,BT_V,1)))/(INDEX(BT_V,MATCH(I12,BT_V,1)+1)-INDEX(BT_V,MATCH(I12,BT_V,1))) -> 74.402034 | M12: =A12 -> 11 | N12: =B1_KhongTonThat!H12 -> 32.165702 | O12: =B1_KhongTonThat!I12 -> 32.165702 | P12: =(N12+O12)/2 -> 32.165702 | Q12: =INDEX(BT_Z,MATCH(P12,BT_V,1))+(P12-INDEX(BT_V,MATCH(P12,BT_V,1)))*(INDEX(BT_Z,MATCH(P12,BT_V,1)+1)-INDEX(BT_Z,MATCH(P12,BT_V,1)))/(INDEX(BT_V,MATCH(P12,BT_V,1)+1)-INDEX(BT_V,MATCH(P12,BT_V,1))) -> 73.995923 | R12: =INDEX(Bang_F,MATCH(Q12,Bang_Z,1))+(Q12-INDEX(Bang_Z,MATCH(Q12,Bang_Z,1)))*(INDEX(Bang_F,MATCH(Q12,Bang_Z,1)+1)-INDEX(Bang_F,MATCH(Q12,Bang_Z,1)))/(INDEX(Bang_Z,MATCH(Q12,Bang_Z,1)+1)-INDEX(Bang_Z,MATCH(Q12,Bang_Z,1))) -> 5.7975536 | S12: =INDEX(BocHoi,1,M12) -> 52.2 | T12: =S12/1000*R12 -> 0.3026323 | U12: =k_tham*P12 -> 0.32165702 | V12: =T12+U12 -> 0.62428931
A13: =MOD(A12,12)+1 -> 12 | B13: =INDEX(DongChay85,1,A13) -> 10.04 | C13: =INDEX(NhuCau_chon,1,A13) -> 15.54 | D13: =V13 -> 0.66137943 | E13: =C13+D13 -> 16.201379 | F13: =MAX(B13-E13,0) -> 0 | G13: =MAX(E13-B13,0) -> 6.1613794 | H13: =I12 -> 34.574416 | I13: =IF(F13>0,MIN(H13+F13,V_chet+$H$20),H13-G13) -> 28.413036 | J13: =IF(F13>0,MAX(H13+F13-(V_chet+$H$20),0),0) -> 0 | K13: =INDEX(BT_Z,MATCH(I13,BT_V,1))+(I13-INDEX(BT_V,MATCH(I13,BT_V,1)))*(INDEX(BT_Z,MATCH(I13,BT_V,1)+1)-INDEX(BT_Z,MATCH(I13,BT_V,1)))/(INDEX(BT_V,MATCH(I13,BT_V,1)+1)-INDEX(BT_V,MATCH(I13,BT_V,1))) -> 73.325285 | M13: =A13 -> 12 | N13: =B1_KhongTonThat!H13 -> 32.165702 | O13: =B1_KhongTonThat!I13 -> 26.665702 | P13: =(N13+O13)/2 -> 29.415702 | Q13: =INDEX(BT_Z,MATCH(P13,BT_V,1))+(P13-INDEX(BT_V,MATCH(P13,BT_V,1)))*(INDEX(BT_Z,MATCH(P13,BT_V,1)+1)-INDEX(BT_Z,MATCH(P13,BT_V,1)))/(INDEX(BT_V,MATCH(P13,BT_V,1)+1)-INDEX(BT_V,MATCH(P13,BT_V,1))) -> 73.509306 | R13: =INDEX(Bang_F,MATCH(Q13,Bang_Z,1))+(Q13-INDEX(Bang_Z,MATCH(Q13,Bang_Z,1)))*(INDEX(Bang_F,MATCH(Q13,Bang_Z,1)+1)-INDEX(Bang_F,MATCH(Q13,Bang_Z,1)))/(INDEX(Bang_Z,MATCH(Q13,Bang_Z,1)+1)-INDEX(Bang_Z,MATCH(Q13,Bang_Z,1))) -> 5.5055834 | S13: =INDEX(BocHoi,1,M13) -> 66.7 | T13: =S13/1000*R13 -> 0.36722241 | U13: =k_tham*P13 -> 0.29415702 | V13: =T13+U13 -> 0.66137943
A14: =MOD(A13,12)+1 -> 1 | B14: =INDEX(DongChay85,1,A14) -> 9.3 | C14: =INDEX(NhuCau_chon,1,A14) -> 13.27 | D14: =V14 -> 0.58487677 | E14: =C14+D14 -> 13.854877 | F14: =MAX(B14-E14,0) -> 0 | G14: =MAX(E14-B14,0) -> 4.5548768 | H14: =I13 -> 28.413036 | I14: =IF(F14>0,MIN(H14+F14,V_chet+$H$20),H14-G14) -> 23.85816 | J14: =IF(F14>0,MAX(H14+F14-(V_chet+$H$20),0),0) -> 0 | K14: =INDEX(BT_Z,MATCH(I14,BT_V,1))+(I14-INDEX(BT_V,MATCH(I14,BT_V,1)))*(INDEX(BT_Z,MATCH(I14,BT_V,1)+1)-INDEX(BT_Z,MATCH(I14,BT_V,1)))/(INDEX(BT_V,MATCH(I14,BT_V,1)+1)-INDEX(BT_V,MATCH(I14,BT_V,1))) -> 72.435495 | M14: =A14 -> 1 | N14: =B1_KhongTonThat!H14 -> 26.665702 | O14: =B1_KhongTonThat!I14 -> 22.695702 | P14: =(N14+O14)/2 -> 24.680702 | Q14: =INDEX(BT_Z,MATCH(P14,BT_V,1))+(P14-INDEX(BT_V,MATCH(P14,BT_V,1)))*(INDEX(BT_Z,MATCH(P14,BT_V,1)+1)-INDEX(BT_Z,MATCH(P14,BT_V,1)))/(INDEX(BT_V,MATCH(P14,BT_V,1)+1)-INDEX(BT_V,MATCH(P14,BT_V,1))) -> 72.603908 | R14: =INDEX(Bang_F,MATCH(Q14,Bang_Z,1))+(Q14-INDEX(Bang_Z,MATCH(Q14,Bang_Z,1)))*(INDEX(Bang_F,MATCH(Q14,Bang_Z,1)+1)-INDEX(Bang_F,MATCH(Q14,Bang_Z,1)))/(INDEX(Bang_Z,MATCH(Q14,Bang_Z,1)+1)-INDEX(Bang_Z,MATCH(Q14,Bang_Z,1))) -> 4.9425402 | S14: =INDEX(BocHoi,1,M14) -> 68.4 | T14: =S14/1000*R14 -> 0.33806975 | U14: =k_tham*P14 -> 0.24680702 | V14: =T14+U14 -> 0.58487677
A15: =MOD(A14,12)+1 -> 2 | B15: =INDEX(DongChay85,1,A15) -> 4.77 | C15: =INDEX(NhuCau_chon,1,A15) -> 10.48 | D15: =V15 -> 0.47415092 | E15: =C15+D15 -> 10.954151 | F15: =MAX(B15-E15,0) -> 0 | G15: =MAX(E15-B15,0) -> 6.1841509 | H15: =I14 -> 23.85816 | I15: =IF(F15>0,MIN(H15+F15,V_chet+$H$20),H15-G15) -> 17.674009 | J15: =IF(F15>0,MAX(H15+F15-(V_chet+$H$20),0),0) -> 0 | K15: =INDEX(BT_Z,MATCH(I15,BT_V,1))+(I15-INDEX(BT_V,MATCH(I15,BT_V,1)))*(INDEX(BT_Z,MATCH(I15,BT_V,1)+1)-INDEX(BT_Z,MATCH(I15,BT_V,1)))/(INDEX(BT_V,MATCH(I15,BT_V,1)+1)-INDEX(BT_V,MATCH(I15,BT_V,1))) -> 71.027558 | M15: =A15 -> 2 | N15: =B1_KhongTonThat!H15 -> 22.695702 | O15: =B1_KhongTonThat!I15 -> 16.985702 | P15: =(N15+O15)/2 -> 19.840702 | Q15: =INDEX(BT_Z,MATCH(P15,BT_V,1))+(P15-INDEX(BT_V,MATCH(P15,BT_V,1)))*(INDEX(BT_Z,MATCH(P15,BT_V,1)+1)-INDEX(BT_Z,MATCH(P15,BT_V,1)))/(INDEX(BT_V,MATCH(P15,BT_V,1)+1)-INDEX(BT_V,MATCH(P15,BT_V,1))) -> 71.552896 | R15: =INDEX(Bang_F,MATCH(Q15,Bang_Z,1))+(Q15-INDEX(Bang_Z,MATCH(Q15,Bang_Z,1)))*(INDEX(Bang_F,MATCH(Q15,Bang_Z,1)+1)-INDEX(Bang_F,MATCH(Q15,Bang_Z,1)))/(INDEX(Bang_Z,MATCH(Q15,Bang_Z,1)+1)-INDEX(Bang_Z,MATCH(Q15,Bang_Z,1))) -> 4.2817376 | S15: =INDEX(BocHoi,1,M15) -> 64.4 | T15: =S15/1000*R15 -> 0.2757439 | U15: =k_tham*P15 -> 0.19840702 | V15: =T15+U15 -> 0.47415092
A16: =MOD(A15,12)+1 -> 3 | B16: =INDEX(DongChay85,1,A16) -> 4.19 | C16: =INDEX(NhuCau_chon,1,A16) -> 9.37 | D16: =V16 -> 0.41511243 | E16: =C16+D16 -> 9.7851124 | F16: =MAX(B16-E16,0) -> 0 | G16: =MAX(E16-B16,0) -> 5.5951124 | H16: =I15 -> 17.674009 | I16: =IF(F16>0,MIN(H16+F16,V_chet+$H$20),H16-G16) -> 12.078896 | J16: =IF(F16>0,MAX(H16+F16-(V_chet+$H$20),0),0) -> 0 | K16: =INDEX(BT_Z,MATCH(I16,BT_V,1))+(I16-INDEX(BT_V,MATCH(I16,BT_V,1)))*(INDEX(BT_Z,MATCH(I16,BT_V,1)+1)-INDEX(BT_Z,MATCH(I16,BT_V,1)))/(INDEX(BT_V,MATCH(I16,BT_V,1)+1)-INDEX(BT_V,MATCH(I16,BT_V,1))) -> 69.460806 | M16: =A16 -> 3 | N16: =B1_KhongTonThat!H16 -> 16.985702 | O16: =B1_KhongTonThat!I16 -> 11.805702 | P16: =(N16+O16)/2 -> 14.395702 | Q16: =INDEX(BT_Z,MATCH(P16,BT_V,1))+(P16-INDEX(BT_V,MATCH(P16,BT_V,1)))*(INDEX(BT_Z,MATCH(P16,BT_V,1)+1)-INDEX(BT_Z,MATCH(P16,BT_V,1)))/(INDEX(BT_V,MATCH(P16,BT_V,1)+1)-INDEX(BT_V,MATCH(P16,BT_V,1))) -> 70.152156 | R16: =INDEX(Bang_F,MATCH(Q16,Bang_Z,1))+(Q16-INDEX(Bang_Z,MATCH(Q16,Bang_Z,1)))*(INDEX(Bang_F,MATCH(Q16,Bang_Z,1)+1)-INDEX(Bang_F,MATCH(Q16,Bang_Z,1)))/(INDEX(Bang_Z,MATCH(Q16,Bang_Z,1)+1)-INDEX(Bang_Z,MATCH(Q16,Bang_Z,1))) -> 3.5260782 | S16: =INDEX(BocHoi,1,M16) -> 76.9 | T16: =S16/1000*R16 -> 0.27115541 | U16: =k_tham*P16 -> 0.14395702 | V16: =T16+U16 -> 0.41511243
A17: =MOD(A16,12)+1 -> 4 | B17: =INDEX(DongChay85,1,A17) -> 9.21 | C17: =INDEX(NhuCau_chon,1,A17) -> 14.2 | D17: =V17 -> 0.27319456 | E17: =C17+D17 -> 14.473195 | F17: =MAX(B17-E17,0) -> 0 | G17: =MAX(E17-B17,0) -> 5.2631946 | H17: =I16 -> 12.078896 | I17: =IF(F17>0,MIN(H17+F17,V_chet+$H$20),H17-G17) -> 6.8157017 | J17: =IF(F17>0,MAX(H17+F17-(V_chet+$H$20),0),0) -> 0 | K17: =INDEX(BT_Z,MATCH(I17,BT_V,1))+(I17-INDEX(BT_V,MATCH(I17,BT_V,1)))*(INDEX(BT_Z,MATCH(I17,BT_V,1)+1)-INDEX(BT_Z,MATCH(I17,BT_V,1)))/(INDEX(BT_V,MATCH(I17,BT_V,1)+1)-INDEX(BT_V,MATCH(I17,BT_V,1))) -> 67.5 | M17: =A17 -> 4 | N17: =B1_KhongTonThat!H17 -> 11.805702 | O17: =B1_KhongTonThat!I17 -> 6.8157017 | P17: =(N17+O17)/2 -> 9.3107017 | Q17: =INDEX(BT_Z,MATCH(P17,BT_V,1))+(P17-INDEX(BT_V,MATCH(P17,BT_V,1)))*(INDEX(BT_Z,MATCH(P17,BT_V,1)+1)-INDEX(BT_Z,MATCH(P17,BT_V,1)))/(INDEX(BT_V,MATCH(P17,BT_V,1)+1)-INDEX(BT_V,MATCH(P17,BT_V,1))) -> 68.518402 | R17: =INDEX(Bang_F,MATCH(Q17,Bang_Z,1))+(Q17-INDEX(Bang_Z,MATCH(Q17,Bang_Z,1)))*(INDEX(Bang_F,MATCH(Q17,Bang_Z,1)+1)-INDEX(Bang_F,MATCH(Q17,Bang_Z,1)))/(INDEX(Bang_Z,MATCH(Q17,Bang_Z,1)+1)-INDEX(Bang_Z,MATCH(Q17,Bang_Z,1))) -> 2.7040172 | S17: =INDEX(BocHoi,1,M17) -> 66.6 | T17: =S17/1000*R17 -> 0.18008754 | U17: =k_tham*P17 -> 0.093107017 | V17: =T17+U17 -> 0.27319456
A18: Cộng | B18: =SUM(B6:B17) -> 175.74 | C18: =SUM(C6:C17) -> 106.64 | D18: =SUM(D6:D17) -> 6.2232591 | E18: =SUM(E6:E17) -> 112.86326 | F18: =SUM(F6:F17) -> 90.635455 | G18: =SUM(G6:G17) -> 27.758714 | J18: =SUM(J6:J17) -> 62.876741 | M18: Cộng | T18: =SUM(T6:T17) -> 3.2784749 | U18: =SUM(U6:U17) -> 2.9447842 | V18: =SUM(V6:V17) -> 6.2232591
A20: Dung tích hữu ích cần Vhi = Σ ΔV− (tổng lượng thiếu của thời kỳ cấp nước) | H20: =G18 -> 27.758714 | M20: Cột D của bảng điều tiết (W tổn thất) lấy từ cột “W tổn thất” của bảng này.
A21: Dung tích ứng MNDBT cần Vbt = Vc + Vhi | H21: =V_chet+H20 -> 34.574416
A22: MNDBT cần = Z(Vbt cần) (m) | H22: =INDEX(BT_Z,MATCH(H21,BT_V,1))+(H21-INDEX(BT_V,MATCH(H21,BT_V,1)))*(INDEX(BT_Z,MATCH(H21,BT_V,1)+1)-INDEX(BT_Z,MATCH(H21,BT_V,1)))/(INDEX(BT_V,MATCH(H21,BT_V,1)+1)-INDEX(BT_V,MATCH(H21,BT_V,1))) -> 74.402034
A23: Kiểm tra: V cuối năm thủy lợi − Vc (phải = 0) | H23: =I17-V_chet -> 0
A24: Kiểm tra: số đợt thiếu nước trong năm (phải = 1) | H24: =SUMPRODUCT((G7:G17>0)*(G6:G16=0))+IF(G6>0,1,0) -> 1
A25: Vhi lần trước (sheet B1_KhongTonThat) | H25: =B1_KhongTonThat!H20 -> 25.35
A26: Sai số |Vhi − Vhi lần trước| / Vhi | H26: =ABS(H20-H25)/H20 -> 0.08677326
A27: Đánh giá | H27: =IF(H26<=SaiSo_cp,"Hội tụ – dừng lặp","Chưa hội tụ – lặp tiếp") -> Chưa hội tụ – lặp tiếp
A29: Cách tích nước: tích sớm – tháng thừa thì tích đến khi đầy (Vc + Vhi), phần thừa còn lại xả qua tràn; tháng thiếu thì hồ cấp nước (dung tích giảm đúng bằng lượng thiếu).

Sheet B3_Lan2
A1: BƯỚC 3 – ĐIỀU TIẾT NĂM CÓ KỂ TỔN THẤT – LẦN 2
A2: TH | B2: =TH_chon -> TH1A | D2: Vc = | E2: =V_chet -> 6.8157017 | G2: k_t = | H2: =k_tham -> 0.01
A4: BẢNG ĐIỀU TIẾT NĂM CÓ KỂ TỔN THẤT | M4: BẢNG TÍNH TỔN THẤT (theo quá trình dung tích của sheet B2_Lan1)
A5: Tháng | B5: W đến (10⁶ m³) | C5: W dùng (10⁶ m³) | D5: W tổn thất (10⁶ m³) | E5: W dùng + W tổn thất | F5: Thừa ΔV+ = W đến − (W dùng + W tt) | G5: Thiếu ΔV− = (W dùng + W tt) − W đến | H5: V đầu tháng (10⁶ m³) | I5: V cuối tháng (10⁶ m³) | J5: W xả thừa (10⁶ m³) | K5: Z cuối tháng (m) | M5: Tháng | N5: V đầu tháng (lần trước) | O5: V cuối tháng (lần trước) | P5: V̄ = (V đầu + V cuối)/2 | Q5: Z̄ (m) tra V ~ Z | R5: F̄ (km²) tra Z ~ F | S5: ΔZ bốc hơi (mm) | T5: W bốc hơi = ΔZ·F̄ | U5: W thấm = k_t·V̄ | V5: W tổn thất
A6: =Thang_dau -> 5 | B6: =INDEX(DongChay85,1,A6) -> 15.62 | C6: =INDEX(NhuCau_chon,1,A6) -> 5.92 | D6: =V6 -> 0.307139 | E6: =C6+D6 -> 6.227139 | F6: =MAX(B6-E6,0) -> 9.392861 | G6: =MAX(E6-B6,0) -> 0 | H6: =V_chet -> 6.8157017 | I6: =IF(F6>0,MIN(H6+F6,V_chet+$H$20),H6-G6) -> 16.208563 | J6: =IF(F6>0,MAX(H6+F6-(V_chet+$H$20),0),0) -> 0 | K6: =INDEX(BT_Z,MATCH(I6,BT_V,1))+(I6-INDEX(BT_V,MATCH(I6,BT_V,1)))*(INDEX(BT_Z,MATCH(I6,BT_V,1)+1)-INDEX(BT_Z,MATCH(I6,BT_V,1)))/(INDEX(BT_V,MATCH(I6,BT_V,1)+1)-INDEX(BT_V,MATCH(I6,BT_V,1))) -> 70.648802 | M6: =A6 -> 5 | N6: =B2_Lan1!H6 -> 6.8157017 | O6: =B2_Lan1!I6 -> 16.20542 | P6: =(N6+O6)/2 -> 11.510561 | Q6: =INDEX(BT_Z,MATCH(P6,BT_V,1))+(P6-INDEX(BT_V,MATCH(P6,BT_V,1)))*(INDEX(BT_Z,MATCH(P6,BT_V,1)+1)-INDEX(BT_Z,MATCH(P6,BT_V,1)))/(INDEX(BT_V,MATCH(P6,BT_V,1)+1)-INDEX(BT_V,MATCH(P6,BT_V,1))) -> 69.279212 | R6: =INDEX(Bang_F,MATCH(Q6,Bang_Z,1))+(Q6-INDEX(Bang_Z,MATCH(Q6,Bang_Z,1)))*(INDEX(Bang_F,MATCH(Q6,Bang_Z,1)+1)-INDEX(Bang_F,MATCH(Q6,Bang_Z,1)))/(INDEX(Bang_Z,MATCH(Q6,Bang_Z,1)+1)-INDEX(Bang_Z,MATCH(Q6,Bang_Z,1))) -> 3.0823979 | S6: =INDEX(BocHoi,1,M6) -> 62.3 | T6: =S6/1000*R6 -> 0.19203339 | U6: =k_tham*P6 -> 0.11510561 | V6: =T6+U6 -> 0.307139
A7: =MOD(A6,12)+1 -> 6 | B7: =INDEX(DongChay85,1,A7) -> 24.62 | C7: =INDEX(NhuCau_chon,1,A7) -> 8.31 | D7: =V7 -> 0.50915682 | E7: =C7+D7 -> 8.8191568 | F7: =MAX(B7-E7,0) -> 15.800843 | G7: =MAX(E7-B7,0) -> 0 | H7: =I6 -> 16.208563 | I7: =IF(F7>0,MIN(H7+F7,V_chet+$H$20),H7-G7) -> 32.009406 | J7: =IF(F7>0,MAX(H7+F7-(V_chet+$H$20),0),0) -> 0 | K7: =INDEX(BT_Z,MATCH(I7,BT_V,1))+(I7-INDEX(BT_V,MATCH(I7,BT_V,1)))*(INDEX(BT_Z,MATCH(I7,BT_V,1)+1)-INDEX(BT_Z,MATCH(I7,BT_V,1)))/(INDEX(BT_V,MATCH(I7,BT_V,1)+1)-INDEX(BT_V,MATCH(I7,BT_V,1))) -> 73.968835 | M7: =A7 -> 6 | N7: =B2_Lan1!H7 -> 16.20542 | O7: =B2_Lan1!I7 -> 32.002158 | P7: =(N7+O7)/2 -> 24.103789 | Q7: =INDEX(BT_Z,MATCH(P7,BT_V,1))+(P7-INDEX(BT_V,MATCH(P7,BT_V,1)))*(INDEX(BT_Z,MATCH(P7,BT_V,1)+1)-INDEX(BT_Z,MATCH(P7,BT_V,1)))/(INDEX(BT_V,MATCH(P7,BT_V,1)+1)-INDEX(BT_V,MATCH(P7,BT_V,1))) -> 72.486219 | R7: =INDEX(Bang_F,MATCH(Q7,Bang_Z,1))+(Q7-INDEX(Bang_Z,MATCH(Q7,Bang_Z,1)))*(INDEX(Bang_F,MATCH(Q7,Bang_Z,1)+1)-INDEX(Bang_F,MATCH(Q7,Bang_Z,1)))/(INDEX(Bang_Z,MATCH(Q7,Bang_Z,1)+1)-INDEX(Bang_Z,MATCH(Q7,Bang_Z,1))) -> 4.8660424 | S7: =INDEX(BocHoi,1,M7) -> 55.1 | T7: =S7/1000*R7 -> 0.26811893 | U7: =k_tham*P7 -> 0.24103789 | V7: =T7+U7 -> 0.50915682
A8: =MOD(A7,12)+1 -> 7 | B8: =INDEX(DongChay85,1,A8) -> 14.01 | C8: =INDEX(NhuCau_chon,1,A8) -> 5.59 | D8: =V8 -> 0.6278834 | E8: =C8+D8 -> 6.2178834 | F8: =MAX(B8-E8,0) -> 7.7921166 | G8: =MAX(E8-B8,0) -> 0 | H8: =I7 -> 32.009406 | I8: =IF(F8>0,MIN(H8+F8,V_chet+$H$20),H8-G8) -> 34.667884 | J8: =IF(F8>0,MAX(H8+F8-(V_chet+$H$20),0),0) -> 5.133638 | K8: =INDEX(BT_Z,MATCH(I8,BT_V,1))+(I8-INDEX(BT_V,MATCH(I8,BT_V,1)))*(INDEX(BT_Z,MATCH(I8,BT_V,1)+1)-INDEX(BT_Z,MATCH(I8,BT_V,1)))/(INDEX(BT_V,MATCH(I8,BT_V,1)+1)-INDEX(BT_V,MATCH(I8,BT_V,1))) -> 74.417364 | M8: =A8 -> 7 | N8: =B2_Lan1!H8 -> 32.002158 | O8: =B2_Lan1!I8 -> 34.574416 | P8: =(N8+O8)/2 -> 33.288287 | Q8: =INDEX(BT_Z,MATCH(P8,BT_V,1))+(P8-INDEX(BT_V,MATCH(P8,BT_V,1)))*(INDEX(BT_Z,MATCH(P8,BT_V,1)+1)-INDEX(BT_Z,MATCH(P8,BT_V,1)))/(INDEX(BT_V,MATCH(P8,BT_V,1)+1)-INDEX(BT_V,MATCH(P8,BT_V,1))) -> 74.187433 | R8: =INDEX(Bang_F,MATCH(Q8,Bang_Z,1))+(Q8-INDEX(Bang_Z,MATCH(Q8,Bang_Z,1)))*(INDEX(Bang_F,MATCH(Q8,Bang_Z,1)+1)-INDEX(Bang_F,MATCH(Q8,Bang_Z,1)))/(INDEX(Bang_Z,MATCH(Q8,Bang_Z,1)+1)-INDEX(Bang_Z,MATCH(Q8,Bang_Z,1))) -> 5.9237055 | S8: =INDEX(BocHoi,1,M8) -> 49.8 | T8: =S8/1000*R8 -> 0.29500053 | U8: =k_tham*P8 -> 0.33288287 | V8: =T8+U8 -> 0.6278834
A9: =MOD(A8,12)+1 -> 8 | B9: =INDEX(DongChay85,1,A9) -> 19.03 | C9: =INDEX(NhuCau_chon,1,A9) -> 8.9 | D9: =V9 -> 0.65992889 | E9: =C9+D9 -> 9.5599289 | F9: =MAX(B9-E9,0) -> 9.4700711 | G9: =MAX(E9-B9,0) -> 0 | H9: =I8 -> 34.667884 | I9: =IF(F9>0,MIN(H9+F9,V_chet+$H$20),H9-G9) -> 34.667884 | J9: =IF(F9>0,MAX(H9+F9-(V_chet+$H$20),0),0) -> 9.4700711 | K9: =INDEX(BT_Z,MATCH(I9,BT_V,1))+(I9-INDEX(BT_V,MATCH(I9,BT_V,1)))*(INDEX(BT_Z,MATCH(I9,BT_V,1)+1)-INDEX(BT_Z,MATCH(I9,BT_V,1)))/(INDEX(BT_V,MATCH(I9,BT_V,1)+1)-INDEX(BT_V,MATCH(I9,BT_V,1))) -> 74.417364 | M9: =A9 -> 8 | N9: =B2_Lan1!H9 -> 34.574416 | O9: =B2_Lan1!I9 -> 34.574416 | P9: =(N9+O9)/2 -> 34.574416 | Q9: =INDEX(BT_Z,MATCH(P9,BT_V,1))+(P9-INDEX(BT_V,MATCH(P9,BT_V,1)))*(INDEX(BT_Z,MATCH(P9,BT_V,1)+1)-INDEX(BT_Z,MATCH(P9,BT_V,1)))/(INDEX(BT_V,MATCH(P9,BT_V,1)+1)-INDEX(BT_V,MATCH(P9,BT_V,1))) -> 74.402034 | R9: =INDEX(Bang_F,MATCH(Q9,Bang_Z,1))+(Q9-INDEX(Bang_Z,MATCH(Q9,Bang_Z,1)))*(INDEX(Bang_F,MATCH(Q9,Bang_Z,1)+1)-INDEX(Bang_F,MATCH(Q9,Bang_Z,1)))/(INDEX(Bang_Z,MATCH(Q9,Bang_Z,1)+1)-INDEX(Bang_Z,MATCH(Q9,Bang_Z,1))) -> 6.0653423 | S9: =INDEX(BocHoi,1,M9) -> 51.8 | T9: =S9/1000*R9 -> 0.31418473 | U9: =k_tham*P9 -> 0.34574416 | V9: =T9+U9 -> 0.65992889
A10: =MOD(A9,12)+1 -> 9 | B10: =INDEX(DongChay85,1,A10) -> 20.02 | C10: =INDEX(NhuCau_chon,1,A10) -> 2.57 | D10: =V10 -> 0.61201268 | E10: =C10+D10 -> 3.1820127 | F10: =MAX(B10-E10,0) -> 16.837987 | G10: =MAX(E10-B10,0) -> 0 | H10: =I9 -> 34.667884 | I10: =IF(F10>0,MIN(H10+F10,V_chet+$H$20),H10-G10) -> 34.667884 | J10: =IF(F10>0,MAX(H10+F10-(V_chet+$H$20),0),0) -> 16.837987 | K10: =INDEX(BT_Z,MATCH(I10,BT_V,1))+(I10-INDEX(BT_V,MATCH(I10,BT_V,1)))*(INDEX(BT_Z,MATCH(I10,BT_V,1)+1)-INDEX(BT_Z,MATCH(I10,BT_V,1)))/(INDEX(BT_V,MATCH(I10,BT_V,1)+1)-INDEX(BT_V,MATCH(I10,BT_V,1))) -> 74.417364 | M10: =A10 -> 9 | N10: =B2_Lan1!H10 -> 34.574416 | O10: =B2_Lan1!I10 -> 34.574416 | P10: =(N10+O10)/2 -> 34.574416 | Q10: =INDEX(BT_Z,MATCH(P10,BT_V,1))+(P10-INDEX(BT_V,MATCH(P10,BT_V,1)))*(INDEX(BT_Z,MATCH(P10,BT_V,1)+1)-INDEX(BT_Z,MATCH(P10,BT_V,1)))/(INDEX(BT_V,MATCH(P10,BT_V,1)+1)-INDEX(BT_V,MATCH(P10,BT_V,1))) -> 74.402034 | R10: =INDEX(Bang_F,MATCH(Q10,Bang_Z,1))+(Q10-INDEX(Bang_Z,MATCH(Q10,Bang_Z,1)))*(INDEX(Bang_F,MATCH(Q10,Bang_Z,1)+1)-INDEX(Bang_F,MATCH(Q10,Bang_Z,1)))/(INDEX(Bang_Z,MATCH(Q10,Bang_Z,1)+1)-INDEX(Bang_Z,MATCH(Q10,Bang_Z,1))) -> 6.0653423 | S10: =INDEX(BocHoi,1,M10) -> 43.9 | T10: =S10/1000*R10 -> 0.26626853 | U10: =k_tham*P10 -> 0.34574416 | V10: =T10+U10 -> 0.61201268
A11: =MOD(A10,12)+1 -> 10 | B11: =INDEX(DongChay85,1,A11) -> 31.97 | C11: =INDEX(NhuCau_chon,1,A11) -> 2.99 | D11: =V11 -> 0.59321012 | E11: =C11+D11 -> 3.5832101 | F11: =MAX(B11-E11,0) -> 28.38679 | G11: =MAX(E11-B11,0) -> 0 | H11: =I10 -> 34.667884 | I11: =IF(F11>0,MIN(H11+F11,V_chet+$H$20),H11-G11) -> 34.667884 | J11: =IF(F11>0,MAX(H11+F11-(V_chet+$H$20),0),0) -> 28.38679 | K11: =INDEX(BT_Z,MATCH(I11,BT_V,1))+(I11-INDEX(BT_V,MATCH(I11,BT_V,1)))*(INDEX(BT_Z,MATCH(I11,BT_V,1)+1)-INDEX(BT_Z,MATCH(I11,BT_V,1)))/(INDEX(BT_V,MATCH(I11,BT_V,1)+1)-INDEX(BT_V,MATCH(I11,BT_V,1))) -> 74.417364 | M11: =A11 -> 10 | N11: =B2_Lan1!H11 -> 34.574416 | O11: =B2_Lan1!I11 -> 34.574416 | P11: =(N11+O11)/2 -> 34.574416 | Q11: =INDEX(BT_Z,MATCH(P11,BT_V,1))+(P11-INDEX(BT_V,MATCH(P11,BT_V,1)))*(INDEX(BT_Z,MATCH(P11,BT_V,1)+1)-INDEX(BT_Z,MATCH(P11,BT_V,1)))/(INDEX(BT_V,MATCH(P11,BT_V,1)+1)-INDEX(BT_V,MATCH(P11,BT_V,1))) -> 74.402034 | R11: =INDEX(Bang_F,MATCH(Q11,Bang_Z,1))+(Q11-INDEX(Bang_Z,MATCH(Q11,Bang_Z,1)))*(INDEX(Bang_F,MATCH(Q11,Bang_Z,1)+1)-INDEX(Bang_F,MATCH(Q11,Bang_Z,1)))/(INDEX(Bang_Z,MATCH(Q11,Bang_Z,1)+1)-INDEX(Bang_Z,MATCH(Q11,Bang_Z,1))) -> 6.0653423 | S11: =INDEX(BocHoi,1,M11) -> 40.8 | T11: =S11/1000*R11 -> 0.24746597 | U11: =k_tham*P11 -> 0.34574416 | V11: =T11+U11 -> 0.59321012
A12: =MOD(A11,12)+1 -> 11 | B12: =INDEX(DongChay85,1,A12) -> 12.96 | C12: =INDEX(NhuCau_chon,1,A12) -> 9.5 | D12: =V12 -> 0.66235503 | E12: =C12+D12 -> 10.162355 | F12: =MAX(B12-E12,0) -> 2.797645 | G12: =MAX(E12-B12,0) -> 0 | H12: =I11 -> 34.667884 | I12: =IF(F12>0,MIN(H12+F12,V_chet+$H$20),H12-G12) -> 34.667884 | J12: =IF(F12>0,MAX(H12+F12-(V_chet+$H$20),0),0) -> 2.797645 | K12: =INDEX(BT_Z,MATCH(I12,BT_V,1))+(I12-INDEX(BT_V,MATCH(I12,BT_V,1)))*(INDEX(BT_Z,MATCH(I12,BT_V,1)+1)-INDEX(BT_Z,MATCH(I12,BT_V,1)))/(INDEX(BT_V,MATCH(I12,BT_V,1)+1)-INDEX(BT_V,MATCH(I12,BT_V,1))) -> 74.417364 | M12: =A12 -> 11 | N12: =B2_Lan1!H12 -> 34.574416 | O12: =B2_Lan1!I12 -> 34.574416 | P12: =(N12+O12)/2 -> 34.574416 | Q12: =INDEX(BT_Z,MATCH(P12,BT_V,1))+(P12-INDEX(BT_V,MATCH(P12,BT_V,1)))*(INDEX(BT_Z,MATCH(P12,BT_V,1)+1)-INDEX(BT_Z,MATCH(P12,BT_V,1)))/(INDEX(BT_V,MATCH(P12,BT_V,1)+1)-INDEX(BT_V,MATCH(P12,BT_V,1))) -> 74.402034 | R12: =INDEX(Bang_F,MATCH(Q12,Bang_Z,1))+(Q12-INDEX(Bang_Z,MATCH(Q12,Bang_Z,1)))*(INDEX(Bang_F,MATCH(Q12,Bang_Z,1)+1)-INDEX(Bang_F,MATCH(Q12,Bang_Z,1)))/(INDEX(Bang_Z,MATCH(Q12,Bang_Z,1)+1)-INDEX(Bang_Z,MATCH(Q12,Bang_Z,1))) -> 6.0653423 | S12: =INDEX(BocHoi,1,M12) -> 52.2 | T12: =S12/1000*R12 -> 0.31661087 | U12: =k_tham*P12 -> 0.34574416 | V12: =T12+U12 -> 0.66235503
A13: =MOD(A12,12)+1 -> 12 | B13: =INDEX(DongChay85,1,A13) -> 10.04 | C13: =INDEX(NhuCau_chon,1,A13) -> 15.54 | D13: =V13 -> 0.69696469 | E13: =C13+D13 -> 16.236965 | F13: =MAX(B13-E13,0) -> 0 | G13: =MAX(E13-B13,0) -> 6.1969647 | H13: =I12 -> 34.667884 | I13: =IF(F13>0,MIN(H13+F13,V_chet+$H$20),H13-G13) -> 28.47092 | J13: =IF(F13>0,MAX(H13+F13-(V_chet+$H$20),0),0) -> 0 | K13: =INDEX(BT_Z,MATCH(I13,BT_V,1))+(I13-INDEX(BT_V,MATCH(I13,BT_V,1)))*(INDEX(BT_Z,MATCH(I13,BT_V,1)+1)-INDEX(BT_Z,MATCH(I13,BT_V,1)))/(INDEX(BT_V,MATCH(I13,BT_V,1)+1)-INDEX(BT_V,MATCH(I13,BT_V,1))) -> 73.335984 | M13: =A13 -> 12 | N13: =B2_Lan1!H13 -> 34.574416 | O13: =B2_Lan1!I13 -> 28.413036 | P13: =(N13+O13)/2 -> 31.493726 | Q13: =INDEX(BT_Z,MATCH(P13,BT_V,1))+(P13-INDEX(BT_V,MATCH(P13,BT_V,1)))*(INDEX(BT_Z,MATCH(P13,BT_V,1)+1)-INDEX(BT_Z,MATCH(P13,BT_V,1)))/(INDEX(BT_V,MATCH(P13,BT_V,1)+1)-INDEX(BT_V,MATCH(P13,BT_V,1))) -> 73.879246 | R13: =INDEX(Bang_F,MATCH(Q13,Bang_Z,1))+(Q13-INDEX(Bang_Z,MATCH(Q13,Bang_Z,1)))*(INDEX(Bang_F,MATCH(Q13,Bang_Z,1)+1)-INDEX(Bang_F,MATCH(Q13,Bang_Z,1)))/(INDEX(Bang_Z,MATCH(Q13,Bang_Z,1)+1)-INDEX(Bang_Z,MATCH(Q13,Bang_Z,1))) -> 5.7275476 | S13: =INDEX(BocHoi,1,M13) -> 66.7 | T13: =S13/1000*R13 -> 0.38202743 | U13: =k_tham*P13 -> 0.31493726 | V13: =T13+U13 -> 0.69696469
A14: =MOD(A13,12)+1 -> 1 | B14: =INDEX(DongChay85,1,A14) -> 9.3 | C14: =INDEX(NhuCau_chon,1,A14) -> 13.27 | D14: =V14 -> 0.61226836 | E14: =C14+D14 -> 13.882268 | F14: =MAX(B14-E14,0) -> 0 | G14: =MAX(E14-B14,0) -> 4.5822684 | H14: =I13 -> 28.47092 | I14: =IF(F14>0,MIN(H14+F14,V_chet+$H$20),H14-G14) -> 23.888651 | J14: =IF(F14>0,MAX(H14+F14-(V_chet+$H$20),0),0) -> 0 | K14: =INDEX(BT_Z,MATCH(I14,BT_V,1))+(I14-INDEX(BT_V,MATCH(I14,BT_V,1)))*(INDEX(BT_Z,MATCH(I14,BT_V,1)+1)-INDEX(BT_Z,MATCH(I14,BT_V,1)))/(INDEX(BT_V,MATCH(I14,BT_V,1)+1)-INDEX(BT_V,MATCH(I14,BT_V,1))) -> 72.441792 | M14: =A14 -> 1 | N14: =B2_Lan1!H14 -> 28.413036 | O14: =B2_Lan1!I14 -> 23.85816 | P14: =(N14+O14)/2 -> 26.135598 | Q14: =INDEX(BT_Z,MATCH(P14,BT_V,1))+(P14-INDEX(BT_V,MATCH(P14,BT_V,1)))*(INDEX(BT_Z,MATCH(P14,BT_V,1)+1)-INDEX(BT_Z,MATCH(P14,BT_V,1)))/(INDEX(BT_V,MATCH(P14,BT_V,1)+1)-INDEX(BT_V,MATCH(P14,BT_V,1))) -> 72.892766 | R14: =INDEX(Bang_F,MATCH(Q14,Bang_Z,1))+(Q14-INDEX(Bang_Z,MATCH(Q14,Bang_Z,1)))*(INDEX(Bang_F,MATCH(Q14,Bang_Z,1)+1)-INDEX(Bang_F,MATCH(Q14,Bang_Z,1)))/(INDEX(Bang_Z,MATCH(Q14,Bang_Z,1)+1)-INDEX(Bang_Z,MATCH(Q14,Bang_Z,1))) -> 5.1302979 | S14: =INDEX(BocHoi,1,M14) -> 68.4 | T14: =S14/1000*R14 -> 0.35091238 | U14: =k_tham*P14 -> 0.26135598 | V14: =T14+U14 -> 0.61226836
A15: =MOD(A14,12)+1 -> 2 | B15: =INDEX(DongChay85,1,A15) -> 4.77 | C15: =INDEX(NhuCau_chon,1,A15) -> 10.48 | D15: =V15 -> 0.49163368 | E15: =C15+D15 -> 10.971634 | F15: =MAX(B15-E15,0) -> 0 | G15: =MAX(E15-B15,0) -> 6.2016337 | H15: =I14 -> 23.888651 | I15: =IF(F15>0,MIN(H15+F15,V_chet+$H$20),H15-G15) -> 17.687018 | J15: =IF(F15>0,MAX(H15+F15-(V_chet+$H$20),0),0) -> 0 | K15: =INDEX(BT_Z,MATCH(I15,BT_V,1))+(I15-INDEX(BT_V,MATCH(I15,BT_V,1)))*(INDEX(BT_Z,MATCH(I15,BT_V,1)+1)-INDEX(BT_Z,MATCH(I15,BT_V,1)))/(INDEX(BT_V,MATCH(I15,BT_V,1)+1)-INDEX(BT_V,MATCH(I15,BT_V,1))) -> 71.030827 | M15: =A15 -> 2 | N15: =B2_Lan1!H15 -> 23.85816 | O15: =B2_Lan1!I15 -> 17.674009 | P15: =(N15+O15)/2 -> 20.766084 | Q15: =INDEX(BT_Z,MATCH(P15,BT_V,1))+(P15-INDEX(BT_V,MATCH(P15,BT_V,1)))*(INDEX(BT_Z,MATCH(P15,BT_V,1)+1)-INDEX(BT_Z,MATCH(P15,BT_V,1)))/(INDEX(BT_V,MATCH(P15,BT_V,1)+1)-INDEX(BT_V,MATCH(P15,BT_V,1))) -> 71.76586 | R15: =INDEX(Bang_F,MATCH(Q15,Bang_Z,1))+(Q15-INDEX(Bang_Z,MATCH(Q15,Bang_Z,1)))*(INDEX(Bang_F,MATCH(Q15,Bang_Z,1)+1)-INDEX(Bang_F,MATCH(Q15,Bang_Z,1)))/(INDEX(Bang_Z,MATCH(Q15,Bang_Z,1)+1)-INDEX(Bang_Z,MATCH(Q15,Bang_Z,1))) -> 4.4095161 | S15: =INDEX(BocHoi,1,M15) -> 64.4 | T15: =S15/1000*R15 -> 0.28397284 | U15: =k_tham*P15 -> 0.20766084 | V15: =T15+U15 -> 0.49163368
A16: =MOD(A15,12)+1 -> 3 | B16: =INDEX(DongChay85,1,A16) -> 4.19 | C16: =INDEX(NhuCau_chon,1,A16) -> 9.37 | D16: =V16 -> 0.4251163 | E16: =C16+D16 -> 9.7951163 | F16: =MAX(B16-E16,0) -> 0 | G16: =MAX(E16-B16,0) -> 5.6051163 | H16: =I15 -> 17.687018 | I16: =IF(F16>0,MIN(H16+F16,V_chet+$H$20),H16-G16) -> 12.081901 | J16: =IF(F16>0,MAX(H16+F16-(V_chet+$H$20),0),0) -> 0 | K16: =INDEX(BT_Z,MATCH(I16,BT_V,1))+(I16-INDEX(BT_V,MATCH(I16,BT_V,1)))*(INDEX(BT_Z,MATCH(I16,BT_V,1)+1)-INDEX(BT_Z,MATCH(I16,BT_V,1)))/(INDEX(BT_V,MATCH(I16,BT_V,1)+1)-INDEX(BT_V,MATCH(I16,BT_V,1))) -> 69.461754 | M16: =A16 -> 3 | N16: =B2_Lan1!H16 -> 17.674009 | O16: =B2_Lan1!I16 -> 12.078896 | P16: =(N16+O16)/2 -> 14.876452 | Q16: =INDEX(BT_Z,MATCH(P16,BT_V,1))+(P16-INDEX(BT_V,MATCH(P16,BT_V,1)))*(INDEX(BT_Z,MATCH(P16,BT_V,1)+1)-INDEX(BT_Z,MATCH(P16,BT_V,1)))/(INDEX(BT_V,MATCH(P16,BT_V,1)+1)-INDEX(BT_V,MATCH(P16,BT_V,1))) -> 70.287302 | R16: =INDEX(Bang_F,MATCH(Q16,Bang_Z,1))+(Q16-INDEX(Bang_Z,MATCH(Q16,Bang_Z,1)))*(INDEX(Bang_F,MATCH(Q16,Bang_Z,1)+1)-INDEX(Bang_F,MATCH(Q16,Bang_Z,1)))/(INDEX(Bang_Z,MATCH(Q16,Bang_Z,1)+1)-INDEX(Bang_Z,MATCH(Q16,Bang_Z,1))) -> 3.5936512 | S16: =INDEX(BocHoi,1,M16) -> 76.9 | T16: =S16/1000*R16 -> 0.27635177 | U16: =k_tham*P16 -> 0.14876452 | V16: =T16+U16 -> 0.4251163
A17: =MOD(A16,12)+1 -> 4 | B17: =INDEX(DongChay85,1,A17) -> 9.21 | C17: =INDEX(NhuCau_chon,1,A17) -> 14.2 | D17: =V17 -> 0.27619972 | E17: =C17+D17 -> 14.4762 | F17: =MAX(B17-E17,0) -> 0 | G17: =MAX(E17-B17,0) -> 5.2661997 | H17: =I16 -> 12.081901 | I17: =IF(F17>0,MIN(H17+F17,V_chet+$H$20),H17-G17) -> 6.8157017 | J17: =IF(F17>0,MAX(H17+F17-(V_chet+$H$20),0),0) -> 0 | K17: =INDEX(BT_Z,MATCH(I17,BT_V,1))+(I17-INDEX(BT_V,MATCH(I17,BT_V,1)))*(INDEX(BT_Z,MATCH(I17,BT_V,1)+1)-INDEX(BT_Z,MATCH(I17,BT_V,1)))/(INDEX(BT_V,MATCH(I17,BT_V,1)+1)-INDEX(BT_V,MATCH(I17,BT_V,1))) -> 67.5 | M17: =A17 -> 4 | N17: =B2_Lan1!H17 -> 12.078896 | O17: =B2_Lan1!I17 -> 6.8157017 | P17: =(N17+O17)/2 -> 9.4472989 | Q17: =INDEX(BT_Z,MATCH(P17,BT_V,1))+(P17-INDEX(BT_V,MATCH(P17,BT_V,1)))*(INDEX(BT_Z,MATCH(P17,BT_V,1)+1)-INDEX(BT_Z,MATCH(P17,BT_V,1)))/(INDEX(BT_V,MATCH(P17,BT_V,1)+1)-INDEX(BT_V,MATCH(P17,BT_V,1))) -> 68.568632 | R17: =INDEX(Bang_F,MATCH(Q17,Bang_Z,1))+(Q17-INDEX(Bang_Z,MATCH(Q17,Bang_Z,1)))*(INDEX(Bang_F,MATCH(Q17,Bang_Z,1)+1)-INDEX(Bang_F,MATCH(Q17,Bang_Z,1)))/(INDEX(Bang_Z,MATCH(Q17,Bang_Z,1)+1)-INDEX(Bang_Z,MATCH(Q17,Bang_Z,1))) -> 2.7286296 | S17: =INDEX(BocHoi,1,M17) -> 66.6 | T17: =S17/1000*R17 -> 0.18172673 | U17: =k_tham*P17 -> 0.094472989 | V17: =T17+U17 -> 0.27619972
A18: Cộng | B18: =SUM(B6:B17) -> 175.74 | C18: =SUM(C6:C17) -> 106.64 | D18: =SUM(D6:D17) -> 6.4738687 | E18: =SUM(E6:E17) -> 113.11387 | F18: =SUM(F6:F17) -> 90.478314 | G18: =SUM(G6:G17) -> 27.852183 | J18: =SUM(J6:J17) -> 62.626131 | M18: Cộng | T18: =SUM(T6:T17) -> 3.3746741 | U18: =SUM(U6:U17) -> 3.0991946 | V18: =SUM(V6:V17) -> 6.4738687
A20: Dung tích hữu ích cần Vhi = Σ ΔV− (tổng lượng thiếu của thời kỳ cấp nước) | H20: =G18 -> 27.852183 | M20: Cột D của bảng điều tiết (W tổn thất) lấy từ cột “W tổn thất” của bảng này.
A21: Dung tích ứng MNDBT cần Vbt = Vc + Vhi | H21: =V_chet+H20 -> 34.667884
A22: MNDBT cần = Z(Vbt cần) (m) | H22: =INDEX(BT_Z,MATCH(H21,BT_V,1))+(H21-INDEX(BT_V,MATCH(H21,BT_V,1)))*(INDEX(BT_Z,MATCH(H21,BT_V,1)+1)-INDEX(BT_Z,MATCH(H21,BT_V,1)))/(INDEX(BT_V,MATCH(H21,BT_V,1)+1)-INDEX(BT_V,MATCH(H21,BT_V,1))) -> 74.417364
A23: Kiểm tra: V cuối năm thủy lợi − Vc (phải = 0) | H23: =I17-V_chet -> 0
A24: Kiểm tra: số đợt thiếu nước trong năm (phải = 1) | H24: =SUMPRODUCT((G7:G17>0)*(G6:G16=0))+IF(G6>0,1,0) -> 1
A25: Vhi lần trước (sheet B2_Lan1) | H25: =B2_Lan1!H20 -> 27.758714
A26: Sai số |Vhi − Vhi lần trước| / Vhi | H26: =ABS(H20-H25)/H20 -> 0.0033558821
A27: Đánh giá | H27: =IF(H26<=SaiSo_cp,"Hội tụ – dừng lặp","Chưa hội tụ – lặp tiếp") -> Hội tụ – dừng lặp
A29: Cách tích nước: tích sớm – tháng thừa thì tích đến khi đầy (Vc + Vhi), phần thừa còn lại xả qua tràn; tháng thiếu thì hồ cấp nước (dung tích giảm đúng bằng lượng thiếu).

Sheet B4_Lan3
A1: BƯỚC 4 – ĐIỀU TIẾT NĂM CÓ KỂ TỔN THẤT – LẦN 3 (kiểm tra hội tụ)
A2: TH | B2: =TH_chon -> TH1A | D2: Vc = | E2: =V_chet -> 6.8157017 | G2: k_t = | H2: =k_tham -> 0.01
A4: BẢNG ĐIỀU TIẾT NĂM CÓ KỂ TỔN THẤT | M4: BẢNG TÍNH TỔN THẤT (theo quá trình dung tích của sheet B3_Lan2)
A5: Tháng | B5: W đến (10⁶ m³) | C5: W dùng (10⁶ m³) | D5: W tổn thất (10⁶ m³) | E5: W dùng + W tổn thất | F5: Thừa ΔV+ = W đến − (W dùng + W tt) | G5: Thiếu ΔV− = (W dùng + W tt) − W đến | H5: V đầu tháng (10⁶ m³) | I5: V cuối tháng (10⁶ m³) | J5: W xả thừa (10⁶ m³) | K5: Z cuối tháng (m) | M5: Tháng | N5: V đầu tháng (lần trước) | O5: V cuối tháng (lần trước) | P5: V̄ = (V đầu + V cuối)/2 | Q5: Z̄ (m) tra V ~ Z | R5: F̄ (km²) tra Z ~ F | S5: ΔZ bốc hơi (mm) | T5: W bốc hơi = ΔZ·F̄ | U5: W thấm = k_t·V̄ | V5: W tổn thất
