Workbook

Sheet HuongDan
B1: HƯỚNG DẪN TÍNH ĐIỀU TIẾT TOÀN CHUỖI 44 NĂM – HỒ CHỨA NƯỚC CÀ GIÂY
B2: File đi kèm thuyết minh ĐATN mục 2.2 (Đánh giá khả năng cấp nước). Mọi ô kết quả là công thức – đổi số liệu ở sheet SoLieu thì toàn bộ file tự tính lại.
B3: 1. Bài toán và trường hợp tính
B4: • Câu hỏi: với MNC +67,50 m, MNDBT +74,70 m (giữ như hiện có) và quan hệ Z ~ F ~ W đo năm 2022, hồ cấp đủ nước cho nhu cầu dùng nước bao nhiêu năm trong 44 năm, và mức bảo đảm có đạt 85% không?
B5: • Trường hợp mặc định: TH1A – tưới 8.965 ha, 50% diện tích cây trồng cạn tưới tiết kiệm + cấp nước sinh hoạt (QTVH Bảng 4-21). Đây là trường hợp sát yêu cầu nhất: 39/44 năm đủ nước, P = 86,7% – vừa đạt (thiếu thêm 1 năm là không đạt).
B6: • Có thể chọn TH1 hoặc TH2 ở ô SoLieu!B5 (TH2: 37/44 năm, 82,2% – gần đạt nhưng chưa đạt; TH1: 18/44 năm, 40,0%).
B7: • Dung tích lấy theo bình đồ 2022: Vc = V(+67,50) = 6,82; Vbt = V(+74,70) = 36,41; Vhi = 29,60 triệu m³ (thiết kế ban đầu 8,41 / 37,24 / 28,83 chỉ để so sánh – bản đồ cũ không còn nên không lập lại được đường V(Z) cũ).
B8: 2. Vì sao tính 44 năm?
B9: • 44 năm là TOÀN BỘ chuỗi dòng chảy tháng đến hồ mà QTVH 2026 đã tính (Bảng 3-13: năm 1981-1982 đến 2024-2025) – không phải con số tự chọn. Dùng hết số liệu có thì chuỗi đại diện tốt nhất cho các tổ hợp năm nhiều nước – ít nước.
B10: • TCVN 10778:2024 mục 8.2.1.2: khi có chuỗi dòng chảy đến từ 15 năm trở lên thì tính điều tiết theo phương pháp toàn chuỗi – mô phỏng lần lượt từng tháng của cả chuỗi – thay cho phương pháp năm đại biểu.
B11: • Toàn chuỗi giữ đúng thứ tự các năm và phân phối dòng chảy thực của từng năm: nếu có năm hồ không tích đầy thì năm sau bắt đầu với dung tích thấp (dung tích chuyển tiếp) – phương pháp một năm đại biểu không thể hiện được. Với hồ Cà Giây, cột “Hồ tích đầy trong năm?” ở sheet KetQua cho thấy năm nào hồ cũng tích đầy MNDBT (dòng chảy đến bình quân 220 triệu m³/năm, gấp khoảng 7 lần dung tích hữu ích 29,6 triệu m³ – hồ điều tiết năm), nên năm thiếu nước là do mùa khô của chính năm đó.
B12: • Mức bảo đảm được xác định bằng cách ĐẾM NĂM: P = m/(n + 1) (TCVN 10778:2024 công thức (14)); điều kiện đạt: m ≥ (n + 1)·P_tk (công thức (9)). Với n = 44: m ≥ 45 × 0,85 = 38,25 → cần ít nhất 39 năm đủ nước, tức chỉ được thiếu tối đa 5 năm; mỗi năm thiếu làm P giảm 1/45 = 2,2%.
... B46: • Tính tay tháng 1 năm đầu theo sheet ViDu (3 lần lặp) rồi so với dòng 5 của sheet DieuTiet.

Sheet SoLieu
A1: SỐ LIỆU ĐẦU VÀO – ĐIỀU TIẾT TOÀN CHUỖI HỒ CÀ GIÂY
A2: Ô nền vàng chữ xanh: được sửa để thử. Chữ xanh: số liệu gốc hồ sơ. Chữ đen: công thức. Dung tích: 10⁶ m³ (triệu m³).
A4: A. THÔNG SỐ TÍNH TOÁN | B4: Giá trị | C4: Đơn vị | D4: Ghi chú, nguồn
A5: Trường hợp dùng nước (chọn TH1 / TH1A / TH2) | B5: TH1A | D5: Mặc định TH1A – trường hợp sát yêu cầu nhất (39/44 năm). Mô tả từng trường hợp ở mục C.
A6: Mực nước chết MNC | B6: 67.5 | C6: m | D6: Giữ như thiết kế; kiểm tra bồi lắng, lấy nước theo TCVN 10778:2024 mục 7 (thuyết minh 2.2.1)
A7: Mực nước dâng bình thường MNDBT | B7: 74.7 | C7: m | D7: Bằng cao trình ngưỡng tràn chính
A8: Tổn thất thấm lòng hồ k_t | B8: 0.01 | C8: /tháng | D8: Phần trăm dung tích bình quân tháng; TCVN 10778:2024 Bảng 1: 0,5 ÷ 1,0%/tháng (địa chất lòng hồ tốt) – đồ án lấy 1%
A9: Mức bảo đảm cấp nước thiết kế P_tk | B9: 0.85 | D9: Công trình cấp II (thuyết minh 1.1.3). TH1A tính chung tưới 85% + sinh hoạt 90% theo trọng số: 85,15% (TCVN 10778:2024 mục 8.2.2.2) – vẫn cần 39 năm
A10: Dung tích chết Vc = V(MNC) | B10: =((INDEX(BT_V,MATCH(Z_MNC,BT_Z,1)+1)-INDEX(BT_V,MATCH(Z_MNC,BT_Z,1)))/(INDEX(BT_Z,MATCH(Z_MNC,BT_Z,1)+1)-INDEX(BT_Z,MATCH(Z_MNC,BT_Z,1))))*(Z_MNC-INDEX(BT_Z,MATCH(Z_MNC,BT_Z,1)))+INDEX(BT_V,MATCH(Z_MNC,BT_Z,1)) -> 6.8162437 | C10: 10⁶ m³ | D10: Tra bảng V ~ Z bình đồ 2022 (sheet BangTraZV). Thiết kế ban đầu: 8,41 (chỉ để so sánh)
A11: Dung tích ứng với MNDBT Vbt = V(MNDBT) | B11: =((INDEX(BT_V,MATCH(Z_MNDBT,BT_Z,1)+1)-INDEX(BT_V,MATCH(Z_MNDBT,BT_Z,1)))/(INDEX(BT_Z,MATCH(Z_MNDBT,BT_Z,1)+1)-INDEX(BT_Z,MATCH(Z_MNDBT,BT_Z,1))))*(Z_MNDBT-INDEX(BT_Z,MATCH(Z_MNDBT,BT_Z,1)))+INDEX(BT_V,MATCH(Z_MNDBT,BT_Z,1)) -> 36.411691 | C11: 10⁶ m³ | D11: Thiết kế ban đầu: 37,24
A12: Dung tích hữu ích Vhi = Vbt − Vc | B12: =B11-B10 -> 29.595448 | C12: 10⁶ m³ | D12: Thiết kế ban đầu: 28,83
A13: Số năm của chuỗi dòng chảy n | B13: =COUNTA(Nam_lbl) -> 44 | D13: Đếm số năm trong bảng dòng chảy (mục E)
A15: B. TỔN THẤT BỐC HƠI PHỤ THÊM ΔZ (mm) – QTVH Bảng 3-24
A16: Tháng | B16: 1 | C16: 2 | D16: 3 | E16: 4 | F16: 5 | G16: 6 | H16: 7 | I16: 8 | J16: 9 | K16: 10 | L16: 11 | M16: 12 | N16: Cả năm
A17: ΔZ (mm) | B17: 68.4 | C17: 64.4 | D17: 76.9 | E17: 66.6 | F17: 62.3 | G17: 55.1 | H17: 49.8 | I17: 51.8 | J17: 43.9 | K17: 40.8 | L17: 52.2 | M17: 66.7 | N17: =SUM(B17:M17) -> 698.9
A19: C. NHU CẦU DÙNG NƯỚC TỔNG (tưới + sinh hoạt), 10⁶ m³/tháng – QTVH Bảng 4-20 ÷ 4-22
A20: Trường hợp | B20: 1 | C20: 2 | D20: 3 | E20: 4 | F20: 5 | G20: 6 | H20: 7 | I20: 8 | J20: 9 | K20: 10 | L20: 11 | M20: 12 | N20: Cả năm | O20: Nội dung
A21: TH1 | B21: 9.8 | C21: 11.93 | D21: 11.22 | E21: 17.62 | F21: 7.04 | G21: 10.13 | H21: 5.73 | I21: 9.91 | J21: 3.62 | K21: 3.2 | L21: 11.75 | M21: 20.19 | N21: =SUM(B21:M21) -> 122.14 | O21: Tưới 8.965 ha theo nhiệm vụ thiết kế, 100% cây trồng cạn tưới truyền thống + sinh hoạt (QTVH Bảng 4-20); trong đó sinh hoạt 3,22 triệu m³/năm
A22: TH1A | B22: 13.27 | C22: 10.48 | D22: 9.37 | E22: 14.2 | F22: 5.92 | G22: 8.31 | H22: 5.59 | I22: 8.9 | J22: 2.57 | K22: 2.99 | L22: 9.5 | M22: 15.54 | N22: =SUM(B22:M22) -> 106.64 | O22: Tưới 8.965 ha, 50% diện tích cây trồng cạn tưới tiết kiệm + sinh hoạt (QTVH Bảng 4-21); trong đó sinh hoạt 3,22 triệu m³/năm
A23: TH2 | B23: 13.48 | C23: 10.69 | D23: 9.61 | E23: 14.44 | F23: 5.94 | G23: 8.31 | H23: 5.59 | I23: 8.9 | J23: 2.57 | K23: 2.99 | L23: 9.5 | M23: 15.54 | N23: =SUM(B23:M23) -> 107.56 | O23: Tưới tiềm năng 9.540 ha, 50% cây trồng cạn tưới tiết kiệm + sinh hoạt (QTVH Bảng 4-22); trong đó sinh hoạt 3,22 triệu m³/năm
A24: → Trường hợp đang chọn | B24: =INDEX(B$21:B$23,MATCH(TH_chon,$A$21:$A$23,0)) -> 13.27 | C24: =INDEX(C$21:C$23,MATCH(TH_chon,$A$21:$A$23,0)) -> 10.48 | D24: =INDEX(D$21:D$23,MATCH(TH_chon,$A$21:$A$23,0)) -> 9.37 | E24: =INDEX(E$21:E$23,MATCH(TH_chon,$A$21:$A$23,0)) -> 14.2 | F24: =INDEX(F$21:F$23,MATCH(TH_chon,$A$21:$A$23,0)) -> 5.92 | G24: =INDEX(G$21:G$23,MATCH(TH_chon,$A$21:$A$23,0)) -> 8.31 | H24: =INDEX(H$21:H$23,MATCH(TH_chon,$A$21:$A$23,0)) -> 5.59 | I24: =INDEX(I$21:I$23,MATCH(TH_chon,$A$21:$A$23,0)) -> 8.9 | ... M24: =INDEX(M$21:M$23,MATCH(TH_chon,$A$21:$A$23,0)) -> 15.54 | N24: =SUM(B24:M24) -> 106.64 | O24: =TH_chon -> TH1A
A26: D. QUAN HỆ Z ~ F ~ W LÒNG HỒ – BÌNH ĐỒ KHẢO SÁT 2022 (QTVH Bảng 1-2; BCNCKT mục 2.1.2)
A27: Z (m) | B27: F (km²) | C27: W hồ sơ | D27: W tính lại từ F | E27: Lệch (hồ sơ − tính lại) | F27: Ghi chú
A28: 59 | B28: 0 | C28: 0 | D28: =0 -> 0 | E28: =C28-D28 -> 0 | F28: Cột F trong hồ sơ ghi đơn vị “ha” nhưng đúng là km² (TKCS Hình 1-1; hồ 37 triệu m³ không thể có mặt hồ vài ha).
A29: 60 | B29: 0.09 | C29: 0.03 | D29: =D28+(A29-A28)/3*(B28+B29+SQRT(B28*B29)) -> 0.03 | E29: =C29-D29 -> 0 | F29: W tính lại theo công thức hình chóp cụt: ΔW = ΔZ/3·(F₁ + F₂ + √(F₁·F₂)) (thuyết minh công thức (1-1)).
A30: 61 | B30: 0.21 | C30: 0.17 | D30: =D29+(A30-A29)/3*(B29+B30+SQRT(B29*B30)) -> 0.17582576 | E30: =C30-D30 -> -0.0058257569 | F30: Dưới +69 m cột W hồ sơ khớp W tính lại (lệch ≤ 0,01) → V(MNC) = 6,82 chắc chắn.
A31: 62 | B31: 0.4 | C31: 0.47 | D31: =D30+(A31-A30)/3*(B30+B31+SQRT(B30*B31)) -> 0.47576827 | E31: =C31-D31 -> -0.0057682686 | F31: Từ +70 m trở lên cột W hồ sơ tăng giảm thất thường, không khớp cột F → đồ án dùng W tính lại từ F.
A32: 63 | B32: 0.62 | C32: 0.98 | D32: =D31+(A32-A31)/3*(B31+B32+SQRT(B31*B32)) -> 0.98176693 | E32: =C32-D32 -> -0.0017669299 | F32: Khi tính, chương trình dùng bảng chi tiết 0,01 m (sheet BangTraZV) để nội suy chính xác hơn bảng 1 m này.
A33: 64 | B33: 0.87 | C33: 1.72 | D33: =D32+(A33-A32)/3*(B32+B33+SQRT(B32*B33)) -> 1.7232465 | E33: =C33-D33 -> -0.0032464503 | F33: Đáy hồ thấp nhất trên bình đồ 2022 ở khoảng +59 m.
A34: 65 | B34: 1.16 | C34: 2.74 | D34: =D33+(A34-A33)/3*(B33+B34+SQRT(B33*B34)) -> 2.7347763 | E34: =C34-D34 -> 0.0052237269
A35: 66 | B35: 1.48 | C35: 4.06 | D35: =D34+(A35-A34)/3*(B34+B35+SQRT(B34*B35)) -> 4.051532 | E35: =C35-D35 -> 0.0084680108
A36: 67 | B36: 1.92 | C36: 5.75 | D36: =D35+(A36-A35)/3*(B35+B36+SQRT(B35*B36)) -> 5.7467669 | E36: =C36-D36 -> 0.003233144
A37: 68 | B37: 2.45 | C37: 7.93 | D37: =D36+(A37-A36)/3*(B36+B37+SQRT(B36*B37)) -> 7.9263904 | E37: =C37-D37 -> 0.0036095861
A38: 69 | B38: 2.94 | C38: 10.63 | D38: =D37+(A38-A37)/3*(B37+B38+SQRT(B37*B38)) -> 10.617671 | E38: =C38-D38 -> 0.012329409
A39: 70 | B39: 3.45 | C39: 14.89 | D39: =D38+(A39-A38)/3*(B38+B39+SQRT(B38*B39)) -> 13.809273 | E39: =C39-D39 -> 1.0807268
A40: 71 | B40: 3.95 | C40: 17.7 | D40: =D39+(A40-A39)/3*(B39+B40+SQRT(B39*B40)) -> 17.506455 | E40: =C40-D40 -> 0.19354538
A41: 72 | B41: 4.55 | C41: 23.14 | D41: =D40+(A41-A40)/3*(B40+B41+SQRT(B40*B41)) -> 21.752921 | E41: =C41-D41 -> 1.3870792
A42: 73 | B42: 5.2 | C42: 28.63 | D42: =D41+(A42-A41)/3*(B41+B42+SQRT(B41*B42)) -> 26.624306 | E42: =C42-D42 -> 2.0056943
A43: 74 | B43: 5.8 | C43: 34.14 | D43: =D42+(A43-A42)/3*(B42+B43+SQRT(B42*B43)) -> 32.121576 | E43: =C43-D43 -> 2.0184236
A44: 75 | B44: 6.46 | C44: 39.68 | D44: =D43+(A44-A43)/3*(B43+B44+SQRT(B43*B44)) -> 38.248613 | E44: =C44-D44 -> 1.4313866
...

Sheet BangTraZV
A1: BẢNG TRA Z ~ F ~ V CHI TIẾT (bước 0,01 m)
A2: F nội suy tuyến tính từ bảng 1 m (SoLieu mục D); V cộng dồn theo chóp cụt ΔV = ΔZ/3·(F₁ + F₂ + √(F₁F₂)) – giống chương trình so_lieu.py của đồ án.
A4: Z (m) | B4: F (km²) | C4: V (10⁶ m³) | E4: Cách tra (nội suy tuyến tính)
A5: 59 | B5: =IF(A5>=MAX(Bang_Z),INDEX(Bang_F,ROWS(Bang_F)),((INDEX(Bang_F,MATCH(A5,Bang_Z,1)+1)-INDEX(Bang_F,MATCH(A5,Bang_Z,1)))/(INDEX(Bang_Z,MATCH(A5,Bang_Z,1)+1)-INDEX(Bang_Z,MATCH(A5,Bang_Z,1))))*(A5-INDEX(Bang_Z,MATCH(A5,Bang_Z,1)))+INDEX(Bang_F,MATCH(A5,Bang_Z,1))) -> 0 | C5: 0 | E5: Biết Z, tìm V: tìm dòng có Z_k ≤ Z < Z_k+1 (hàm MATCH), V = V_k + (Z − Z_k)·(V_k+1 − V_k)/(Z_k+1 − Z_k).
A6: =ROUND(A5+0.01,2) -> 59.01 | B6: =IF(A6>=MAX(Bang_Z),INDEX(Bang_F,ROWS(Bang_F)),((INDEX(Bang_F,MATCH(A6,Bang_Z,1)+1)-INDEX(Bang_F,MATCH(A6,Bang_Z,1)))/(INDEX(Bang_Z,MATCH(A6,Bang_Z,1)+1)-INDEX(Bang_Z,MATCH(A6,Bang_Z,1))))*(A6-INDEX(Bang_Z,MATCH(A6,Bang_Z,1)))+INDEX(Bang_F,MATCH(A6,Bang_Z,1))) -> 0.0009 | C6: =C5+(A6-A5)/3*(B5+B6+SQRT(B5*B6)) -> 3e-06 | E6: Biết V, tìm Z: tương tự, đổi vai Z và V. Ví dụ: Vc = V(+67,50) = 6,816 triệu m³; Vbt = V(+74,70) = 36,412 triệu m³.
A7: =ROUND(A6+0.01,2) -> 59.02 | B7: =IF(A7>=MAX(Bang_Z),INDEX(Bang_F,ROWS(Bang_F)),((INDEX(Bang_F,MATCH(A7,Bang_Z,1)+1)-INDEX(Bang_F,MATCH(A7,Bang_Z,1)))/(INDEX(Bang_Z,MATCH(A7,Bang_Z,1)+1)-INDEX(Bang_Z,MATCH(A7,Bang_Z,1))))*(A7-INDEX(Bang_Z,MATCH(A7,Bang_Z,1)))+INDEX(Bang_F,MATCH(A7,Bang_Z,1))) -> 0.0018 | C7: =C6+(A7-A6)/3*(B6+B7+SQRT(B6*B7)) -> 1.6242641e-05 | E7: F(Z) lấy từ bảng 1 m của SoLieu mục D (nội suy tuyến tính) – dùng để tính tổn thất bốc hơi.
A8: =ROUND(A7+0.01,2) -> 59.03 | B8: =IF(A8>=MAX(Bang_Z),INDEX(Bang_F,ROWS(Bang_F)),((INDEX(Bang_F,MATCH(A8,Bang_Z,1)+1)-INDEX(Bang_F,MATCH(A8,Bang_Z,1)))/(INDEX(Bang_Z,MATCH(A8,Bang_Z,1)+1)-INDEX(Bang_Z,MATCH(A8,Bang_Z,1))))*(A8-INDEX(Bang_Z,MATCH(A8,Bang_Z,1)))+INDEX(Bang_F,MATCH(A8,Bang_Z,1))) -> 0.0027 | C8: =C7+(A8-A7)/3*(B7+B8+SQRT(B7*B8)) -> 3.859111e-05
A9: =ROUND(A8+0.01,2) -> 59.04 | B9: =IF(A9>=MAX(Bang_Z),INDEX(Bang_F,ROWS(Bang_F)),((INDEX(Bang_F,MATCH(A9,Bang_Z,1)+1)-INDEX(Bang_F,MATCH(A9,Bang_Z,1)))/(INDEX(Bang_Z,MATCH(A9,Bang_Z,1)+1)-INDEX(Bang_Z,MATCH(A9,Bang_Z,1))))*(A9-INDEX(Bang_Z,MATCH(A9,Bang_Z,1)))+INDEX(Bang_F,MATCH(A9,Bang_Z,1))) -> 0.0036 | C9: =C8+(A9-A8)/3*(B8+B9+SQRT(B8*B9)) -> 6.9983415e-05
A10: =ROUND(A9+0.01,2) -> 59.05 | B10: =IF(A10>=MAX(Bang_Z),INDEX(Bang_F,ROWS(Bang_F)),((INDEX(Bang_F,MATCH(A10,Bang_Z,1)+1)-INDEX(Bang_F,MATCH(A10,Bang_Z,1)))/(INDEX(Bang_Z,MATCH(A10,Bang_Z,1)+1)-INDEX(Bang_Z,MATCH(A10,Bang_Z,1))))*(A10-INDEX(Bang_Z,MATCH(A10,Bang_Z,1)))+INDEX(Bang_F,MATCH(A10,Bang_Z,1))) -> 0.0045 | C10: =C9+(A10-A9)/3*(B9+B10+SQRT(B9*B10)) -> 0.00011039982
A11: =ROUND(A10+0.01,2) -> 59.06 | B11: =IF(A11>=MAX(Bang_Z),INDEX(Bang_F,ROWS(Bang_F)),((INDEX(Bang_F,MATCH(A11,Bang_Z,1)+1)-INDEX(Bang_F,MATCH(A11,Bang_Z,1)))/(INDEX(Bang_Z,MATCH(A11,Bang_Z,1)+1)-INDEX(Bang_Z,MATCH(A11,Bang_Z,1))))*(A11-INDEX(Bang_Z,MATCH(A11,Bang_Z,1)))+INDEX(Bang_F,MATCH(A11,Bang_Z,1))) -> 0.0054 | C11: =C10+(A11-A10)/3*(B10+B11+SQRT(B10*B11)) -> 0.0001598315
A12: =ROUND(A11+0.01,2) -> 59.07 | B12: =IF(A12>=MAX(Bang_Z),INDEX(Bang_F,ROWS(Bang_F)),((INDEX(Bang_F,MATCH(A12,Bang_Z,1)+1)-INDEX(Bang_F,MATCH(A12,Bang_Z,1)))/(INDEX(Bang_Z,MATCH(A12,Bang_Z,1)+1)-INDEX(Bang_Z,MATCH(A12,Bang_Z,1))))*(A12-INDEX(Bang_Z,MATCH(A12,Bang_Z,1)))+INDEX(Bang_F,MATCH(A12,Bang_Z,1))) -> 0.0063 | C12: =C11+(A12-A11)/3*(B11+B12+SQRT(B11*B12)) -> 0.00021827372
A13: =ROUND(A12+0.01,2) -> 59.08 | B13: =IF(A13>=MAX(Bang_Z),INDEX(Bang_F,ROWS(Bang_F)),((INDEX(Bang_F,MATCH(A13,Bang_Z,1)+1)-INDEX(Bang_F,MATCH(A13,Bang_Z,1)))/(INDEX(Bang_Z,MATCH(A13,Bang_Z,1)+1)-INDEX(Bang_Z,MATCH(A13,Bang_Z,1))))*(A13-INDEX(Bang_Z,MATCH(A13,Bang_Z,1)))+INDEX(Bang_F,MATCH(A13,Bang_Z,1))) -> 0.0072 | C13: =C12+(A13-A12)/3*(B12+B13+SQRT(B12*B13)) -> 0.00028572367
A14: =ROUND(A13+0.01,2) -> 59.09 | B14: =IF(A14>=MAX(Bang_Z),INDEX(Bang_F,ROWS(Bang_F)),((INDEX(Bang_F,MATCH(A14,Bang_Z,1)+1)-INDEX(Bang_F,MATCH(A14,Bang_Z,1)))/(INDEX(Bang_Z,MATCH(A14,Bang_Z,1)+1)-INDEX(Bang_Z,MATCH(A14,Bang_Z,1))))*(A14-INDEX(Bang_Z,MATCH(A14,Bang_Z,1)))+INDEX(Bang_F,MATCH(A14,Bang_Z,1))) -> 0.0081 | C14: =C13+(A14-A13)/3*(B13+B14+SQRT(B13*B14)) -> 0.00036217951
A15: =ROUND(A14+0.01,2) -> 59.1 | B15: =IF(A15>=MAX(Bang_Z),INDEX(Bang_F,ROWS(Bang_F)),((INDEX(Bang_F,MATCH(A15,Bang_Z,1)+1)-INDEX(Bang_F,MATCH(A15,Bang_Z,1)))/(INDEX(Bang_Z,MATCH(A15,Bang_Z,1)+1)-INDEX(Bang_Z,MATCH(A15,Bang_Z,1))))*(A15-INDEX(Bang_Z,MATCH(A15,Bang_Z,1)))+INDEX(Bang_F,MATCH(A15,Bang_Z,1))) -> 0.009 | C15: =C14+(A15-A14)/3*(B14+B15+SQRT(B14*B15)) -> 0.00044764001
A16: =ROUND(A15+0.01,2) -> 59.11 | B16: =IF(A16>=MAX(Bang_Z),INDEX(Bang_F,ROWS(Bang_F)),((INDEX(Bang_F,MATCH(A16,Bang_Z,1)+1)-INDEX(Bang_F,MATCH(A16,Bang_Z,1)))/(INDEX(Bang_Z,MATCH(A16,Bang_Z,1)+1)-INDEX(Bang_Z,MATCH(A16,Bang_Z,1))))*(A16-INDEX(Bang_Z,MATCH(A16,Bang_Z,1)))+INDEX(Bang_F,MATCH(A16,Bang_Z,1))) -> 0.0099 | C16: =C15+(A16-A15)/3*(B15+B16+SQRT(B15*B16)) -> 0.00054210427
A17: =ROUND(A16+0.01,2) -> 59.12 | B17: =IF(A17>=MAX(Bang_Z),INDEX(Bang_F,ROWS(Bang_F)),((INDEX(Bang_F,MATCH(A17,Bang_Z,1)+1)-INDEX(Bang_F,MATCH(A17,Bang_Z,1)))/(INDEX(Bang_Z,MATCH(A17,Bang_Z,1)+1)-INDEX(Bang_Z,MATCH(A17,Bang_Z,1))))*(A17-INDEX(Bang_Z,MATCH(A17,Bang_Z,1)))+INDEX(Bang_F,MATCH(A17,Bang_Z,1))) -> 0.0108 | C17: =C16+(A17-A16)/3*(B16+B17+SQRT(B16*B17)) -> 0.00064557165
A18: =ROUND(A17+0.01,2) -> 59.13 | B18: =IF(A18>=MAX(Bang_Z),INDEX(Bang_F,ROWS(Bang_F)),((INDEX(Bang_F,MATCH(A18,Bang_Z,1)+1)-INDEX(Bang_F,MATCH(A18,Bang_Z,1)))/(INDEX(Bang_Z,MATCH(A18,Bang_Z,1)+1)-INDEX(Bang_Z,MATCH(A18,Bang_Z,1))))*(A18-INDEX(Bang_Z,MATCH(A18,Bang_Z,1)))+INDEX(Bang_F,MATCH(A18,Bang_Z,1))) -> 0.0117 | C18: =C17+(A18-A17)/3*(B17+B18+SQRT(B17*B18)) -> 0.00075804164
A19: =ROUND(A18+0.01,2) -> 59.14 | B19: =IF(A19>=MAX(Bang_Z),INDEX(Bang_F,ROWS(Bang_F)),((INDEX(Bang_F,MATCH(A19,Bang_Z,1)+1)-INDEX(Bang_F,MATCH(A19,Bang_Z,1)))/(INDEX(Bang_Z,MATCH(A19,Bang_Z,1)+1)-INDEX(Bang_Z,MATCH(A19,Bang_Z,1))))*(A19-INDEX(Bang_Z,MATCH(A19,Bang_Z,1)))+INDEX(Bang_F,MATCH(A19,Bang_Z,1))) -> 0.0126 | C19: =C18+(A19-A18)/3*(B18+B19+SQRT(B18*B19)) -> 0.00087951385
... A2605: =ROUND(A2604+0.01,2) -> 85 | B2605: =IF(A2605>=MAX(Bang_Z),INDEX(Bang_F,ROWS(Bang_F)),((INDEX(Bang_F,MATCH(A2605,Bang_Z,1)+1)-INDEX(Bang_F,MATCH(A2605,Bang_Z,1)))/(INDEX(Bang_Z,MATCH(A2605,Bang_Z,1)+1)-INDEX(Bang_Z,MATCH(A2605,Bang_Z,1))))*(A2605-INDEX(Bang_Z,MATCH(A2605,Bang_Z,1)))+INDEX(Bang_F,MATCH(A2605,Bang_Z,1))) -> 12.95 | C2605: =C2604+(A2605-A2604)/3*(B2604+B2605+SQRT(B2604*B2605)) -> 131.45499

Sheet DieuTiet
A1: ĐIỀU TIẾT TOÀN CHUỖI THEO THÁNG – 44 NĂM × 12 THÁNG = 528 THÁNG
A2: Trường hợp | C2: =TH_chon -> TH1A | D2: Vc = | E2: =V_chet -> 6.8162437 | F2: Vbt = | G2: =V_bt -> 36.411691 | H2: k_t = | I2: =k_tham -> 0.01 | J2: ← đổi ở sheet SoLieu. Dòng nền đỏ: tháng thiếu nước.
A3: SỐ LIỆU THÁNG | H3: LẦN LẶP 1 – giả thiết Vtb = V đầu tháng | N3: LẦN LẶP 2 – Vtb = (V đầu + V′₁)/2 | T3: LẦN LẶP 3 – Vtb = (V đầu + V′₂)/2 | Z3: KẾT QUẢ THÁNG
A4: TT tháng | B4: Năm | C4: Tháng | D4: W đến (10⁶ m³) | E4: W dùng (10⁶ m³) | F4: ΔZ bốc hơi (m) | G4: V đầu tháng (10⁶ m³) | H4: Vtb₁ = V đầu | I4: Ztb₁ (m) tra V~Z | J4: F₁ (km²) | K4: W bh₁ = ΔZ·F₁ | L4: W thấm₁ = k_t·Vtb₁ | M4: V′₁ = V đầu + W đến − W dùng − W bh₁ − W thấm₁ | N4: Vtb₂ = (V đầu + V′₁*)/2 | O4: Ztb₂ (m) | P4: F₂ (km²) | Q4: W bh₂ | R4: W thấm₂ | S4: V′₂ | T4: Vtb₃ = (V đầu + V′₂*)/2 | U4: Ztb₃ (m) | V4: F₃ (km²) | W4: W bh₃ | X4: W thấm₃ | Y4: V′₃ (kết quả lặp) | Z4: W xả thừa = max(V′₃ − Vbt; 0) | AA4: W thiếu = max(Vc − V′₃; 0) | AB4: V cuối tháng (giới hạn Vc ÷ Vbt) | AC4: Z cuối tháng (m) | AD4: Tháng thiếu (1 = có)
A5: 1 | B5: =INDEX(Nam_lbl,INT((A5-1)/12)+1) -> 1981-1982 | C5: =MOD(A5-1,12)+1 -> 1 | D5: =INDEX(DongChay,INT((A5-1)/12)+1,C5) -> 10.29 | E5: =INDEX(NhuCau_chon,1,C5) -> 13.27 | F5: =INDEX(BocHoi,1,C5)/1000 -> 0.0684 | G5: =V_bt -> 36.411691 | H5: =G5 -> 36.411691 | I5: =((INDEX(BT_Z,MATCH(H5,BT_V,1)+1)-INDEX(BT_Z,MATCH(H5,BT_V,1)))/(INDEX(BT_V,MATCH(H5,BT_V,1)+1)-INDEX(BT_V,MATCH(H5,BT_V,1))))*(H5-INDEX(BT_V,MATCH(H5,BT_V,1)))+INDEX(BT_Z,MATCH(H5,BT_V,1)) -> 74.7 | J5: =((INDEX(Bang_F,MATCH(I5,Bang_Z,1)+1)-INDEX(Bang_F,MATCH(I5,Bang_Z,1)))/(INDEX(Bang_Z,MATCH(I5,Bang_Z,1)+1)-INDEX(Bang_Z,MATCH(I5,Bang_Z,1))))*(I5-INDEX(Bang_Z,MATCH(I5,Bang_Z,1)))+INDEX(Bang_F,MATCH(I5,Bang_Z,1)) -> 6.262 | K5: =F5*J5 -> 0.4283208 | L5: =k_tham*H5 -> 0.36411691 | M5: =G5+D5-E5-K5-L5 -> 32.639253 | N5: =(G5+MIN(MAX(M5,V_chet),V_bt))/2 -> 34.525472 | O5: =((INDEX(BT_Z,MATCH(N5,BT_V,1)+1)-INDEX(BT_Z,MATCH(N5,BT_V,1)))/(INDEX(BT_V,MATCH(N5,BT_V,1)+1)-INDEX(BT_V,MATCH(N5,BT_V,1))))*(N5-INDEX(BT_V,MATCH(N5,BT_V,1)))+INDEX(BT_Z,MATCH(N5,BT_V,1)) -> 74.393842 | P5: =((INDEX(Bang_F,MATCH(O5,Bang_Z,1)+1)-INDEX(Bang_F,MATCH(O5,Bang_Z,1)))/(INDEX(Bang_Z,MATCH(O5,Bang_Z,1)+1)-INDEX(Bang_Z,MATCH(O5,Bang_Z,1))))*(O5-INDEX(Bang_Z,MATCH(O5,Bang_Z,1)))+INDEX(Bang_F,MATCH(O5,Bang_Z,1)) -> 6.059936 | Q5: =F5*P5 -> 0.41449962 | R5: =k_tham*N5 -> 0.34525472 | S5: =G5+D5-E5-Q5-R5 -> 32.671937 | T5: =(G5+MIN(MAX(S5,V_chet),V_bt))/2 -> 34.541814 | U5: =((INDEX(BT_Z,MATCH(T5,BT_V,1)+1)-INDEX(BT_Z,MATCH(T5,BT_V,1)))/(INDEX(BT_V,MATCH(T5,BT_V,1)+1)-INDEX(BT_V,MATCH(T5,BT_V,1))))*(T5-INDEX(BT_V,MATCH(T5,BT_V,1)))+INDEX(BT_Z,MATCH(T5,BT_V,1)) -> 74.396539 | V5: =((INDEX(Bang_F,MATCH(U5,Bang_Z,1)+1)-INDEX(Bang_F,MATCH(U5,Bang_Z,1)))/(INDEX(Bang_Z,MATCH(U5,Bang_Z,1)+1)-INDEX(Bang_Z,MATCH(U5,Bang_Z,1))))*(U5-INDEX(Bang_Z,MATCH(U5,Bang_Z,1)))+INDEX(Bang_F,MATCH(U5,Bang_Z,1)) -> 6.0617156 | W5: =F5*V5 -> 0.41462135 | X5: =k_tham*T5 -> 0.34541814 | Y5: =G5+D5-E5-W5-X5 -> 32.671652 | Z5: =MAX(Y5-V_bt,0) -> 0 | AA5: =MAX(V_chet-Y5,0) -> 0 | AB5: =MIN(MAX(Y5,V_chet),V_bt) -> 32.671652 | AC5: =((INDEX(BT_Z,MATCH(AB5,BT_V,1)+1)-INDEX(BT_Z,MATCH(AB5,BT_V,1)))/(INDEX(BT_V,MATCH(AB5,BT_V,1)+1)-INDEX(BT_V,MATCH(AB5,BT_V,1))))*(AB5-INDEX(BT_V,MATCH(AB5,BT_V,1)))+INDEX(BT_Z,MATCH(AB5,BT_V,1)) -> 74.082655 | AD5: =IF(AA5>0.000001,1,0) -> 0
A6: 2 | B6: =INDEX(Nam_lbl,INT((A6-1)/12)+1) -> 1981-1982 | C6: =MOD(A6-1,12)+1 -> 2 | D6: =INDEX(DongChay,INT((A6-1)/12)+1,C6) -> 5.35 | E6: =INDEX(NhuCau_chon,1,C6) -> 10.48 | F6: =INDEX(BocHoi,1,C6)/1000 -> 0.0644 | G6: =AB5 -> 32.671652 | H6: =G6 -> 32.671652 | I6: =((INDEX(BT_Z,MATCH(H6,BT_V,1)+1)-INDEX(BT_Z,MATCH(H6,BT_V,1)))/(INDEX(BT_V,MATCH(H6,BT_V,1)+1)-INDEX(BT_V,MATCH(H6,BT_V,1))))*(H6-INDEX(BT_V,MATCH(H6,BT_V,1)))+INDEX(BT_Z,MATCH(H6,BT_V,1)) -> 74.082655 | J6: =((INDEX(Bang_F,MATCH(I6,Bang_Z,1)+1)-INDEX(Bang_F,MATCH(I6,Bang_Z,1)))/(INDEX(Bang_Z,MATCH(I6,Bang_Z,1)+1)-INDEX(Bang_Z,MATCH(I6,Bang_Z,1))))*(I6-INDEX(Bang_Z,MATCH(I6,Bang_Z,1)))+INDEX(Bang_F,MATCH(I6,Bang_Z,1)) -> 5.8545523 | K6: =F6*J6 -> 0.37703317 | L6: =k_tham*H6 -> 0.32671652 | M6: =G6+D6-E6-K6-L6 -> 26.837902 | N6: =(G6+MIN(MAX(M6,V_chet),V_bt))/2 -> 29.754777 | O6: =((INDEX(BT_Z,MATCH(N6,BT_V,1)+1)-INDEX(BT_Z,MATCH(N6,BT_V,1)))/(INDEX(BT_V,MATCH(N6,BT_V,1)+1)-INDEX(BT_V,MATCH(N6,BT_V,1))))*(N6-INDEX(BT_V,MATCH(N6,BT_V,1)))+INDEX(BT_Z,MATCH(N6,BT_V,1)) -> 73.570598 | P6: =((INDEX(Bang_F,MATCH(O6,Bang_Z,1)+1)-INDEX(Bang_F,MATCH(O6,Bang_Z,1)))/(INDEX(Bang_Z,MATCH(O6,Bang_Z,1)+1)-INDEX(Bang_Z,MATCH(O6,Bang_Z,1))))*(O6-INDEX(Bang_Z,MATCH(O6,Bang_Z,1)))+INDEX(Bang_F,MATCH(O6,Bang_Z,1)) -> 5.5423587 | Q6: =F6*P6 -> 0.3569279 | R6: =k_tham*N6 -> 0.29754777 | S6: =G6+D6-E6-Q6-R6 -> 26.887176 | T6: =(G6+MIN(MAX(S6,V_chet),V_bt))/2 -> 29.779414 | U6: =((INDEX(BT_Z,MATCH(T6,BT_V,1)+1)-INDEX(BT_Z,MATCH(T6,BT_V,1)))/(INDEX(BT_V,MATCH(T6,BT_V,1)+1)-INDEX(BT_V,MATCH(T6,BT_V,1))))*(T6-INDEX(BT_V,MATCH(T6,BT_V,1)))+INDEX(BT_Z,MATCH(T6,BT_V,1)) -> 73.575041 | V6: =((INDEX(Bang_F,MATCH(U6,Bang_Z,1)+1)-INDEX(Bang_F,MATCH(U6,Bang_Z,1)))/(INDEX(Bang_Z,MATCH(U6,Bang_Z,1)+1)-INDEX(Bang_Z,MATCH(U6,Bang_Z,1))))*(U6-INDEX(Bang_Z,MATCH(U6,Bang_Z,1)))+INDEX(Bang_F,MATCH(U6,Bang_Z,1)) -> 5.5450246 | W6: =F6*V6 -> 0.35709958 | X6: =k_tham*T6 -> 0.29779414 | Y6: =G6+D6-E6-W6-X6 -> 26.886758 | Z6: =MAX(Y6-V_bt,0) -> 0 | AA6: =MAX(V_chet-Y6,0) -> 0 | AB6: =MIN(MAX(Y6,V_chet),V_bt) -> 26.886758 | AC6: =((INDEX(BT_Z,MATCH(AB6,BT_V,1)+1)-INDEX(BT_Z,MATCH(AB6,BT_V,1)))/(INDEX(BT_V,MATCH(AB6,BT_V,1)+1)-INDEX(BT_V,MATCH(AB6,BT_V,1))))*(AB6-INDEX(BT_V,MATCH(AB6,BT_V,1)))+INDEX(BT_Z,MATCH(AB6,BT_V,1)) -> 73.037756 | AD6: =IF(AA6>0.000001,1,0) -> 0
A7: 3 | B7: =INDEX(Nam_lbl,INT((A7-1)/12)+1) -> 1981-1982 | C7: =MOD(A7-1,12)+1 -> 3 | D7: =INDEX(DongChay,INT((A7-1)/12)+1,C7) -> 4.54 | E7: =INDEX(NhuCau_chon,1,C7) -> 9.37 | F7: =INDEX(BocHoi,1,C7)/1000 -> 0.0769 | G7: =AB6 -> 26.886758 | H7: =G7 -> 26.886758 | I7: =((INDEX(BT_Z,MATCH(H7,BT_V,1)+1)-INDEX(BT_Z,MATCH(H7,BT_V,1)))/(INDEX(BT_V,MATCH(H7,BT_V,1)+1)-INDEX(BT_V,MATCH(H7,BT_V,1))))*(H7-INDEX(BT_V,MATCH(H7,BT_V,1)))+INDEX(BT_Z,MATCH(H7,BT_V,1)) -> 73.037756 | J7: =((INDEX(Bang_F,MATCH(I7,Bang_Z,1)+1)-INDEX(Bang_F,MATCH(I7,Bang_Z,1)))/(INDEX(Bang_Z,MATCH(I7,Bang_Z,1)+1)-INDEX(Bang_Z,MATCH(I7,Bang_Z,1))))*(I7-INDEX(Bang_Z,MATCH(I7,Bang_Z,1)))+INDEX(Bang_F,MATCH(I7,Bang_Z,1)) -> 5.2226539 | K7: =F7*J7 -> 0.40162208 | L7: =k_tham*H7 -> 0.26886758 | M7: =G7+D7-E7-K7-L7 -> 21.386268 | N7: =(G7+MIN(MAX(M7,V_chet),V_bt))/2 -> 24.136513 | O7: =((INDEX(BT_Z,MATCH(N7,BT_V,1)+1)-INDEX(BT_Z,MATCH(N7,BT_V,1)))/(INDEX(BT_V,MATCH(N7,BT_V,1)+1)-INDEX(BT_V,MATCH(N7,BT_V,1))))*(N7-INDEX(BT_V,MATCH(N7,BT_V,1)))+INDEX(BT_Z,MATCH(N7,BT_V,1)) -> 72.492871 | P7: =((INDEX(Bang_F,MATCH(O7,Bang_Z,1)+1)-INDEX(Bang_F,MATCH(O7,Bang_Z,1)))/(INDEX(Bang_Z,MATCH(O7,Bang_Z,1)+1)-INDEX(Bang_Z,MATCH(O7,Bang_Z,1))))*(O7-INDEX(Bang_Z,MATCH(O7,Bang_Z,1)))+INDEX(Bang_F,MATCH(O7,Bang_Z,1)) -> 4.8703664 | Q7: =F7*P7 -> 0.37453118 | R7: =k_tham*N7 -> 0.24136513 | S7: =G7+D7-E7-Q7-R7 -> 21.440862 | T7: =(G7+MIN(MAX(S7,V_chet),V_bt))/2 -> 24.16381 | U7: =((INDEX(BT_Z,MATCH(T7,BT_V,1)+1)-INDEX(BT_Z,MATCH(T7,BT_V,1)))/(INDEX(BT_V,MATCH(T7,BT_V,1)+1)-INDEX(BT_V,MATCH(T7,BT_V,1))))*(T7-INDEX(BT_V,MATCH(T7,BT_V,1)))+INDEX(BT_Z,MATCH(T7,BT_V,1)) -> 72.498474 | V7: =((INDEX(Bang_F,MATCH(U7,Bang_Z,1)+1)-INDEX(Bang_F,MATCH(U7,Bang_Z,1)))/(INDEX(Bang_Z,MATCH(U7,Bang_Z,1)+1)-INDEX(Bang_Z,MATCH(U7,Bang_Z,1))))*(U7-INDEX(Bang_Z,MATCH(U7,Bang_Z,1)))+INDEX(Bang_F,MATCH(U7,Bang_Z,1)) -> 4.8740084 | W7: =F7*V7 -> 0.37481125 | X7: =k_tham*T7 -> 0.2416381 | Y7: =G7+D7-E7-W7-X7 -> 21.440309 | Z7: =MAX(Y7-V_bt,0) -> 0 | AA7: =MAX(V_chet-Y7,0) -> 0 | AB7: =MIN(MAX(Y7,V_chet),V_bt) -> 21.440309 | AC7: =((INDEX(BT_Z,MATCH(AB7,BT_V,1)+1)-INDEX(BT_Z,MATCH(AB7,BT_V,1)))/(INDEX(BT_V,MATCH(AB7,BT_V,1)+1)-INDEX(BT_V,MATCH(AB7,BT_V,1))))*(AB7-INDEX(BT_V,MATCH(AB7,BT_V,1)))+INDEX(BT_Z,MATCH(AB7,BT_V,1)) -> 71.917199 | AD7: =IF(AA7>0.000001,1,0) -> 0
A8: 4 | B8: =INDEX(Nam_lbl,INT((A8-1)/12)+1) -> 1981-1982 | C8: =MOD(A8-1,12)+1 -> 4 | D8: =INDEX(DongChay,INT((A8-1)/12)+1,C8) -> 8.22 | E8: =INDEX(NhuCau_chon,1,C8) -> 14.2 | F8: =INDEX(BocHoi,1,C8)/1000 -> 0.0666 | G8: =AB7 -> 21.440309 | H8: =G8 -> 21.440309 | I8: =((INDEX(BT_Z,MATCH(H8,BT_V,1)+1)-INDEX(BT_Z,MATCH(H8,BT_V,1)))/(INDEX(BT_V,MATCH(H8,BT_V,1)+1)-INDEX(BT_V,MATCH(H8,BT_V,1))))*(H8-INDEX(BT_V,MATCH(H8,BT_V,1)))+INDEX(BT_Z,MATCH(H8,BT_V,1)) -> 71.917199 | J8: =((INDEX(Bang_F,MATCH(I8,Bang_Z,1)+1)-INDEX(Bang_F,MATCH(I8,Bang_Z,1)))/(INDEX(Bang_Z,MATCH(I8,Bang_Z,1)+1)-INDEX(Bang_Z,MATCH(I8,Bang_Z,1))))*(I8-INDEX(Bang_Z,MATCH(I8,Bang_Z,1)))+INDEX(Bang_F,MATCH(I8,Bang_Z,1)) -> 4.5003192 | K8: =F8*J8 -> 0.29972126 | L8: =k_tham*H8 -> 0.21440309 | M8: =G8+D8-E8-K8-L8 -> 14.946184 | N8: =(G8+MIN(MAX(M8,V_chet),V_bt))/2 -> 18.193246 | O8: =((INDEX(BT_Z,MATCH(N8,BT_V,1)+1)-INDEX(BT_Z,MATCH(N8,BT_V,1)))/(INDEX(BT_V,MATCH(N8,BT_V,1)+1)-INDEX(BT_V,MATCH(N8,BT_V,1))))*(N8-INDEX(BT_V,MATCH(N8,BT_V,1)))+INDEX(BT_Z,MATCH(N8,BT_V,1)) -> 71.157174 | P8: =((INDEX(Bang_F,MATCH(O8,Bang_Z,1)+1)-INDEX(Bang_F,MATCH(O8,Bang_Z,1)))/(INDEX(Bang_Z,MATCH(O8,Bang_Z,1)+1)-INDEX(Bang_Z,MATCH(O8,Bang_Z,1))))*(O8-INDEX(Bang_Z,MATCH(O8,Bang_Z,1)))+INDEX(Bang_F,MATCH(O8,Bang_Z,1)) -> 4.0443043 | Q8: =F8*P8 -> 0.26935067 | R8: =k_tham*N8 -> 0.18193246 | S8: =G8+D8-E8-Q8-R8 -> 15.009026 | T8: =(G8+MIN(MAX(S8,V_chet),V_bt))/2 -> 18.224667 | U8: =((INDEX(BT_Z,MATCH(T8,BT_V,1)+1)-INDEX(BT_Z,MATCH(T8,BT_V,1)))/(INDEX(BT_V,MATCH(T8,BT_V,1)+1)-INDEX(BT_V,MATCH(T8,BT_V,1))))*(T8-INDEX(BT_V,MATCH(T8,BT_V,1)))+INDEX(BT_Z,MATCH(T8,BT_V,1)) -> 71.164938 | V8: =((INDEX(Bang_F,MATCH(U8,Bang_Z,1)+1)-INDEX(Bang_F,MATCH(U8,Bang_Z,1)))/(INDEX(Bang_Z,MATCH(U8,Bang_Z,1)+1)-INDEX(Bang_Z,MATCH(U8,Bang_Z,1))))*(U8-INDEX(Bang_Z,MATCH(U8,Bang_Z,1)))+INDEX(Bang_F,MATCH(U8,Bang_Z,1)) -> 4.0489629 | W8: =F8*V8 -> 0.26966093 | X8: =k_tham*T8 -> 0.18224667 | Y8: =G8+D8-E8-W8-X8 -> 15.008401 | Z8: =MAX(Y8-V_bt,0) -> 0 | AA8: =MAX(V_chet-Y8,0) -> 0 | AB8: =MIN(MAX(Y8,V_chet),V_bt) -> 15.008401 | AC8: =((INDEX(BT_Z,MATCH(AB8,BT_V,1)+1)-INDEX(BT_Z,MATCH(AB8,BT_V,1)))/(INDEX(BT_V,MATCH(AB8,BT_V,1)+1)-INDEX(BT_V,MATCH(AB8,BT_V,1))))*(AB8-INDEX(BT_V,MATCH(AB8,BT_V,1)))+INDEX(BT_Z,MATCH(AB8,BT_V,1)) -> 70.323822 | AD8: =IF(AA8>0.000001,1,0) -> 0
A9: 5 | B9: =INDEX(Nam_lbl,INT((A9-1)/12)+1) -> 1981-1982 | C9: =MOD(A9-1,12)+1 -> 5 | D9: =INDEX(DongChay,INT((A9-1)/12)+1,C9) -> 6.11 | E9: =INDEX(NhuCau_chon,1,C9) -> 5.92 | F9: =INDEX(BocHoi,1,C9)/1000 -> 0.0623 | G9: =AB8 -> 15.008401 | H9: =G9 -> 15.008401 | I9: =((INDEX(BT_Z,MATCH(H9,BT_V,1)+1)-INDEX(BT_Z,MATCH(H9,BT_V,1)))/(INDEX(BT_V,MATCH(H9,BT_V,1)+1)-INDEX(BT_V,MATCH(H9,BT_V,1))))*(H9-INDEX(BT_V,MATCH(H9,BT_V,1)))+INDEX(BT_Z,MATCH(H9,BT_V,1)) -> 70.323822 | J9: =((INDEX(Bang_F,MATCH(I9,Bang_Z,1)+1)-INDEX(Bang_F,MATCH(I9,Bang_Z,1)))/(INDEX(Bang_Z,MATCH(I9,Bang_Z,1)+1)-INDEX(Bang_Z,MATCH(I9,Bang_Z,1))))*(I9-INDEX(Bang_Z,MATCH(I9,Bang_Z,1)))+INDEX(Bang_F,MATCH(I9,Bang_Z,1)) -> 3.6119112 | K9: =F9*J9 -> 0.22502207 | L9: =k_tham*H9 -> 0.15008401 | M9: =G9+D9-E9-K9-L9 -> 14.823295 | N9: =(G9+MIN(MAX(M9,V_chet),V_bt))/2 -> 14.915848 | O9: =((INDEX(BT_Z,MATCH(N9,BT_V,1)+1)-INDEX(BT_Z,MATCH(N9,BT_V,1)))/(INDEX(BT_V,MATCH(N9,BT_V,1)+1)-INDEX(BT_V,MATCH(N9,BT_V,1))))*(N9-INDEX(BT_V,MATCH(N9,BT_V,1)))+INDEX(BT_Z,MATCH(N9,BT_V,1)) -> 70.298153 | P9: =((INDEX(Bang_F,MATCH(O9,Bang_Z,1)+1)-INDEX(Bang_F,MATCH(O9,Bang_Z,1)))/(INDEX(Bang_Z,MATCH(O9,Bang_Z,1)+1)-INDEX(Bang_Z,MATCH(O9,Bang_Z,1))))*(O9-INDEX(Bang_Z,MATCH(O9,Bang_Z,1)))+INDEX(Bang_F,MATCH(O9,Bang_Z,1)) -> 3.5990765 | Q9: =F9*P9 -> 0.22422247 | R9: =k_tham*N9 -> 0.14915848 | S9: =G9+D9-E9-Q9-R9 -> 14.82502 | T9: =(G9+MIN(MAX(S9,V_chet),V_bt))/2 -> 14.916711 | U9: =((INDEX(BT_Z,MATCH(T9,BT_V,1)+1)-INDEX(BT_Z,MATCH(T9,BT_V,1)))/(INDEX(BT_V,MATCH(T9,BT_V,1)+1)-INDEX(BT_V,MATCH(T9,BT_V,1))))*(T9-INDEX(BT_V,MATCH(T9,BT_V,1)))+INDEX(BT_Z,MATCH(T9,BT_V,1)) -> 70.298393 | V9: =((INDEX(Bang_F,MATCH(U9,Bang_Z,1)+1)-INDEX(Bang_F,MATCH(U9,Bang_Z,1)))/(INDEX(Bang_Z,MATCH(U9,Bang_Z,1)+1)-INDEX(Bang_Z,MATCH(U9,Bang_Z,1))))*(U9-INDEX(Bang_Z,MATCH(U9,Bang_Z,1)))+INDEX(Bang_F,MATCH(U9,Bang_Z,1)) -> 3.5991964 | W9: =F9*V9 -> 0.22422993 | X9: =k_tham*T9 -> 0.14916711 | Y9: =G9+D9-E9-W9-X9 -> 14.825004 | Z9: =MAX(Y9-V_bt,0) -> 0 | AA9: =MAX(V_chet-Y9,0) -> 0 | AB9: =MIN(MAX(Y9,V_chet),V_bt) -> 14.825004 | AC9: =((INDEX(BT_Z,MATCH(AB9,BT_V,1)+1)-INDEX(BT_Z,MATCH(AB9,BT_V,1)))/(INDEX(BT_V,MATCH(AB9,BT_V,1)+1)-INDEX(BT_V,MATCH(AB9,BT_V,1))))*(AB9-INDEX(BT_V,MATCH(AB9,BT_V,1)))+INDEX(BT_Z,MATCH(AB9,BT_V,1)) -> 70.272867 | AD9: =IF(AA9>0.000001,1,0) -> 0
A10: 6 | B10: =INDEX(Nam_lbl,INT((A10-1)/12)+1) -> 1981-1982 | C10: =MOD(A10-1,12)+1 -> 6 | D10: =INDEX(DongChay,INT((A10-1)/12)+1,C10) -> 8.62 | E10: =INDEX(NhuCau_chon,1,C10) -> 8.31 | F10: =INDEX(BocHoi,1,C10)/1000 -> 0.0551 | G10: =AB9 -> 14.825004 | H10: =G10 -> 14.825004 | I10: =((INDEX(BT_Z,MATCH(H10,BT_V,1)+1)-INDEX(BT_Z,MATCH(H10,BT_V,1)))/(INDEX(BT_V,MATCH(H10,BT_V,1)+1)-INDEX(BT_V,MATCH(H10,BT_V,1))))*(H10-INDEX(BT_V,MATCH(H10,BT_V,1)))+INDEX(BT_Z,MATCH(H10,BT_V,1)) -> 70.272867 | J10: =((INDEX(Bang_F,MATCH(I10,Bang_Z,1)+1)-INDEX(Bang_F,MATCH(I10,Bang_Z,1)))/(INDEX(Bang_Z,MATCH(I10,Bang_Z,1)+1)-INDEX(Bang_Z,MATCH(I10,Bang_Z,1))))*(I10-INDEX(Bang_Z,MATCH(I10,Bang_Z,1)))+INDEX(Bang_F,MATCH(I10,Bang_Z,1)) -> 3.5864336 | K10: =F10*J10 -> 0.19761249 | L10: =k_tham*H10 -> 0.14825004 | M10: =G10+D10-E10-K10-L10 -> 14.789141 | N10: =(G10+MIN(MAX(M10,V_chet),V_bt))/2 -> 14.807073 | O10: =((INDEX(BT_Z,MATCH(N10,BT_V,1)+1)-INDEX(BT_Z,MATCH(N10,BT_V,1)))/(INDEX(BT_V,MATCH(N10,BT_V,1)+1)-INDEX(BT_V,MATCH(N10,BT_V,1))))*(N10-INDEX(BT_V,MATCH(N10,BT_V,1)))+INDEX(BT_Z,MATCH(N10,BT_V,1)) -> 70.267866 | P10: =((INDEX(Bang_F,MATCH(O10,Bang_Z,1)+1)-INDEX(Bang_F,MATCH(O10,Bang_Z,1)))/(INDEX(Bang_Z,MATCH(O10,Bang_Z,1)+1)-INDEX(Bang_Z,MATCH(O10,Bang_Z,1))))*(O10-INDEX(Bang_Z,MATCH(O10,Bang_Z,1)))+INDEX(Bang_F,MATCH(O10,Bang_Z,1)) -> 3.583933 | Q10: =F10*P10 -> 0.19747471 | R10: =k_tham*N10 -> 0.14807073 | S10: =G10+D10-E10-Q10-R10 -> 14.789459 | T10: =(G10+MIN(MAX(S10,V_chet),V_bt))/2 -> 14.807231 | U10: =((INDEX(BT_Z,MATCH(T10,BT_V,1)+1)-INDEX(BT_Z,MATCH(T10,BT_V,1)))/(INDEX(BT_V,MATCH(T10,BT_V,1)+1)-INDEX(BT_V,MATCH(T10,BT_V,1))))*(T10-INDEX(BT_V,MATCH(T10,BT_V,1)))+INDEX(BT_Z,MATCH(T10,BT_V,1)) -> 70.26791 | V10: =((INDEX(Bang_F,MATCH(U10,Bang_Z,1)+1)-INDEX(Bang_F,MATCH(U10,Bang_Z,1)))/(INDEX(Bang_Z,MATCH(U10,Bang_Z,1)+1)-INDEX(Bang_Z,MATCH(U10,Bang_Z,1))))*(U10-INDEX(Bang_Z,MATCH(U10,Bang_Z,1)))+INDEX(Bang_F,MATCH(U10,Bang_Z,1)) -> 3.5839552 | W10: =F10*V10 -> 0.19747593 | X10: =k_tham*T10 -> 0.14807231 | Y10: =G10+D10-E10-W10-X10 -> 14.789456 | Z10: =MAX(Y10-V_bt,0) -> 0 | AA10: =MAX(V_chet-Y10,0) -> 0 | AB10: =MIN(MAX(Y10,V_chet),V_bt) -> 14.789456 | AC10: =((INDEX(BT_Z,MATCH(AB10,BT_V,1)+1)-INDEX(BT_Z,MATCH(AB10,BT_V,1)))/(INDEX(BT_V,MATCH(AB10,BT_V,1)+1)-INDEX(BT_V,MATCH(AB10,BT_V,1))))*(AB10-INDEX(BT_V,MATCH(AB10,BT_V,1)))+INDEX(BT_Z,MATCH(AB10,BT_V,1)) -> 70.262949 | AD10: =IF(AA10>0.000001,1,0) -> 0
A11: 7 | B11: =INDEX(Nam_lbl,INT((A11-1)/12)+1) -> 1981-1982 | C11: =MOD(A11-1,12)+1 -> 7 | D11: =INDEX(DongChay,INT((A11-1)/12)+1,C11) -> 7.16 | E11: =INDEX(NhuCau_chon,1,C11) -> 5.59 | F11: =INDEX(BocHoi,1,C11)/1000 -> 0.0498 | G11: =AB10 -> 14.789456 | H11: =G11 -> 14.789456 | I11: =((INDEX(BT_Z,MATCH(H11,BT_V,1)+1)-INDEX(BT_Z,MATCH(H11,BT_V,1)))/(INDEX(BT_V,MATCH(H11,BT_V,1)+1)-INDEX(BT_V,MATCH(H11,BT_V,1))))*(H11-INDEX(BT_V,MATCH(H11,BT_V,1)))+INDEX(BT_Z,MATCH(H11,BT_V,1)) -> 70.262949 | J11: =((INDEX(Bang_F,MATCH(I11,Bang_Z,1)+1)-INDEX(Bang_F,MATCH(I11,Bang_Z,1)))/(INDEX(Bang_Z,MATCH(I11,Bang_Z,1)+1)-INDEX(Bang_Z,MATCH(I11,Bang_Z,1))))*(I11-INDEX(Bang_Z,MATCH(I11,Bang_Z,1)))+INDEX(Bang_F,MATCH(I11,Bang_Z,1)) -> 3.5814743 | K11: =F11*J11 -> 0.17835742 | L11: =k_tham*H11 -> 0.14789456 | M11: =G11+D11-E11-K11-L11 -> 16.033204 | N11: =(G11+MIN(MAX(M11,V_chet),V_bt))/2 -> 15.41133 | O11: =((INDEX(BT_Z,MATCH(N11,BT_V,1)+1)-INDEX(BT_Z,MATCH(N11,BT_V,1)))/(INDEX(BT_V,MATCH(N11,BT_V,1)+1)-INDEX(BT_V,MATCH(N11,BT_V,1))))*(N11-INDEX(BT_V,MATCH(N11,BT_V,1)))+INDEX(BT_Z,MATCH(N11,BT_V,1)) -> 70.43453 | P11: =((INDEX(Bang_F,MATCH(O11,Bang_Z,1)+1)-INDEX(Bang_F,MATCH(O11,Bang_Z,1)))/(INDEX(Bang_Z,MATCH(O11,Bang_Z,1)+1)-INDEX(Bang_Z,MATCH(O11,Bang_Z,1))))*(O11-INDEX(Bang_Z,MATCH(O11,Bang_Z,1)))+INDEX(Bang_F,MATCH(O11,Bang_Z,1)) -> 3.6672648 | Q11: =F11*P11 -> 0.18262979 | R11: =k_tham*N11 -> 0.1541133 | S11: =G11+D11-E11-Q11-R11 -> 16.022713 | T11: =(G11+MIN(MAX(S11,V_chet),V_bt))/2 -> 15.406084 | U11: =((INDEX(BT_Z,MATCH(T11,BT_V,1)+1)-INDEX(BT_Z,MATCH(T11,BT_V,1)))/(INDEX(BT_V,MATCH(T11,BT_V,1)+1)-INDEX(BT_V,MATCH(T11,BT_V,1))))*(T11-INDEX(BT_V,MATCH(T11,BT_V,1)))+INDEX(BT_Z,MATCH(T11,BT_V,1)) -> 70.433099 | V11: =((INDEX(Bang_F,MATCH(U11,Bang_Z,1)+1)-INDEX(Bang_F,MATCH(U11,Bang_Z,1)))/(INDEX(Bang_Z,MATCH(U11,Bang_Z,1)+1)-INDEX(Bang_Z,MATCH(U11,Bang_Z,1))))*(U11-INDEX(Bang_Z,MATCH(U11,Bang_Z,1)))+INDEX(Bang_F,MATCH(U11,Bang_Z,1)) -> 3.6665496 | W11: =F11*V11 -> 0.18259417 | X11: =k_tham*T11 -> 0.15406084 | Y11: =G11+D11-E11-W11-X11 -> 16.022801 | Z11: =MAX(Y11-V_bt,0) -> 0 | AA11: =MAX(V_chet-Y11,0) -> 0 | AB11: =MIN(MAX(Y11,V_chet),V_bt) -> 16.022801 | AC11: =((INDEX(BT_Z,MATCH(AB11,BT_V,1)+1)-INDEX(BT_Z,MATCH(AB11,BT_V,1)))/(INDEX(BT_V,MATCH(AB11,BT_V,1)+1)-INDEX(BT_V,MATCH(AB11,BT_V,1))))*(AB11-INDEX(BT_V,MATCH(AB11,BT_V,1)))+INDEX(BT_Z,MATCH(AB11,BT_V,1)) -> 70.599415 | AD11: =IF(AA11>0.000001,1,0) -> 0
A12: 8 | B12: =INDEX(Nam_lbl,INT((A12-1)/12)+1) -> 1981-1982 | C12: =MOD(A12-1,12)+1 -> 8 | D12: =INDEX(DongChay,INT((A12-1)/12)+1,C12) -> 17.13 | E12: =INDEX(NhuCau_chon,1,C12) -> 8.9 | F12: =INDEX(BocHoi,1,C12)/1000 -> 0.0518 | G12: =AB11 -> 16.022801 | H12: =G12 -> 16.022801 | I12: =((INDEX(BT_Z,MATCH(H12,BT_V,1)+1)-INDEX(BT_Z,MATCH(H12,BT_V,1)))/(INDEX(BT_V,MATCH(H12,BT_V,1)+1)-INDEX(BT_V,MATCH(H12,BT_V,1))))*(H12-INDEX(BT_V,MATCH(H12,BT_V,1)))+INDEX(BT_Z,MATCH(H12,BT_V,1)) -> 70.599415 | J12: =((INDEX(Bang_F,MATCH(I12,Bang_Z,1)+1)-INDEX(Bang_F,MATCH(I12,Bang_Z,1)))/(INDEX(Bang_Z,MATCH(I12,Bang_Z,1)+1)-INDEX(Bang_Z,MATCH(I12,Bang_Z,1))))*(I12-INDEX(Bang_Z,MATCH(I12,Bang_Z,1)))+INDEX(Bang_F,MATCH(I12,Bang_Z,1)) -> 3.7497076 | K12: =F12*J12 -> 0.19423485 | L12: =k_tham*H12 -> 0.16022801 | M12: =G12+D12-E12-K12-L12 -> 23.898338 | N12: =(G12+MIN(MAX(M12,V_chet),V_bt))/2 -> 19.960569 | O12: =((INDEX(BT_Z,MATCH(N12,BT_V,1)+1)-INDEX(BT_Z,MATCH(N12,BT_V,1)))/(INDEX(BT_V,MATCH(N12,BT_V,1)+1)-INDEX(BT_V,MATCH(N12,BT_V,1))))*(N12-INDEX(BT_V,MATCH(N12,BT_V,1)))+INDEX(BT_Z,MATCH(N12,BT_V,1)) -> 71.58085 | P12: =((INDEX(Bang_F,MATCH(O12,Bang_Z,1)+1)-INDEX(Bang_F,MATCH(O12,Bang_Z,1)))/(INDEX(Bang_Z,MATCH(O12,Bang_Z,1)+1)-INDEX(Bang_Z,MATCH(O12,Bang_Z,1))))*(O12-INDEX(Bang_Z,MATCH(O12,Bang_Z,1)))+INDEX(Bang_F,MATCH(O12,Bang_Z,1)) -> 4.2985102 | Q12: =F12*P12 -> 0.22266283 | R12: =k_tham*N12 -> 0.19960569 | S12: =G12+D12-E12-Q12-R12 -> 23.830532 | T12: =(G12+MIN(MAX(S12,V_chet),V_bt))/2 -> 19.926666 | U12: =((INDEX(BT_Z,MATCH(T12,BT_V,1)+1)-INDEX(BT_Z,MATCH(T12,BT_V,1)))/(INDEX(BT_V,MATCH(T12,BT_V,1)+1)-INDEX(BT_V,MATCH(T12,BT_V,1))))*(T12-INDEX(BT_V,MATCH(T12,BT_V,1)))+INDEX(BT_Z,MATCH(T12,BT_V,1)) -> 71.572958 | V12: =((INDEX(Bang_F,MATCH(U12,Bang_Z,1)+1)-INDEX(Bang_F,MATCH(U12,Bang_Z,1)))/(INDEX(Bang_Z,MATCH(U12,Bang_Z,1)+1)-INDEX(Bang_Z,MATCH(U12,Bang_Z,1))))*(U12-INDEX(Bang_Z,MATCH(U12,Bang_Z,1)))+INDEX(Bang_F,MATCH(U12,Bang_Z,1)) -> 4.2937748 | W12: =F12*V12 -> 0.22241753 | X12: =k_tham*T12 -> 0.19926666 | Y12: =G12+D12-E12-W12-X12 -> 23.831117 | Z12: =MAX(Y12-V_bt,0) -> 0 | AA12: =MAX(V_chet-Y12,0) -> 0 | AB12: =MIN(MAX(Y12,V_chet),V_bt) -> 23.831117 | AC12: =((INDEX(BT_Z,MATCH(AB12,BT_V,1)+1)-INDEX(BT_Z,MATCH(AB12,BT_V,1)))/(INDEX(BT_V,MATCH(AB12,BT_V,1)+1)-INDEX(BT_V,MATCH(AB12,BT_V,1))))*(AB12-INDEX(BT_V,MATCH(AB12,BT_V,1)))+INDEX(BT_Z,MATCH(AB12,BT_V,1)) -> 72.429903 | AD12: =IF(AA12>0.000001,1,0) -> 0
A13: 9 | B13: =INDEX(Nam_lbl,INT((A13-1)/12)+1) -> 1981-1982 | C13: =MOD(A13-1,12)+1 -> 9 | D13: =INDEX(DongChay,INT((A13-1)/12)+1,C13) -> 34.08 | E13: =INDEX(NhuCau_chon,1,C13) -> 2.57 | F13: =INDEX(BocHoi,1,C13)/1000 -> 0.0439 | G13: =AB12 -> 23.831117 | H13: =G13 -> 23.831117 | I13: =((INDEX(BT_Z,MATCH(H13,BT_V,1)+1)-INDEX(BT_Z,MATCH(H13,BT_V,1)))/(INDEX(BT_V,MATCH(H13,BT_V,1)+1)-INDEX(BT_V,MATCH(H13,BT_V,1))))*(H13-INDEX(BT_V,MATCH(H13,BT_V,1)))+INDEX(BT_Z,MATCH(H13,BT_V,1)) -> 72.429903 | J13: =((INDEX(Bang_F,MATCH(I13,Bang_Z,1)+1)-INDEX(Bang_F,MATCH(I13,Bang_Z,1)))/(INDEX(Bang_Z,MATCH(I13,Bang_Z,1)+1)-INDEX(Bang_Z,MATCH(I13,Bang_Z,1))))*(I13-INDEX(Bang_Z,MATCH(I13,Bang_Z,1)))+INDEX(Bang_F,MATCH(I13,Bang_Z,1)) -> 4.829437 | K13: =F13*J13 -> 0.21201228 | L13: =k_tham*H13 -> 0.23831117 | M13: =G13+D13-E13-K13-L13 -> 54.890793 | N13: =(G13+MIN(MAX(M13,V_chet),V_bt))/2 -> 30.121404 | O13: =((INDEX(BT_Z,MATCH(N13,BT_V,1)+1)-INDEX(BT_Z,MATCH(N13,BT_V,1)))/(INDEX(BT_V,MATCH(N13,BT_V,1)+1)-INDEX(BT_V,MATCH(N13,BT_V,1))))*(N13-INDEX(BT_V,MATCH(N13,BT_V,1)))+INDEX(BT_Z,MATCH(N13,BT_V,1)) -> 73.636512 | P13: =((INDEX(Bang_F,MATCH(O13,Bang_Z,1)+1)-INDEX(Bang_F,MATCH(O13,Bang_Z,1)))/(INDEX(Bang_Z,MATCH(O13,Bang_Z,1)+1)-INDEX(Bang_Z,MATCH(O13,Bang_Z,1))))*(O13-INDEX(Bang_Z,MATCH(O13,Bang_Z,1)))+INDEX(Bang_F,MATCH(O13,Bang_Z,1)) -> 5.5819071 | Q13: =F13*P13 -> 0.24504572 | R13: =k_tham*N13 -> 0.30121404 | S13: =G13+D13-E13-Q13-R13 -> 54.794857 | T13: =(G13+MIN(MAX(S13,V_chet),V_bt))/2 -> 30.121404 | U13: =((INDEX(BT_Z,MATCH(T13,BT_V,1)+1)-INDEX(BT_Z,MATCH(T13,BT_V,1)))/(INDEX(BT_V,MATCH(T13,BT_V,1)+1)-INDEX(BT_V,MATCH(T13,BT_V,1))))*(T13-INDEX(BT_V,MATCH(T13,BT_V,1)))+INDEX(BT_Z,MATCH(T13,BT_V,1)) -> 73.636512 | V13: =((INDEX(Bang_F,MATCH(U13,Bang_Z,1)+1)-INDEX(Bang_F,MATCH(U13,Bang_Z,1)))/(INDEX(Bang_Z,MATCH(U13,Bang_Z,1)+1)-INDEX(Bang_Z,MATCH(U13,Bang_Z,1))))*(U13-INDEX(Bang_Z,MATCH(U13,Bang_Z,1)))+INDEX(Bang_F,MATCH(U13,Bang_Z,1)) -> 5.5819071 | W13: =F13*V13 -> 0.24504572 | X13: =k_tham*T13 -> 0.30121404 | Y13: =G13+D13-E13-W13-X13 -> 54.794857 | Z13: =MAX(Y13-V_bt,0) -> 18.383166 | AA13: =MAX(V_chet-Y13,0) -> 0 | AB13: =MIN(MAX(Y13,V_chet),V_bt) -> 36.411691 | AC13: =((INDEX(BT_Z,MATCH(AB13,BT_V,1)+1)-INDEX(BT_Z,MATCH(AB13,BT_V,1)))/(INDEX(BT_V,MATCH(AB13,BT_V,1)+1)-INDEX(BT_V,MATCH(AB13,BT_V,1))))*(AB13-INDEX(BT_V,MATCH(AB13,BT_V,1)))+INDEX(BT_Z,MATCH(AB13,BT_V,1)) -> 74.7 | AD13: =IF(AA13>0.000001,1,0) -> 0
A14: 10 | B14: =INDEX(Nam_lbl,INT((A14-1)/12)+1) -> 1981-1982 | C14: =MOD(A14-1,12)+1 -> 10 | D14: =INDEX(DongChay,INT((A14-1)/12)+1,C14) -> 47.49 | E14: =INDEX(NhuCau_chon,1,C14) -> 2.99 | F14: =INDEX(BocHoi,1,C14)/1000 -> 0.0408 | G14: =AB13 -> 36.411691 | H14: =G14 -> 36.411691 | I14: =((INDEX(BT_Z,MATCH(H14,BT_V,1)+1)-INDEX(BT_Z,MATCH(H14,BT_V,1)))/(INDEX(BT_V,MATCH(H14,BT_V,1)+1)-INDEX(BT_V,MATCH(H14,BT_V,1))))*(H14-INDEX(BT_V,MATCH(H14,BT_V,1)))+INDEX(BT_Z,MATCH(H14,BT_V,1)) -> 74.7 | J14: =((INDEX(Bang_F,MATCH(I14,Bang_Z,1)+1)-INDEX(Bang_F,MATCH(I14,Bang_Z,1)))/(INDEX(Bang_Z,MATCH(I14,Bang_Z,1)+1)-INDEX(Bang_Z,MATCH(I14,Bang_Z,1))))*(I14-INDEX(Bang_Z,MATCH(I14,Bang_Z,1)))+INDEX(Bang_F,MATCH(I14,Bang_Z,1)) -> 6.262 | K14: =F14*J14 -> 0.2554896 | L14: =k_tham*H14 -> 0.36411691 | M14: =G14+D14-E14-K14-L14 -> 80.292085 | N14: =(G14+MIN(MAX(M14,V_chet),V_bt))/2 -> 36.411691 | O14: =((INDEX(BT_Z,MATCH(N14,BT_V,1)+1)-INDEX(BT_Z,MATCH(N14,BT_V,1)))/(INDEX(BT_V,MATCH(N14,BT_V,1)+1)-INDEX(BT_V,MATCH(N14,BT_V,1))))*(N14-INDEX(BT_V,MATCH(N14,BT_V,1)))+INDEX(BT_Z,MATCH(N14,BT_V,1)) -> 74.7 | P14: =((INDEX(Bang_F,MATCH(O14,Bang_Z,1)+1)-INDEX(Bang_F,MATCH(O14,Bang_Z,1)))/(INDEX(Bang_Z,MATCH(O14,Bang_Z,1)+1)-INDEX(Bang_Z,MATCH(O14,Bang_Z,1))))*(O14-INDEX(Bang_Z,MATCH(O14,Bang_Z,1)))+INDEX(Bang_F,MATCH(O14,Bang_Z,1)) -> 6.262 | Q14: =F14*P14 -> 0.2554896 | R14: =k_tham*N14 -> 0.36411691 | S14: =G14+D14-E14-Q14-R14 -> 80.292085 | T14: =(G14+MIN(MAX(S14,V_chet),V_bt))/2 -> 36.411691 | U14: =((INDEX(BT_Z,MATCH(T14,BT_V,1)+1)-INDEX(BT_Z,MATCH(T14,BT_V,1)))/(INDEX(BT_V,MATCH(T14,BT_V,1)+1)-INDEX(BT_V,MATCH(T14,BT_V,1))))*(T14-INDEX(BT_V,MATCH(T14,BT_V,1)))+INDEX(BT_Z,MATCH(T14,BT_V,1)) -> 74.7 | V14: =((INDEX(Bang_F,MATCH(U14,Bang_Z,1)+1)-INDEX(Bang_F,MATCH(U14,Bang_Z,1)))/(INDEX(Bang_Z,MATCH(U14,Bang_Z,1)+1)-INDEX(Bang_Z,MATCH(U14,Bang_Z,1))))*(U14-INDEX(Bang_Z,MATCH(U14,Bang_Z,1)))+INDEX(Bang_F,MATCH(U14,Bang_Z,1)) -> 6.262 | W14: =F14*V14 -> 0.2554896 | X14: =k_tham*T14 -> 0.36411691 | Y14: =G14+D14-E14-W14-X14 -> 80.292085 | Z14: =MAX(Y14-V_bt,0) -> 43.880393 | AA14: =MAX(V_chet-Y14,0) -> 0 | AB14: =MIN(MAX(Y14,V_chet),V_bt) -> 36.411691 | AC14: =((INDEX(BT_Z,MATCH(AB14,BT_V,1)+1)-INDEX(BT_Z,MATCH(AB14,BT_V,1)))/(INDEX(BT_V,MATCH(AB14,BT_V,1)+1)-INDEX(BT_V,MATCH(AB14,BT_V,1))))*(AB14-INDEX(BT_V,MATCH(AB14,BT_V,1)))+INDEX(BT_Z,MATCH(AB14,BT_V,1)) -> 74.7 | AD14: =IF(AA14>0.000001,1,0) -> 0
A15: 11 | B15: =INDEX(Nam_lbl,INT((A15-1)/12)+1) -> 1981-1982 | C15: =MOD(A15-1,12)+1 -> 11 | D15: =INDEX(DongChay,INT((A15-1)/12)+1,C15) -> 27.55 | E15: =INDEX(NhuCau_chon,1,C15) -> 9.5 | F15: =INDEX(BocHoi,1,C15)/1000 -> 0.0522 | G15: =AB14 -> 36.411691 | H15: =G15 -> 36.411691 | I15: =((INDEX(BT_Z,MATCH(H15,BT_V,1)+1)-INDEX(BT_Z,MATCH(H15,BT_V,1)))/(INDEX(BT_V,MATCH(H15,BT_V,1)+1)-INDEX(BT_V,MATCH(H15,BT_V,1))))*(H15-INDEX(BT_V,MATCH(H15,BT_V,1)))+INDEX(BT_Z,MATCH(H15,BT_V,1)) -> 74.7 | J15: =((INDEX(Bang_F,MATCH(I15,Bang_Z,1)+1)-INDEX(Bang_F,MATCH(I15,Bang_Z,1)))/(INDEX(Bang_Z,MATCH(I15,Bang_Z,1)+1)-INDEX(Bang_Z,MATCH(I15,Bang_Z,1))))*(I15-INDEX(Bang_Z,MATCH(I15,Bang_Z,1)))+INDEX(Bang_F,MATCH(I15,Bang_Z,1)) -> 6.262 | K15: =F15*J15 -> 0.3268764 | L15: =k_tham*H15 -> 0.36411691 | M15: =G15+D15-E15-K15-L15 -> 53.770698 | N15: =(G15+MIN(MAX(M15,V_chet),V_bt))/2 -> 36.411691 | O15: =((INDEX(BT_Z,MATCH(N15,BT_V,1)+1)-INDEX(BT_Z,MATCH(N15,BT_V,1)))/(INDEX(BT_V,MATCH(N15,BT_V,1)+1)-INDEX(BT_V,MATCH(N15,BT_V,1))))*(N15-INDEX(BT_V,MATCH(N15,BT_V,1)))+INDEX(BT_Z,MATCH(N15,BT_V,1)) -> 74.7 | P15: =((INDEX(Bang_F,MATCH(O15,Bang_Z,1)+1)-INDEX(Bang_F,MATCH(O15,Bang_Z,1)))/(INDEX(Bang_Z,MATCH(O15,Bang_Z,1)+1)-INDEX(Bang_Z,MATCH(O15,Bang_Z,1))))*(O15-INDEX(Bang_Z,MATCH(O15,Bang_Z,1)))+INDEX(Bang_F,MATCH(O15,Bang_Z,1)) -> 6.262 | Q15: =F15*P15 -> 0.3268764 | R15: =k_tham*N15 -> 0.36411691 | S15: =G15+D15-E15-Q15-R15 -> 53.770698 | T15: =(G15+MIN(MAX(S15,V_chet),V_bt))/2 -> 36.411691 | U15: =((INDEX(BT_Z,MATCH(T15,BT_V,1)+1)-INDEX(BT_Z,MATCH(T15,BT_V,1)))/(INDEX(BT_V,MATCH(T15,BT_V,1)+1)-INDEX(BT_V,MATCH(T15,BT_V,1))))*(T15-INDEX(BT_V,MATCH(T15,BT_V,1)))+INDEX(BT_Z,MATCH(T15,BT_V,1)) -> 74.7 | V15: =((INDEX(Bang_F,MATCH(U15,Bang_Z,1)+1)-INDEX(Bang_F,MATCH(U15,Bang_Z,1)))/(INDEX(Bang_Z,MATCH(U15,Bang_Z,1)+1)-INDEX(Bang_Z,MATCH(U15,Bang_Z,1))))*(U15-INDEX(Bang_Z,MATCH(U15,Bang_Z,1)))+INDEX(Bang_F,MATCH(U15,Bang_Z,1)) -> 6.262 | W15: =F15*V15 -> 0.3268764 | X15: =k_tham*T15 -> 0.36411691 | Y15: =G15+D15-E15-W15-X15 -> 53.770698 | Z15: =MAX(Y15-V_bt,0) -> 17.359007 | AA15: =MAX(V_chet-Y15,0) -> 0 | AB15: =MIN(MAX(Y15,V_chet),V_bt) -> 36.411691 | AC15: =((INDEX(BT_Z,MATCH(AB15,BT_V,1)+1)-INDEX(BT_Z,MATCH(AB15,BT_V,1)))/(INDEX(BT_V,MATCH(AB15,BT_V,1)+1)-INDEX(BT_V,MATCH(AB15,BT_V,1))))*(AB15-INDEX(BT_V,MATCH(AB15,BT_V,1)))+INDEX(BT_Z,MATCH(AB15,BT_V,1)) -> 74.7 | AD15: =IF(AA15>0.000001,1,0) -> 0
A16: 12 | B16: =INDEX(Nam_lbl,INT((A16-1)/12)+1) -> 1981-1982 | C16: =MOD(A16-1,12)+1 -> 12 | D16: =INDEX(DongChay,INT((A16-1)/12)+1,C16) -> 13.98 | E16: =INDEX(NhuCau_chon,1,C16) -> 15.54 | F16: =INDEX(BocHoi,1,C16)/1000 -> 0.0667 | G16: =AB15 -> 36.411691 | H16: =G16 -> 36.411691 | I16: =((INDEX(BT_Z,MATCH(H16,BT_V,1)+1)-INDEX(BT_Z,MATCH(H16,BT_V,1)))/(INDEX(BT_V,MATCH(H16,BT_V,1)+1)-INDEX(BT_V,MATCH(H16,BT_V,1))))*(H16-INDEX(BT_V,MATCH(H16,BT_V,1)))+INDEX(BT_Z,MATCH(H16,BT_V,1)) -> 74.7 | J16: =((INDEX(Bang_F,MATCH(I16,Bang_Z,1)+1)-INDEX(Bang_F,MATCH(I16,Bang_Z,1)))/(INDEX(Bang_Z,MATCH(I16,Bang_Z,1)+1)-INDEX(Bang_Z,MATCH(I16,Bang_Z,1))))*(I16-INDEX(Bang_Z,MATCH(I16,Bang_Z,1)))+INDEX(Bang_F,MATCH(I16,Bang_Z,1)) -> 6.262 | K16: =F16*J16 -> 0.4176754 | L16: =k_tham*H16 -> 0.36411691 | M16: =G16+D16-E16-K16-L16 -> 34.069899 | N16: =(G16+MIN(MAX(M16,V_chet),V_bt))/2 -> 35.240795 | O16: =((INDEX(BT_Z,MATCH(N16,BT_V,1)+1)-INDEX(BT_Z,MATCH(N16,BT_V,1)))/(INDEX(BT_V,MATCH(N16,BT_V,1)+1)-INDEX(BT_V,MATCH(N16,BT_V,1))))*(N16-INDEX(BT_V,MATCH(N16,BT_V,1)))+INDEX(BT_Z,MATCH(N16,BT_V,1)) -> 74.511135 | P16: =((INDEX(Bang_F,MATCH(O16,Bang_Z,1)+1)-INDEX(Bang_F,MATCH(O16,Bang_Z,1)))/(INDEX(Bang_Z,MATCH(O16,Bang_Z,1)+1)-INDEX(Bang_Z,MATCH(O16,Bang_Z,1))))*(O16-INDEX(Bang_Z,MATCH(O16,Bang_Z,1)))+INDEX(Bang_F,MATCH(O16,Bang_Z,1)) -> 6.1373493 | Q16: =F16*P16 -> 0.4093612 | R16: =k_tham*N16 -> 0.35240795 | S16: =G16+D16-E16-Q16-R16 -> 34.089922 | T16: =(G16+MIN(MAX(S16,V_chet),V_bt))/2 -> 35.250807 | U16: =((INDEX(BT_Z,MATCH(T16,BT_V,1)+1)-INDEX(BT_Z,MATCH(T16,BT_V,1)))/(INDEX(BT_V,MATCH(T16,BT_V,1)+1)-INDEX(BT_V,MATCH(T16,BT_V,1))))*(T16-INDEX(BT_V,MATCH(T16,BT_V,1)))+INDEX(BT_Z,MATCH(T16,BT_V,1)) -> 74.512766 | V16: =((INDEX(Bang_F,MATCH(U16,Bang_Z,1)+1)-INDEX(Bang_F,MATCH(U16,Bang_Z,1)))/(INDEX(Bang_Z,MATCH(U16,Bang_Z,1)+1)-INDEX(Bang_Z,MATCH(U16,Bang_Z,1))))*(U16-INDEX(Bang_Z,MATCH(U16,Bang_Z,1)))+INDEX(Bang_F,MATCH(U16,Bang_Z,1)) -> 6.1384255 | W16: =F16*V16 -> 0.40943298 | X16: =k_tham*T16 -> 0.35250807 | Y16: =G16+D16-E16-W16-X16 -> 34.08975 | Z16: =MAX(Y16-V_bt,0) -> 0 | AA16: =MAX(V_chet-Y16,0) -> 0 | AB16: =MIN(MAX(Y16,V_chet),V_bt) -> 34.08975 | AC16: =((INDEX(BT_Z,MATCH(AB16,BT_V,1)+1)-INDEX(BT_Z,MATCH(AB16,BT_V,1)))/(INDEX(BT_V,MATCH(AB16,BT_V,1)+1)-INDEX(BT_V,MATCH(AB16,BT_V,1))))*(AB16-INDEX(BT_V,MATCH(AB16,BT_V,1)))+INDEX(BT_Z,MATCH(AB16,BT_V,1)) -> 74.321657 | AD16: =IF(AA16>0.000001,1,0) -> 0
A17: 13 | B17: =INDEX(Nam_lbl,INT((A17-1)/12)+1) -> 1982-1983 | C17: =MOD(A17-1,12)+1 -> 1 | D17: =INDEX(DongChay,INT((A17-1)/12)+1,C17) -> 9.24 | E17: =INDEX(NhuCau_chon,1,C17) -> 13.27 | F17: =INDEX(BocHoi,1,C17)/1000 -> 0.0684 | G17: =AB16 -> 34.08975 | H17: =G17 -> 34.08975 | I17: =((INDEX(BT_Z,MATCH(H17,BT_V,1)+1)-INDEX(BT_Z,MATCH(H17,BT_V,1)))/(INDEX(BT_V,MATCH(H17,BT_V,1)+1)-INDEX(BT_V,MATCH(H17,BT_V,1))))*(H17-INDEX(BT_V,MATCH(H17,BT_V,1)))+INDEX(BT_Z,MATCH(H17,BT_V,1)) -> 74.321657 | J17: =((INDEX(Bang_F,MATCH(I17,Bang_Z,1)+1)-INDEX(Bang_F,MATCH(I17,Bang_Z,1)))/(INDEX(Bang_Z,MATCH(I17,Bang_Z,1)+1)-INDEX(Bang_Z,MATCH(I17,Bang_Z,1))))*(I17-INDEX(Bang_Z,MATCH(I17,Bang_Z,1)))+INDEX(Bang_F,MATCH(I17,Bang_Z,1)) -> 6.0122937 | K17: =F17*J17 -> 0.41124089 | L17: =k_tham*H17 -> 0.3408975 | M17: =G17+D17-E17-K17-L17 -> 29.307612 | N17: =(G17+MIN(MAX(M17,V_chet),V_bt))/2 -> 31.698681 | O17: =((INDEX(BT_Z,MATCH(N17,BT_V,1)+1)-INDEX(BT_Z,MATCH(N17,BT_V,1)))/(INDEX(BT_V,MATCH(N17,BT_V,1)+1)-INDEX(BT_V,MATCH(N17,BT_V,1))))*(N17-INDEX(BT_V,MATCH(N17,BT_V,1)))+INDEX(BT_Z,MATCH(N17,BT_V,1)) -> 73.914916 | P17: =((INDEX(Bang_F,MATCH(O17,Bang_Z,1)+1)-INDEX(Bang_F,MATCH(O17,Bang_Z,1)))/(INDEX(Bang_Z,MATCH(O17,Bang_Z,1)+1)-INDEX(Bang_Z,MATCH(O17,Bang_Z,1))))*(O17-INDEX(Bang_Z,MATCH(O17,Bang_Z,1)))+INDEX(Bang_F,MATCH(O17,Bang_Z,1)) -> 5.7489493 | Q17: =F17*P17 -> 0.39322813 | R17: =k_tham*N17 -> 0.31698681 | S17: =G17+D17-E17-Q17-R17 -> 29.349535 | T17: =(G17+MIN(MAX(S17,V_chet),V_bt))/2 -> 31.719643 | U17: =((INDEX(BT_Z,MATCH(T17,BT_V,1)+1)-INDEX(BT_Z,MATCH(T17,BT_V,1)))/(INDEX(BT_V,MATCH(T17,BT_V,1)+1)-INDEX(BT_V,MATCH(T17,BT_V,1))))*(T17-INDEX(BT_V,MATCH(T17,BT_V,1)))+INDEX(BT_Z,MATCH(T17,BT_V,1)) -> 73.918562 | V17: =((INDEX(Bang_F,MATCH(U17,Bang_Z,1)+1)-INDEX(Bang_F,MATCH(U17,Bang_Z,1)))/(INDEX(Bang_Z,MATCH(U17,Bang_Z,1)+1)-INDEX(Bang_Z,MATCH(U17,Bang_Z,1))))*(U17-INDEX(Bang_Z,MATCH(U17,Bang_Z,1)))+INDEX(Bang_F,MATCH(U17,Bang_Z,1)) -> 5.751137 | W17: =F17*V17 -> 0.39337777 | X17: =k_tham*T17 -> 0.31719643 | Y17: =G17+D17-E17-W17-X17 -> 29.349176 | Z17: =MAX(Y17-V_bt,0) -> 0 | AA17: =MAX(V_chet-Y17,0) -> 0 | AB17: =MIN(MAX(Y17,V_chet),V_bt) -> 29.349176 | AC17: =((INDEX(BT_Z,MATCH(AB17,BT_V,1)+1)-INDEX(BT_Z,MATCH(AB17,BT_V,1)))/(INDEX(BT_V,MATCH(AB17,BT_V,1)+1)-INDEX(BT_V,MATCH(AB17,BT_V,1))))*(AB17-INDEX(BT_V,MATCH(AB17,BT_V,1)))+INDEX(BT_Z,MATCH(AB17,BT_V,1)) -> 73.497123 | AD17: =IF(AA17>0.000001,1,0) -> 0
... A532: 528 | B532: =INDEX(Nam_lbl,INT((A532-1)/12)+1) -> 2024-2025 | C532: =MOD(A532-1,12)+1 -> 12 | D532: =INDEX(DongChay,INT((A532-1)/12)+1,C532) -> 19.05 | E532: =INDEX(NhuCau_chon,1,C532) -> 15.54 | F532: =INDEX(BocHoi,1,C532)/1000 -> 0.0667 | G532: =AB531 -> 36.411691 | H532: =G532 -> 36.411691 | I532: =((INDEX(BT_Z,MATCH(H532,BT_V,1)+1)-INDEX(BT_Z,MATCH(H532,BT_V,1)))/(INDEX(BT_V,MATCH(H532,BT_V,1)+1)-INDEX(BT_V,MATCH(H532,BT_V,1))))*(H532-INDEX(BT_V,MATCH(H532,BT_V,1)))+INDEX(BT_Z,MATCH(H532,BT_V,1)) -> 74.7 | J532: =((INDEX(Bang_F,MATCH(I532,Bang_Z,1)+1)-INDEX(Bang_F,MATCH(I532,Bang_Z,1)))/(INDEX(Bang_Z,MATCH(I532,Bang_Z,1)+1)-INDEX(Bang_Z,MATCH(I532,Bang_Z,1))))*(I532-INDEX(Bang_Z,MATCH(I532,Bang_Z,1)))+INDEX(Bang_F,MATCH(I532,Bang_Z,1)) -> 6.262 | K532: =F532*J532 -> 0.4176754 | L532: =k_tham*H532 -> 0.36411691 | M532: =G532+D532-E532-K532-L532 -> 39.139899 | N532: =(G532+MIN(MAX(M532,V_chet),V_bt))/2 -> 36.411691 | O532: =((INDEX(BT_Z,MATCH(N532,BT_V,1)+1)-INDEX(BT_Z,MATCH(N532,BT_V,1)))/(INDEX(BT_V,MATCH(N532,BT_V,1)+1)-INDEX(BT_V,MATCH(N532,BT_V,1))))*(N532-INDEX(BT_V,MATCH(N532,BT_V,1)))+INDEX(BT_Z,MATCH(N532,BT_V,1)) -> 74.7 | P532: =((INDEX(Bang_F,MATCH(O532,Bang_Z,1)+1)-INDEX(Bang_F,MATCH(O532,Bang_Z,1)))/(INDEX(Bang_Z,MATCH(O532,Bang_Z,1)+1)-INDEX(Bang_Z,MATCH(O532,Bang_Z,1))))*(O532-INDEX(Bang_Z,MATCH(O532,Bang_Z,1)))+INDEX(Bang_F,MATCH(O532,Bang_Z,1)) -> 6.262 | Q532: =F532*P532 -> 0.4176754 | R532: =k_tham*N532 -> 0.36411691 | S532: =G532+D532-E532-Q532-R532 -> 39.139899 | T532: =(G532+MIN(MAX(S532,V_chet),V_bt))/2 -> 36.411691 | U532: =((INDEX(BT_Z,MATCH(T532,BT_V,1)+1)-INDEX(BT_Z,MATCH(T532,BT_V,1)))/(INDEX(BT_V,MATCH(T532,BT_V,1)+1)-INDEX(BT_V,MATCH(T532,BT_V,1))))*(T532-INDEX(BT_V,MATCH(T532,BT_V,1)))+INDEX(BT_Z,MATCH(T532,BT_V,1)) -> 74.7 | V532: =((INDEX(Bang_F,MATCH(U532,Bang_Z,1)+1)-INDEX(Bang_F,MATCH(U532,Bang_Z,1)))/(INDEX(Bang_Z,MATCH(U532,Bang_Z,1)+1)-INDEX(Bang_Z,MATCH(U532,Bang_Z,1))))*(U532-INDEX(Bang_Z,MATCH(U532,Bang_Z,1)))+INDEX(Bang_F,MATCH(U532,Bang_Z,1)) -> 6.262 | W532: =F532*V532 -> 0.4176754 | X532: =k_tham*T532 -> 0.36411691 | Y532: =G532+D532-E532-W532-X532 -> 39.139899 | Z532: =MAX(Y532-V_bt,0) -> 2.7282077 | AA532: =MAX(V_chet-Y532,0) -> 0 | AB532: =MIN(MAX(Y532,V_chet),V_bt) -> 36.411691 | AC532: =((INDEX(BT_Z,MATCH(AB532,BT_V,1)+1)-INDEX(BT_Z,MATCH(AB532,BT_V,1)))/(INDEX(BT_V,MATCH(AB532,BT_V,1)+1)-INDEX(BT_V,MATCH(AB532,BT_V,1))))*(AB532-INDEX(BT_V,MATCH(AB532,BT_V,1)))+INDEX(BT_Z,MATCH(AB532,BT_V,1)) -> 74.7 | AD532: =IF(AA532>0.000001,1,0) -> 0

Sheet KetQua
A1: KẾT QUẢ ĐIỀU TIẾT THEO NĂM VÀ MỨC BẢO ĐẢM CẤP NƯỚC
B3: =TH_chon -> TH1A | C3: Trường hợp dùng nước
B4: =n_nam -> 44 | C4: Số năm tính toán n
B5: =SUM(M19:M62) -> 39 | C5: Số năm đủ nước m (năm không có tháng thiếu)
B6: =B4-B5 -> 5 | C6: Số năm thiếu nước n − m
B7: =B5/(B4+1) -> 0.86666667 | C7: Mức bảo đảm P = m/(n + 1) – TCVN 10778:2024 công thức (14)
B8: =(B4+1)*P_tk -> 38.25 | C8: Điều kiện đạt (công thức (9)): m ≥ (n + 1)·P_tk =
B9: =ROUNDUP(B8,0) -> 39 | C9: → cần ít nhất (năm đủ nước)
B10: =IF(B5>=B8,"ĐẠT","KHÔNG ĐẠT") -> ĐẠT | C10: KẾT LUẬN
B11: =B5/B4 -> 0.88636364 | C11: Tham khảo: P = m/n (cách QTVH tính)
B12: =SUM(I19:I62) -> 6 | C12: Số tháng thiếu nước / tổng lượng thiếu (10⁶ m³) | M12: =SUM(H19:H62) -> 6.8434054
B13: =COUNTIF(N19:N62,0) -> 0 | C13: Số năm hồ KHÔNG tích đầy MNDBT (> 0 thì năm sau bắt đầu với dung tích thấp – ảnh hưởng chuyển tiếp)
B14: =(DieuTiet!AB532-DieuTiet!G5)-(SUM(C19:C62)-SUM(D19:D62)-SUM(E19:E62)-SUM(F19:F62)-SUM(G19:G62)+SUM(H19:H62)) -> 1.5560886e-12 | C14: Kiểm tra cân bằng nước toàn chuỗi: ΔV − (ΣW đến − ΣW dùng − ΣW bh − ΣW thấm − ΣW xả + ΣW thiếu) =
A15: Kiểm chứng: chương trình Python của đồ án (kt_dong_chay_toi_thieu.py, k_t = 1%) cho TH1A 39/44 năm (86,7%), TH2 37/44 (82,2%), TH1 18/44 (40,0%).
A17: Đơn vị dung tích: 10⁶ m³. Mỗi dòng cộng 12 tháng tương ứng của sheet DieuTiet.
A18: Năm thứ | B18: Năm | C18: W đến | D18: W dùng | E18: W bốc hơi | F18: W thấm | G18: W xả thừa | H18: W thiếu | I18: Số tháng thiếu | J18: V đầu năm (tháng 1) | K18: V cuối năm (tháng 12) | L18: Z thấp nhất trong năm (m) | M18: Đủ nước? (1 = đủ) | N18: Hồ tích đầy trong năm? (1 = có)
A19: 1 | B19: =INDEX(Nam_lbl,A19) -> 1981-1982 | C19: =SUM(OFFSET(DieuTiet!$D$5,(A19-1)*12,0,12,1)) -> 190.52 | D19: =SUM(OFFSET(DieuTiet!$E$5,(A19-1)*12,0,12,1)) -> 106.64 | E19: =SUM(OFFSET(DieuTiet!$W$5,(A19-1)*12,0,12,1)) -> 3.4797554 | F19: =SUM(OFFSET(DieuTiet!$X$5,(A19-1)*12,0,12,1)) -> 3.0996199 | G19: =SUM(OFFSET(DieuTiet!$Z$5,(A19-1)*12,0,12,1)) -> 79.622566 | H19: =SUM(OFFSET(DieuTiet!$AA$5,(A19-1)*12,0,12,1)) -> 0 | I19: =SUM(OFFSET(DieuTiet!$AD$5,(A19-1)*12,0,12,1)) -> 0 | J19: =INDEX(DieuTiet!$G$5:$G$532,(A19-1)*12+1) -> 36.411691 | K19: =INDEX(DieuTiet!$AB$5:$AB$532,A19*12) -> 34.08975 | L19: =MIN(OFFSET(DieuTiet!$AC$5,(A19-1)*12,0,12,1)) -> 70.262949 | M19: =IF(I19=0,1,0) -> 1 | N19: =IF(MAX(OFFSET(DieuTiet!$AB$5,(A19-1)*12,0,12,1))>=V_bt-0.000001,1,0) -> 1
A20: 2 | B20: =INDEX(Nam_lbl,A20) -> 1982-1983 | C20: =SUM(OFFSET(DieuTiet!$D$5,(A20-1)*12,0,12,1)) -> 219.11 | D20: =SUM(OFFSET(DieuTiet!$E$5,(A20-1)*12,0,12,1)) -> 106.64 | E20: =SUM(OFFSET(DieuTiet!$W$5,(A20-1)*12,0,12,1)) -> 3.8029642 | F20: =SUM(OFFSET(DieuTiet!$X$5,(A20-1)*12,0,12,1)) -> 3.6197281 | G20: =SUM(OFFSET(DieuTiet!$Z$5,(A20-1)*12,0,12,1)) -> 106.31639 | H20: =SUM(OFFSET(DieuTiet!$AA$5,(A20-1)*12,0,12,1)) -> 0 | I20: =SUM(OFFSET(DieuTiet!$AD$5,(A20-1)*12,0,12,1)) -> 0 | J20: =INDEX(DieuTiet!$G$5:$G$532,(A20-1)*12+1) -> 34.08975 | K20: =INDEX(DieuTiet!$AB$5:$AB$532,A20*12) -> 32.820671 | L20: =MIN(OFFSET(DieuTiet!$AC$5,(A20-1)*12,0,12,1)) -> 70.933593 | M20: =IF(I20=0,1,0) -> 1 | N20: =IF(MAX(OFFSET(DieuTiet!$AB$5,(A20-1)*12,0,12,1))>=V_bt-0.000001,1,0) -> 1
A21: 3 | B21: =INDEX(Nam_lbl,A21) -> 1983-1984 | C21: =SUM(OFFSET(DieuTiet!$D$5,(A21-1)*12,0,12,1)) -> 265.44 | D21: =SUM(OFFSET(DieuTiet!$E$5,(A21-1)*12,0,12,1)) -> 106.64 | E21: =SUM(OFFSET(DieuTiet!$W$5,(A21-1)*12,0,12,1)) -> 3.64514 | F21: =SUM(OFFSET(DieuTiet!$X$5,(A21-1)*12,0,12,1)) -> 3.454076 | G21: =SUM(OFFSET(DieuTiet!$Z$5,(A21-1)*12,0,12,1)) -> 150.32264 | H21: =SUM(OFFSET(DieuTiet!$AA$5,(A21-1)*12,0,12,1)) -> 0 | I21: =SUM(OFFSET(DieuTiet!$AD$5,(A21-1)*12,0,12,1)) -> 0 | J21: =INDEX(DieuTiet!$G$5:$G$532,(A21-1)*12+1) -> 32.820671 | K21: =INDEX(DieuTiet!$AB$5:$AB$532,A21*12) -> 34.198814 | L21: =MIN(OFFSET(DieuTiet!$AC$5,(A21-1)*12,0,12,1)) -> 68.273224 | M21: =IF(I21=0,1,0) -> 1 | N21: =IF(MAX(OFFSET(DieuTiet!$AB$5,(A21-1)*12,0,12,1))>=V_bt-0.000001,1,0) -> 1
A22: 4 | B22: =INDEX(Nam_lbl,A22) -> 1984-1985 | C22: =SUM(OFFSET(DieuTiet!$D$5,(A22-1)*12,0,12,1)) -> 182.96 | D22: =SUM(OFFSET(DieuTiet!$E$5,(A22-1)*12,0,12,1)) -> 106.64 | E22: =SUM(OFFSET(DieuTiet!$W$5,(A22-1)*12,0,12,1)) -> 3.5255939 | F22: =SUM(OFFSET(DieuTiet!$X$5,(A22-1)*12,0,12,1)) -> 3.2256183 | G22: =SUM(OFFSET(DieuTiet!$Z$5,(A22-1)*12,0,12,1)) -> 72.325013 | H22: =SUM(OFFSET(DieuTiet!$AA$5,(A22-1)*12,0,12,1)) -> 0 | I22: =SUM(OFFSET(DieuTiet!$AD$5,(A22-1)*12,0,12,1)) -> 0 | J22: =INDEX(DieuTiet!$G$5:$G$532,(A22-1)*12+1) -> 34.198814 | K22: =INDEX(DieuTiet!$AB$5:$AB$532,A22*12) -> 31.442589 | L22: =MIN(OFFSET(DieuTiet!$AC$5,(A22-1)*12,0,12,1)) -> 69.280573 | M22: =IF(I22=0,1,0) -> 1 | N22: =IF(MAX(OFFSET(DieuTiet!$AB$5,(A22-1)*12,0,12,1))>=V_bt-0.000001,1,0) -> 1
A23: 5 | B23: =INDEX(Nam_lbl,A23) -> 1985-1986 | C23: =SUM(OFFSET(DieuTiet!$D$5,(A23-1)*12,0,12,1)) -> 150.72 | D23: =SUM(OFFSET(DieuTiet!$E$5,(A23-1)*12,0,12,1)) -> 106.64 | E23: =SUM(OFFSET(DieuTiet!$W$5,(A23-1)*12,0,12,1)) -> 3.5443074 | F23: =SUM(OFFSET(DieuTiet!$X$5,(A23-1)*12,0,12,1)) -> 3.2405648 | G23: =SUM(OFFSET(DieuTiet!$Z$5,(A23-1)*12,0,12,1)) -> 37.245558 | H23: =SUM(OFFSET(DieuTiet!$AA$5,(A23-1)*12,0,12,1)) -> 0 | I23: =SUM(OFFSET(DieuTiet!$AD$5,(A23-1)*12,0,12,1)) -> 0 | J23: =INDEX(DieuTiet!$G$5:$G$532,(A23-1)*12+1) -> 31.442589 | K23: =INDEX(DieuTiet!$AB$5:$AB$532,A23*12) -> 31.492159 | L23: =MIN(OFFSET(DieuTiet!$AC$5,(A23-1)*12,0,12,1)) -> 69.822516 | M23: =IF(I23=0,1,0) -> 1 | N23: =IF(MAX(OFFSET(DieuTiet!$AB$5,(A23-1)*12,0,12,1))>=V_bt-0.000001,1,0) -> 1
A24: 6 | B24: =INDEX(Nam_lbl,A24) -> 1986-1987 | C24: =SUM(OFFSET(DieuTiet!$D$5,(A24-1)*12,0,12,1)) -> 181.58 | D24: =SUM(OFFSET(DieuTiet!$E$5,(A24-1)*12,0,12,1)) -> 106.64 | E24: =SUM(OFFSET(DieuTiet!$W$5,(A24-1)*12,0,12,1)) -> 2.9793203 | F24: =SUM(OFFSET(DieuTiet!$X$5,(A24-1)*12,0,12,1)) -> 2.5461089 | G24: =SUM(OFFSET(DieuTiet!$Z$5,(A24-1)*12,0,12,1)) -> 67.746619 | H24: =SUM(OFFSET(DieuTiet!$AA$5,(A24-1)*12,0,12,1)) -> 1.891397 | I24: =SUM(OFFSET(DieuTiet!$AD$5,(A24-1)*12,0,12,1)) -> 2 | J24: =INDEX(DieuTiet!$G$5:$G$532,(A24-1)*12+1) -> 31.492159 | K24: =INDEX(DieuTiet!$AB$5:$AB$532,A24*12) -> 35.051508 | L24: =MIN(OFFSET(DieuTiet!$AC$5,(A24-1)*12,0,12,1)) -> 67.5 | M24: =IF(I24=0,1,0) -> 0 | N24: =IF(MAX(OFFSET(DieuTiet!$AB$5,(A24-1)*12,0,12,1))>=V_bt-0.000001,1,0) -> 1
A25: 7 | B25: =INDEX(Nam_lbl,A25) -> 1987-1988 | C25: =SUM(OFFSET(DieuTiet!$D$5,(A25-1)*12,0,12,1)) -> 210.42 | D25: =SUM(OFFSET(DieuTiet!$E$5,(A25-1)*12,0,12,1)) -> 106.64 | E25: =SUM(OFFSET(DieuTiet!$W$5,(A25-1)*12,0,12,1)) -> 3.4810751 | F25: =SUM(OFFSET(DieuTiet!$X$5,(A25-1)*12,0,12,1)) -> 3.1391645 | G25: =SUM(OFFSET(DieuTiet!$Z$5,(A25-1)*12,0,12,1)) -> 97.348148 | H25: =SUM(OFFSET(DieuTiet!$AA$5,(A25-1)*12,0,12,1)) -> 0 | I25: =SUM(OFFSET(DieuTiet!$AD$5,(A25-1)*12,0,12,1)) -> 0 | J25: =INDEX(DieuTiet!$G$5:$G$532,(A25-1)*12+1) -> 35.051508 | K25: =INDEX(DieuTiet!$AB$5:$AB$532,A25*12) -> 34.86312 | L25: =MIN(OFFSET(DieuTiet!$AC$5,(A25-1)*12,0,12,1)) -> 69.76499 | M25: =IF(I25=0,1,0) -> 1 | N25: =IF(MAX(OFFSET(DieuTiet!$AB$5,(A25-1)*12,0,12,1))>=V_bt-0.000001,1,0) -> 1
A26: 8 | B26: =INDEX(Nam_lbl,A26) -> 1988-1989 | C26: =SUM(OFFSET(DieuTiet!$D$5,(A26-1)*12,0,12,1)) -> 176.53 | D26: =SUM(OFFSET(DieuTiet!$E$5,(A26-1)*12,0,12,1)) -> 106.64 | E26: =SUM(OFFSET(DieuTiet!$W$5,(A26-1)*12,0,12,1)) -> 3.3758595 | F26: =SUM(OFFSET(DieuTiet!$X$5,(A26-1)*12,0,12,1)) -> 2.9695581 | G26: =SUM(OFFSET(DieuTiet!$Z$5,(A26-1)*12,0,12,1)) -> 66.78666 | H26: =SUM(OFFSET(DieuTiet!$AA$5,(A26-1)*12,0,12,1)) -> 0 | I26: =SUM(OFFSET(DieuTiet!$AD$5,(A26-1)*12,0,12,1)) -> 0 | J26: =INDEX(DieuTiet!$G$5:$G$532,(A26-1)*12+1) -> 34.86312 | K26: =INDEX(DieuTiet!$AB$5:$AB$532,A26*12) -> 31.621042 | L26: =MIN(OFFSET(DieuTiet!$AC$5,(A26-1)*12,0,12,1)) -> 69.630858 | M26: =IF(I26=0,1,0) -> 1 | N26: =IF(MAX(OFFSET(DieuTiet!$AB$5,(A26-1)*12,0,12,1))>=V_bt-0.000001,1,0) -> 1
A27: 9 | B27: =INDEX(Nam_lbl,A27) -> 1989-1990 | C27: =SUM(OFFSET(DieuTiet!$D$5,(A27-1)*12,0,12,1)) -> 211.85 | D27: =SUM(OFFSET(DieuTiet!$E$5,(A27-1)*12,0,12,1)) -> 106.64 | E27: =SUM(OFFSET(DieuTiet!$W$5,(A27-1)*12,0,12,1)) -> 3.4472109 | F27: =SUM(OFFSET(DieuTiet!$X$5,(A27-1)*12,0,12,1)) -> 3.1777816 | G27: =SUM(OFFSET(DieuTiet!$Z$5,(A27-1)*12,0,12,1)) -> 97.117686 | H27: =SUM(OFFSET(DieuTiet!$AA$5,(A27-1)*12,0,12,1)) -> 0 | I27: =SUM(OFFSET(DieuTiet!$AD$5,(A27-1)*12,0,12,1)) -> 0 | J27: =INDEX(DieuTiet!$G$5:$G$532,(A27-1)*12+1) -> 31.621042 | K27: =INDEX(DieuTiet!$AB$5:$AB$532,A27*12) -> 33.088363 | L27: =MIN(OFFSET(DieuTiet!$AC$5,(A27-1)*12,0,12,1)) -> 68.401024 | M27: =IF(I27=0,1,0) -> 1 | N27: =IF(MAX(OFFSET(DieuTiet!$AB$5,(A27-1)*12,0,12,1))>=V_bt-0.000001,1,0) -> 1
